Workbook
Name AREA_CATEGORY: INDEX!$F$514:$G$515
Name EQUIPMENT_SLOT: INDEX!$B$410:$C$414
Name EQUIPMENT_TIER: INDEX!$F$410:$G$417
Name GAIN_TYPE: INDEX!$B$514:$C$536
Name ID규칙_고유무기_아이디_단위: INDEX!$L$6
Name ID규칙_기본능력치그룹_단위: [1]INDEX!$L$39
Name ID규칙_기본능력치그룹_단위: INDEX!$L$39
Name ID규칙_대사_그룹_단위: [1]INDEX!$L$231
Name ID규칙_대사_그룹_단위: INDEX!$L$231
Name ID규칙_대상_장비_아이디_단위: INDEX!$L$471
Name ID규칙_등급_단위: [1]INDEX!$L$159
Name ID규칙_등급_단위: INDEX!$L$159
Name ID규칙_사용학생_아이디_단위: [1]INDEX!$L$5
Name ID규칙_사용학생_아이디_단위: INDEX!$L$5
Name ID규칙_스테이지_난이도_단위: INDEX!$L$544
Name ID규칙_스테이지_아이디_단위: INDEX!$L$543
Name ID규칙_스테이지_챕터_단위: INDEX!$L$545
Name ID규칙_슬롯_단위: INDEX!$L$393
Name ID규칙_아이템_구분_단위: [1]INDEX!$L$562
Name ID규칙_아이템_구분_단위: INDEX!$L$562
Name ID규칙_아이템_타입_단위: [1]INDEX!$L$563
Name ID규칙_아이템_타입_단위: INDEX!$L$563
Name ID규칙_애용품_강화_스킬_그룹_단위: [1]INDEX!$L$340
Name ID규칙_애용품_강화_스킬_그룹_단위: INDEX!$L$340
Name ID규칙_애용품_그룹_단위: [1]INDEX!$L$283
Name ID규칙_애용품_그룹_단위: INDEX!$L$283
Name ID규칙_애용품_아이디_단위: [1]INDEX!$L$282
Name ID규칙_애용품_아이디_단위: INDEX!$L$282
Name ID규칙_애용품_티어_단위: [1]INDEX!$L$283
Name ID규칙_애용품_티어_단위: INDEX!$L$283
Name ID규칙_장비_아이디_단위: INDEX!$L$392
Name ID규칙_장비성장_그룹_단위: INDEX!$L$424
Name ID규칙_장비성장_티어_단위: INDEX!$L$425
Name ID규칙_티어_단위: INDEX!$L$394
Name ID규칙_학생_등급_단위: [1]INDEX!$L$183
Name ID규칙_학생_등급_단위: INDEX!$L$183
Name ID규칙_학생_상세_역할_단위: [1]INDEX!$L$182
Name ID규칙_학생_상세_역할_단위: INDEX!$L$182
Name ID규칙_학생_역할_단위: [1]INDEX!$L$181
Name ID규칙_학생_역할_단위: INDEX!$L$181
Name ID규칙_한계_해방_그룹_단위: [1]INDEX!$L$67
Name ID규칙_한계_해방_그룹_단위: INDEX!$L$67
Name ID규칙_획득처_그룹_단위: [1]INDEX!$L$502
Name ID규칙_획득처_그룹_단위: INDEX!$L$502
Name INDEX_WEAPON_TYPE: INDEX!$B$22:$D$32
Name ITEM_FILTER: INDEX!$B$577:$C$582
Name ITEM_TYPE: INDEX!$F$577:$G$592
Name LINK_STUDENT_SPEECH: STRING!$A$305:$B$5017
Name MAIN_STATS_TYPE: INDEX!$B$448:$C$464
Name SKILL_TYPE: [1]INDEX!$B$107:$C$128
Name SKILL_TYPE: INDEX!$B$107:$C$128
Name SPEECH_MAIN_TYPE: [1]INDEX!$B$245:$C$252
Name SPEECH_MAIN_TYPE: INDEX!$B$245:$C$252
Name SPEECH_SUB_TYPE: [1]INDEX!$F$245:$G$275
Name SPEECH_SUB_TYPE: INDEX!$F$245:$G$275
Name STAGE_DIFFICULTY: INDEX!$B$554:$C$555
Name STATS_TYPE: [1]INDEX!$B$58:$C$60
Name STATS_TYPE: INDEX!$B$58:$C$60
Name UNIQUE_CONDITION_TYPE: [1]INDEX!$B$364:$C$371
Name UNIQUE_CONDITION_TYPE: INDEX!$B$364:$C$371

Sheet DATA
G1: 데이터 구조
B2: ※ 각 제목 클릭 시 해당 테이블로 이등
C4: WEAPON_EXP_INFO | E4: WEAPON_STATUS | G4: WEAPON | I4: STUDENT | K4: STUDENT_SPEECH
C5: ID | E5: ID | G5: ID | I5: ID | K5: ID
C6: RANK | E6: STATUS_GROUP | G6: USED_STUDENT_ID | I6: ROLE | K6: SPEECH_GROUP
C7: LEVEL | E7: LEVEL | G7: WEAPON_TYPE | I7: DETAIL_ROLE | K7: MAIN_TYPE
C8: NEED_EXP | E8: STATUS_TYPE_1 | G8: STATUS_GROUP | I8: RANK | K8: SUB_TYPE
C9: ACCURE_EXP | E9: STATUS_VALUE_1 | G9: LIMIT_BREAK_GROUP | I9: MAX_LEVEL | K9: SUB_TYPE_VALUE
C10: NEED_CREDIT | E10: ISRATE_1 | G10: WEAPON_NAME | I10: POSITION_TYPE | K10: SPEECH_DESC
E11: STATUS_TYPE_2 | G11: WEAPON_IMAGE | I11: OFFENSE_TYPE | K11: SPEECH_AUDIO
E12: STATUS_VALUE_2 | G12: WEAPON_DESC | I12: DEFENSE_TYPE
E13: ISRATE_2 | I13: CITY_WAR_RANK
E14: STATUS_TYPE_3 | I14: OUTSIDE_WAR_RANK | K14: UNIQUE_SKILL_REINFORCE
E15: STATUS_VALUE_3 | I15: INSIDE_WAR_RANK | K15: ID
E16: ISRATE_3 | I16: SPEECH_GROUP | K16: UNIQUE_SKILL_REINFORCE_GROUP
I17: UNIQUE_ITEM_GROUP | K17: SKILL_LEVEL
I18: STUDENT_NAME | K18: CONDITION_TYPE_1
E19: WEAPON_LIMIT_BREAK | I19: STUDENT_IMAGE | K19: OPTION_TYPE_1
C20: SKILL_REINFORCE | E20: ID | K20: OPTION_VALUE_1
C21: ID | E21: LIMIT_BREAK_GROUP | G21: ITEM | K21: OPTION_ISRATE_1
C22: SKILL_REINFORCE_GROUP | E22: LIMIT_BREAK_RANK | G22: ID | I22: STUDENT_UNIQUE_ITEM | K22: TIME_1
C23: SKILL_LEVEL | E23: MAX_LEVEL | G23: ITEM_FILTER | I23: ID | K23: COUNT_1
C24: SKILL_TYPE | E24: ITEM_ID | G24: ITEM_TYPE | I24: UNIQUE_ITEM_GROUP | K24: COOLTIME_1
C25: SKILL_VALUE | E25: NEED_ELEPH | G25: GAIN_GROUP | I25: TIER | K25: CONDITION_TYPE_2
C26: ISRATE | E26: NEED_CREDIT | G26: STACK | I26: SLOT | K26: OPTION_TYPE_2
C27: SKILL_REINFORCE_NAME | E27: SKILL_REINFORCE_GROUP | G27: ITEM_NAME | I27: UNIQUE_LIMIT_BREAK_ID | K27: OPTION_VALUE_2
C28: SKILL_REINFORCE_ICON | E28: WARFARE_REINFORCE_ID | G28: ITEM_ICON | I28: UNIQUE_ITEM_NAME | K28: OPTION_ISRATE_2
G29: ITEM_DESC | I29: UNIQUE_ITEM_IMAGE | K29: TIME_2
I30: UNIQUE_ITEM_DESC | K30: COUNT_2
C31: WARFARE_REINFORCE | K31: COOLTIME_2
C32: ID | G32: GAIN_INFO
C33: WARFARE_TYPE | G33: ID | I33: STUDENT_UNIQUE_LIMIT_BREAK
C34: WARFARE_RANK | G34: GAIN_GROUP | I34: ID
C35: WARFARE_DESC | G35: GAIN_TYPE | I35: NEED_RELATIONSHIP
C36: WARFARE_ICON | G36: VALUE | I36: NEED_CREDIT
G37: GAIN_NAME | I37: ITEM_ID_1
I38: ITEM_COUNT_1
I39: ITEM_ID_2
I40: ITEM_COUNT_2
I41: ITEM_ID_3
...

Sheet COMMON
A1: 내용 | B1: 타입 | C1: 값 | D1: #내용
A2: KEY | B2: TYPE | C2: VALUE | D2: 참조
A3: WEAPON_LIMIT_BREAK_RANK | B3: INT | C3: 5 | D3: 학생 신비 해방 달성 (5등급)

Sheet INDEX
B3: INDEX_WEAPON
B4: ID 규칙
B5: 0 | C5: 0 | D5: 0 | E5: 0 | F5: 1 | G5: 0 | H5: 1 | K5: 사용 학생 아이디 단위 | L5: 100
B6: USED_STUDENT_ID | G6: WEAPON_TYPE
B8: 한글 변수 | C8: 영어 변수 | E8: 자료형 | F8: 설명
B9: 아이디 | C9: ID | E9: INT | F9: 고유무기 아이디
B10: 사용 학생 아이디 | C10: USED_STUDENT_ID | E10: INT | F10: 사용 학생의 아이디 값
B11: 고유무기 타입 | C11: WEAPON_TYPE | E11: INT | F11: 고유무기의 타입
B12: 기본 능력치 그룹 | C12: STATUS_GROUP | E12: INT | F12: 고유무기의 기본 능력치 그룹
B13: 한계 해방 그룹 | C13: LIMIT_BREAK_GROUP | E13: INT | F13: 고유무기의 한계 해방 그룹
B14: 스킬 강화 그룹 | C14: SKILL_REINFORCE_GROUP | E14: INT | F14: 고유무기가 ★2 달성 시 강화되는 스킬 그룹
B15: 상성 강화 그룹 | C15: WARFARE_REINFORCE_ID | E15: INT | F15: 고유무기가 ★3 달성 시 강화되는 상성 그룹
B16: 고유무기 이름 | C16: WEAPON_NAME | E16: STRING | F16: 고유무기 이름
B17: 고유무기 이미지 | C17: WEAPON_IMAGE | E17: STRING | F17: 고유무기 이미지
B18: 고유무기 설명 | C18: WEAPON_DESC | E18: STRING | F18: 고유무기 설명
B20: WEAPON_TYPE
B21: INDEX | C21: 영문 설명 | D21: 한글 설명
B22: 1 | C22: HG | D22: 권총
B23: 2 | C23: SMG | D23: 기관단총
B24: 3 | C24: AR | D24: 돌격소총
B25: 4 | C25: SR | D25: 저격총
B26: 5 | C26: SG | D26: 샷건
B27: 6 | C27: MG | D27: 기관총
B28: 7 | C28: GL | D28: 유탄발사기
B29: 8 | C29: RL | D29: 로켓 런처
B30: 9 | C30: RG | D30: 레일건
B31: 10 | C31: MT | D31: 박격포
B32: 11 | C32: FT | D32: 화염방사기
B37: INDEX_WEAPON_STATUS
B38: ID 규칙
B39: 0 | C39: 1 | D39: 0 | E39: 0 | F39: 1 | K39: 기본 능력치 그룹 단위 | L39: 1000
B40: BASIC_STATUS_GROUP | F40: 순번
B42: 한글 변수 | C42: 영어 변수 | E42: 자료형 | F42: 설명
B43: 아이디 | C43: ID | E43: INT | F43: 기본 능력치 아이디
B44: 기본 능력치 그룹 | C44: STATUS_GROUP | E44: INT | F44: 기본 능력치 그룹
B45: 레벨 | C45: LEVEL | E45: INT | F45: 고유무기의 레벨
B46: 능력치 타입_1 | C46: STATUS_TYPE_1 | E46: INT | F46: 고유무기의 능력치 타입 (첫 번째)
B47: 능력치 값_1 | C47: STATUS_VALUE_1 | E47: INT | F47: 고유무기 능력치의 값 (첫 번째)
B48: 비율_1 | C48: ISRATE_1 | E48: INT | F48: 능력치 비율의 여부 (첫 번째)
B49: 능력치 타입_2 | C49: STATUS_TYPE_2 | E49: INT | F49: 고유무기의 능력치 타입 (두 번째)
...

Sheet WEAPON
A1: 아이디 | B1: #고유무기 이름 | C1: #학생 이름 | D1: 사용 학생 아이디 | E1: 고유무기 타입 | F1: 기본 능력치 그룹 | G1: 한계 해방 그룹 | H1: 고유무기 이름 | I1: 고유무기 이미지 | J1: 고유무기 설명
A2: ID | B2: WEAPON_NAME | C2: STUDENT_NAME | D2: USED_STUDENT_ID | E2: WEAPON_TYPE | F2: STATUS_GROUP | G2: LIMIT_BREAK_GROUP | H2: WEAPON_NAME | I2: WEAPON_IMAGE | J2: WEAPON_DESC
A3: int | B3: 참조 | C3: 참조 | D3: int | E3: int | F3: int | G3: int | H3: string | I3: string | J3: string
A4: =D4*ID규칙_사용학생_아이디_단위+E4 -> 1130103 | B4: WHITE FANG 465 | C4: 시로코 | D4: =INDEX(STUDENT!$A$4:$A$99,MATCH(WEAPON!C4,STUDENT!$B$4:$B$99,0)) -> 11301 | E4: 3 | F4: =INDEX(WEAPON_STATUS!$C:$C,MATCH(B4,WEAPON_STATUS!$B:$B,0)) -> 11301 | G4: =INDEX(WEAPON_LIMIT_BREAK!C:C,MATCH(B4,WEAPON_LIMIT_BREAK!B:B,0)) -> 11301 | H4: ="WEAPON_NAME_"&A4 -> WEAPON_NAME_1130103 | I4: ="WEAPON_IMAGE_"&A4 -> WEAPON_IMAGE_1130103 | J4: ="WEAPON_DESC_"&A4 -> WEAPON_DESC_1130103
A5: =D5*ID규칙_사용학생_아이디_단위+E5 -> 1230205 | B5: 호루스의 눈 | C5: 호시노 | D5: =INDEX(STUDENT!$A$4:$A$99,MATCH(WEAPON!C5,STUDENT!$B$4:$B$99,0)) -> 12302 | E5: 5 | F5: =INDEX(WEAPON_STATUS!$C:$C,MATCH(B5,WEAPON_STATUS!$B:$B,0)) -> 12302 | G5: =INDEX(WEAPON_LIMIT_BREAK!C:C,MATCH(B5,WEAPON_LIMIT_BREAK!B:B,0)) -> 12302 | H5: ="WEAPON_NAME_"&A5 -> WEAPON_NAME_1230205 | I5: ="WEAPON_IMAGE_"&A5 -> WEAPON_IMAGE_1230205 | J5: ="WEAPON_DESC_"&A5 -> WEAPON_DESC_1230205
A6: =D6*ID규칙_사용학생_아이디_단위+E6 -> 1120303 | B6: 신시어리티 | C6: 세리카 | D6: =INDEX(STUDENT!$A$4:$A$99,MATCH(WEAPON!C6,STUDENT!$B$4:$B$99,0)) -> 11203 | E6: 3 | F6: =INDEX(WEAPON_STATUS!$C:$C,MATCH(B6,WEAPON_STATUS!$B:$B,0)) -> 11203 | G6: =INDEX(WEAPON_LIMIT_BREAK!C:C,MATCH(B6,WEAPON_LIMIT_BREAK!B:B,0)) -> 11203 | H6: ="WEAPON_NAME_"&A6 -> WEAPON_NAME_1120303 | I6: ="WEAPON_IMAGE_"&A6 -> WEAPON_IMAGE_1120303 | J6: ="WEAPON_DESC_"&A6 -> WEAPON_DESC_1120303
A7: =D7*ID규칙_사용학생_아이디_단위+E7 -> 1120406 | B7: 미니 NO.5 | C7: 노노미 | D7: =INDEX(STUDENT!$A$4:$A$99,MATCH(WEAPON!C7,STUDENT!$B$4:$B$99,0)) -> 11204 | E7: 6 | F7: =INDEX(WEAPON_STATUS!$C:$C,MATCH(B7,WEAPON_STATUS!$B:$B,0)) -> 11204 | G7: =INDEX(WEAPON_LIMIT_BREAK!C:C,MATCH(B7,WEAPON_LIMIT_BREAK!B:B,0)) -> 11204 | H7: ="WEAPON_NAME_"&A7 -> WEAPON_NAME_1120406 | I7: ="WEAPON_IMAGE_"&A7 -> WEAPON_IMAGE_1120406 | J7: ="WEAPON_DESC_"&A7 -> WEAPON_DESC_1120406
A8: =D8*ID규칙_사용학생_아이디_단위+E8 -> 2320101 | B8: 상식적 수단 | C8: 아야네 | D8: =INDEX(STUDENT!$A$4:$A$99,MATCH(WEAPON!C8,STUDENT!$B$4:$B$99,0)) -> 23201 | E8: 1 | F8: =INDEX(WEAPON_STATUS!$C:$C,MATCH(B8,WEAPON_STATUS!$B:$B,0)) -> 23201 | G8: =INDEX(WEAPON_LIMIT_BREAK!C:C,MATCH(B8,WEAPON_LIMIT_BREAK!B:B,0)) -> 23201 | H8: ="WEAPON_NAME_"&A8 -> WEAPON_NAME_2320101 | I8: ="WEAPON_IMAGE_"&A8 -> WEAPON_IMAGE_2320101 | J8: ="WEAPON_DESC_"&A8 -> WEAPON_DESC_2320101
A9: =D9*ID규칙_사용학생_아이디_단위+E9 -> 1130504 | B9: 와인레드·어드마이어 | C9: 아루 | D9: =INDEX(STUDENT!$A$4:$A$99,MATCH(WEAPON!C9,STUDENT!$B$4:$B$99,0)) -> 11305 | E9: 4 | F9: =INDEX(WEAPON_STATUS!$C:$C,MATCH(B9,WEAPON_STATUS!$B:$B,0)) -> 11305 | G9: =INDEX(WEAPON_LIMIT_BREAK!C:C,MATCH(B9,WEAPON_LIMIT_BREAK!B:B,0)) -> 11305 | H9: ="WEAPON_NAME_"&A9 -> WEAPON_NAME_1130504 | I9: ="WEAPON_IMAGE_"&A9 -> WEAPON_IMAGE_1130504 | J9: ="WEAPON_DESC_"&A9 -> WEAPON_DESC_1130504
A10: =D10*ID규칙_사용학생_아이디_단위+E10 -> 1120606 | B10: 트릭 오어 트릭 | C10: 무츠키 | D10: =INDEX(STUDENT!$A$4:$A$99,MATCH(WEAPON!C10,STUDENT!$B$4:$B$99,0)) -> 11206 | E10: 6 | F10: =INDEX(WEAPON_STATUS!$C:$C,MATCH(B10,WEAPON_STATUS!$B:$B,0)) -> 11206 | G10: =INDEX(WEAPON_LIMIT_BREAK!C:C,MATCH(B10,WEAPON_LIMIT_BREAK!B:B,0)) -> 11206 | H10: ="WEAPON_NAME_"&A10 -> WEAPON_NAME_1120606 | I10: ="WEAPON_IMAGE_"&A10 -> WEAPON_IMAGE_1120606 | J10: ="WEAPON_DESC_"&A10 -> WEAPON_DESC_1120606
A11: =D11*ID규칙_사용학생_아이디_단위+E11 -> 1420701 | B11: 데몬스 로어 | C11: 카요코 | D11: =INDEX(STUDENT!$A$4:$A$99,MATCH(WEAPON!C11,STUDENT!$B$4:$B$99,0)) -> 14207 | E11: 1 | F11: =INDEX(WEAPON_STATUS!$C:$C,MATCH(B11,WEAPON_STATUS!$B:$B,0)) -> 14207 | G11: =INDEX(WEAPON_LIMIT_BREAK!C:C,MATCH(B11,WEAPON_LIMIT_BREAK!B:B,0)) -> 14207 | H11: ="WEAPON_NAME_"&A11 -> WEAPON_NAME_1420701 | I11: ="WEAPON_IMAGE_"&A11 -> WEAPON_IMAGE_1420701 | J11: ="WEAPON_DESC_"&A11 -> WEAPON_DESC_1420701
A12: =D12*ID규칙_사용학생_아이디_단위+E12 -> 1110805 | B12: 블로우 어웨이 | C12: 하루카 | D12: =INDEX(STUDENT!$A$4:$A$99,MATCH(WEAPON!C12,STUDENT!$B$4:$B$99,0)) -> 11108 | E12: 5 | F12: =INDEX(WEAPON_STATUS!$C:$C,MATCH(B12,WEAPON_STATUS!$B:$B,0)) -> 11108 | G12: =INDEX(WEAPON_LIMIT_BREAK!C:C,MATCH(B12,WEAPON_LIMIT_BREAK!B:B,0)) -> 11108 | H12: ="WEAPON_NAME_"&A12 -> WEAPON_NAME_1110805 | I12: ="WEAPON_IMAGE_"&A12 -> WEAPON_IMAGE_1110805 | J12: ="WEAPON_DESC_"&A12 -> WEAPON_DESC_1110805
A13: =D13*ID규칙_사용학생_아이디_단위+E13 -> 1130906 | B13: 종막의 디스트로이어 | C13: 히나 | D13: =INDEX(STUDENT!$A$4:$A$99,MATCH(WEAPON!C13,STUDENT!$B$4:$B$99,0)) -> 11309 | E13: 6 | F13: =INDEX(WEAPON_STATUS!$C:$C,MATCH(B13,WEAPON_STATUS!$B:$B,0)) -> 11309 | G13: =INDEX(WEAPON_LIMIT_BREAK!C:C,MATCH(B13,WEAPON_LIMIT_BREAK!B:B,0)) -> 11309 | H13: ="WEAPON_NAME_"&A13 -> WEAPON_NAME_1130906 | I13: ="WEAPON_IMAGE_"&A13 -> WEAPON_IMAGE_1130906 | J13: ="WEAPON_DESC_"&A13 -> WEAPON_DESC_1130906
A14: =D14*ID규칙_사용학생_아이디_단위+E14 -> 2430201 | B14: 핫 샷 | C14: 아코 | D14: =INDEX(STUDENT!$A$4:$A$99,MATCH(WEAPON!C14,STUDENT!$B$4:$B$99,0)) -> 24302 | E14: 1 | F14: =INDEX(WEAPON_STATUS!$C:$C,MATCH(B14,WEAPON_STATUS!$B:$B,0)) -> 24302 | G14: =INDEX(WEAPON_LIMIT_BREAK!C:C,MATCH(B14,WEAPON_LIMIT_BREAK!B:B,0)) -> 24302 | H14: ="WEAPON_NAME_"&A14 -> WEAPON_NAME_2430201 | I14: ="WEAPON_IMAGE_"&A14 -> WEAPON_IMAGE_2430201 | J14: ="WEAPON_DESC_"&A14 -> WEAPON_DESC_2430201
A15: =D15*ID규칙_사용학생_아이디_단위+E15 -> 1131004 | B15: 크랙 샷 | C15: 이오리 | D15: =INDEX(STUDENT!$A$4:$A$99,MATCH(WEAPON!C15,STUDENT!$B$4:$B$99,0)) -> 11310 | E15: 4 | F15: =INDEX(WEAPON_STATUS!$C:$C,MATCH(B15,WEAPON_STATUS!$B:$B,0)) -> 11310 | G15: =INDEX(WEAPON_LIMIT_BREAK!C:C,MATCH(B15,WEAPON_LIMIT_BREAK!B:B,0)) -> 11310 | H15: ="WEAPON_NAME_"&A15 -> WEAPON_NAME_1131004 | I15: ="WEAPON_IMAGE_"&A15 -> WEAPON_IMAGE_1131004 | J15: ="WEAPON_DESC_"&A15 -> WEAPON_DESC_1131004
... A99: =D99*ID규칙_사용학생_아이디_단위+E99 -> 2433007 | B99: 공연용 티셔츠 캐논 | C99: 미쿠 | D99: =INDEX(STUDENT!$A$4:$A$99,MATCH(WEAPON!C99,STUDENT!$B$4:$B$99,0)) -> 24330 | E99: 7 | F99: =INDEX(WEAPON_STATUS!$C:$C,MATCH(B99,WEAPON_STATUS!$B:$B,0)) -> 24330 | G99: =INDEX(WEAPON_LIMIT_BREAK!C:C,MATCH(B99,WEAPON_LIMIT_BREAK!B:B,0)) -> 24330 | H99: ="WEAPON_NAME_"&A99 -> WEAPON_NAME_2433007 | I99: ="WEAPON_IMAGE_"&A99 -> WEAPON_IMAGE_2433007 | J99: ="WEAPON_DESC_"&A99 -> WEAPON_DESC_2433007

Sheet WEAPON_STATUS
A1: 아이디 | B1: #고유무기 이름 | C1: 기본 능력치 그룹 | D1: 레벨 | E1: 능력치 타입_1 | F1: 능력치 값_1 | G1: 비율_1 | H1: 능력치 타입_2 | I1: 능력치 값_2 | J1: 비율_2 | K1: 능력치 타입_3 | L1: 능력치 값_3 | M1: 비율_3 | N1: #기본 능력치 설명_1 | O1: #기본 능력치 설명_2 | P1: #기본 능력치 설명_3
A2: ID | B2: WEAPON_NAME | C2: STATUS_GROUP | D2: LEVEL | E2: STATUS_TYPE_1 | F2: STATUS_VALUE_1 | G2: ISRATE_1 | H2: STATUS_TYPE_2 | I2: STATUS_VALUE_2 | J2: ISRATE_2 | K2: STATUS_TYPE_3 | L2: STATUS_VALUE_3 | M2: ISRATE_3 | N2: STATUS_DESC_1 | O2: STATUS_DESC_2 | P2: STATUS_DESC_3
A3: int | B3: 참조 | C3: int | D3: int | E3: int | F3: int | G3: int | H3: int | I3: int | J3: int | K3: int | L3: int | M3: int | N3: 참조 | O3: 참조 | P3: 참조
A4: =C4*ID규칙_기본능력치그룹_단위+COUNTIF($C$4:C4,C4) -> 11301001 | B4: WHITE FANG 465 | C4: =VLOOKUP(B4,WEAPON!$B:$D,3,0) -> 11301 | D4: 1 | E4: 1 | F4: 123 | G4: 0 | H4: 2 | I4: 640 | J4: 0 | K4: 0 | L4: 0 | M4: 0 | N4: =IF(E4=0,"-",VLOOKUP(E4,STATS_TYPE,2,0)&" +")&IF(E4=0,"",IF(G4=0,F4,F4/100&"%")) -> 공격력 +123 | O4: =IF(H4=0,"-",VLOOKUP(H4,STATS_TYPE,2,0)&" +")&IF(H4=0,"",IF(J4=0,I4,I4/100&"%")) -> 최대 체력 +640 | P4: =IF(K4=0,"-",VLOOKUP(K4,STATS_TYPE,2,0)&" +")&IF(K4=0,"",IF(M4=0,L4,L4/100&"%")) -> -
A5: =C5*ID규칙_기본능력치그룹_단위+COUNTIF($C$4:C5,C5) -> 11301002 | B5: WHITE FANG 465 | C5: =VLOOKUP(B5,WEAPON!$B:$D,3,0) -> 11301 | D5: 2 | E5: 1 | F5: 134 | G5: 0 | H5: 2 | I5: 698 | J5: 0 | K5: 0 | L5: 0 | M5: 0 | N5: =IF(E5=0,"-",VLOOKUP(E5,STATS_TYPE,2,0)&" +")&IF(E5=0,"",IF(G5=0,F5,F5/100&"%")) -> 공격력 +134 | O5: =IF(H5=0,"-",VLOOKUP(H5,STATS_TYPE,2,0)&" +")&IF(H5=0,"",IF(J5=0,I5,I5/100&"%")) -> 최대 체력 +698 | P5: =IF(K5=0,"-",VLOOKUP(K5,STATS_TYPE,2,0)&" +")&IF(K5=0,"",IF(M5=0,L5,L5/100&"%")) -> -
A6: =C6*ID규칙_기본능력치그룹_단위+COUNTIF($C$4:C6,C6) -> 11301003 | B6: WHITE FANG 465 | C6: =VLOOKUP(B6,WEAPON!$B:$D,3,0) -> 11301 | D6: 3 | E6: 1 | F6: 145 | G6: 0 | H6: 2 | I6: 756 | J6: 0 | K6: 0 | L6: 0 | M6: 0 | N6: =IF(E6=0,"-",VLOOKUP(E6,STATS_TYPE,2,0)&" +")&IF(E6=0,"",IF(G6=0,F6,F6/100&"%")) -> 공격력 +145 | O6: =IF(H6=0,"-",VLOOKUP(H6,STATS_TYPE,2,0)&" +")&IF(H6=0,"",IF(J6=0,I6,I6/100&"%")) -> 최대 체력 +756 | P6: =IF(K6=0,"-",VLOOKUP(K6,STATS_TYPE,2,0)&" +")&IF(K6=0,"",IF(M6=0,L6,L6/100&"%")) -> -
A7: =C7*ID규칙_기본능력치그룹_단위+COUNTIF($C$4:C7,C7) -> 11301004 | B7: WHITE FANG 465 | C7: =VLOOKUP(B7,WEAPON!$B:$D,3,0) -> 11301 | D7: 4 | E7: 1 | F7: 156 | G7: 0 | H7: 2 | I7: 815 | J7: 0 | K7: 0 | L7: 0 | M7: 0 | N7: =IF(E7=0,"-",VLOOKUP(E7,STATS_TYPE,2,0)&" +")&IF(E7=0,"",IF(G7=0,F7,F7/100&"%")) -> 공격력 +156 | O7: =IF(H7=0,"-",VLOOKUP(H7,STATS_TYPE,2,0)&" +")&IF(H7=0,"",IF(J7=0,I7,I7/100&"%")) -> 최대 체력 +815 | P7: =IF(K7=0,"-",VLOOKUP(K7,STATS_TYPE,2,0)&" +")&IF(K7=0,"",IF(M7=0,L7,L7/100&"%")) -> -
A8: =C8*ID규칙_기본능력치그룹_단위+COUNTIF($C$4:C8,C8) -> 11301005 | B8: WHITE FANG 465 | C8: =VLOOKUP(B8,WEAPON!$B:$D,3,0) -> 11301 | D8: 5 | E8: 1 | F8: 168 | G8: 0 | H8: 2 | I8: 873 | J8: 0 | K8: 0 | L8: 0 | M8: 0 | N8: =IF(E8=0,"-",VLOOKUP(E8,STATS_TYPE,2,0)&" +")&IF(E8=0,"",IF(G8=0,F8,F8/100&"%")) -> 공격력 +168 | O8: =IF(H8=0,"-",VLOOKUP(H8,STATS_TYPE,2,0)&" +")&IF(H8=0,"",IF(J8=0,I8,I8/100&"%")) -> 최대 체력 +873 | P8: =IF(K8=0,"-",VLOOKUP(K8,STATS_TYPE,2,0)&" +")&IF(K8=0,"",IF(M8=0,L8,L8/100&"%")) -> -
A9: =C9*ID규칙_기본능력치그룹_단위+COUNTIF($C$4:C9,C9) -> 11301006 | B9: WHITE FANG 465 | C9: =VLOOKUP(B9,WEAPON!$B:$D,3,0) -> 11301 | D9: 6 | E9: 1 | F9: 179 | G9: 0 | H9: 2 | I9: 931 | J9: 0 | K9: 0 | L9: 0 | M9: 0 | N9: =IF(E9=0,"-",VLOOKUP(E9,STATS_TYPE,2,0)&" +")&IF(E9=0,"",IF(G9=0,F9,F9/100&"%")) -> 공격력 +179 | O9: =IF(H9=0,"-",VLOOKUP(H9,STATS_TYPE,2,0)&" +")&IF(H9=0,"",IF(J9=0,I9,I9/100&"%")) -> 최대 체력 +931 | P9: =IF(K9=0,"-",VLOOKUP(K9,STATS_TYPE,2,0)&" +")&IF(K9=0,"",IF(M9=0,L9,L9/100&"%")) -> -
A10: =C10*ID규칙_기본능력치그룹_단위+COUNTIF($C$4:C10,C10) -> 11301007 | B10: WHITE FANG 465 | C10: =VLOOKUP(B10,WEAPON!$B:$D,3,0) -> 11301 | D10: 7 | E10: 1 | F10: 190 | G10: 0 | H10: 2 | I10: 989 | J10: 0 | K10: 0 | L10: 0 | M10: 0 | N10: =IF(E10=0,"-",VLOOKUP(E10,STATS_TYPE,2,0)&" +")&IF(E10=0,"",IF(G10=0,F10,F10/100&"%")) -> 공격력 +190 | O10: =IF(H10=0,"-",VLOOKUP(H10,STATS_TYPE,2,0)&" +")&IF(H10=0,"",IF(J10=0,I10,I10/100&"%")) -> 최대 체력 +989 | P10: =IF(K10=0,"-",VLOOKUP(K10,STATS_TYPE,2,0)&" +")&IF(K10=0,"",IF(M10=0,L10,L10/100&"%")) -> -
A11: =C11*ID규칙_기본능력치그룹_단위+COUNTIF($C$4:C11,C11) -> 11301008 | B11: WHITE FANG 465 | C11: =VLOOKUP(B11,WEAPON!$B:$D,3,0) -> 11301 | D11: 8 | E11: 1 | F11: 201 | G11: 0 | H11: 2 | I11: 1047 | J11: 0 | K11: 0 | L11: 0 | M11: 0 | N11: =IF(E11=0,"-",VLOOKUP(E11,STATS_TYPE,2,0)&" +")&IF(E11=0,"",IF(G11=0,F11,F11/100&"%")) -> 공격력 +201 | O11: =IF(H11=0,"-",VLOOKUP(H11,STATS_TYPE,2,0)&" +")&IF(H11=0,"",IF(J11=0,I11,I11/100&"%")) -> 최대 체력 +1047 | P11: =IF(K11=0,"-",VLOOKUP(K11,STATS_TYPE,2,0)&" +")&IF(K11=0,"",IF(M11=0,L11,L11/100&"%")) -> -
A12: =C12*ID규칙_기본능력치그룹_단위+COUNTIF($C$4:C12,C12) -> 11301009 | B12: WHITE FANG 465 | C12: =VLOOKUP(B12,WEAPON!$B:$D,3,0) -> 11301 | D12: 9 | E12: 1 | F12: 212 | G12: 0 | H12: 2 | I12: 1105 | J12: 0 | K12: 0 | L12: 0 | M12: 0 | N12: =IF(E12=0,"-",VLOOKUP(E12,STATS_TYPE,2,0)&" +")&IF(E12=0,"",IF(G12=0,F12,F12/100&"%")) -> 공격력 +212 | O12: =IF(H12=0,"-",VLOOKUP(H12,STATS_TYPE,2,0)&" +")&IF(H12=0,"",IF(J12=0,I12,I12/100&"%")) -> 최대 체력 +1105 | P12: =IF(K12=0,"-",VLOOKUP(K12,STATS_TYPE,2,0)&" +")&IF(K12=0,"",IF(M12=0,L12,L12/100&"%")) -> -
A13: =C13*ID규칙_기본능력치그룹_단위+COUNTIF($C$4:C13,C13) -> 11301010 | B13: WHITE FANG 465 | C13: =VLOOKUP(B13,WEAPON!$B:$D,3,0) -> 11301 | D13: 10 | E13: 1 | F13: 223 | G13: 0 | H13: 2 | I13: 1164 | J13: 0 | K13: 0 | L13: 0 | M13: 0 | N13: =IF(E13=0,"-",VLOOKUP(E13,STATS_TYPE,2,0)&" +")&IF(E13=0,"",IF(G13=0,F13,F13/100&"%")) -> 공격력 +223 | O13: =IF(H13=0,"-",VLOOKUP(H13,STATS_TYPE,2,0)&" +")&IF(H13=0,"",IF(J13=0,I13,I13/100&"%")) -> 최대 체력 +1164 | P13: =IF(K13=0,"-",VLOOKUP(K13,STATS_TYPE,2,0)&" +")&IF(K13=0,"",IF(M13=0,L13,L13/100&"%")) -> -
A14: =C14*ID규칙_기본능력치그룹_단위+COUNTIF($C$4:C14,C14) -> 11301011 | B14: WHITE FANG 465 | C14: =VLOOKUP(B14,WEAPON!$B:$D,3,0) -> 11301 | D14: 11 | E14: 1 | F14: 234 | G14: 0 | H14: 2 | I14: 1222 | J14: 0 | K14: 0 | L14: 0 | M14: 0 | N14: =IF(E14=0,"-",VLOOKUP(E14,STATS_TYPE,2,0)&" +")&IF(E14=0,"",IF(G14=0,F14,F14/100&"%")) -> 공격력 +234 | O14: =IF(H14=0,"-",VLOOKUP(H14,STATS_TYPE,2,0)&" +")&IF(H14=0,"",IF(J14=0,I14,I14/100&"%")) -> 최대 체력 +1222 | P14: =IF(K14=0,"-",VLOOKUP(K14,STATS_TYPE,2,0)&" +")&IF(K14=0,"",IF(M14=0,L14,L14/100&"%")) -> -
A15: =C15*ID규칙_기본능력치그룹_단위+COUNTIF($C$4:C15,C15) -> 11301012 | B15: WHITE FANG 465 | C15: =VLOOKUP(B15,WEAPON!$B:$D,3,0) -> 11301 | D15: 12 | E15: 1 | F15: 245 | G15: 0 | H15: 2 | I15: 1280 | J15: 0 | K15: 0 | L15: 0 | M15: 0 | N15: =IF(E15=0,"-",VLOOKUP(E15,STATS_TYPE,2,0)&" +")&IF(E15=0,"",IF(G15=0,F15,F15/100&"%")) -> 공격력 +245 | O15: =IF(H15=0,"-",VLOOKUP(H15,STATS_TYPE,2,0)&" +")&IF(H15=0,"",IF(J15=0,I15,I15/100&"%")) -> 최대 체력 +1280 | P15: =IF(K15=0,"-",VLOOKUP(K15,STATS_TYPE,2,0)&" +")&IF(K15=0,"",IF(M15=0,L15,L15/100&"%")) -> -
... A1302: =C1302*ID규칙_기본능력치그룹_단위+COUNTIF($C$4:C1302,C1302) -> 21308049 | B1302: 백도어 | C1302: =VLOOKUP(B1302,WEAPON!$B:$D,3,0) -> 21308 | D1302: 49 | E1302: 1 | F1302: 637 | G1302: 0 | H1302: 2 | I1302: 2590 | J1302: 0 | K1302: 3 | L1302: 1028 | M1302: 0 | N1302: =IF(E1302=0,"-",VLOOKUP(E1302,STATS_TYPE,2,0)&" +")&IF(E1302=0,"",IF(G1302=0,F1302,F1302/100&"%")) -> 공격력 +637 | O1302: =IF(H1302=0,"-",VLOOKUP(H1302,STATS_TYPE,2,0)&" +")&IF(H1302=0,"",IF(J1302=0,I1302,I1302/100&"%")) -> 최대 체력 +2590 | P1302: =IF(K1302=0,"-",VLOOKUP(K1302,STATS_TYPE,2,0)&" +")&IF(K1302=0,"",IF(M1302=0,L1302,L1302/100&"%")) -> 치유력 +1028
A1303: =C1303*ID규칙_기본능력치그룹_단위+COUNTIF($C$4:C1303,C1303) -> 21308050 | B1303: 백도어 | C1303: =VLOOKUP(B1303,WEAPON!$B:$D,3,0) -> 21308 | D1303: 50 | E1303: 1 | F1303: 648 | G1303: 0 | H1303: 2 | I1303: 2634 | J1303: 0 | K1303: 3 | L1303: d | M1303: 0 | N1303: =IF(E1303=0,"-",VLOOKUP(E1303,STATS_TYPE,2,0)&" +")&IF(E1303=0,"",IF(G1303=0,F1303,F1303/100&"%")) -> 공격력 +648 | O1303: =IF(H1303=0,"-",VLOOKUP(H1303,STATS_TYPE,2,0)&" +")&IF(H1303=0,"",IF(J1303=0,I1303,I1303/100&"%")) -> 최대 체력 +2634 | P1303: =IF(K1303=0,"-",VLOOKUP(K1303,STATS_TYPE,2,0)&" +")&IF(K1303=0,"",IF(M1303=0,L1303,L1303/100&"%")) -> 치유력 +d
A1304: =C1304*ID규칙_기본능력치그룹_단위+COUNTIF($C$4:C1304,C1304) -> 24209001 | B1304: 자동 표적 조준 장치 | C1304: =VLOOKUP(B1304,WEAPON!$B:$D,3,0) -> 24209 | D1304: 1 | E1304: 1 | F1304: 76 | G1304: 0 | H1304: 2 | I1304: 432 | J1304: 0 | K1304: 3 | L1304: 174 | M1304: 0 | N1304: =IF(E1304=0,"-",VLOOKUP(E1304,STATS_TYPE,2,0)&" +")&IF(E1304=0,"",IF(G1304=0,F1304,F1304/100&"%")) -> 공격력 +76 | O1304: =IF(H1304=0,"-",VLOOKUP(H1304,STATS_TYPE,2,0)&" +")&IF(H1304=0,"",IF(J1304=0,I1304,I1304/100&"%")) -> 최대 체력 +432 | P1304: =IF(K1304=0,"-",VLOOKUP(K1304,STATS_TYPE,2,0)&" +")&IF(K1304=0,"",IF(M1304=0,L1304,L1304/100&"%")) -> 치유력 +174
A1305: =C1305*ID규칙_기본능력치그룹_단위+COUNTIF($C$4:C1305,C1305) -> 24209002 | B1305: 자동 표적 조준 장치 | C1305: =VLOOKUP(B1305,WEAPON!$B:$D,3,0) -> 24209 | D1305: 2 | E1305: 1 | F1305: 83 | G1305: 0 | H1305: 2 | I1305: 471 | J1305: 0 | K1305: 3 | L1305: 190 | M1305: 0 | N1305: =IF(E1305=0,"-",VLOOKUP(E1305,STATS_TYPE,2,0)&" +")&IF(E1305=0,"",IF(G1305=0,F1305,F1305/100&"%")) -> 공격력 +83 | O1305: =IF(H1305=0,"-",VLOOKUP(H1305,STATS_TYPE,2,0)&" +")&IF(H1305=0,"",IF(J1305=0,I1305,I1305/100&"%")) -> 최대 체력 +471 | P1305: =IF(K1305=0,"-",VLOOKUP(K1305,STATS_TYPE,2,0)&" +")&IF(K1305=0,"",IF(M1305=0,L1305,L1305/100&"%")) -> 치유력 +190
A1306: =C1306*ID규칙_기본능력치그룹_단위+COUNTIF($C$4:C1306,C1306) -> 24209003 | B1306: 자동 표적 조준 장치 | C1306: =VLOOKUP(B1306,WEAPON!$B:$D,3,0) -> 24209 | D1306: 3 | E1306: 1 | F1306: 90 | G1306: 0 | H1306: 2 | I1306: 510 | J1306: 0 | K1306: 3 | L1306: 206 | M1306: 0 | N1306: =IF(E1306=0,"-",VLOOKUP(E1306,STATS_TYPE,2,0)&" +")&IF(E1306=0,"",IF(G1306=0,F1306,F1306/100&"%")) -> 공격력 +90 | O1306: =IF(H1306=0,"-",VLOOKUP(H1306,STATS_TYPE,2,0)&" +")&IF(H1306=0,"",IF(J1306=0,I1306,I1306/100&"%")) -> 최대 체력 +510 | P1306: =IF(K1306=0,"-",VLOOKUP(K1306,STATS_TYPE,2,0)&" +")&IF(K1306=0,"",IF(M1306=0,L1306,L1306/100&"%")) -> 치유력 +206
A1307: =C1307*ID규칙_기본능력치그룹_단위+COUNTIF($C$4:C1307,C1307) -> 24209004 | B1307: 자동 표적 조준 장치 | C1307: =VLOOKUP(B1307,WEAPON!$B:$D,3,0) -> 24209 | D1307: 4 | E1307: 1 | F1307: 97 | G1307: 0 | H1307: 2 | I1307: 550 | J1307: 0 | K1307: 3 | L1307: 221 | M1307: 0 | N1307: =IF(E1307=0,"-",VLOOKUP(E1307,STATS_TYPE,2,0)&" +")&IF(E1307=0,"",IF(G1307=0,F1307,F1307/100&"%")) -> 공격력 +97 | O1307: =IF(H1307=0,"-",VLOOKUP(H1307,STATS_TYPE,2,0)&" +")&IF(H1307=0,"",IF(J1307=0,I1307,I1307/100&"%")) -> 최대 체력 +550 | P1307: =IF(K1307=0,"-",VLOOKUP(K1307,STATS_TYPE,2,0)&" +")&IF(K1307=0,"",IF(M1307=0,L1307,L1307/100&"%")) -> 치유력 +221
A1308: =C1308*ID규칙_기본능력치그룹_단위+COUNTIF($C$4:C1308,C1308) -> 24209005 | B1308: 자동 표적 조준 장치 | C1308: =VLOOKUP(B1308,WEAPON!$B:$D,3,0) -> 24209 | D1308: 5 | E1308: 1 | F1308: 104 | G1308: 0 | H1308: 2 | I1308: 589 | J1308: 0 | K1308: 3 | L1308: 237 | M1308: 0 | N1308: =IF(E1308=0,"-",VLOOKUP(E1308,STATS_TYPE,2,0)&" +")&IF(E1308=0,"",IF(G1308=0,F1308,F1308/100&"%")) -> 공격력 +104 | O1308: =IF(H1308=0,"-",VLOOKUP(H1308,STATS_TYPE,2,0)&" +")&IF(H1308=0,"",IF(J1308=0,I1308,I1308/100&"%")) -> 최대 체력 +589 | P1308: =IF(K1308=0,"-",VLOOKUP(K1308,STATS_TYPE,2,0)&" +")&IF(K1308=0,"",IF(M1308=0,L1308,L1308/100&"%")) -> 치유력 +237
A1309: =C1309*ID규칙_기본능력치그룹_단위+COUNTIF($C$4:C1309,C1309) -> 24209006 | B1309: 자동 표적 조준 장치 | C1309: =VLOOKUP(B1309,WEAPON!$B:$D,3,0) -> 24209 | D1309: 6 | E1309: 1 | F1309: 111 | G1309: 0 | H1309: 2 | I1309: 628 | J1309: 0 | K1309: 3 | L1309: 253 | M1309: 0 | N1309: =IF(E1309=0,"-",VLOOKUP(E1309,STATS_TYPE,2,0)&" +")&IF(E1309=0,"",IF(G1309=0,F1309,F1309/100&"%")) -> 공격력 +111 | O1309: =IF(H1309=0,"-",VLOOKUP(H1309,STATS_TYPE,2,0)&" +")&IF(H1309=0,"",IF(J1309=0,I1309,I1309/100&"%")) -> 최대 체력 +628 | P1309: =IF(K1309=0,"-",VLOOKUP(K1309,STATS_TYPE,2,0)&" +")&IF(K1309=0,"",IF(M1309=0,L1309,L1309/100&"%")) -> 치유력 +253
A1310: =C1310*ID규칙_기본능력치그룹_단위+COUNTIF($C$4:C1310,C1310) -> 24209007 | B1310: 자동 표적 조준 장치 | C1310: =VLOOKUP(B1310,WEAPON!$B:$D,3,0) -> 24209 | D1310: 7 | E1310: 1 | F1310: 118 | G1310: 0 | H1310: 2 | I1310: 667 | J1310: 0 | K1310: 3 | L1310: 269 | M1310: 0 | N1310: =IF(E1310=0,"-",VLOOKUP(E1310,STATS_TYPE,2,0)&" +")&IF(E1310=0,"",IF(G1310=0,F1310,F1310/100&"%")) -> 공격력 +118 | O1310: =IF(H1310=0,"-",VLOOKUP(H1310,STATS_TYPE,2,0)&" +")&IF(H1310=0,"",IF(J1310=0,I1310,I1310/100&"%")) -> 최대 체력 +667 | P1310: =IF(K1310=0,"-",VLOOKUP(K1310,STATS_TYPE,2,0)&" +")&IF(K1310=0,"",IF(M1310=0,L1310,L1310/100&"%")) -> 치유력 +269
A1311: =C1311*ID규칙_기본능력치그룹_단위+COUNTIF($C$4:C1311,C1311) -> 24209008 | B1311: 자동 표적 조준 장치 | C1311: =VLOOKUP(B1311,WEAPON!$B:$D,3,0) -> 24209 | D1311: 8 | E1311: 1 | F1311: 125 | G1311: 0 | H1311: 2 | I1311: 706 | J1311: 0 | K1311: 3 | L1311: 285 | M1311: 0 | N1311: =IF(E1311=0,"-",VLOOKUP(E1311,STATS_TYPE,2,0)&" +")&IF(E1311=0,"",IF(G1311=0,F1311,F1311/100&"%")) -> 공격력 +125 | O1311: =IF(H1311=0,"-",VLOOKUP(H1311,STATS_TYPE,2,0)&" +")&IF(H1311=0,"",IF(J1311=0,I1311,I1311/100&"%")) -> 최대 체력 +706 | P1311: =IF(K1311=0,"-",VLOOKUP(K1311,STATS_TYPE,2,0)&" +")&IF(K1311=0,"",IF(M1311=0,L1311,L1311/100&"%")) -> 치유력 +285
A1312: =C1312*ID규칙_기본능력치그룹_단위+COUNTIF($C$4:C1312,C1312) -> 24209009 | B1312: 자동 표적 조준 장치 | C1312: =VLOOKUP(B1312,WEAPON!$B:$D,3,0) -> 24209 | D1312: 9 | E1312: 1 | F1312: 131 | G1312: 0 | H1312: 2 | I1312: 745 | J1312: 0 | K1312: 3 | L1312: 300 | M1312: 0 | N1312: =IF(E1312=0,"-",VLOOKUP(E1312,STATS_TYPE,2,0)&" +")&IF(E1312=0,"",IF(G1312=0,F1312,F1312/100&"%")) -> 공격력 +131 | O1312: =IF(H1312=0,"-",VLOOKUP(H1312,STATS_TYPE,2,0)&" +")&IF(H1312=0,"",IF(J1312=0,I1312,I1312/100&"%")) -> 최대 체력 +745 | P1312: =IF(K1312=0,"-",VLOOKUP(K1312,STATS_TYPE,2,0)&" +")&IF(K1312=0,"",IF(M1312=0,L1312,L1312/100&"%")) -> 치유력 +300
A1313: =C1313*ID규칙_기본능력치그룹_단위+COUNTIF($C$4:C1313,C1313) -> 24209010 | B1313: 자동 표적 조준 장치 | C1313: =VLOOKUP(B1313,WEAPON!$B:$D,3,0) -> 24209 | D1313: 10 | E1313: 1 | F1313: 138 | G1313: 0 | H1313: 2 | I1313: 785 | J1313: 0 | K1313: 3 | L1313: 316 | M1313: 0 | N1313: =IF(E1313=0,"-",VLOOKUP(E1313,STATS_TYPE,2,0)&" +")&IF(E1313=0,"",IF(G1313=0,F1313,F1313/100&"%")) -> 공격력 +138 | O1313: =IF(H1313=0,"-",VLOOKUP(H1313,STATS_TYPE,2,0)&" +")&IF(H1313=0,"",IF(J1313=0,I1313,I1313/100&"%")) -> 최대 체력 +785 | P1313: =IF(K1313=0,"-",VLOOKUP(K1313,STATS_TYPE,2,0)&" +")&IF(K1313=0,"",IF(M1313=0,L1313,L1313/100&"%")) -> 치유력 +316
A1314: =C1314*ID규칙_기본능력치그룹_단위+COUNTIF($C$4:C1314,C1314) -> 24209011 | B1314: 자동 표적 조준 장치 | C1314: =VLOOKUP(B1314,WEAPON!$B:$D,3,0) -> 24209 | D1314: 11 | E1314: 1 | F1314: 145 | G1314: 0 | H1314: 2 | I1314: 824 | J1314: 0 | K1314: 3 | L1314: 332 | M1314: 0 | N1314: =IF(E1314=0,"-",VLOOKUP(E1314,STATS_TYPE,2,0)&" +")&IF(E1314=0,"",IF(G1314=0,F1314,F1314/100&"%")) -> 공격력 +145 | O1314: =IF(H1314=0,"-",VLOOKUP(H1314,STATS_TYPE,2,0)&" +")&IF(H1314=0,"",IF(J1314=0,I1314,I1314/100&"%")) -> 최대 체력 +824 | P1314: =IF(K1314=0,"-",VLOOKUP(K1314,STATS_TYPE,2,0)&" +")&IF(K1314=0,"",IF(M1314=0,L1314,L1314/100&"%")) -> 치유력 +332
A1315: =C1315*ID규칙_기본능력치그룹_단위+COUNTIF($C$4:C1315,C1315) -> 24209012 | B1315: 자동 표적 조준 장치 | C1315: =VLOOKUP(B1315,WEAPON!$B:$D,3,0) -> 24209 | D1315: 12 | E1315: 1 | F1315: 152 | G1315: 0 | H1315: 2 | I1315: 863 | J1315: 0 | K1315: 3 | L1315: 348 | M1315: 0 | N1315: =IF(E1315=0,"-",VLOOKUP(E1315,STATS_TYPE,2,0)&" +")&IF(E1315=0,"",IF(G1315=0,F1315,F1315/100&"%")) -> 공격력 +152 | O1315: =IF(H1315=0,"-",VLOOKUP(H1315,STATS_TYPE,2,0)&" +")&IF(H1315=0,"",IF(J1315=0,I1315,I1315/100&"%")) -> 최대 체력 +863 | P1315: =IF(K1315=0,"-",VLOOKUP(K1315,STATS_TYPE,2,0)&" +")&IF(K1315=0,"",IF(M1315=0,L1315,L1315/100&"%")) -> 치유력 +348
... A4803: =C4803*ID규칙_기본능력치그룹_단위+COUNTIF($C$4:C4803,C4803) -> 24330050 | B4803: 공연용 티셔츠 캐논 | C4803: =VLOOKUP(B4803,WEAPON!$B:$D,3,0) -> 24330 | D4803: 50 | E4803: 1 | F4803: 441 | G4803: 0 | H4803: 2 | I4803: 2416 | J4803: 0 | K4803: 3 | L4803: 1130 | M4803: 0 | N4803: =IF(E4803=0,"-",VLOOKUP(E4803,STATS_TYPE,2,0)&" +")&IF(E4803=0,"",IF(G4803=0,F4803,F4803/100&"%")) -> 공격력 +441 | O4803: =IF(H4803=0,"-",VLOOKUP(H4803,STATS_TYPE,2,0)&" +")&IF(H4803=0,"",IF(J4803=0,I4803,I4803/100&"%")) -> 최대 체력 +2416 | P4803: =IF(K4803=0,"-",VLOOKUP(K4803,STATS_TYPE,2,0)&" +")&IF(K4803=0,"",IF(M4803=0,L4803,L4803/100&"%")) -> 치유력 +1130

Sheet WEAPON_LIMIT_BREAK
A1: 아이디 | B1: #고유무기 이름 | C1: 한계 해방 그룹 | D1: 해방 등급 | E1: 등급 내 최대 레벨 | F1: 아이템 아이디 | G1: 필요 엘레프 조각 | H1: 필요 크레딧 | I1: 강화 스킬 그룹 | J1: 상성 강화 아이디
A2: ID | B2: WEAPON_NAME | C2: LIMIT_BREAK_GROUP | D2: LIMIT_BREAK_RANK | E2: MAX_LEVEL | F2: ITEM_ID | G2: NEED_ELEPH | H2: NEED_CREDIT | I2: SKILL_REINFORCE_GROUP | J2: WARFARE_REINFORCE_ID
A3: int | B3: 참조 | C3: int | D3: int | E3: int | F3: int | G3: int | H3: int | I3: int | J3: int
A4: =C4*ID규칙_한계_해방_그룹_단위+D4 -> 113011 | B4: WHITE FANG 465 | C4: =INDEX(WEAPON!D:D,MATCH(B4,WEAPON!B:B,0)) -> 11301 | D4: =COUNTIF($C$4:C4,C4) -> 1 | E4: =IF(D4=1,30,D4*10+20) -> 30 | F4: 101001 | G4: 0 | H4: 0 | I4: 0 | J4: 0
A5: =C5*ID규칙_한계_해방_그룹_단위+D5 -> 113012 | B5: WHITE FANG 465 | C5: =INDEX(WEAPON!D:D,MATCH(B5,WEAPON!B:B,0)) -> 11301 | D5: =COUNTIF($C$4:C5,C5) -> 2 | E5: =IF(D5=1,30,D5*10+20) -> 40 | F5: 101001 | G5: 120 | H5: 1000000 | I5: 11301 | J5: 0
A6: =C6*ID규칙_한계_해방_그룹_단위+D6 -> 113013 | B6: WHITE FANG 465 | C6: =INDEX(WEAPON!D:D,MATCH(B6,WEAPON!B:B,0)) -> 11301 | D6: =COUNTIF($C$4:C6,C6) -> 3 | E6: =IF(D6=1,30,D6*10+20) -> 50 | F6: 101001 | G6: 180 | H6: 1500000 | I6: 0 | J6: 113011
A7: =C7*ID규칙_한계_해방_그룹_단위+D7 -> 123021 | B7: 호루스의 눈 | C7: =INDEX(WEAPON!D:D,MATCH(B7,WEAPON!B:B,0)) -> 12302 | D7: =COUNTIF($C$4:C7,C7) -> 1 | E7: =IF(D7=1,30,D7*10+20) -> 30 | F7: =IF(E6=50,F6+1,F6) -> 101002 | G7: =IF(G6=180,0,G4) -> 0 | H7: =IF(H6=1500000,H4,H4) -> 0 | I7: 0 | J7: 0
A8: =C8*ID규칙_한계_해방_그룹_단위+D8 -> 123022 | B8: 호루스의 눈 | C8: =INDEX(WEAPON!D:D,MATCH(B8,WEAPON!B:B,0)) -> 12302 | D8: =COUNTIF($C$4:C8,C8) -> 2 | E8: =IF(D8=1,30,D8*10+20) -> 40 | F8: =IF(E7=50,F7+1,F7) -> 101002 | G8: =IF(G7=180,0,G5) -> 120 | H8: =IF(H7=1500000,H5,H5) -> 1000000 | I8: 12302 | J8: 0
A9: =C9*ID규칙_한계_해방_그룹_단위+D9 -> 123023 | B9: 호루스의 눈 | C9: =INDEX(WEAPON!D:D,MATCH(B9,WEAPON!B:B,0)) -> 12302 | D9: =COUNTIF($C$4:C9,C9) -> 3 | E9: =IF(D9=1,30,D9*10+20) -> 50 | F9: =IF(E8=50,F8+1,F8) -> 101002 | G9: =IF(G8=180,0,G6) -> 180 | H9: =IF(H8=1500000,H6,H6) -> 1500000 | I9: 0 | J9: 123022
A10: =C10*ID규칙_한계_해방_그룹_단위+D10 -> 112031 | B10: 신시어리티 | C10: =INDEX(WEAPON!D:D,MATCH(B10,WEAPON!B:B,0)) -> 11203 | D10: =COUNTIF($C$4:C10,C10) -> 1 | E10: =IF(D10=1,30,D10*10+20) -> 30 | F10: =IF(E9=50,F9+1,F9) -> 101003 | G10: =IF(G9=180,0,G7) -> 0 | H10: =IF(H9=1500000,H7,H7) -> 0 | I10: 0 | J10: 0
A11: =C11*ID규칙_한계_해방_그룹_단위+D11 -> 112032 | B11: 신시어리티 | C11: =INDEX(WEAPON!D:D,MATCH(B11,WEAPON!B:B,0)) -> 11203 | D11: =COUNTIF($C$4:C11,C11) -> 2 | E11: =IF(D11=1,30,D11*10+20) -> 40 | F11: =IF(E10=50,F10+1,F10) -> 101003 | G11: =IF(G10=180,0,G8) -> 120 | H11: =IF(H10=1500000,H8,H8) -> 1000000 | I11: 11203 | J11: 0
A12: =C12*ID규칙_한계_해방_그룹_단위+D12 -> 112033 | B12: 신시어리티 | C12: =INDEX(WEAPON!D:D,MATCH(B12,WEAPON!B:B,0)) -> 11203 | D12: =COUNTIF($C$4:C12,C12) -> 3 | E12: =IF(D12=1,30,D12*10+20) -> 50 | F12: =IF(E11=50,F11+1,F11) -> 101003 | G12: =IF(G11=180,0,G9) -> 180 | H12: =IF(H11=1500000,H9,H9) -> 1500000 | I12: 0 | J12: 112032
A13: =C13*ID규칙_한계_해방_그룹_단위+D13 -> 112041 | B13: 미니 NO.5 | C13: =INDEX(WEAPON!D:D,MATCH(B13,WEAPON!B:B,0)) -> 11204 | D13: =COUNTIF($C$4:C13,C13) -> 1 | E13: =IF(D13=1,30,D13*10+20) -> 30 | F13: =IF(E12=50,F12+1,F12) -> 101004 | G13: =IF(G12=180,0,G10) -> 0 | H13: =IF(H12=1500000,H10,H10) -> 0 | I13: 0 | J13: 0
A14: =C14*ID규칙_한계_해방_그룹_단위+D14 -> 112042 | B14: 미니 NO.5 | C14: =INDEX(WEAPON!D:D,MATCH(B14,WEAPON!B:B,0)) -> 11204 | D14: =COUNTIF($C$4:C14,C14) -> 2 | E14: =IF(D14=1,30,D14*10+20) -> 40 | F14: =IF(E13=50,F13+1,F13) -> 101004 | G14: =IF(G13=180,0,G11) -> 120 | H14: =IF(H13=1500000,H11,H11) -> 1000000 | I14: 11204 | J14: 0
A15: =C15*ID규칙_한계_해방_그룹_단위+D15 -> 112043 | B15: 미니 NO.5 | C15: =INDEX(WEAPON!D:D,MATCH(B15,WEAPON!B:B,0)) -> 11204 | D15: =COUNTIF($C$4:C15,C15) -> 3 | E15: =IF(D15=1,30,D15*10+20) -> 50 | F15: =IF(E14=50,F14+1,F14) -> 101004 | G15: =IF(G14=180,0,G12) -> 180 | H15: =IF(H14=1500000,H12,H12) -> 1500000 | I15: 0 | J15: 112043
A16: =C16*ID규칙_한계_해방_그룹_단위+D16 -> 232011 | B16: 상식적 수단 | C16: =INDEX(WEAPON!D:D,MATCH(B16,WEAPON!B:B,0)) -> 23201 | D16: =COUNTIF($C$4:C16,C16) -> 1 | E16: =IF(D16=1,30,D16*10+20) -> 30 | F16: =IF(E15=50,F15+1,F15) -> 101005 | G16: =IF(G15=180,0,G13) -> 0 | H16: =IF(H15=1500000,H13,H13) -> 0 | I16: 0 | J16: 0
A17: =C17*ID규칙_한계_해방_그룹_단위+D17 -> 232012 | B17: 상식적 수단 | C17: =INDEX(WEAPON!D:D,MATCH(B17,WEAPON!B:B,0)) -> 23201 | D17: =COUNTIF($C$4:C17,C17) -> 2 | E17: =IF(D17=1,30,D17*10+20) -> 40 | F17: =IF(E16=50,F16+1,F16) -> 101005 | G17: =IF(G16=180,0,G14) -> 120 | H17: =IF(H16=1500000,H14,H14) -> 1000000 | I17: 23201 | J17: 0
A18: =C18*ID규칙_한계_해방_그룹_단위+D18 -> 232013 | B18: 상식적 수단 | C18: =INDEX(WEAPON!D:D,MATCH(B18,WEAPON!B:B,0)) -> 23201 | D18: =COUNTIF($C$4:C18,C18) -> 3 | E18: =IF(D18=1,30,D18*10+20) -> 50 | F18: =IF(E17=50,F17+1,F17) -> 101005 | G18: =IF(G17=180,0,G15) -> 180 | H18: =IF(H17=1500000,H15,H15) -> 1500000 | I18: 0 | J18: 232011
... A291: =C291*ID규칙_한계_해방_그룹_단위+D291 -> 243303 | B291: 공연용 티셔츠 캐논 | C291: =INDEX(WEAPON!D:D,MATCH(B291,WEAPON!B:B,0)) -> 24330 | D291: =COUNTIF($C$4:C291,C291) -> 3 | E291: =IF(D291=1,30,D291*10+20) -> 50 | F291: =IF(E290=50,F290+1,F290) -> 101096 | G291: =IF(G290=180,0,G288) -> 180 | H291: =IF(H290=1500000,H288,H288) -> 1500000 | I291: 0 | J291: 243301

Sheet SKILL_REINFORCE
A1: 아이디 | B1: #고유무기 이름 | C1: 강화 스킬 그룹 | D1: 스킬 레벨 | E1: 스킬 타입 | F1: 스킬 값 | G1: 비율 | H1: 강화 스킬 이름 | I1: 강화 스킬 아이콘 | J1: #강화 스킬 내용
A2: ID | B2: WEAPON_NAME | C2: SKILL_REINFORCE_GROUP | D2: SKILL_LEVEL | E2: SKILL_TYPE | F2: SKILL_VALUE | G2: ISRATE | H2: SKILL_REINFORCE_NAME | I2: SKILL_REINFORCE_ICON | J2: SKILL_REINFORCE_DESC
A3: int | B3: 참조 | C3: int | D3: int | E3: int | F3: int | G3: int | H3: string | I3: string | J3: 참조
A4: =C4*스킬_강화_그룹_단위+D4 -> 1130101 | B4: WHITE FANG 465 | C4: =VLOOKUP(B4,WEAPON!$B:$D,3,0) -> 11301 | D4: =COUNTIF($C$4:C4,C4) -> 1 | E4: 3 | F4: 100 | G4: 0 | H4: ="WEAPON_SKILL_REINFORCE_NAME_"&C4 -> WEAPON_SKILL_REINFORCE_NAME_11301 | I4: ="WEAPON_SKILL_REINFORCE_ICON_"&C4 -> WEAPON_SKILL_REINFORCE_ICON_11301 | J4: =VLOOKUP(E4,SKILL_TYPE,2,0)&" "&IF(G4=0,F4,F4/100&"%")&" 증가" -> 치명 수치 100 증가
A5: =C5*스킬_강화_그룹_단위+D5 -> 1130102 | B5: WHITE FANG 465 | C5: =VLOOKUP(B5,WEAPON!$B:$D,3,0) -> 11301 | D5: 2 | E5: 3 | F5: 105 | G5: 0 | H5: ="WEAPON_SKILL_REINFORCE_NAME_"&C5 -> WEAPON_SKILL_REINFORCE_NAME_11301 | I5: ="WEAPON_SKILL_REINFORCE_ICON_"&C5 -> WEAPON_SKILL_REINFORCE_ICON_11301 | J5: =VLOOKUP(E5,SKILL_TYPE,2,0)&" "&IF(G5=0,F5,F5/100&"%")&" 증가" -> 치명 수치 105 증가
A6: =C6*스킬_강화_그룹_단위+D6 -> 1130103 | B6: WHITE FANG 465 | C6: =VLOOKUP(B6,WEAPON!$B:$D,3,0) -> 11301 | D6: =COUNTIF($C$4:C6,C6) -> 3 | E6: 3 | F6: 110 | G6: 0 | H6: ="WEAPON_SKILL_REINFORCE_NAME_"&C6 -> WEAPON_SKILL_REINFORCE_NAME_11301 | I6: ="WEAPON_SKILL_REINFORCE_ICON_"&C6 -> WEAPON_SKILL_REINFORCE_ICON_11301 | J6: =VLOOKUP(E6,SKILL_TYPE,2,0)&" "&IF(G6=0,F6,F6/100&"%")&" 증가" -> 치명 수치 110 증가
A7: =C7*스킬_강화_그룹_단위+D7 -> 1130104 | B7: WHITE FANG 465 | C7: =VLOOKUP(B7,WEAPON!$B:$D,3,0) -> 11301 | D7: =COUNTIF($C$4:C7,C7) -> 4 | E7: 3 | F7: 130 | G7: 0 | H7: ="WEAPON_SKILL_REINFORCE_NAME_"&C7 -> WEAPON_SKILL_REINFORCE_NAME_11301 | I7: ="WEAPON_SKILL_REINFORCE_ICON_"&C7 -> WEAPON_SKILL_REINFORCE_ICON_11301 | J7: =VLOOKUP(E7,SKILL_TYPE,2,0)&" "&IF(G7=0,F7,F7/100&"%")&" 증가" -> 치명 수치 130 증가
A8: =C8*스킬_강화_그룹_단위+D8 -> 1130105 | B8: WHITE FANG 465 | C8: =VLOOKUP(B8,WEAPON!$B:$D,3,0) -> 11301 | D8: =COUNTIF($C$4:C8,C8) -> 5 | E8: 3 | F8: 135 | G8: 0 | H8: ="WEAPON_SKILL_REINFORCE_NAME_"&C8 -> WEAPON_SKILL_REINFORCE_NAME_11301 | I8: ="WEAPON_SKILL_REINFORCE_ICON_"&C8 -> WEAPON_SKILL_REINFORCE_ICON_11301 | J8: =VLOOKUP(E8,SKILL_TYPE,2,0)&" "&IF(G8=0,F8,F8/100&"%")&" 증가" -> 치명 수치 135 증가
A9: =C9*스킬_강화_그룹_단위+D9 -> 1130106 | B9: WHITE FANG 465 | C9: =VLOOKUP(B9,WEAPON!$B:$D,3,0) -> 11301 | D9: =COUNTIF($C$4:C9,C9) -> 6 | E9: 3 | F9: 140 | G9: 0 | H9: ="WEAPON_SKILL_REINFORCE_NAME_"&C9 -> WEAPON_SKILL_REINFORCE_NAME_11301 | I9: ="WEAPON_SKILL_REINFORCE_ICON_"&C9 -> WEAPON_SKILL_REINFORCE_ICON_11301 | J9: =VLOOKUP(E9,SKILL_TYPE,2,0)&" "&IF(G9=0,F9,F9/100&"%")&" 증가" -> 치명 수치 140 증가
A10: =C10*스킬_강화_그룹_단위+D10 -> 1130107 | B10: WHITE FANG 465 | C10: =VLOOKUP(B10,WEAPON!$B:$D,3,0) -> 11301 | D10: =COUNTIF($C$4:C10,C10) -> 7 | E10: 3 | F10: 160 | G10: 0 | H10: ="WEAPON_SKILL_REINFORCE_NAME_"&C10 -> WEAPON_SKILL_REINFORCE_NAME_11301 | I10: ="WEAPON_SKILL_REINFORCE_ICON_"&C10 -> WEAPON_SKILL_REINFORCE_ICON_11301 | J10: =VLOOKUP(E10,SKILL_TYPE,2,0)&" "&IF(G10=0,F10,F10/100&"%")&" 증가" -> 치명 수치 160 증가
A11: =C11*스킬_강화_그룹_단위+D11 -> 1130108 | B11: WHITE FANG 465 | C11: =VLOOKUP(B11,WEAPON!$B:$D,3,0) -> 11301 | D11: =COUNTIF($C$4:C11,C11) -> 8 | E11: 3 | F11: 165 | G11: 0 | H11: ="WEAPON_SKILL_REINFORCE_NAME_"&C11 -> WEAPON_SKILL_REINFORCE_NAME_11301 | I11: ="WEAPON_SKILL_REINFORCE_ICON_"&C11 -> WEAPON_SKILL_REINFORCE_ICON_11301 | J11: =VLOOKUP(E11,SKILL_TYPE,2,0)&" "&IF(G11=0,F11,F11/100&"%")&" 증가" -> 치명 수치 165 증가
A12: =C12*스킬_강화_그룹_단위+D12 -> 1130109 | B12: WHITE FANG 465 | C12: =VLOOKUP(B12,WEAPON!$B:$D,3,0) -> 11301 | D12: =COUNTIF($C$4:C12,C12) -> 9 | E12: 3 | F12: 170 | G12: 0 | H12: ="WEAPON_SKILL_REINFORCE_NAME_"&C12 -> WEAPON_SKILL_REINFORCE_NAME_11301 | I12: ="WEAPON_SKILL_REINFORCE_ICON_"&C12 -> WEAPON_SKILL_REINFORCE_ICON_11301 | J12: =VLOOKUP(E12,SKILL_TYPE,2,0)&" "&IF(G12=0,F12,F12/100&"%")&" 증가" -> 치명 수치 170 증가
A13: =C13*스킬_강화_그룹_단위+D13 -> 1130110 | B13: WHITE FANG 465 | C13: =VLOOKUP(B13,WEAPON!$B:$D,3,0) -> 11301 | D13: =COUNTIF($C$4:C13,C13) -> 10 | E13: 3 | F13: 190 | G13: 0 | H13: ="WEAPON_SKILL_REINFORCE_NAME_"&C13 -> WEAPON_SKILL_REINFORCE_NAME_11301 | I13: ="WEAPON_SKILL_REINFORCE_ICON_"&C13 -> WEAPON_SKILL_REINFORCE_ICON_11301 | J13: =VLOOKUP(E13,SKILL_TYPE,2,0)&" "&IF(G13=0,F13,F13/100&"%")&" 증가" -> 치명 수치 190 증가
A14: =C14*스킬_강화_그룹_단위+D14 -> 1230201 | B14: 호루스의 눈 | C14: =VLOOKUP(B14,WEAPON!$B:$D,3,0) -> 12302 | D14: =COUNTIF($C$4:C14,C14) -> 1 | E14: 8 | F14: 200 | G14: 0 | H14: ="WEAPON_SKILL_REINFORCE_NAME_"&C14 -> WEAPON_SKILL_REINFORCE_NAME_12302 | I14: ="WEAPON_SKILL_REINFORCE_ICON_"&C14 -> WEAPON_SKILL_REINFORCE_ICON_12302 | J14: =VLOOKUP(E14,SKILL_TYPE,2,0)&" "&IF(G14=0,F14,F14/100&"%")&" 증가" -> 방어력 200 증가
A15: =C15*스킬_강화_그룹_단위+D15 -> 1230202 | B15: 호루스의 눈 | C15: =VLOOKUP(B15,WEAPON!$B:$D,3,0) -> 12302 | D15: =COUNTIF($C$4:C15,C15) -> 2 | E15: 8 | F15: 210 | G15: 0 | H15: ="WEAPON_SKILL_REINFORCE_NAME_"&C15 -> WEAPON_SKILL_REINFORCE_NAME_12302 | I15: ="WEAPON_SKILL_REINFORCE_ICON_"&C15 -> WEAPON_SKILL_REINFORCE_ICON_12302 | J15: =VLOOKUP(E15,SKILL_TYPE,2,0)&" "&IF(G15=0,F15,F15/100&"%")&" 증가" -> 방어력 210 증가
A16: =C16*스킬_강화_그룹_단위+D16 -> 1230203 | B16: 호루스의 눈 | C16: =VLOOKUP(B16,WEAPON!$B:$D,3,0) -> 12302 | D16: =COUNTIF($C$4:C16,C16) -> 3 | E16: 8 | F16: 220 | G16: 0 | H16: ="WEAPON_SKILL_REINFORCE_NAME_"&C16 -> WEAPON_SKILL_REINFORCE_NAME_12302 | I16: ="WEAPON_SKILL_REINFORCE_ICON_"&C16 -> WEAPON_SKILL_REINFORCE_ICON_12302 | J16: =VLOOKUP(E16,SKILL_TYPE,2,0)&" "&IF(G16=0,F16,F16/100&"%")&" 증가" -> 방어력 220 증가
A17: =C17*스킬_강화_그룹_단위+D17 -> 1230204 | B17: 호루스의 눈 | C17: =VLOOKUP(B17,WEAPON!$B:$D,3,0) -> 12302 | D17: =COUNTIF($C$4:C17,C17) -> 4 | E17: 8 | F17: 260 | G17: 0 | H17: ="WEAPON_SKILL_REINFORCE_NAME_"&C17 -> WEAPON_SKILL_REINFORCE_NAME_12302 | I17: ="WEAPON_SKILL_REINFORCE_ICON_"&C17 -> WEAPON_SKILL_REINFORCE_ICON_12302 | J17: =VLOOKUP(E17,SKILL_TYPE,2,0)&" "&IF(G17=0,F17,F17/100&"%")&" 증가" -> 방어력 260 증가
... A963: =C963*스킬_강화_그룹_단위+D963 -> 2433010 | B963: 공연용 티셔츠 캐논 | C963: =VLOOKUP(B963,WEAPON!$B:$D,3,0) -> 24330 | D963: =COUNTIF($C$4:C963,C963) -> 10 | E963: 11 | F963: 1340 | G963: 0 | H963: ="WEAPON_SKILL_REINFORCE_NAME_"&C963 -> WEAPON_SKILL_REINFORCE_NAME_24330 | I963: ="WEAPON_SKILL_REINFORCE_ICON_"&C963 -> WEAPON_SKILL_REINFORCE_ICON_24330 | J963: =VLOOKUP(E963,SKILL_TYPE,2,0)&" "&IF(G963=0,F963,F963/100&"%")&" 증가" -> 치유력 1340 증가

Sheet WARFARE_REINFORCE
A1: 아이디 | B1: #학생 이름 | C1: 강화 전투 장소 타입 | D1: 강화 전투 장소 값 | E1: 상성 강화 설명 | F1: 상성 강화 아이콘 | G1: #상성 강화 설명
A2: ID | B2: STUDENT_NAME | C2: WARFARE_TYPE | D2: WARFARE_VALUE | E2: WARFARE_REINFORCE_DESC | F2: WARFARE_REINFORCE_ICON | G2: WARFARE_DESC
A3: int | B3: 참조 | C3: int | D3: int | E3: string | F3: string | G3: 참조
A4: =INDEX(STUDENT!A:A,MATCH(B4,STUDENT!B:B,0))*상성_강화_아이디_단위+C4 -> 113011 | B4: 시로코 | C4: 1 | D4: 1 | E4: ="WEAPON_WARFARE_REINFORCE_DESC_"&A4 -> WEAPON_WARFARE_REINFORCE_DESC_113011 | F4: ="WEAPON_WARFARE_REINFORCE_ICON_"&A4 -> WEAPON_WARFARE_REINFORCE_ICON_113011 | G4: =VLOOKUP(C4,상성_강화_장소_타입,2,0)&" 지형전투력을 "&VLOOKUP(D4,상성_등급_단위,2,0)&"로 강화" -> 시가전 지형전투력을 SS로 강화
A5: =INDEX(STUDENT!A:A,MATCH(B5,STUDENT!B:B,0))*상성_강화_아이디_단위+C5 -> 123022 | B5: 호시노 | C5: 2 | D5: 1 | E5: ="WEAPON_WARFARE_REINFORCE_DESC_"&A5 -> WEAPON_WARFARE_REINFORCE_DESC_123022 | F5: ="WEAPON_WARFARE_REINFORCE_ICON_"&A5 -> WEAPON_WARFARE_REINFORCE_ICON_123022 | G5: =VLOOKUP(C5,상성_강화_장소_타입,2,0)&" 지형전투력을 "&VLOOKUP(D5,상성_등급_단위,2,0)&"로 강화" -> 야전 지형전투력을 SS로 강화
A6: =INDEX(STUDENT!A:A,MATCH(B6,STUDENT!B:B,0))*상성_강화_아이디_단위+C6 -> 112032 | B6: 세리카 | C6: 2 | D6: 4 | E6: ="WEAPON_WARFARE_REINFORCE_DESC_"&A6 -> WEAPON_WARFARE_REINFORCE_DESC_112032 | F6: ="WEAPON_WARFARE_REINFORCE_ICON_"&A6 -> WEAPON_WARFARE_REINFORCE_ICON_112032 | G6: =VLOOKUP(C6,상성_강화_장소_타입,2,0)&" 지형전투력을 "&VLOOKUP(D6,상성_등급_단위,2,0)&"로 강화" -> 야전 지형전투력을 B로 강화
A7: =INDEX(STUDENT!A:A,MATCH(B7,STUDENT!B:B,0))*상성_강화_아이디_단위+C7 -> 112043 | B7: 노노미 | C7: 3 | D7: 4 | E7: ="WEAPON_WARFARE_REINFORCE_DESC_"&A7 -> WEAPON_WARFARE_REINFORCE_DESC_112043 | F7: ="WEAPON_WARFARE_REINFORCE_ICON_"&A7 -> WEAPON_WARFARE_REINFORCE_ICON_112043 | G7: =VLOOKUP(C7,상성_강화_장소_타입,2,0)&" 지형전투력을 "&VLOOKUP(D7,상성_등급_단위,2,0)&"로 강화" -> 실내전 지형전투력을 B로 강화
A8: =INDEX(STUDENT!A:A,MATCH(B8,STUDENT!B:B,0))*상성_강화_아이디_단위+C8 -> 232011 | B8: 아야네 | C8: 1 | D8: 4 | E8: ="WEAPON_WARFARE_REINFORCE_DESC_"&A8 -> WEAPON_WARFARE_REINFORCE_DESC_232011 | F8: ="WEAPON_WARFARE_REINFORCE_ICON_"&A8 -> WEAPON_WARFARE_REINFORCE_ICON_232011 | G8: =VLOOKUP(C8,상성_강화_장소_타입,2,0)&" 지형전투력을 "&VLOOKUP(D8,상성_등급_단위,2,0)&"로 강화" -> 시가전 지형전투력을 B로 강화
A9: =INDEX(STUDENT!A:A,MATCH(B9,STUDENT!B:B,0))*상성_강화_아이디_단위+C9 -> 113051 | B9: 아루 | C9: 1 | D9: 1 | E9: ="WEAPON_WARFARE_REINFORCE_DESC_"&A9 -> WEAPON_WARFARE_REINFORCE_DESC_113051 | F9: ="WEAPON_WARFARE_REINFORCE_ICON_"&A9 -> WEAPON_WARFARE_REINFORCE_ICON_113051 | G9: =VLOOKUP(C9,상성_강화_장소_타입,2,0)&" 지형전투력을 "&VLOOKUP(D9,상성_등급_단위,2,0)&"로 강화" -> 시가전 지형전투력을 SS로 강화
A10: =INDEX(STUDENT!A:A,MATCH(B10,STUDENT!B:B,0))*상성_강화_아이디_단위+C10 -> 112063 | B10: 무츠키 | C10: 3 | D10: 4 | E10: ="WEAPON_WARFARE_REINFORCE_DESC_"&A10 -> WEAPON_WARFARE_REINFORCE_DESC_112063 | F10: ="WEAPON_WARFARE_REINFORCE_ICON_"&A10 -> WEAPON_WARFARE_REINFORCE_ICON_112063 | G10: =VLOOKUP(C10,상성_강화_장소_타입,2,0)&" 지형전투력을 "&VLOOKUP(D10,상성_등급_단위,2,0)&"로 강화" -> 실내전 지형전투력을 B로 강화
A11: =INDEX(STUDENT!A:A,MATCH(B11,STUDENT!B:B,0))*상성_강화_아이디_단위+C11 -> 142072 | B11: 카요코 | C11: 2 | D11: 4 | E11: ="WEAPON_WARFARE_REINFORCE_DESC_"&A11 -> WEAPON_WARFARE_REINFORCE_DESC_142072 | F11: ="WEAPON_WARFARE_REINFORCE_ICON_"&A11 -> WEAPON_WARFARE_REINFORCE_ICON_142072 | G11: =VLOOKUP(C11,상성_강화_장소_타입,2,0)&" 지형전투력을 "&VLOOKUP(D11,상성_등급_단위,2,0)&"로 강화" -> 야전 지형전투력을 B로 강화
A12: =INDEX(STUDENT!A:A,MATCH(B12,STUDENT!B:B,0))*상성_강화_아이디_단위+C12 -> 111081 | B12: 하루카 | C12: 1 | D12: 4 | E12: ="WEAPON_WARFARE_REINFORCE_DESC_"&A12 -> WEAPON_WARFARE_REINFORCE_DESC_111081 | F12: ="WEAPON_WARFARE_REINFORCE_ICON_"&A12 -> WEAPON_WARFARE_REINFORCE_ICON_111081 | G12: =VLOOKUP(C12,상성_강화_장소_타입,2,0)&" 지형전투력을 "&VLOOKUP(D12,상성_등급_단위,2,0)&"로 강화" -> 시가전 지형전투력을 B로 강화
A13: =INDEX(STUDENT!A:A,MATCH(B13,STUDENT!B:B,0))*상성_강화_아이디_단위+C13 -> 113091 | B13: 히나 | C13: 1 | D13: 1 | E13: ="WEAPON_WARFARE_REINFORCE_DESC_"&A13 -> WEAPON_WARFARE_REINFORCE_DESC_113091 | F13: ="WEAPON_WARFARE_REINFORCE_ICON_"&A13 -> WEAPON_WARFARE_REINFORCE_ICON_113091 | G13: =VLOOKUP(C13,상성_강화_장소_타입,2,0)&" 지형전투력을 "&VLOOKUP(D13,상성_등급_단위,2,0)&"로 강화" -> 시가전 지형전투력을 SS로 강화
A14: =INDEX(STUDENT!A:A,MATCH(B14,STUDENT!B:B,0))*상성_강화_아이디_단위+C14 -> 243023 | B14: 아코 | C14: 3 | D14: 1 | E14: ="WEAPON_WARFARE_REINFORCE_DESC_"&A14 -> WEAPON_WARFARE_REINFORCE_DESC_243023 | F14: ="WEAPON_WARFARE_REINFORCE_ICON_"&A14 -> WEAPON_WARFARE_REINFORCE_ICON_243023 | G14: =VLOOKUP(C14,상성_강화_장소_타입,2,0)&" 지형전투력을 "&VLOOKUP(D14,상성_등급_단위,2,0)&"로 강화" -> 실내전 지형전투력을 SS로 강화
A15: =INDEX(STUDENT!A:A,MATCH(B15,STUDENT!B:B,0))*상성_강화_아이디_단위+C15 -> 113103 | B15: 이오리 | C15: 3 | D15: 1 | E15: ="WEAPON_WARFARE_REINFORCE_DESC_"&A15 -> WEAPON_WARFARE_REINFORCE_DESC_113103 | F15: ="WEAPON_WARFARE_REINFORCE_ICON_"&A15 -> WEAPON_WARFARE_REINFORCE_ICON_113103 | G15: =VLOOKUP(C15,상성_강화_장소_타입,2,0)&" 지형전투력을 "&VLOOKUP(D15,상성_등급_단위,2,0)&"로 강화" -> 실내전 지형전투력을 SS로 강화
... A99: =INDEX(STUDENT!A:A,MATCH(B99,STUDENT!B:B,0))*상성_강화_아이디_단위+C99 -> 243301 | B99: 미쿠 | C99: 1 | D99: 1 | E99: ="WEAPON_WARFARE_REINFORCE_DESC_"&A99 -> WEAPON_WARFARE_REINFORCE_DESC_243301 | F99: ="WEAPON_WARFARE_REINFORCE_ICON_"&A99 -> WEAPON_WARFARE_REINFORCE_ICON_243301 | G99: =VLOOKUP(C99,상성_강화_장소_타입,2,0)&" 지형전투력을 "&VLOOKUP(D99,상성_등급_단위,2,0)&"로 강화" -> 시가전 지형전투력을 SS로 강화

Sheet WEAPON_EXP_INFO
A1: 아이디 | B1: 등급 | C1: 레벨 | D1: 필요 경험치 | E1: 누적 경험치 | F1: 필요 크레딧
A2: ID | B2: RANK | C2: LEVEL | D2: NEED_EXP | E2: ACCURE_EXP | F2: NEED_CREDIT
A3: int | B3: int | C3: int | D3: int | E3: int | F3: int
A4: =B4*ID규칙_등급_단위+C4 -> 101 | B4: 1 | C4: 1 | D4: 25 | E4: 25 | F4: 4500
A5: =B5*ID규칙_등급_단위+C5 -> 102 | B5: 1 | C5: 2 | D5: 30 | E5: 55 | F5: 5400
A6: =B6*ID규칙_등급_단위+C6 -> 103 | B6: 1 | C6: 3 | D6: 35 | E6: 90 | F6: 6300
A7: =B7*ID규칙_등급_단위+C7 -> 104 | B7: 1 | C7: 4 | D7: 40 | E7: 130 | F7: 7200
A8: =B8*ID규칙_등급_단위+C8 -> 105 | B8: 1 | C8: 5 | D8: 45 | E8: 175 | F8: 8100
A9: =B9*ID규칙_등급_단위+C9 -> 106 | B9: 1 | C9: 6 | D9: 50 | E9: 225 | F9: 9000
A10: =B10*ID규칙_등급_단위+C10 -> 107 | B10: 1 | C10: 7 | D10: 55 | E10: 280 | F10: 9900
A11: =B11*ID규칙_등급_단위+C11 -> 108 | B11: 1 | C11: 8 | D11: 60 | E11: 340 | F11: 10800
A12: =B12*ID규칙_등급_단위+C12 -> 109 | B12: 1 | C12: 9 | D12: 65 | E12: 405 | F12: 11700
A13: =B13*ID규칙_등급_단위+C13 -> 110 | B13: 1 | C13: 10 | D13: 70 | E13: 475 | F13: 12600
A14: =B14*ID규칙_등급_단위+C14 -> 111 | B14: 1 | C14: 11 | D14: 80 | E14: 555 | F14: 14400
A15: =B15*ID규칙_등급_단위+C15 -> 112 | B15: 1 | C15: 12 | D15: 90 | E15: 645 | F15: 16200
... A53: =B53*ID규칙_등급_단위+C53 -> 350 | B53: 3 | C53: 50 | D53: 0 | E53: 0 | F53: 0

Sheet STUDENT
A1: 아이디 | B1: #학생 이름 | C1: 역할 | D1: 상세 역할 | E1: 등급 | F1: 최대 레벨 | G1: 공격 위치 | H1: 공격 타입 | I1: 방어 타입 | J1: 시가전 등급 | K1: 야전 등급 | L1: 실내전 등급 | M1: 대사 그룹 | N1: 애용품 그룹 | O1: 학생 이름 | P1: 학생 이미지
A2: ID | B2: STUDENT_NAME | C2: ROLE | D2: DETAIL_ROLE | E2: RANK | F2: MAX_LEVEL | G2: POSITION_TYPE | H2: OFFENSE_TYPE | I2: DEFENSE_TYPE | J2: CITY_WAR_RANK | K2: OUTSIDE_WAR_RANK | L2: INSIDE_WAR_RANK | M2: SPEECH_GROUP | N2: UNIQUE_ITEM_GROUP | O2: STUDENT_NAME | P2: STUDENT_IMAGE
A3: int | B3: 참조 | C3: int | D3: int | E3: int | F3: int | G3: int | H3: int | I3: int | J3: int | K3: int | L3: int | M3: int | N3: int | O3: string | P3: string
A4: =C4*ID규칙_학생_역할_단위+D4*ID규칙_학생_상세_역할_단위+E4*ID규칙_학생_등급_단위+COUNTIF($C$4:C4,C4) -> 11301 | B4: 시로코 | C4: 1 | D4: 1 | E4: 3 | F4: 81 | G4: 2 | H4: 1 | I4: 1 | J4: 2 | K4: 4 | L4: 6 | M4: =C4*10000+D4*1000+E4*100+COUNTIF($C$4:C4,C4) -> 11301 | N4: =IFERROR(VLOOKUP(B4,STUDENT_UNIQUE_ITEM!$C:$D,2,0),0) -> 11301 | O4: ="STUDENT_NAME_"&A4 -> STUDENT_NAME_11301 | P4: ="STUDENT_IMAGE_"&A4 -> STUDENT_IMAGE_11301
A5: =C5*ID규칙_학생_역할_단위+D5*ID규칙_학생_상세_역할_단위+E5*ID규칙_학생_등급_단위+COUNTIF($C$4:C5,C5) -> 12302 | B5: 호시노 | C5: 1 | D5: 2 | E5: 3 | F5: 81 | G5: 1 | H5: 2 | I5: 2 | J5: 6 | K5: 2 | L5: 4 | M5: =C5*10000+D5*1000+E5*100+COUNTIF($C$4:C5,C5) -> 12302 | N5: =IFERROR(VLOOKUP(B5,STUDENT_UNIQUE_ITEM!$C:$D,2,0),0) -> 0 | O5: ="STUDENT_NAME_"&A5 -> STUDENT_NAME_12302 | P5: ="STUDENT_IMAGE_"&A5 -> STUDENT_IMAGE_12302
A6: =C6*ID규칙_학생_역할_단위+D6*ID규칙_학생_상세_역할_단위+E6*ID규칙_학생_등급_단위+COUNTIF($C$4:C6,C6) -> 11203 | B6: 세리카 | C6: 1 | D6: 1 | E6: 2 | F6: 81 | G6: 2 | H6: 1 | I6: 1 | J6: 3 | K6: 6 | L6: 3 | M6: =C6*10000+D6*1000+E6*100+COUNTIF($C$4:C6,C6) -> 11203 | N6: =IFERROR(VLOOKUP(B6,STUDENT_UNIQUE_ITEM!$C:$D,2,0),0) -> 0 | O6: ="STUDENT_NAME_"&A6 -> STUDENT_NAME_11203 | P6: ="STUDENT_IMAGE_"&A6 -> STUDENT_IMAGE_11203
A7: =C7*ID규칙_학생_역할_단위+D7*ID규칙_학생_상세_역할_단위+E7*ID규칙_학생_등급_단위+COUNTIF($C$4:C7,C7) -> 11204 | B7: 노노미 | C7: 1 | D7: 1 | E7: 2 | F7: 81 | G7: 3 | H7: 2 | I7: 2 | J7: 3 | K7: 3 | L7: 6 | M7: =C7*10000+D7*1000+E7*100+COUNTIF($C$4:C7,C7) -> 11204 | N7: =IFERROR(VLOOKUP(B7,STUDENT_UNIQUE_ITEM!$C:$D,2,0),0) -> 0 | O7: ="STUDENT_NAME_"&A7 -> STUDENT_NAME_11204 | P7: ="STUDENT_IMAGE_"&A7 -> STUDENT_IMAGE_11204
A8: =C8*ID규칙_학생_역할_단위+D8*ID규칙_학생_상세_역할_단위+E8*ID규칙_학생_등급_단위+COUNTIF($C$4:C8,C8) -> 23201 | B8: 아야네 | C8: 2 | D8: 3 | E8: 2 | F8: 81 | G8: 3 | H8: 2 | I8: 1 | J8: 6 | K8: 3 | L8: 3 | M8: =C8*10000+D8*1000+E8*100+COUNTIF($C$4:C8,C8) -> 23201 | N8: =IFERROR(VLOOKUP(B8,STUDENT_UNIQUE_ITEM!$C:$D,2,0),0) -> 0 | O8: ="STUDENT_NAME_"&A8 -> STUDENT_NAME_23201 | P8: ="STUDENT_IMAGE_"&A8 -> STUDENT_IMAGE_23201
A9: =C9*ID규칙_학생_역할_단위+D9*ID규칙_학생_상세_역할_단위+E9*ID규칙_학생_등급_단위+COUNTIF($C$4:C9,C9) -> 11305 | B9: 아루 | C9: 1 | D9: 1 | E9: 3 | F9: 81 | G9: 3 | H9: 1 | I9: 1 | J9: 2 | K9: 4 | L9: 6 | M9: =C9*10000+D9*1000+E9*100+COUNTIF($C$4:C9,C9) -> 11305 | N9: =IFERROR(VLOOKUP(B9,STUDENT_UNIQUE_ITEM!$C:$D,2,0),0) -> 11305 | O9: ="STUDENT_NAME_"&A9 -> STUDENT_NAME_11305 | P9: ="STUDENT_IMAGE_"&A9 -> STUDENT_IMAGE_11305
A10: =C10*ID규칙_학생_역할_단위+D10*ID규칙_학생_상세_역할_단위+E10*ID규칙_학생_등급_단위+COUNTIF($C$4:C10,C10) -> 11206 | B10: 무츠키 | C10: 1 | D10: 1 | E10: 2 | F10: 81 | G10: 3 | H10: 1 | I10: 1 | J10: 3 | K10: 3 | L10: 6 | M10: =C10*10000+D10*1000+E10*100+COUNTIF($C$4:C10,C10) -> 11206 | N10: =IFERROR(VLOOKUP(B10,STUDENT_UNIQUE_ITEM!$C:$D,2,0),0) -> 0 | O10: ="STUDENT_NAME_"&A10 -> STUDENT_NAME_11206 | P10: ="STUDENT_IMAGE_"&A10 -> STUDENT_IMAGE_11206
A11: =C11*ID규칙_학생_역할_단위+D11*ID규칙_학생_상세_역할_단위+E11*ID규칙_학생_등급_단위+COUNTIF($C$4:C11,C11) -> 14207 | B11: 카요코 | C11: 1 | D11: 4 | E11: 2 | F11: 81 | G11: 1 | H11: 1 | I11: 2 | J11: 3 | K11: 6 | L11: 3 | M11: =C11*10000+D11*1000+E11*100+COUNTIF($C$4:C11,C11) -> 14207 | N11: =IFERROR(VLOOKUP(B11,STUDENT_UNIQUE_ITEM!$C:$D,2,0),0) -> 0 | O11: ="STUDENT_NAME_"&A11 -> STUDENT_NAME_14207 | P11: ="STUDENT_IMAGE_"&A11 -> STUDENT_IMAGE_14207
A12: =C12*ID규칙_학생_역할_단위+D12*ID규칙_학생_상세_역할_단위+E12*ID규칙_학생_등급_단위+COUNTIF($C$4:C12,C12) -> 11108 | B12: 하루카 | C12: 1 | D12: 1 | E12: 1 | F12: 81 | G12: 1 | H12: 1 | I12: 1 | J12: 5 | K12: 4 | L12: 3 | M12: =C12*10000+D12*1000+E12*100+COUNTIF($C$4:C12,C12) -> 11108 | N12: =IFERROR(VLOOKUP(B12,STUDENT_UNIQUE_ITEM!$C:$D,2,0),0) -> 0 | O12: ="STUDENT_NAME_"&A12 -> STUDENT_NAME_11108 | P12: ="STUDENT_IMAGE_"&A12 -> STUDENT_IMAGE_11108
A13: =C13*ID규칙_학생_역할_단위+D13*ID규칙_학생_상세_역할_단위+E13*ID규칙_학생_등급_단위+COUNTIF($C$4:C13,C13) -> 11309 | B13: 히나 | C13: 1 | D13: 1 | E13: 3 | F13: 81 | G13: 3 | H13: 1 | I13: 2 | J13: 2 | K13: 6 | L13: 6 | M13: =C13*10000+D13*1000+E13*100+COUNTIF($C$4:C13,C13) -> 11309 | N13: =IFERROR(VLOOKUP(B13,STUDENT_UNIQUE_ITEM!$C:$D,2,0),0) -> 11309 | O13: ="STUDENT_NAME_"&A13 -> STUDENT_NAME_11309 | P13: ="STUDENT_IMAGE_"&A13 -> STUDENT_IMAGE_11309
A14: =C14*ID규칙_학생_역할_단위+D14*ID규칙_학생_상세_역할_단위+E14*ID규칙_학생_등급_단위+COUNTIF($C$4:C14,C14) -> 24302 | B14: 아코 | C14: 2 | D14: 4 | E14: 3 | F14: 81 | G14: 3 | H14: 3 | I14: 2 | J14: 6 | K14: 4 | L14: 2 | M14: =C14*10000+D14*1000+E14*100+COUNTIF($C$4:C14,C14) -> 24302 | N14: =IFERROR(VLOOKUP(B14,STUDENT_UNIQUE_ITEM!$C:$D,2,0),0) -> 0 | O14: ="STUDENT_NAME_"&A14 -> STUDENT_NAME_24302 | P14: ="STUDENT_IMAGE_"&A14 -> STUDENT_IMAGE_24302
A15: =C15*ID규칙_학생_역할_단위+D15*ID규칙_학생_상세_역할_단위+E15*ID규칙_학생_등급_단위+COUNTIF($C$4:C15,C15) -> 11310 | B15: 이오리 | C15: 1 | D15: 1 | E15: 3 | F15: 81 | G15: 3 | H15: 1 | I15: 3 | J15: 5 | K15: 5 | L15: 2 | M15: =C15*10000+D15*1000+E15*100+COUNTIF($C$4:C15,C15) -> 11310 | N15: =IFERROR(VLOOKUP(B15,STUDENT_UNIQUE_ITEM!$C:$D,2,0),0) -> 0 | O15: ="STUDENT_NAME_"&A15 -> STUDENT_NAME_11310 | P15: ="STUDENT_IMAGE_"&A15 -> STUDENT_IMAGE_11310
... A99: =C99*ID규칙_학생_역할_단위+D99*ID규칙_학생_상세_역할_단위+E99*ID규칙_학생_등급_단위+COUNTIF($C$4:C99,C99) -> 24330 | B99: 미쿠 | C99: 2 | D99: 4 | E99: 3 | F99: 81 | G99: 3 | H99: 1 | I99: 1 | J99: 2 | K99: 6 | L99: 4 | M99: =C99*10000+D99*1000+E99*100+COUNTIF($C$4:C99,C99) -> 24330 | N99: =IFERROR(VLOOKUP(B99,STUDENT_UNIQUE_ITEM!$C:$D,2,0),0) -> 0 | O99: ="STUDENT_NAME_"&A99 -> STUDENT_NAME_24330 | P99: ="STUDENT_IMAGE_"&A99 -> STUDENT_IMAGE_24330

Sheet STUDENT_SPEECH
A1: 아이디 | B1: #학생 이름 | C1: 대사 그룹 | D1: 메인 타입 | E1: 서브 타입 | F1: 서브 타입 값 | G1: 대사 내용 | H1: 오디오 파일 경로 | I1: #메인 타입 내용 | J1: #서브 타입 내용 | K1: 학생 대사 STRING으로 이동
A2: ID | B2: STUDENT_NAME | C2: SPEECH_GROUP | D2: MAIN_TYPE | E2: SUB_TYPE | F2: SUB_TYPE_VALUE | G2: SPEECH_DESC | H2: SPEECH_AUDIO | I2: MAIN_TYPE_DESC | J2: SUB_TYPE_DESC
A3: int | B3: 참조 | C3: int | D3: int | E3: int | F3: int | G3: string | H3: string | I3: 참고 | J3: 참고
A4: =C4*ID규칙_대사_그룹_단위+COUNTIF($C$4:C4,C4) -> 1130101 | B4: 시로코 | C4: =INDEX(STUDENT!$A:$A,MATCH(B4,STUDENT!$B:$B,0)) -> 11301 | D4: 1 | E4: 1 | F4: 0 | G4: ="SPEECH_DESC_"&A4 -> SPEECH_DESC_1130101 | H4: ="SPEECH_AUDIO_"&A4 -> SPEECH_AUDIO_1130101 | I4: =VLOOKUP(D4,SPEECH_MAIN_TYPE,2,0) -> 일상 | J4: =VLOOKUP(E4,SPEECH_SUB_TYPE,2,0)&IF(F4=0,""," "&F4) -> 입수
A5: =C5*ID규칙_대사_그룹_단위+COUNTIF($C$4:C5,C5) -> 1130102 | B5: 시로코 | C5: =INDEX(STUDENT!$A:$A,MATCH(B5,STUDENT!$B:$B,0)) -> 11301 | D5: 1 | E5: 2 | F5: 1 | G5: ="SPEECH_DESC_"&A5 -> SPEECH_DESC_1130102 | H5: ="SPEECH_AUDIO_"&A5 -> SPEECH_AUDIO_1130102 | I5: =VLOOKUP(D5,SPEECH_MAIN_TYPE,2,0) -> 일상 | J5: =VLOOKUP(E5,SPEECH_SUB_TYPE,2,0)&IF(F5=0,""," "&F5) -> 로비 방문 1
A6: =C6*ID규칙_대사_그룹_단위+COUNTIF($C$4:C6,C6) -> 1130103 | B6: 시로코 | C6: =INDEX(STUDENT!$A:$A,MATCH(B6,STUDENT!$B:$B,0)) -> 11301 | D6: 1 | E6: 2 | F6: 2 | G6: ="SPEECH_DESC_"&A6 -> SPEECH_DESC_1130103 | H6: ="SPEECH_AUDIO_"&A6 -> SPEECH_AUDIO_1130103 | I6: =VLOOKUP(D6,SPEECH_MAIN_TYPE,2,0) -> 일상 | J6: =VLOOKUP(E6,SPEECH_SUB_TYPE,2,0)&IF(F6=0,""," "&F6) -> 로비 방문 2
A7: =C7*ID규칙_대사_그룹_단위+COUNTIF($C$4:C7,C7) -> 1130104 | B7: 시로코 | C7: =INDEX(STUDENT!$A:$A,MATCH(B7,STUDENT!$B:$B,0)) -> 11301 | D7: 1 | E7: 3 | F7: 1 | G7: ="SPEECH_DESC_"&A7 -> SPEECH_DESC_1130104 | H7: ="SPEECH_AUDIO_"&A7 -> SPEECH_AUDIO_1130104 | I7: =VLOOKUP(D7,SPEECH_MAIN_TYPE,2,0) -> 일상 | J7: =VLOOKUP(E7,SPEECH_SUB_TYPE,2,0)&IF(F7=0,""," "&F7) -> 잡담 1
A8: =C8*ID규칙_대사_그룹_단위+COUNTIF($C$4:C8,C8) -> 1130105 | B8: 시로코 | C8: =INDEX(STUDENT!$A:$A,MATCH(B8,STUDENT!$B:$B,0)) -> 11301 | D8: 1 | E8: 3 | F8: 2 | G8: ="SPEECH_DESC_"&A8 -> SPEECH_DESC_1130105 | H8: ="SPEECH_AUDIO_"&A8 -> SPEECH_AUDIO_1130105 | I8: =VLOOKUP(D8,SPEECH_MAIN_TYPE,2,0) -> 일상 | J8: =VLOOKUP(E8,SPEECH_SUB_TYPE,2,0)&IF(F8=0,""," "&F8) -> 잡담 2
A9: =C9*ID규칙_대사_그룹_단위+COUNTIF($C$4:C9,C9) -> 1130106 | B9: 시로코 | C9: =INDEX(STUDENT!$A:$A,MATCH(B9,STUDENT!$B:$B,0)) -> 11301 | D9: 1 | E9: 3 | F9: 3 | G9: ="SPEECH_DESC_"&A9 -> SPEECH_DESC_1130106 | H9: ="SPEECH_AUDIO_"&A9 -> SPEECH_AUDIO_1130106 | I9: =VLOOKUP(D9,SPEECH_MAIN_TYPE,2,0) -> 일상 | J9: =VLOOKUP(E9,SPEECH_SUB_TYPE,2,0)&IF(F9=0,""," "&F9) -> 잡담 3
A10: =C10*ID규칙_대사_그룹_단위+COUNTIF($C$4:C10,C10) -> 1130107 | B10: 시로코 | C10: =INDEX(STUDENT!$A:$A,MATCH(B10,STUDENT!$B:$B,0)) -> 11301 | D10: 2 | E10: 4 | F10: 1 | G10: ="SPEECH_DESC_"&A10 -> SPEECH_DESC_1130107 | H10: ="SPEECH_AUDIO_"&A10 -> SPEECH_AUDIO_1130107 | I10: =VLOOKUP(D10,SPEECH_MAIN_TYPE,2,0) -> 배치 | J10: =VLOOKUP(E10,SPEECH_SUB_TYPE,2,0)&IF(F10=0,""," "&F10) -> 편성 1
A11: =C11*ID규칙_대사_그룹_단위+COUNTIF($C$4:C11,C11) -> 1130108 | B11: 시로코 | C11: =INDEX(STUDENT!$A:$A,MATCH(B11,STUDENT!$B:$B,0)) -> 11301 | D11: 2 | E11: 4 | F11: 2 | G11: ="SPEECH_DESC_"&A11 -> SPEECH_DESC_1130108 | H11: ="SPEECH_AUDIO_"&A11 -> SPEECH_AUDIO_1130108 | I11: =VLOOKUP(D11,SPEECH_MAIN_TYPE,2,0) -> 배치 | J11: =VLOOKUP(E11,SPEECH_SUB_TYPE,2,0)&IF(F11=0,""," "&F11) -> 편성 2
A12: =C12*ID규칙_대사_그룹_단위+COUNTIF($C$4:C12,C12) -> 1130109 | B12: 시로코 | C12: =INDEX(STUDENT!$A:$A,MATCH(B12,STUDENT!$B:$B,0)) -> 11301 | D12: 2 | E12: 4 | F12: 3 | G12: ="SPEECH_DESC_"&A12 -> SPEECH_DESC_1130109 | H12: ="SPEECH_AUDIO_"&A12 -> SPEECH_AUDIO_1130109 | I12: =VLOOKUP(D12,SPEECH_MAIN_TYPE,2,0) -> 배치 | J12: =VLOOKUP(E12,SPEECH_SUB_TYPE,2,0)&IF(F12=0,""," "&F12) -> 편성 3
A13: =C13*ID규칙_대사_그룹_단위+COUNTIF($C$4:C13,C13) -> 1130110 | B13: 시로코 | C13: =INDEX(STUDENT!$A:$A,MATCH(B13,STUDENT!$B:$B,0)) -> 11301 | D13: 2 | E13: 5 | F13: 1 | G13: ="SPEECH_DESC_"&A13 -> SPEECH_DESC_1130110 | H13: ="SPEECH_AUDIO_"&A13 -> SPEECH_AUDIO_1130110 | I13: =VLOOKUP(D13,SPEECH_MAIN_TYPE,2,0) -> 배치 | J13: =VLOOKUP(E13,SPEECH_SUB_TYPE,2,0)&IF(F13=0,""," "&F13) -> 출격 1
A14: =C14*ID규칙_대사_그룹_단위+COUNTIF($C$4:C14,C14) -> 1130111 | B14: 시로코 | C14: =INDEX(STUDENT!$A:$A,MATCH(B14,STUDENT!$B:$B,0)) -> 11301 | D14: 2 | E14: 5 | F14: 2 | G14: ="SPEECH_DESC_"&A14 -> SPEECH_DESC_1130111 | H14: ="SPEECH_AUDIO_"&A14 -> SPEECH_AUDIO_1130111 | I14: =VLOOKUP(D14,SPEECH_MAIN_TYPE,2,0) -> 배치 | J14: =VLOOKUP(E14,SPEECH_SUB_TYPE,2,0)&IF(F14=0,""," "&F14) -> 출격 2
A15: =C15*ID규칙_대사_그룹_단위+COUNTIF($C$4:C15,C15) -> 1130112 | B15: 시로코 | C15: =INDEX(STUDENT!$A:$A,MATCH(B15,STUDENT!$B:$B,0)) -> 11301 | D15: 3 | E15: 6 | F15: 1 | G15: ="SPEECH_DESC_"&A15 -> SPEECH_DESC_1130112 | H15: ="SPEECH_AUDIO_"&A15 -> SPEECH_AUDIO_1130112 | I15: =VLOOKUP(D15,SPEECH_MAIN_TYPE,2,0) -> 전투 | J15: =VLOOKUP(E15,SPEECH_SUB_TYPE,2,0)&IF(F15=0,""," "&F15) -> 전투개시 1
... A4684: =C4684*ID규칙_대사_그룹_단위+COUNTIF($C$4:C4684,C4684) -> 2433037 | B4684: 미쿠 | C4684: =INDEX(STUDENT!$A:$A,MATCH(B4684,STUDENT!$B:$B,0)) -> 24330 | D4684: 7 | E4684: 29 | F4684: 0 | G4684: ="SPEECH_DESC_"&A4684 -> SPEECH_DESC_2433037 | H4684: ="SPEECH_AUDIO_"&A4684 -> SPEECH_AUDIO_2433037 | I4684: =VLOOKUP(D4684,SPEECH_MAIN_TYPE,2,0) -> 기념일 | J4684: =VLOOKUP(E4684,SPEECH_SUB_TYPE,2,0)&IF(F4684=0,""," "&F4684) -> 신년

Sheet STUDENT_UNIQUE_ITEM
A1: 아이디 | B1: #애용품 이름 | C1: #사용 학생 이름 | D1: 애용품 그룹 | E1: 티어 | F1: 착용 슬롯 | G1: 애용품 해방 아이디 | H1: 애용품 이름 | I1: 애용품 이미지 | J1: 애용품 설명
A2: ID | B2: UNIQUE_ITEM_NAME | C2: USED_STUDENT_NAME | D2: UNIQUE_ITEM_GROUP | E2: TIER | F2: SLOT | G2: UNIQUE_LIMIT_BREAK_ID | H2: UNIQUE_ITEM_NAME | I2: UNIQUE_ITEM_IMAGE | J2: UNIQUE_ITEM_DESC
A3: int | B3: 참조 | C3: 참조 | D3: int | E3: int | F3: int | G3: int | H3: string | I3: string | J3: string
A4: =ID규칙_애용품_아이디_단위+D4*ID규칙_애용품_그룹_단위+E4 -> 1113051 | B4: 아루의 엄청 귀중한 지갑 | C4: 아루 | D4: =INDEX(STUDENT!$A:$A,MATCH(C4,STUDENT!$B:$B,0)) -> 11305 | E4: 1 | F4: 4 | G4: =D4*10+E4 -> 113051 | H4: ="UNIQUE_ITEM_NAME_"&D4 -> UNIQUE_ITEM_NAME_11305 | I4: ="UNIQUE_ITEM_IMAGE_"&D4 -> UNIQUE_ITEM_IMAGE_11305 | J4: ="UNIQUE_ITEM_DESC_"&D4 -> UNIQUE_ITEM_DESC_11305
