Workbook
Name ID규칙_등급_단위: INDEX_ITEM!$J$5
Name ID규칙_몬스터_레벨_단위: INDEX_ABYSS!$K$53
Name ID규칙_보상_그룹_단위: INDEX_ABYSS!$K$199
Name ID규칙_비경_그룹_단위: INDEX_ABYSS!$K$4
Name ID규칙_비경_조건_그룹_단위: INDEX_ABYSS!$K$90
Name ID규칙_세트_그룹_단위: INDEX_ITEM!$J$113
Name ID규칙_스테이지_타입_단위: INDEX_ABYSS!$K$5
Name ID규칙_아이템_타입_단위: INDEX_ITEM!$J$4
Name ID규칙_옵션_그룹_단위: INDEX_ITEM!$J$77
Name ID규칙_요일_단위: INDEX_ABYSS!$K$200
Name ID규칙_지맥_이상_그룹_단위: INDEX_ABYSS!$K$123
Name ID규칙_추천_원소_그룹_단위: INDEX_ABYSS!$K$67
Name ID규칙_토벌_리스트_그룹_단위: INDEX_ABYSS!$K$41
Name ID규칙_획득처_그룹_단위: INDEX_ITEM!$J$181
Name 세트_옵션타입: INDEX_ITEM!$B$133:$C$171
Name 세트_컨디션타입: INDEX_ITEM!$F$133:$G$163
Name 옵션_타입: INDEX_ABYSS!$B$139:$C$189
Name 주옵션_타입: INDEX_ITEM!$B$90:$C$108
Name 컨디션_타입: INDEX_ABYSS!$E$139:$F$179
Name 필요조건그룹: INDEX_ABYSS!$B$101:$C$108
Name 획득_컨텐츠: INDEX_ITEM!$B$193:$C$271

Sheet DATA
F1: 데이터 구조도
D5: PENALTY_OPTION | F5: ABYSS | H5: ABYSS_CONDITION | J5: QUEST
D6: ID | F6: ID | H6: ID | J6: ID
D7: PENALTY_GROUP | F7: ABYSS_GROUP | H7: CONDITION_GROUP | J7: QUEST_NAME
D8: CONDITION_TYPE | F8: STAGE_TYPE | H8: CONDITION_TYPE
D9: OPTION_TYPE | F9: DIFFICULTY | H9: CONDITION_VALUE
D10: IS_RATE | F10: CONDITION_GROUP
D11: OPTION_VALUE | F11: NEED_LEVEL
D12: TIME | F12: REQ_LEVEL | H12: ABYSS_MONSTER_LIST | J12: MONSTER
D13: COUNT | F13: RESET | H13: ID | J13: ID
D14: PENALTY_DESC | F14: RESIN_POINT | H14: MONSTER_LIST_GROUP | J14: MONSTER_LEVEL
F15: PENALTY_OPTION_GROUP | H15: MONSTER_ID | J15: MONSTER_NAME
F16: MONSTER_LIST_GROUP | J16: MONSTER_ICON
F17: ATTRIBUTE_GROUP
D18: REWARD | F18: FIND_REWARD_GROUP | H18: ATTRIBUTE_GROUP
D19: ID | F19: CLEAR_REWARD_GROUP | H19: ID
D20: REWARD_GROUP | F20: GROUP_NAME | H20: ATTRIBUTE_GROUP
D21: DAY | F21: GROUP_DESC | H21: ELEMENT_TYPE
D22: ITEM_ID | F22: GROUP_IMAGE
D23: SORT | F23: ABYSS_NAME
D24: ITEM_COUNT | F24: ABYSS_DESC
D25: PROBABILITY_GROUP | F25: ABYSS_IMAGE
D26: PROBABILITY
B30: ITEM_OPTION_GROUP | D30: ITEM_OPTION | F30: ITEM | H30: CATEGORY
B31: ID | D31: ID | F31: ID | H31: ID
B32: OPTION_GROUP | D32: MAIN_OPTION_GROUP | F32: CATEGORY | H32: CATEGORY
B33: OPTION_TYPE | D33: SUB_OPTION_GROUP_1 | F33: ITEM_TYPE | H33: MAX_STACK
B34: IS_RATE | D34: SUB_OPTION_PROB_1 | F34: RARE | H34: SORT
B35: OPTION_VALUE_1 | D35: SUB_OPTION_GROUP_2 | F35: IS_LOCK | H35: CATEGORY_NAME
B36: OPTION_VALUE_2 | D36: SUB_OPTION_PROB_2 | F36: MAX_STACK | H36: CATEGORY_ICON
D37: SUB_OPTION_GROUP_3 | F37: ITEM_OPTION
D38: SUB_OPTION_PROB_3 | F38: SET_GROUP | H38: SET_GROUP
D39: SUB_OPTION_GROUP_4 | F39: GAIN_GROUP | H39: ID
D40: SUB_OPTION_PROB_4 | F40: ITEM_NAME | H40: SET_GROUP
F41: ITEM_ICON | H41: SET
F42: ITEM_DESC | H42: CONDITION_TYPE
D43: ITEM_GAIN_INFO | H43: CONDITION_IS_RATE
D44: ID | H44: CONDITION_VALUE
D45: GAIN_GROUP | H45: OPTION_TYPE
D46: CONTENTS_TYPE | H46: OPTION_IS_RATE
...

Sheet INDEX_ABYSS
B2: INDEX_ABYSS
B3: ID 규칙
B4: 1 | C4: 0 | D4: 1 | E4: 1 | F4: 1 | J4: 비경 그룹 단위 | K4: 100
D5: ABYSS_GROUP | E5: STAGE_TYPE | F5: 순번 | J5: 스테이지 타입 단위 | K5: 10
B7: 한글 변수 | C7: 영어 변수 | E7: 자료형 | F7: 설명
B8: 아이디 | C8: ID | E8: INT | F8: 비경 아이디
B9: 비경 그룹 | C9: ABYSS_GROUP | E9: INT | F9: 비경 그룹 아이디
B10: 스테이지 타입 | C10: STAGE_TYPE | E10: INT | F10: 스테이지 타입
B11: 난이도 | C11: DIFFICULTY | E11: INT | F11: 난이도/단계
B12: 비경 조건 그룹 | C12: CONDITION_GROUP | E12: INT | F12: 비경 해금을 위한 요구 조건 그룹
B13: 필요 모험 등급 | C13: NEED_LEVEL | E13: INT | F13: 필요 모험 레벨
B14: 추천 파티 레벨 | C14: REQ_LEVEL | E14: INT | F14: 추천 파티 레벨
B15: 초기화 | C15: RESET | E15: INT | F15: 초기화 주기
B16: 소모 레진 | C16: RESIN_POINT | E16: INT | F16: 소모되는 레진 개수
B17: 지맥 이상 그룹 | C17: PENALTY_OPTION_GROUP | E17: INT | F17: 지맥 이상 옵션 그룹
B18: 토벌 리스트 그룹 | C18: MONSTER_LIST_GROUP | E18: INT | F18: 비경 내 토벌 리스트 그룹
... B27: 비경 이미지 경로 | C27: ABYSS_IMAGE | E27: STRING | F27: 비경 이미지
B29: STAGE_TYPE | F29: RESET
B30: INDEX | C30: 설명 | F30: INDEX | G30: 설명
B31: 1 | C31: 축성 비경 (성유물) | F31: 0 | G31: 초기화 없음
B32: 2 | C32: 연무 비경 (무기 소재) | F32: 1 | G32: 일일
B33: 3 | C33: 숙달 비경 (특성 소재) | F33: 2 | G33: 주간
B34: 4 | C34: 영역 토벌 | F34: 3 | G34: 월간
B35: 5 | C35: 나선 비경
B39: INDEX_ABYSS_MONSTER_LIST
B40: ID 규칙
B41: 1 | C41: 0 | D41: 0 | E41: 0 | F41: 1 | G41: 0 | H41: 1 | J41: 토벌 리스트 그룹 단위 | K41: 100
F42: MONSTER_LIST_GROUP | H42: 순번
B44: 한글 변수 | C44: 영어 변수 | E44: 자료형 | F44: 설명
B45: 아이디 | C45: ID | E45: INT | F45: 아이디
B46: 토벌 리스트 그룹 | C46: MONSTER_LIST_GROUP | E46: INT | F46: 토벌 리스트 그룹
B47: 몬스터 ID | C47: MONSTER_ID | E47: INT | F47: 몬스터 아이디
B51: INDEX_MONSTER
B52: ID 규칙
B53: 1 | C53: 0 | D53: 1 | E53: 0 | F53: 0 | G53: 1 | J53: 몬스터 레벨 단위 | K53: 1000
D54: MONSTER_LEVEL | G54: 순번
B56: 한글 변수 | C56: 영어 변수 | E56: 자료형 | F56: 설명
B57: 아이디 | C57: ID | E57: INT | F57: 아이디
B58: 몬스터 레벨 | C58: MONSTER_LEVEL | E58: INT | F58: 비경 조건 그룹
B59: 몬스터 이름 | C59: MONSTER_NAME | E59: STRING | F59: 몬스터 이름
...

Sheet ABYSS
A1: 아이디 | B1: #그룹 이름 | C1: #비경 이름 | D1: 비경 그룹 | E1: 스테이지 타입 | F1: 난이도 | G1: 비경 조건 그룹 | H1: 필요 모험 등급 | I1: 추천 파티 레벨 | J1: 초기화 | K1: 소모 레진 | L1: 지맥 이상 그룹 | M1: 토벌 리스트 그룹 | N1: 추천 원소 그룹 | O1: 발견 보상 그룹 | P1: 클리어 보상 그룹 | Q1: 그룹 이름 | R1: 그룹 설명 | S1: 그룹 이미지 경로 | T1: 비경 이름 | U1: 비경 설명 | V1: 비경 이미지 경로
A2: ID | B2: GROUP_NAME | C2: ABYSS_NAME | D2: ABYSS_GROUP | E2: STAGE_TYPE | F2: DIFFICULTY | G2: CONDITION_GROUP | H2: NEED_LEVEL | I2: REQ_LEVEL | J2: RESET | K2: RESIN_POINT | L2: PENALTY_OPTION_GROUP | M2: MONSTER_LIST_GROUP | N2: ATTRIBUTE_GROUP | O2: FIND_REWARD_GROUP | P2: CLEAR_REWARD_GROUP | Q2: GROUP_NAME | R2: GROUP_DESC | S2: GROUP_IMAGE | T2: ABYSS_NAME | U2: ABYSS_DESC | V2: ABYSS_IMAGE
A3: int | B3: 참조 | C3: 참조 | D3: int | E3: int | F3: int | G3: int | H3: int | I3: int | J3: int | K3: int | L3: int | M3: int | N3: int | O3: int | P3: int | Q3: string | R3: string | S3: string | T3: string | U3: string | V3: string
A4: =10000+D4*ID규칙_비경_그룹_단위+E4*ID규칙_스테이지_타입_단위+COUNTIF($D$4:D4,D4) -> 10111 | B4: =VLOOKUP(Q4,STRING!$A$3:$B$28,2,0) -> 한 여름의 정원 | C4: =VLOOKUP(T4,STRING!$A$29:$B$202,2,0) -> 축성 비경: 정화의 화염 I | D4: 1 | E4: 1 | F4: 1 | G4: =INDEX(ABYSS_CONDITION!$B$4:$B$34,MATCH(ABYSS!B4,ABYSS_CONDITION!$F$4:$F$34,0)) -> 1 | H4: 22 | I4: 34 | J4: 1 | K4: 20 | L4: =IFERROR(INDEX(PENALTY_OPTION!$B$4:$B$248,MATCH(ABYSS!C4,PENALTY_OPTION!$L$4:$L$248,0)),0) -> 1 | M4: =IFERROR(INDEX(ABYSS_MONSTER_LIST!$B:$B,MATCH(ABYSS!C4,ABYSS_MONSTER_LIST!$E:$E,0)),0) -> 1011 | N4: =IFERROR(INDEX(ATTRIBUTE_GROUP!$B:$B,MATCH(ABYSS!C4,ATTRIBUTE_GROUP!$E:$E,0)),0) -> 1011 | O4: =IF(E4=4,0,1) -> 1 | P4: =INDEX(REWARD!$B$6:$B$4545,MATCH(ABYSS!C4,REWARD!$J$6:$J$4545,0)) -> 2 | Q4: ="GROUP_NAME_"&D4 -> GROUP_NAME_1 | R4: ="GROUP_DESC_"&D4 -> GROUP_DESC_1 | S4: ="GROUP_IMAGE_"&D4 -> GROUP_IMAGE_1 | T4: ="ABYSS_NAME_"&A4 -> ABYSS_NAME_10111 | U4: ="ABYSS_DESC_"&D4 -> ABYSS_DESC_1 | V4: ="ABYSS_IMAGE_"&A4 -> ABYSS_IMAGE_10111
A5: =10000+D5*ID규칙_비경_그룹_단위+E5*ID규칙_스테이지_타입_단위+COUNTIF($D$4:D5,D5) -> 10112 | B5: =VLOOKUP(Q5,STRING!$A$3:$B$28,2,0) -> 한 여름의 정원 | C5: =VLOOKUP(T5,STRING!$A$29:$B$202,2,0) -> 축성 비경: 정화의 화염 II | D5: 1 | E5: 1 | F5: 2 | G5: =INDEX(ABYSS_CONDITION!$B$4:$B$34,MATCH(ABYSS!B5,ABYSS_CONDITION!$F$4:$F$34,0)) -> 1 | H5: 25 | I5: 47 | J5: 1 | K5: 20 | L5: =IFERROR(INDEX(PENALTY_OPTION!$B$4:$B$248,MATCH(ABYSS!C5,PENALTY_OPTION!$L$4:$L$248,0)),0) -> 2 | M5: =IFERROR(INDEX(ABYSS_MONSTER_LIST!$B:$B,MATCH(ABYSS!C5,ABYSS_MONSTER_LIST!$E:$E,0)),0) -> 1012 | N5: =IFERROR(INDEX(ATTRIBUTE_GROUP!$B:$B,MATCH(ABYSS!C5,ATTRIBUTE_GROUP!$E:$E,0)),0) -> 1012 | O5: =IF(E5=4,0,1) -> 1 | P5: =INDEX(REWARD!$B$6:$B$4545,MATCH(ABYSS!C5,REWARD!$J$6:$J$4545,0)) -> 3 | Q5: ="GROUP_NAME_"&D5 -> GROUP_NAME_1 | R5: ="GROUP_DESC_"&D5 -> GROUP_DESC_1 | S5: ="GROUP_IMAGE_"&D5 -> GROUP_IMAGE_1 | T5: ="ABYSS_NAME_"&A5 -> ABYSS_NAME_10112 | U5: ="ABYSS_DESC_"&D5 -> ABYSS_DESC_1 | V5: ="ABYSS_IMAGE_"&A5 -> ABYSS_IMAGE_10112
A6: =10000+D6*ID규칙_비경_그룹_단위+E6*ID규칙_스테이지_타입_단위+COUNTIF($D$4:D6,D6) -> 10113 | B6: =VLOOKUP(Q6,STRING!$A$3:$B$28,2,0) -> 한 여름의 정원 | C6: =VLOOKUP(T6,STRING!$A$29:$B$202,2,0) -> 축성 비경: 정화의 화염 III | D6: 1 | E6: 1 | F6: 3 | G6: =INDEX(ABYSS_CONDITION!$B$4:$B$34,MATCH(ABYSS!B6,ABYSS_CONDITION!$F$4:$F$34,0)) -> 1 | H6: 30 | I6: 59 | J6: 1 | K6: 20 | L6: =IFERROR(INDEX(PENALTY_OPTION!$B$4:$B$248,MATCH(ABYSS!C6,PENALTY_OPTION!$L$4:$L$248,0)),0) -> 3 | M6: =IFERROR(INDEX(ABYSS_MONSTER_LIST!$B:$B,MATCH(ABYSS!C6,ABYSS_MONSTER_LIST!$E:$E,0)),0) -> 1013 | N6: =IFERROR(INDEX(ATTRIBUTE_GROUP!$B:$B,MATCH(ABYSS!C6,ATTRIBUTE_GROUP!$E:$E,0)),0) -> 1013 | O6: =IF(E6=4,0,1) -> 1 | P6: =INDEX(REWARD!$B$6:$B$4545,MATCH(ABYSS!C6,REWARD!$J$6:$J$4545,0)) -> 4 | Q6: ="GROUP_NAME_"&D6 -> GROUP_NAME_1 | R6: ="GROUP_DESC_"&D6 -> GROUP_DESC_1 | S6: ="GROUP_IMAGE_"&D6 -> GROUP_IMAGE_1 | T6: ="ABYSS_NAME_"&A6 -> ABYSS_NAME_10113 | U6: ="ABYSS_DESC_"&D6 -> ABYSS_DESC_1 | V6: ="ABYSS_IMAGE_"&A6 -> ABYSS_IMAGE_10113
A7: =10000+D7*ID규칙_비경_그룹_단위+E7*ID규칙_스테이지_타입_단위+COUNTIF($D$4:D7,D7) -> 10114 | B7: =VLOOKUP(Q7,STRING!$A$3:$B$28,2,0) -> 한 여름의 정원 | C7: =VLOOKUP(T7,STRING!$A$29:$B$202,2,0) -> 축성 비경: 정화의 화염 IV | D7: 1 | E7: 1 | F7: 4 | G7: =INDEX(ABYSS_CONDITION!$B$4:$B$34,MATCH(ABYSS!B7,ABYSS_CONDITION!$F$4:$F$34,0)) -> 1 | H7: 35 | I7: 69 | J7: 1 | K7: 20 | L7: =IFERROR(INDEX(PENALTY_OPTION!$B$4:$B$248,MATCH(ABYSS!C7,PENALTY_OPTION!$L$4:$L$248,0)),0) -> 4 | M7: =IFERROR(INDEX(ABYSS_MONSTER_LIST!$B:$B,MATCH(ABYSS!C7,ABYSS_MONSTER_LIST!$E:$E,0)),0) -> 1014 | N7: =IFERROR(INDEX(ATTRIBUTE_GROUP!$B:$B,MATCH(ABYSS!C7,ATTRIBUTE_GROUP!$E:$E,0)),0) -> 1014 | O7: =IF(E7=4,0,1) -> 1 | P7: =INDEX(REWARD!$B$6:$B$4545,MATCH(ABYSS!C7,REWARD!$J$6:$J$4545,0)) -> 5 | Q7: ="GROUP_NAME_"&D7 -> GROUP_NAME_1 | R7: ="GROUP_DESC_"&D7 -> GROUP_DESC_1 | S7: ="GROUP_IMAGE_"&D7 -> GROUP_IMAGE_1 | T7: ="ABYSS_NAME_"&A7 -> ABYSS_NAME_10114 | U7: ="ABYSS_DESC_"&D7 -> ABYSS_DESC_1 | V7: ="ABYSS_IMAGE_"&A7 -> ABYSS_IMAGE_10114
A8: =10000+D8*ID규칙_비경_그룹_단위+E8*ID규칙_스테이지_타입_단위+COUNTIF($D$4:D8,D8) -> 10115 | B8: =VLOOKUP(Q8,STRING!$A$3:$B$28,2,0) -> 한 여름의 정원 | C8: =VLOOKUP(T8,STRING!$A$29:$B$202,2,0) -> 축성 비경: 정화의 화염 V | D8: 1 | E8: 1 | F8: 5 | G8: =INDEX(ABYSS_CONDITION!$B$4:$B$34,MATCH(ABYSS!B8,ABYSS_CONDITION!$F$4:$F$34,0)) -> 1 | H8: 40 | I8: 80 | J8: 1 | K8: 20 | L8: =IFERROR(INDEX(PENALTY_OPTION!$B$4:$B$248,MATCH(ABYSS!C8,PENALTY_OPTION!$L$4:$L$248,0)),0) -> 5 | M8: =IFERROR(INDEX(ABYSS_MONSTER_LIST!$B:$B,MATCH(ABYSS!C8,ABYSS_MONSTER_LIST!$E:$E,0)),0) -> 1015 | N8: =IFERROR(INDEX(ATTRIBUTE_GROUP!$B:$B,MATCH(ABYSS!C8,ATTRIBUTE_GROUP!$E:$E,0)),0) -> 1015 | O8: =IF(E8=4,0,1) -> 1 | P8: =INDEX(REWARD!$B$6:$B$4545,MATCH(ABYSS!C8,REWARD!$J$6:$J$4545,0)) -> 6 | Q8: ="GROUP_NAME_"&D8 -> GROUP_NAME_1 | R8: ="GROUP_DESC_"&D8 -> GROUP_DESC_1 | S8: ="GROUP_IMAGE_"&D8 -> GROUP_IMAGE_1 | T8: ="ABYSS_NAME_"&A8 -> ABYSS_NAME_10115 | U8: ="ABYSS_DESC_"&D8 -> ABYSS_DESC_1 | V8: ="ABYSS_IMAGE_"&A8 -> ABYSS_IMAGE_10115
A9: =10000+D9*ID규칙_비경_그룹_단위+E9*ID규칙_스테이지_타입_단위+COUNTIF($D$4:D9,D9) -> 10116 | B9: =VLOOKUP(Q9,STRING!$A$3:$B$28,2,0) -> 한 여름의 정원 | C9: =VLOOKUP(T9,STRING!$A$29:$B$202,2,0) -> 축성 비경: 정화의 화염 VI | D9: 1 | E9: 1 | F9: 6 | G9: =INDEX(ABYSS_CONDITION!$B$4:$B$34,MATCH(ABYSS!B9,ABYSS_CONDITION!$F$4:$F$34,0)) -> 1 | H9: 45 | I9: 90 | J9: 1 | K9: 20 | L9: =IFERROR(INDEX(PENALTY_OPTION!$B$4:$B$248,MATCH(ABYSS!C9,PENALTY_OPTION!$L$4:$L$248,0)),0) -> 6 | M9: =IFERROR(INDEX(ABYSS_MONSTER_LIST!$B:$B,MATCH(ABYSS!C9,ABYSS_MONSTER_LIST!$E:$E,0)),0) -> 1016 | N9: =IFERROR(INDEX(ATTRIBUTE_GROUP!$B:$B,MATCH(ABYSS!C9,ATTRIBUTE_GROUP!$E:$E,0)),0) -> 1016 | O9: =IF(E9=4,0,1) -> 1 | P9: =INDEX(REWARD!$B$6:$B$4545,MATCH(ABYSS!C9,REWARD!$J$6:$J$4545,0)) -> 7 | Q9: ="GROUP_NAME_"&D9 -> GROUP_NAME_1 | R9: ="GROUP_DESC_"&D9 -> GROUP_DESC_1 | S9: ="GROUP_IMAGE_"&D9 -> GROUP_IMAGE_1 | T9: ="ABYSS_NAME_"&A9 -> ABYSS_NAME_10116 | U9: ="ABYSS_DESC_"&D9 -> ABYSS_DESC_1 | V9: ="ABYSS_IMAGE_"&A9 -> ABYSS_IMAGE_10116
A10: =10000+D10*ID규칙_비경_그룹_단위+E10*ID규칙_스테이지_타입_단위+COUNTIF($D$4:D10,D10) -> 10211 | B10: =VLOOKUP(Q10,STRING!$A$3:$B$28,2,0) -> 각인의 골짜기 | C10: =VLOOKUP(T10,STRING!$A$29:$B$202,2,0) -> 축성 비경: 강철의 춤 I | D10: 2 | E10: 1 | F10: 1 | G10: =INDEX(ABYSS_CONDITION!$B$4:$B$34,MATCH(ABYSS!B10,ABYSS_CONDITION!$F$4:$F$34,0)) -> 2 | H10: 25 | I10: 47 | J10: 1 | K10: 20 | L10: =IFERROR(INDEX(PENALTY_OPTION!$B$4:$B$248,MATCH(ABYSS!C10,PENALTY_OPTION!$L$4:$L$248,0)),0) -> 7 | M10: =IFERROR(INDEX(ABYSS_MONSTER_LIST!$B:$B,MATCH(ABYSS!C10,ABYSS_MONSTER_LIST!$E:$E,0)),0) -> 1021 | N10: =IFERROR(INDEX(ATTRIBUTE_GROUP!$B:$B,MATCH(ABYSS!C10,ATTRIBUTE_GROUP!$E:$E,0)),0) -> 1021 | O10: =IF(E10=4,0,1) -> 1 | P10: =INDEX(REWARD!$B$6:$B$4545,MATCH(ABYSS!C10,REWARD!$J$6:$J$4545,0)) -> 8 | Q10: ="GROUP_NAME_"&D10 -> GROUP_NAME_2 | R10: ="GROUP_DESC_"&D10 -> GROUP_DESC_2 | S10: ="GROUP_IMAGE_"&D10 -> GROUP_IMAGE_2 | T10: ="ABYSS_NAME_"&A10 -> ABYSS_NAME_10211 | U10: ="ABYSS_DESC_"&D10 -> ABYSS_DESC_2 | V10: ="ABYSS_IMAGE_"&A10 -> ABYSS_IMAGE_10211
A11: =10000+D11*ID규칙_비경_그룹_단위+E11*ID규칙_스테이지_타입_단위+COUNTIF($D$4:D11,D11) -> 10212 | B11: =VLOOKUP(Q11,STRING!$A$3:$B$28,2,0) -> 각인의 골짜기 | C11: =VLOOKUP(T11,STRING!$A$29:$B$202,2,0) -> 축성 비경: 강철의 춤 II | D11: 2 | E11: 1 | F11: 2 | G11: =INDEX(ABYSS_CONDITION!$B$4:$B$34,MATCH(ABYSS!B11,ABYSS_CONDITION!$F$4:$F$34,0)) -> 2 | H11: 30 | I11: 59 | J11: 1 | K11: 20 | L11: =IFERROR(INDEX(PENALTY_OPTION!$B$4:$B$248,MATCH(ABYSS!C11,PENALTY_OPTION!$L$4:$L$248,0)),0) -> 8 | M11: =IFERROR(INDEX(ABYSS_MONSTER_LIST!$B:$B,MATCH(ABYSS!C11,ABYSS_MONSTER_LIST!$E:$E,0)),0) -> 1022 | N11: =IFERROR(INDEX(ATTRIBUTE_GROUP!$B:$B,MATCH(ABYSS!C11,ATTRIBUTE_GROUP!$E:$E,0)),0) -> 1022 | O11: =IF(E11=4,0,1) -> 1 | P11: =INDEX(REWARD!$B$6:$B$4545,MATCH(ABYSS!C11,REWARD!$J$6:$J$4545,0)) -> 9 | Q11: ="GROUP_NAME_"&D11 -> GROUP_NAME_2 | R11: ="GROUP_DESC_"&D11 -> GROUP_DESC_2 | S11: ="GROUP_IMAGE_"&D11 -> GROUP_IMAGE_2 | T11: ="ABYSS_NAME_"&A11 -> ABYSS_NAME_10212 | U11: ="ABYSS_DESC_"&D11 -> ABYSS_DESC_2 | V11: ="ABYSS_IMAGE_"&A11 -> ABYSS_IMAGE_10212
A12: =10000+D12*ID규칙_비경_그룹_단위+E12*ID규칙_스테이지_타입_단위+COUNTIF($D$4:D12,D12) -> 10213 | B12: =VLOOKUP(Q12,STRING!$A$3:$B$28,2,0) -> 각인의 골짜기 | C12: =VLOOKUP(T12,STRING!$A$29:$B$202,2,0) -> 축성 비경: 강철의 춤 III | D12: 2 | E12: 1 | F12: 3 | G12: =INDEX(ABYSS_CONDITION!$B$4:$B$34,MATCH(ABYSS!B12,ABYSS_CONDITION!$F$4:$F$34,0)) -> 2 | H12: 35 | I12: 69 | J12: 1 | K12: 20 | L12: =IFERROR(INDEX(PENALTY_OPTION!$B$4:$B$248,MATCH(ABYSS!C12,PENALTY_OPTION!$L$4:$L$248,0)),0) -> 9 | M12: =IFERROR(INDEX(ABYSS_MONSTER_LIST!$B:$B,MATCH(ABYSS!C12,ABYSS_MONSTER_LIST!$E:$E,0)),0) -> 1023 | N12: =IFERROR(INDEX(ATTRIBUTE_GROUP!$B:$B,MATCH(ABYSS!C12,ATTRIBUTE_GROUP!$E:$E,0)),0) -> 1023 | O12: =IF(E12=4,0,1) -> 1 | P12: =INDEX(REWARD!$B$6:$B$4545,MATCH(ABYSS!C12,REWARD!$J$6:$J$4545,0)) -> 10 | Q12: ="GROUP_NAME_"&D12 -> GROUP_NAME_2 | R12: ="GROUP_DESC_"&D12 -> GROUP_DESC_2 | S12: ="GROUP_IMAGE_"&D12 -> GROUP_IMAGE_2 | T12: ="ABYSS_NAME_"&A12 -> ABYSS_NAME_10213 | U12: ="ABYSS_DESC_"&D12 -> ABYSS_DESC_2 | V12: ="ABYSS_IMAGE_"&A12 -> ABYSS_IMAGE_10213
A13: =10000+D13*ID규칙_비경_그룹_단위+E13*ID규칙_스테이지_타입_단위+COUNTIF($D$4:D13,D13) -> 10214 | B13: =VLOOKUP(Q13,STRING!$A$3:$B$28,2,0) -> 각인의 골짜기 | C13: =VLOOKUP(T13,STRING!$A$29:$B$202,2,0) -> 축성 비경: 강철의 춤 IV | D13: 2 | E13: 1 | F13: 4 | G13: =INDEX(ABYSS_CONDITION!$B$4:$B$34,MATCH(ABYSS!B13,ABYSS_CONDITION!$F$4:$F$34,0)) -> 2 | H13: 40 | I13: 80 | J13: 1 | K13: 20 | L13: =IFERROR(INDEX(PENALTY_OPTION!$B$4:$B$248,MATCH(ABYSS!C13,PENALTY_OPTION!$L$4:$L$248,0)),0) -> 10 | M13: =IFERROR(INDEX(ABYSS_MONSTER_LIST!$B:$B,MATCH(ABYSS!C13,ABYSS_MONSTER_LIST!$E:$E,0)),0) -> 1024 | N13: =IFERROR(INDEX(ATTRIBUTE_GROUP!$B:$B,MATCH(ABYSS!C13,ATTRIBUTE_GROUP!$E:$E,0)),0) -> 1024 | O13: =IF(E13=4,0,1) -> 1 | P13: =INDEX(REWARD!$B$6:$B$4545,MATCH(ABYSS!C13,REWARD!$J$6:$J$4545,0)) -> 11 | Q13: ="GROUP_NAME_"&D13 -> GROUP_NAME_2 | R13: ="GROUP_DESC_"&D13 -> GROUP_DESC_2 | S13: ="GROUP_IMAGE_"&D13 -> GROUP_IMAGE_2 | T13: ="ABYSS_NAME_"&A13 -> ABYSS_NAME_10214 | U13: ="ABYSS_DESC_"&D13 -> ABYSS_DESC_2 | V13: ="ABYSS_IMAGE_"&A13 -> ABYSS_IMAGE_10214
A14: =10000+D14*ID규칙_비경_그룹_단위+E14*ID규칙_스테이지_타입_단위+COUNTIF($D$4:D14,D14) -> 10215 | B14: =VLOOKUP(Q14,STRING!$A$3:$B$28,2,0) -> 각인의 골짜기 | C14: =VLOOKUP(T14,STRING!$A$29:$B$202,2,0) -> 축성 비경: 강철의 춤 V | D14: 2 | E14: 1 | F14: 5 | G14: =INDEX(ABYSS_CONDITION!$B$4:$B$34,MATCH(ABYSS!B14,ABYSS_CONDITION!$F$4:$F$34,0)) -> 2 | H14: 45 | I14: 90 | J14: 1 | K14: 20 | L14: =IFERROR(INDEX(PENALTY_OPTION!$B$4:$B$248,MATCH(ABYSS!C14,PENALTY_OPTION!$L$4:$L$248,0)),0) -> 11 | M14: =IFERROR(INDEX(ABYSS_MONSTER_LIST!$B:$B,MATCH(ABYSS!C14,ABYSS_MONSTER_LIST!$E:$E,0)),0) -> 1025 | N14: =IFERROR(INDEX(ATTRIBUTE_GROUP!$B:$B,MATCH(ABYSS!C14,ATTRIBUTE_GROUP!$E:$E,0)),0) -> 1025 | O14: =IF(E14=4,0,1) -> 1 | P14: =INDEX(REWARD!$B$6:$B$4545,MATCH(ABYSS!C14,REWARD!$J$6:$J$4545,0)) -> 12 | Q14: ="GROUP_NAME_"&D14 -> GROUP_NAME_2 | R14: ="GROUP_DESC_"&D14 -> GROUP_DESC_2 | S14: ="GROUP_IMAGE_"&D14 -> GROUP_IMAGE_2 | T14: ="ABYSS_NAME_"&A14 -> ABYSS_NAME_10215 | U14: ="ABYSS_DESC_"&D14 -> ABYSS_DESC_2 | V14: ="ABYSS_IMAGE_"&A14 -> ABYSS_IMAGE_10215
A15: =10000+D15*ID규칙_비경_그룹_단위+E15*ID규칙_스테이지_타입_단위+COUNTIF($D$4:D15,D15) -> 10311 | B15: =VLOOKUP(Q15,STRING!$A$3:$B$28,2,0) -> 하늘을 찌르는 땅 | C15: =VLOOKUP(T15,STRING!$A$29:$B$202,2,0) -> 축성 비경: 경칩 I | D15: 3 | E15: 1 | F15: 1 | G15: =INDEX(ABYSS_CONDITION!$B$4:$B$34,MATCH(ABYSS!B15,ABYSS_CONDITION!$F$4:$F$34,0)) -> 3 | H15: 22 | I15: 34 | J15: 1 | K15: 20 | L15: =IFERROR(INDEX(PENALTY_OPTION!$B$4:$B$248,MATCH(ABYSS!C15,PENALTY_OPTION!$L$4:$L$248,0)),0) -> 12 | M15: =IFERROR(INDEX(ABYSS_MONSTER_LIST!$B:$B,MATCH(ABYSS!C15,ABYSS_MONSTER_LIST!$E:$E,0)),0) -> 1031 | N15: =IFERROR(INDEX(ATTRIBUTE_GROUP!$B:$B,MATCH(ABYSS!C15,ATTRIBUTE_GROUP!$E:$E,0)),0) -> 1031 | O15: =IF(E15=4,0,1) -> 1 | P15: =INDEX(REWARD!$B$6:$B$4545,MATCH(ABYSS!C15,REWARD!$J$6:$J$4545,0)) -> 13 | Q15: ="GROUP_NAME_"&D15 -> GROUP_NAME_3 | R15: ="GROUP_DESC_"&D15 -> GROUP_DESC_3 | S15: ="GROUP_IMAGE_"&D15 -> GROUP_IMAGE_3 | T15: ="ABYSS_NAME_"&A15 -> ABYSS_NAME_10311 | U15: ="ABYSS_DESC_"&D15 -> ABYSS_DESC_3 | V15: ="ABYSS_IMAGE_"&A15 -> ABYSS_IMAGE_10311
... A177: =10000+D177*ID규칙_비경_그룹_단위+E177*ID규칙_스테이지_타입_단위+COUNTIF($D$4:D177,D177) -> 12644 | B177: =VLOOKUP(Q177,STRING!$A$3:$B$28,2,0) -> 조루리 공방 | C177: =VLOOKUP(T177,STRING!$A$29:$B$202,2,0) -> 추억: 칠엽 중존의 유리단 IV | D177: 26 | E177: 4 | F177: 4 | G177: =INDEX(ABYSS_CONDITION!$B$4:$B$34,MATCH(ABYSS!B177,ABYSS_CONDITION!$F$4:$F$34,0)) -> 26 | H177: 50 | I177: 90 | J177: 2 | K177: 60 | L177: =IFERROR(INDEX(PENALTY_OPTION!$B$4:$B$248,MATCH(ABYSS!C177,PENALTY_OPTION!$L$4:$L$248,0)),0) -> 164 | M177: =IFERROR(INDEX(ABYSS_MONSTER_LIST!$B:$B,MATCH(ABYSS!C177,ABYSS_MONSTER_LIST!$E:$E,0)),0) -> 0 | N177: =IFERROR(INDEX(ATTRIBUTE_GROUP!$B:$B,MATCH(ABYSS!C177,ATTRIBUTE_GROUP!$E:$E,0)),0) -> 0 | O177: =IF(E177=4,0,1) -> 0 | P177: =INDEX(REWARD!$B$6:$B$4545,MATCH(ABYSS!C177,REWARD!$J$6:$J$4545,0)) -> 175 | Q177: ="GROUP_NAME_"&D177 -> GROUP_NAME_26 | R177: ="GROUP_DESC_"&D177 -> GROUP_DESC_26 | S177: ="GROUP_IMAGE_"&D177 -> GROUP_IMAGE_26 | T177: ="ABYSS_NAME_"&A177 -> ABYSS_NAME_12644 | U177: ="ABYSS_DESC_"&D177 -> ABYSS_DESC_26 | V177: ="ABYSS_IMAGE_"&A177 -> ABYSS_IMAGE_12644

Sheet ABYSS_MONSTER_LIST
A1: 아이디 | B1: 토벌 리스트 그룹 | C1: 몬스터 ID | D1: #몬스터 이름 | E1: #비경 이름
A2: ID | B2: MONSTER_LIST_GROUP | C2: MONSTER_ID | D2: MONSTER_NAME | E2: ABYSS_NAME
A3: int | B3: int | C3: int | D3: 참조 | E3: 참조
A4: =1000000+B4*ID규칙_토벌_리스트_그룹_단위+COUNTIF($B$4:B4,B4) -> 1101101 | B4: =1000+VLOOKUP(E4,ABYSS!C$4:$D$177,2,0)*10+VLOOKUP(E4,ABYSS!$C$4:$F$177,4,0) -> 1011 | C4: 134003 | D4: =VLOOKUP(C4,MONSTER!$A:$E,5,0) -> 물 슬라임 Lv.34 | E4: 축성 비경: 정화의 화염 I
A5: =1000000+B5*ID규칙_토벌_리스트_그룹_단위+COUNTIF($B$4:B5,B5) -> 1101102 | B5: =1000+VLOOKUP(E5,ABYSS!C$4:$D$177,2,0)*10+VLOOKUP(E5,ABYSS!$C$4:$F$177,4,0) -> 1011 | C5: 134013 | D5: =VLOOKUP(C5,MONSTER!$A:$E,5,0) -> 거대 얼음 슬라임 Lv.34 | E5: 축성 비경: 정화의 화염 I
A6: =1000000+B6*ID규칙_토벌_리스트_그룹_단위+COUNTIF($B$4:B6,B6) -> 1101103 | B6: =1000+VLOOKUP(E6,ABYSS!C$4:$D$177,2,0)*10+VLOOKUP(E6,ABYSS!$C$4:$F$177,4,0) -> 1011 | C6: 134004 | D6: =VLOOKUP(C6,MONSTER!$A:$E,5,0) -> 거대 물 슬라임 Lv.34 | E6: 축성 비경: 정화의 화염 I
A7: =1000000+B7*ID규칙_토벌_리스트_그룹_단위+COUNTIF($B$4:B7,B7) -> 1101104 | B7: =1000+VLOOKUP(E7,ABYSS!C$4:$D$177,2,0)*10+VLOOKUP(E7,ABYSS!$C$4:$F$177,4,0) -> 1011 | C7: 134022 | D7: =VLOOKUP(C7,MONSTER!$A:$E,5,0) -> 나무방패 츄츄 Lv.34 | E7: 축성 비경: 정화의 화염 I
A8: =1000000+B8*ID규칙_토벌_리스트_그룹_단위+COUNTIF($B$4:B8,B8) -> 1101105 | B8: =1000+VLOOKUP(E8,ABYSS!C$4:$D$177,2,0)*10+VLOOKUP(E8,ABYSS!$C$4:$F$177,4,0) -> 1011 | C8: 134045 | D8: =VLOOKUP(C8,MONSTER!$A:$E,5,0) -> 얼음의 심연 메이지 Lv.34 | E8: 축성 비경: 정화의 화염 I
A9: =1000000+B9*ID규칙_토벌_리스트_그룹_단위+COUNTIF($B$4:B9,B9) -> 1101201 | B9: =1000+VLOOKUP(E9,ABYSS!C$4:$D$177,2,0)*10+VLOOKUP(E9,ABYSS!$C$4:$F$177,4,0) -> 1012 | C9: 147007 | D9: =VLOOKUP(C9,MONSTER!$A:$E,5,0) -> 번개 슬라임 Lv.47 | E9: 축성 비경: 정화의 화염 II
A10: =1000000+B10*ID규칙_토벌_리스트_그룹_단위+COUNTIF($B$4:B10,B10) -> 1101202 | B10: =1000+VLOOKUP(E10,ABYSS!C$4:$D$177,2,0)*10+VLOOKUP(E10,ABYSS!$C$4:$F$177,4,0) -> 1012 | C10: 147008 | D10: =VLOOKUP(C10,MONSTER!$A:$E,5,0) -> 거대 번개 슬라임 Lv.47 | E10: 축성 비경: 정화의 화염 II
A11: =1000000+B11*ID규칙_토벌_리스트_그룹_단위+COUNTIF($B$4:B11,B11) -> 1101203 | B11: =1000+VLOOKUP(E11,ABYSS!C$4:$D$177,2,0)*10+VLOOKUP(E11,ABYSS!$C$4:$F$177,4,0) -> 1012 | C11: 147009 | D11: =VLOOKUP(C11,MONSTER!$A:$E,5,0) -> 돌연변이 번개 슬라임 Lv.47 | E11: 축성 비경: 정화의 화염 II
A12: =1000000+B12*ID규칙_토벌_리스트_그룹_단위+COUNTIF($B$4:B12,B12) -> 1101204 | B12: =1000+VLOOKUP(E12,ABYSS!C$4:$D$177,2,0)*10+VLOOKUP(E12,ABYSS!$C$4:$F$177,4,0) -> 1012 | C12: 147051 | D12: =VLOOKUP(C12,MONSTER!$A:$E,5,0) -> 번개 치친술사 Lv.47 | E12: 축성 비경: 정화의 화염 II
A13: =1000000+B13*ID규칙_토벌_리스트_그룹_단위+COUNTIF($B$4:B13,B13) -> 1101301 | B13: =1000+VLOOKUP(E13,ABYSS!C$4:$D$177,2,0)*10+VLOOKUP(E13,ABYSS!$C$4:$F$177,4,0) -> 1013 | C13: 159012 | D13: =VLOOKUP(C13,MONSTER!$A:$E,5,0) -> 얼음 슬라임 Lv.59 | E13: 축성 비경: 정화의 화염 III
A14: =1000000+B14*ID규칙_토벌_리스트_그룹_단위+COUNTIF($B$4:B14,B14) -> 1101302 | B14: =1000+VLOOKUP(E14,ABYSS!C$4:$D$177,2,0)*10+VLOOKUP(E14,ABYSS!$C$4:$F$177,4,0) -> 1013 | C14: 159013 | D14: =VLOOKUP(C14,MONSTER!$A:$E,5,0) -> 거대 얼음 슬라임 Lv.59 | E14: 축성 비경: 정화의 화염 III
A15: =1000000+B15*ID규칙_토벌_리스트_그룹_단위+COUNTIF($B$4:B15,B15) -> 1101303 | B15: =1000+VLOOKUP(E15,ABYSS!C$4:$D$177,2,0)*10+VLOOKUP(E15,ABYSS!$C$4:$F$177,4,0) -> 1013 | C15: 159045 | D15: =VLOOKUP(C15,MONSTER!$A:$E,5,0) -> 얼음의 심연 메이지 Lv.59 | E15: 축성 비경: 정화의 화염 III
... A513: =1000000+B513*ID규칙_토벌_리스트_그룹_단위+COUNTIF($B$4:B513,B513) -> 1120406 | B513: =1000+VLOOKUP(E513,ABYSS!C$4:$D$177,2,0)*10+VLOOKUP(E513,ABYSS!$C$4:$F$177,4,0) -> 1204 | C513: 188062 | D513: =VLOOKUP(C513,MONSTER!$A:$E,5,0) -> 유적 드레이크: 천공의 수호자 Lv.88 | E513: 숙달 비경: 율장 IV

Sheet MONSTER
A1: 아이디 | B1: 몬스터 레벨 | C1: 몬스터 이름 | D1: 몬스터 아이콘 | E1: #몬스터 이름
A2: ID | B2: MONSTER_LEVEL | C2: MONSTER_NAME | D2: MONSTER_ICON | E2: MONSTER_NAME
A3: int | B3: int | C3: string | D3: string | E3: 참조
A4: =100000+B4*ID규칙_몬스터_레벨_단위+COUNTIF($B$4:B4,B4) -> 115001 | B4: 15 | C4: ="MONSTER_NAME_"&A4 -> MONSTER_NAME_115001 | D4: ="MONSTER_ICON_"&A4 -> MONSTER_ICON_115001 | E4: =VLOOKUP(C4,STRING!$A:$B,2,0) -> 화염 슬라임 Lv.15
A5: =100000+B5*ID규칙_몬스터_레벨_단위+COUNTIF($B$4:B5,B5) -> 134001 | B5: 34 | C5: ="MONSTER_NAME_"&A5 -> MONSTER_NAME_134001 | D5: ="MONSTER_ICON_"&A5 -> MONSTER_ICON_134001 | E5: =VLOOKUP(C5,STRING!$A:$B,2,0) -> 화염 슬라임 Lv.34 | G5: ※ 임시로 관련 정보만 표시했습니다
A6: =100000+B6*ID규칙_몬스터_레벨_단위+COUNTIF($B$4:B6,B6) -> 136001 | B6: 36 | C6: ="MONSTER_NAME_"&A6 -> MONSTER_NAME_136001 | D6: ="MONSTER_ICON_"&A6 -> MONSTER_ICON_136001 | E6: =VLOOKUP(C6,STRING!$A:$B,2,0) -> 화염 슬라임 Lv.36
A7: =100000+B7*ID규칙_몬스터_레벨_단위+COUNTIF($B$4:B7,B7) -> 138001 | B7: 38 | C7: ="MONSTER_NAME_"&A7 -> MONSTER_NAME_138001 | D7: ="MONSTER_ICON_"&A7 -> MONSTER_ICON_138001 | E7: =VLOOKUP(C7,STRING!$A:$B,2,0) -> 화염 슬라임 Lv.38
A8: =100000+B8*ID규칙_몬스터_레벨_단위+COUNTIF($B$4:B8,B8) -> 147001 | B8: 47 | C8: ="MONSTER_NAME_"&A8 -> MONSTER_NAME_147001 | D8: ="MONSTER_ICON_"&A8 -> MONSTER_ICON_147001 | E8: =VLOOKUP(C8,STRING!$A:$B,2,0) -> 화염 슬라임 Lv.47
A9: =100000+B9*ID규칙_몬스터_레벨_단위+COUNTIF($B$4:B9,B9) -> 154001 | B9: 54 | C9: ="MONSTER_NAME_"&A9 -> MONSTER_NAME_154001 | D9: ="MONSTER_ICON_"&A9 -> MONSTER_ICON_154001 | E9: =VLOOKUP(C9,STRING!$A:$B,2,0) -> 화염 슬라임 Lv.54
A10: =100000+B10*ID규칙_몬스터_레벨_단위+COUNTIF($B$4:B10,B10) -> 159001 | B10: 59 | C10: ="MONSTER_NAME_"&A10 -> MONSTER_NAME_159001 | D10: ="MONSTER_ICON_"&A10 -> MONSTER_ICON_159001 | E10: =VLOOKUP(C10,STRING!$A:$B,2,0) -> 화염 슬라임 Lv.59
A11: =100000+B11*ID규칙_몬스터_레벨_단위+COUNTIF($B$4:B11,B11) -> 169001 | B11: 69 | C11: ="MONSTER_NAME_"&A11 -> MONSTER_NAME_169001 | D11: ="MONSTER_ICON_"&A11 -> MONSTER_ICON_169001 | E11: =VLOOKUP(C11,STRING!$A:$B,2,0) -> 화염 슬라임 Lv.69
A12: =100000+B12*ID규칙_몬스터_레벨_단위+COUNTIF($B$4:B12,B12) -> 171001 | B12: 71 | C12: ="MONSTER_NAME_"&A12 -> MONSTER_NAME_171001 | D12: ="MONSTER_ICON_"&A12 -> MONSTER_ICON_171001 | E12: =VLOOKUP(C12,STRING!$A:$B,2,0) -> 화염 슬라임 Lv.71
A13: =100000+B13*ID규칙_몬스터_레벨_단위+COUNTIF($B$4:B13,B13) -> 180001 | B13: 80 | C13: ="MONSTER_NAME_"&A13 -> MONSTER_NAME_180001 | D13: ="MONSTER_ICON_"&A13 -> MONSTER_ICON_180001 | E13: =VLOOKUP(C13,STRING!$A:$B,2,0) -> 화염 슬라임 Lv.80
A14: =100000+B14*ID규칙_몬스터_레벨_단위+COUNTIF($B$4:B14,B14) -> 188001 | B14: 88 | C14: ="MONSTER_NAME_"&A14 -> MONSTER_NAME_188001 | D14: ="MONSTER_ICON_"&A14 -> MONSTER_ICON_188001 | E14: =VLOOKUP(C14,STRING!$A:$B,2,0) -> 화염 슬라임 Lv.88
A15: =100000+B15*ID규칙_몬스터_레벨_단위+COUNTIF($B$4:B15,B15) -> 190001 | B15: 90 | C15: ="MONSTER_NAME_"&A15 -> MONSTER_NAME_190001 | D15: ="MONSTER_ICON_"&A15 -> MONSTER_ICON_190001 | E15: =VLOOKUP(C15,STRING!$A:$B,2,0) -> 화염 슬라임 Lv.90
A16: =100000+B16*ID규칙_몬스터_레벨_단위+COUNTIF($B$4:B16,B16) -> 115002 | B16: 15 | C16: ="MONSTER_NAME_"&A16 -> MONSTER_NAME_115002 | D16: ="MONSTER_ICON_"&A16 -> MONSTER_ICON_115002 | E16: =VLOOKUP(C16,STRING!$A:$B,2,0) -> 거대 화염 슬라임 Lv.15
A17: =100000+B17*ID규칙_몬스터_레벨_단위+COUNTIF($B$4:B17,B17) -> 134002 | B17: 34 | C17: ="MONSTER_NAME_"&A17 -> MONSTER_NAME_134002 | D17: ="MONSTER_ICON_"&A17 -> MONSTER_ICON_134002 | E17: =VLOOKUP(C17,STRING!$A:$B,2,0) -> 거대 화염 슬라임 Lv.34
... A901: =100000+B901*ID규칙_몬스터_레벨_단위+COUNTIF($B$4:B901,B901) -> 190097 | B901: 90 | C901: ="MONSTER_NAME_"&A901 -> MONSTER_NAME_190097 | D901: ="MONSTER_ICON_"&A901 -> MONSTER_ICON_190097 | E901: =VLOOKUP(C901,STRING!$A:$B,2,0) -> 포롱 얼음 버섯몬 Lv.90

Sheet ATTRIBUTE_GROUP
A1: 아이디 | B1: 추천 원소 그룹 | C1: 원소 타입 | D1: 순서 | E1: #비경 이름
A2: ID | B2: ATTRIBUTE_GROUP | C2: ATTRIBUTE_TYPE | D2: SORT | E2: ABYSS_NAME
A3: int | B3: int | C3: int | D3: int | E3: 참조
A4: =1000000+B4*ID규칙_추천_원소_그룹_단위+COUNTIF($B$4:B4,B4) -> 1101101 | B4: =1000+VLOOKUP(E4,ABYSS!C$4:$D$177,2,0)*10+VLOOKUP(E4,ABYSS!$C$4:$F$177,4,0) -> 1011 | C4: 1 | D4: =COUNTIF($B$4:B4,B4) -> 1 | E4: 축성 비경: 정화의 화염 I
A5: =1000000+B5*ID규칙_추천_원소_그룹_단위+COUNTIF($B$4:B5,B5) -> 1101201 | B5: =1000+VLOOKUP(E5,ABYSS!C$4:$D$177,2,0)*10+VLOOKUP(E5,ABYSS!$C$4:$F$177,4,0) -> 1012 | C5: 1 | D5: =COUNTIF($B$4:B5,B5) -> 1 | E5: 축성 비경: 정화의 화염 II
A6: =1000000+B6*ID규칙_추천_원소_그룹_단위+COUNTIF($B$4:B6,B6) -> 1101301 | B6: =1000+VLOOKUP(E6,ABYSS!C$4:$D$177,2,0)*10+VLOOKUP(E6,ABYSS!$C$4:$F$177,4,0) -> 1013 | C6: 1 | D6: =COUNTIF($B$4:B6,B6) -> 1 | E6: 축성 비경: 정화의 화염 III
A7: =1000000+B7*ID규칙_추천_원소_그룹_단위+COUNTIF($B$4:B7,B7) -> 1101401 | B7: =1000+VLOOKUP(E7,ABYSS!C$4:$D$177,2,0)*10+VLOOKUP(E7,ABYSS!$C$4:$F$177,4,0) -> 1014 | C7: 1 | D7: =COUNTIF($B$4:B7,B7) -> 1 | E7: 축성 비경: 정화의 화염 IV
A8: =1000000+B8*ID규칙_추천_원소_그룹_단위+COUNTIF($B$4:B8,B8) -> 1101501 | B8: =1000+VLOOKUP(E8,ABYSS!C$4:$D$177,2,0)*10+VLOOKUP(E8,ABYSS!$C$4:$F$177,4,0) -> 1015 | C8: 1 | D8: =COUNTIF($B$4:B8,B8) -> 1 | E8: 축성 비경: 정화의 화염 V
A9: =1000000+B9*ID규칙_추천_원소_그룹_단위+COUNTIF($B$4:B9,B9) -> 1101601 | B9: =1000+VLOOKUP(E9,ABYSS!C$4:$D$177,2,0)*10+VLOOKUP(E9,ABYSS!$C$4:$F$177,4,0) -> 1016 | C9: 1 | D9: =COUNTIF($B$4:B9,B9) -> 1 | E9: 축성 비경: 정화의 화염 VI
A10: =1000000+B10*ID규칙_추천_원소_그룹_단위+COUNTIF($B$4:B10,B10) -> 1102101 | B10: =1000+VLOOKUP(E10,ABYSS!C$4:$D$177,2,0)*10+VLOOKUP(E10,ABYSS!$C$4:$F$177,4,0) -> 1021 | C10: 0 | D10: =COUNTIF($B$4:B10,B10) -> 1 | E10: 축성 비경: 강철의 춤 I
A11: =1000000+B11*ID규칙_추천_원소_그룹_단위+COUNTIF($B$4:B11,B11) -> 1102201 | B11: =1000+VLOOKUP(E11,ABYSS!C$4:$D$177,2,0)*10+VLOOKUP(E11,ABYSS!$C$4:$F$177,4,0) -> 1022 | C11: 0 | D11: =COUNTIF($B$4:B11,B11) -> 1 | E11: 축성 비경: 강철의 춤 II
A12: =1000000+B12*ID규칙_추천_원소_그룹_단위+COUNTIF($B$4:B12,B12) -> 1102301 | B12: =1000+VLOOKUP(E12,ABYSS!C$4:$D$177,2,0)*10+VLOOKUP(E12,ABYSS!$C$4:$F$177,4,0) -> 1023 | C12: 0 | D12: =COUNTIF($B$4:B12,B12) -> 1 | E12: 축성 비경: 강철의 춤 III
A13: =1000000+B13*ID규칙_추천_원소_그룹_단위+COUNTIF($B$4:B13,B13) -> 1102401 | B13: =1000+VLOOKUP(E13,ABYSS!C$4:$D$177,2,0)*10+VLOOKUP(E13,ABYSS!$C$4:$F$177,4,0) -> 1024 | C13: 0 | D13: =COUNTIF($B$4:B13,B13) -> 1 | E13: 축성 비경: 강철의 춤 IV
A14: =1000000+B14*ID규칙_추천_원소_그룹_단위+COUNTIF($B$4:B14,B14) -> 1102501 | B14: =1000+VLOOKUP(E14,ABYSS!C$4:$D$177,2,0)*10+VLOOKUP(E14,ABYSS!$C$4:$F$177,4,0) -> 1025 | C14: 0 | D14: =COUNTIF($B$4:B14,B14) -> 1 | E14: 축성 비경: 강철의 춤 V
A15: =1000000+B15*ID규칙_추천_원소_그룹_단위+COUNTIF($B$4:B15,B15) -> 1103101 | B15: =1000+VLOOKUP(E15,ABYSS!C$4:$D$177,2,0)*10+VLOOKUP(E15,ABYSS!$C$4:$F$177,4,0) -> 1031 | C15: 4 | D15: =COUNTIF($B$4:B15,B15) -> 1 | E15: 축성 비경: 경칩 I
... A321: =1000000+B321*ID규칙_추천_원소_그룹_단위+COUNTIF($B$4:B321,B321) -> 1120412 | B321: =1000+VLOOKUP(E321,ABYSS!C$4:$D$177,2,0)*10+VLOOKUP(E321,ABYSS!$C$4:$F$177,4,0) -> 1204 | C321: 2 | D321: =COUNTIF($B$4:B321,B321) -> 12 | E321: 숙달 비경: 율장 IV

Sheet ABYSS_CONDITION
A1: 아이디 | B1: 비경 조건 그룹 | C1: 비경 조건 타입 | D1: 비경 조건 값 | E1: #비경 조건 내용 | F1: #비경 그룹 이름
A2: ID | B2: CONDITION_GROUP | C2: CONDITION_TYPE | D2: CONDITION_VALUE | E2: CONDITION_DESC | F2: GROUP_NAME
A3: int | B3: int | C3: int | D3: int | E3: 참조 | F3: 참조
A4: =1000+B4*ID규칙_비경_조건_그룹_단위+COUNTIF($B$4:B4,B4) -> 1011 | B4: 1 | C4: 2 | D4: 110 | E4: =VLOOKUP(C4,INDEX_ABYSS!$B$101:$C$109,2,0)&IF(C4>=3," "&D4&VLOOKUP(C4,INDEX_ABYSS!$B$101:$D$109,3,0),"")&IFERROR(": <"&VLOOKUP(D4,QUEST!A:C,3,0)&">","") -> 비경 발견: <한 여름의 정원> | F4: 한 여름의 정원
A5: =1000+B5*ID규칙_비경_조건_그룹_단위+COUNTIF($B$4:B5,B5) -> 1021 | B5: 2 | C5: 2 | D5: 111 | E5: =VLOOKUP(C5,INDEX_ABYSS!$B$101:$C$109,2,0)&IF(C5>=3," "&D5&VLOOKUP(C5,INDEX_ABYSS!$B$101:$D$109,3,0),"")&IFERROR(": <"&VLOOKUP(D5,QUEST!A:C,3,0)&">","") -> 비경 발견: <각인의 골짜기> | F5: 각인의 골짜기
A6: =1000+B6*ID규칙_비경_조건_그룹_단위+COUNTIF($B$4:B6,B6) -> 1031 | B6: 3 | C6: 2 | D6: 112 | E6: =VLOOKUP(C6,INDEX_ABYSS!$B$101:$C$109,2,0)&IF(C6>=3," "&D6&VLOOKUP(C6,INDEX_ABYSS!$B$101:$D$109,3,0),"")&IFERROR(": <"&VLOOKUP(D6,QUEST!A:C,3,0)&">","") -> 비경 발견: <하늘을 찌르는 땅> | F6: 하늘을 찌르는 땅
A7: =1000+B7*ID규칙_비경_조건_그룹_단위+COUNTIF($B$4:B7,B7) -> 1041 | B7: 4 | C7: 3 | D7: 4 | E7: =VLOOKUP(C7,INDEX_ABYSS!$B$101:$C$109,2,0)&IF(C7>=3," "&D7&VLOOKUP(C7,INDEX_ABYSS!$B$101:$D$109,3,0),"")&IFERROR(": <"&VLOOKUP(D7,QUEST!A:C,3,0)&">","") -> 퍼즐: 토템 원소 반응 4개 | F7: 무망 인구 밀궁
A8: =1000+B8*ID규칙_비경_조건_그룹_단위+COUNTIF($B$4:B8,B8) -> 1042 | B8: 4 | C8: 4 | D8: 1 | E8: =VLOOKUP(C8,INDEX_ABYSS!$B$101:$C$109,2,0)&IF(C8>=3," "&D8&VLOOKUP(C8,INDEX_ABYSS!$B$101:$D$109,3,0),"")&IFERROR(": <"&VLOOKUP(D8,QUEST!A:C,3,0)&">","") -> 퍼즐: 정령 기둥 활성화 1개 | F8: 무망 인구 밀궁
A9: =1000+B9*ID규칙_비경_조건_그룹_단위+COUNTIF($B$4:B9,B9) -> 1051 | B9: 5 | C9: 2 | D9: 113 | E9: =VLOOKUP(C9,INDEX_ABYSS!$B$101:$C$109,2,0)&IF(C9>=3," "&D9&VLOOKUP(C9,INDEX_ABYSS!$B$101:$D$109,3,0),"")&IFERROR(": <"&VLOOKUP(D9,QUEST!A:C,3,0)&">","") -> 비경 발견: <화지 산굴> | F9: 화지 산굴
A10: =1000+B10*ID규칙_비경_조건_그룹_단위+COUNTIF($B$4:B10,B10) -> 1061 | B10: 6 | C10: 1 | D10: 101 | E10: =VLOOKUP(C10,INDEX_ABYSS!$B$101:$C$109,2,0)&IF(C10>=3," "&D10&VLOOKUP(C10,INDEX_ABYSS!$B$101:$D$109,3,0),"")&IFERROR(": <"&VLOOKUP(D10,QUEST!A:C,3,0)&">","") -> 선행 임무 달성: <월드 임무: 모든 「파편」 녹이기> | F10: 빈다그니르의 정상
A11: =1000+B11*ID규칙_비경_조건_그룹_단위+COUNTIF($B$4:B11,B11) -> 1071 | B11: 7 | C11: 2 | D11: 114 | E11: =VLOOKUP(C11,INDEX_ABYSS!$B$101:$C$109,2,0)&IF(C11>=3," "&D11&VLOOKUP(C11,INDEX_ABYSS!$B$101:$D$109,3,0),"")&IFERROR(": <"&VLOOKUP(D11,QUEST!A:C,3,0)&">","") -> 비경 발견: <산등성이의 파수꾼> | F11: 산등성이의 파수꾼
A12: =1000+B12*ID규칙_비경_조건_그룹_단위+COUNTIF($B$4:B12,B12) -> 1081 | B12: 8 | C12: 1 | D12: 102 | E12: =VLOOKUP(C12,INDEX_ABYSS!$B$101:$C$109,2,0)&IF(C12>=3," "&D12&VLOOKUP(C12,INDEX_ABYSS!$B$101:$D$109,3,0),"")&IFERROR(": <"&VLOOKUP(D12,QUEST!A:C,3,0)&">","") -> 선행 임무 달성: <월드 임무: 오로바시유사 · V> | F12: 단풍의 정원
A13: =1000+B13*ID규칙_비경_조건_그룹_단위+COUNTIF($B$4:B13,B13) -> 1091 | B13: 9 | C13: 1 | D13: 102 | E13: =VLOOKUP(C13,INDEX_ABYSS!$B$101:$C$109,2,0)&IF(C13>=3," "&D13&VLOOKUP(C13,INDEX_ABYSS!$B$101:$D$109,3,0),"")&IFERROR(": <"&VLOOKUP(D13,QUEST!A:C,3,0)&">","") -> 선행 임무 달성: <월드 임무: 오로바시유사 · V> | F13: 깊이 잠든 정원
A14: =1000+B14*ID규칙_비경_조건_그룹_단위+COUNTIF($B$4:B14,B14) -> 1101 | B14: 10 | C14: 5 | D14: 1 | E14: =VLOOKUP(C14,INDEX_ABYSS!$B$101:$C$109,2,0)&IF(C14>=3," "&D14&VLOOKUP(C14,INDEX_ABYSS!$B$101:$D$109,3,0),"")&IFERROR(": <"&VLOOKUP(D14,QUEST!A:C,3,0)&">","") -> 퍼즐: 발판 활성화 1개 | F14: 암중 협곡
A15: =1000+B15*ID규칙_비경_조건_그룹_단위+COUNTIF($B$4:B15,B15) -> 1102 | B15: 10 | C15: 1 | D15: 103 | E15: =VLOOKUP(C15,INDEX_ABYSS!$B$101:$C$109,2,0)&IF(C15>=3," "&D15&VLOOKUP(C15,INDEX_ABYSS!$B$101:$D$109,3,0),"")&IFERROR(": <"&VLOOKUP(D15,QUEST!A:C,3,0)&">","") -> 선행 임무 달성: <마신 임무 프롤로그·제3막 「드래곤과 자유의 노래」> | F15: 암중 협곡
... A34: =1000+B34*ID규칙_비경_조건_그룹_단위+COUNTIF($B$4:B34,B34) -> 1261 | B34: 26 | C34: 1 | D34: 109 | E34: =VLOOKUP(C34,INDEX_ABYSS!$B$101:$C$109,2,0)&IF(C34>=3," "&D34&VLOOKUP(C34,INDEX_ABYSS!$B$101:$D$109,3,0),"")&IFERROR(": <"&VLOOKUP(D34,QUEST!A:C,3,0)&">","") -> 선행 임무 달성: <마신 임무: 제3장·제5막 「허공의 선동, 타오르는 겁화」> | F34: 조루리 공방

Sheet QUEST
A1: 아이디 | B1: 퀘스트 이름 | C1: #퀘스트 이름
A2: ID | B2: QUEST_NAME | C2: QUEST_NAME
A3: int | B3: string | C3: 참조
A4: 101 | B4: ="QUEST_NAME_"&A4 -> QUEST_NAME_101 | C4: 월드 임무: 모든 「파편」 녹이기 | E4: ※ 임시로 관련 정보만 표시했습니다
A5: 102 | B5: ="QUEST_NAME_"&A5 -> QUEST_NAME_102 | C5: 월드 임무: 오로바시유사 · V
A6: 103 | B6: ="QUEST_NAME_"&A6 -> QUEST_NAME_103 | C6: 마신 임무 프롤로그·제3막 「드래곤과 자유의 노래」
A7: 104 | B7: ="QUEST_NAME_"&A7 -> QUEST_NAME_104 | C7: 마신 임무: 제2장·제1막 「이도 탈출 계획」
A8: 105 | B8: ="QUEST_NAME_"&A8 -> QUEST_NAME_105 | C8: 마신 임무: 제1장·제3막 「다가오는 객성」
A9: 106 | B9: ="QUEST_NAME_"&A9 -> QUEST_NAME_106 | C9: 옛 이야기의 장: 제2막 「굳은 심지」
A10: 107 | B10: ="QUEST_NAME_"&A10 -> QUEST_NAME_107 | C10: 마신 임무: 제2장·제3막 「천수백안의 세상」
A11: 108 | B11: ="QUEST_NAME_"&A11 -> QUEST_NAME_108 | C11: 천하인의 장: 제2막 「찰나의 꿈」
A12: 109 | B12: ="QUEST_NAME_"&A12 -> QUEST_NAME_109 | C12: 마신 임무: 제3장·제5막 「허공의 선동, 타오르는 겁화」
A13: 110 | B13: ="QUEST_NAME_"&A13 -> QUEST_NAME_110 | C13: 한 여름의 정원
A14: 111 | B14: ="QUEST_NAME_"&A14 -> QUEST_NAME_111 | C14: 각인의 골짜기
A15: 112 | B15: ="QUEST_NAME_"&A15 -> QUEST_NAME_112 | C15: 하늘을 찌르는 땅
A16: 113 | B16: ="QUEST_NAME_"&A16 -> QUEST_NAME_113 | C16: 화지 산굴
... A23: 120 | B23: ="QUEST_NAME_"&A23 -> QUEST_NAME_120 | C23: 무지의 탑

Sheet PENALTY_OPTION
A1: 아이디 | B1: 지맥 이상 그룹 | C1: 컨디션 타입 | D1: 옵션 타입 | E1: 옵션 비율 | F1: 옵션 값 | G1: 지속 시간 | H1: 지속 시간 발동 횟수 | I1: 지맥 이상 옵션 설명 | J1: #지맥 이상 옵션 설명 | K1: #지맥 이상 옵션 설명 | L1: #스테이지 이름
A2: ID | B2: PENALTY_GROUP | C2: CONDITION_TYPE | D2: OPTION_TYPE | E2: IS_RATE | F2: OPTION_VALUE | G2: TIME | H2: COUNT | I2: PENALTY_OPTION_DESC | J2: CONDITION_TYPE | K2: OPTION_TYPE | L2: STAGE_NAME
A3: int | B3: int | C3: int | D3: int | E3: int | F3: int | G3: int | H3: int | I3: string | J3: 참조 | K3: 참조 | L3: 참조
A4: =10000+B4*ID규칙_지맥_이상_그룹_단위+COUNTIF($B$4:B4,B4) -> 10011 | B4: 1 | C4: 2 | D4: 9 | E4: 0 | F4: 0 | G4: 0 | H4: 0 | I4: ="PENALTY_OPTION_DESC_"&B4 -> PENALTY_OPTION_DESC_1 | J4: =IF(C4=0,"-",VLOOKUP(C4,컨디션_타입,2,0)) -> 융해 반응 시 | K4: =VLOOKUP(D4,옵션_타입,2,0)&IF(F4=0,"",IF(E4=0,F4," "&F4/100&"%"))&IF(G4=0,"",(IF(H4>=1," ["&G4/1000&"초마다 ",(IF(H4>=1,G4," ["&G4/1000&"초 동안]"))))&IF(H4=0,"",H4&"회]")) -> 에너지 블라스트 방출 | L4: 축성 비경: 정화의 화염 I
A5: =10000+B5*ID규칙_지맥_이상_그룹_단위+COUNTIF($B$4:B5,B5) -> 10021 | B5: 2 | C5: 3 | D5: 9 | E5: 0 | F5: 0 | G5: 0 | H5: 0 | I5: ="PENALTY_OPTION_DESC_"&B5 -> PENALTY_OPTION_DESC_2 | J5: =IF(C5=0,"-",VLOOKUP(C5,컨디션_타입,2,0)) -> 과부하 반응 시 | K5: =VLOOKUP(D5,옵션_타입,2,0)&IF(F5=0,"",IF(E5=0,F5," "&F5/100&"%"))&IF(G5=0,"",(IF(H5>=1," ["&G5/1000&"초마다 ",(IF(H5>=1,G5," ["&G5/1000&"초 동안]"))))&IF(H5=0,"",H5&"회]")) -> 에너지 블라스트 방출 | L5: 축성 비경: 정화의 화염 II
A6: =10000+B6*ID규칙_지맥_이상_그룹_단위+COUNTIF($B$4:B6,B6) -> 10022 | B6: 2 | C6: 4 | D6: 11 | E6: 0 | F6: 0 | G6: 0 | H6: 0 | I6: ="PENALTY_OPTION_DESC_"&B6 -> PENALTY_OPTION_DESC_2 | J6: =IF(C6=0,"-",VLOOKUP(C6,컨디션_타입,2,0)) -> 초전도 반응 시 | K6: =VLOOKUP(D6,옵션_타입,2,0)&IF(F6=0,"",IF(E6=0,F6," "&F6/100&"%"))&IF(G6=0,"",(IF(H6>=1," ["&G6/1000&"초마다 ",(IF(H6>=1,G6," ["&G6/1000&"초 동안]"))))&IF(H6=0,"",H6&"회]")) -> 고에너지 타격 | L6: 축성 비경: 정화의 화염 II
A7: =10000+B7*ID규칙_지맥_이상_그룹_단위+COUNTIF($B$4:B7,B7) -> 10031 | B7: 3 | C7: 2 | D7: 9 | E7: 0 | F7: 0 | G7: 0 | H7: 0 | I7: ="PENALTY_OPTION_DESC_"&B7 -> PENALTY_OPTION_DESC_3 | J7: =IF(C7=0,"-",VLOOKUP(C7,컨디션_타입,2,0)) -> 융해 반응 시 | K7: =VLOOKUP(D7,옵션_타입,2,0)&IF(F7=0,"",IF(E7=0,F7," "&F7/100&"%"))&IF(G7=0,"",(IF(H7>=1," ["&G7/1000&"초마다 ",(IF(H7>=1,G7," ["&G7/1000&"초 동안]"))))&IF(H7=0,"",H7&"회]")) -> 에너지 블라스트 방출 | L7: 축성 비경: 정화의 화염 III
A8: =10000+B8*ID규칙_지맥_이상_그룹_단위+COUNTIF($B$4:B8,B8) -> 10032 | B8: 3 | C8: 4 | D8: 11 | E8: 0 | F8: 0 | G8: 0 | H8: 0 | I8: ="PENALTY_OPTION_DESC_"&B8 -> PENALTY_OPTION_DESC_3 | J8: =IF(C8=0,"-",VLOOKUP(C8,컨디션_타입,2,0)) -> 초전도 반응 시 | K8: =VLOOKUP(D8,옵션_타입,2,0)&IF(F8=0,"",IF(E8=0,F8," "&F8/100&"%"))&IF(G8=0,"",(IF(H8>=1," ["&G8/1000&"초마다 ",(IF(H8>=1,G8," ["&G8/1000&"초 동안]"))))&IF(H8=0,"",H8&"회]")) -> 고에너지 타격 | L8: 축성 비경: 정화의 화염 III
A9: =10000+B9*ID규칙_지맥_이상_그룹_단위+COUNTIF($B$4:B9,B9) -> 10041 | B9: 4 | C9: 1 | D9: 9 | E9: 0 | F9: 0 | G9: 0 | H9: 0 | I9: ="PENALTY_OPTION_DESC_"&B9 -> PENALTY_OPTION_DESC_4 | J9: =IF(C9=0,"-",VLOOKUP(C9,컨디션_타입,2,0)) -> 증발 반응 시 | K9: =VLOOKUP(D9,옵션_타입,2,0)&IF(F9=0,"",IF(E9=0,F9," "&F9/100&"%"))&IF(G9=0,"",(IF(H9>=1," ["&G9/1000&"초마다 ",(IF(H9>=1,G9," ["&G9/1000&"초 동안]"))))&IF(H9=0,"",H9&"회]")) -> 에너지 블라스트 방출 | L9: 축성 비경: 정화의 화염 IV
A10: =10000+B10*ID규칙_지맥_이상_그룹_단위+COUNTIF($B$4:B10,B10) -> 10042 | B10: 4 | C10: 5 | D10: 11 | E10: 0 | F10: 0 | G10: 0 | H10: 0 | I10: ="PENALTY_OPTION_DESC_"&B10 -> PENALTY_OPTION_DESC_4 | J10: =IF(C10=0,"-",VLOOKUP(C10,컨디션_타입,2,0)) -> 감전 반응 시 | K10: =VLOOKUP(D10,옵션_타입,2,0)&IF(F10=0,"",IF(E10=0,F10," "&F10/100&"%"))&IF(G10=0,"",(IF(H10>=1," ["&G10/1000&"초마다 ",(IF(H10>=1,G10," ["&G10/1000&"초 동안]"))))&IF(H10=0,"",H10&"회]")) -> 고에너지 타격 | L10: 축성 비경: 정화의 화염 IV
A11: =10000+B11*ID규칙_지맥_이상_그룹_단위+COUNTIF($B$4:B11,B11) -> 10051 | B11: 5 | C11: 2 | D11: 9 | E11: 0 | F11: 0 | G11: 0 | H11: 0 | I11: ="PENALTY_OPTION_DESC_"&B11 -> PENALTY_OPTION_DESC_5 | J11: =IF(C11=0,"-",VLOOKUP(C11,컨디션_타입,2,0)) -> 융해 반응 시 | K11: =VLOOKUP(D11,옵션_타입,2,0)&IF(F11=0,"",IF(E11=0,F11," "&F11/100&"%"))&IF(G11=0,"",(IF(H11>=1," ["&G11/1000&"초마다 ",(IF(H11>=1,G11," ["&G11/1000&"초 동안]"))))&IF(H11=0,"",H11&"회]")) -> 에너지 블라스트 방출 | L11: 축성 비경: 정화의 화염 V
A12: =10000+B12*ID규칙_지맥_이상_그룹_단위+COUNTIF($B$4:B12,B12) -> 10052 | B12: 5 | C12: 4 | D12: 11 | E12: 0 | F12: 0 | G12: 0 | H12: 0 | I12: ="PENALTY_OPTION_DESC_"&B12 -> PENALTY_OPTION_DESC_5 | J12: =IF(C12=0,"-",VLOOKUP(C12,컨디션_타입,2,0)) -> 초전도 반응 시 | K12: =VLOOKUP(D12,옵션_타입,2,0)&IF(F12=0,"",IF(E12=0,F12," "&F12/100&"%"))&IF(G12=0,"",(IF(H12>=1," ["&G12/1000&"초마다 ",(IF(H12>=1,G12," ["&G12/1000&"초 동안]"))))&IF(H12=0,"",H12&"회]")) -> 고에너지 타격 | L12: 축성 비경: 정화의 화염 V
A13: =10000+B13*ID규칙_지맥_이상_그룹_단위+COUNTIF($B$4:B13,B13) -> 10061 | B13: 6 | C13: 3 | D13: 9 | E13: 0 | F13: 0 | G13: 0 | H13: 0 | I13: ="PENALTY_OPTION_DESC_"&B13 -> PENALTY_OPTION_DESC_6 | J13: =IF(C13=0,"-",VLOOKUP(C13,컨디션_타입,2,0)) -> 과부하 반응 시 | K13: =VLOOKUP(D13,옵션_타입,2,0)&IF(F13=0,"",IF(E13=0,F13," "&F13/100&"%"))&IF(G13=0,"",(IF(H13>=1," ["&G13/1000&"초마다 ",(IF(H13>=1,G13," ["&G13/1000&"초 동안]"))))&IF(H13=0,"",H13&"회]")) -> 에너지 블라스트 방출 | L13: 축성 비경: 정화의 화염 VI
A14: =10000+B14*ID규칙_지맥_이상_그룹_단위+COUNTIF($B$4:B14,B14) -> 10062 | B14: 6 | C14: 4 | D14: 11 | E14: 0 | F14: 0 | G14: 0 | H14: 0 | I14: ="PENALTY_OPTION_DESC_"&B14 -> PENALTY_OPTION_DESC_6 | J14: =IF(C14=0,"-",VLOOKUP(C14,컨디션_타입,2,0)) -> 초전도 반응 시 | K14: =VLOOKUP(D14,옵션_타입,2,0)&IF(F14=0,"",IF(E14=0,F14," "&F14/100&"%"))&IF(G14=0,"",(IF(H14>=1," ["&G14/1000&"초마다 ",(IF(H14>=1,G14," ["&G14/1000&"초 동안]"))))&IF(H14=0,"",H14&"회]")) -> 고에너지 타격 | L14: 축성 비경: 정화의 화염 VI
A15: =10000+B15*ID규칙_지맥_이상_그룹_단위+COUNTIF($B$4:B15,B15) -> 10071 | B15: 7 | C15: 9 | D15: 13 | E15: 1 | F15: 7500 | G15: 0 | H15: 0 | I15: ="PENALTY_OPTION_DESC_"&B15 -> PENALTY_OPTION_DESC_7 | J15: =IF(C15=0,"-",VLOOKUP(C15,컨디션_타입,2,0)) -> 파티 내 모든 캐릭터의 | K15: =VLOOKUP(D15,옵션_타입,2,0)&IF(F15=0,"",IF(E15=0,F15," "&F15/100&"%"))&IF(G15=0,"",(IF(H15>=1," ["&G15/1000&"초마다 ",(IF(H15>=1,G15," ["&G15/1000&"초 동안]"))))&IF(H15=0,"",H15&"회]")) -> 물리 피해 보너스 75% | L15: 축성 비경: 강철의 춤 I
... A248: =10000+B248*ID규칙_지맥_이상_그룹_단위+COUNTIF($B$4:B248,B248) -> 11645 | B248: 164 | C248: 40 | D248: 51 | E248: 0 | F248: 0 | G248: 0 | H248: 0 | I248: ="PENALTY_OPTION_DESC_"&B248 -> PENALTY_OPTION_DESC_164 | J248: =IF(C248=0,"-",VLOOKUP(C248,컨디션_타입,2,0)) -> 캐릭터가 지면의 원소 매트릭스 위에 있을 시 | K248: =VLOOKUP(D248,옵션_타입,2,0)&IF(F248=0,"",IF(E248=0,F248," "&F248/100&"%"))&IF(G248=0,"",(IF(H248>=1," ["&G248/1000&"초마다 ",(IF(H248>=1,G248," ["&G248/1000&"초 동안]"))))&IF(H248=0,"",H248&"회]")) -> 번개 원소: 정기의 신 제압 및 과부하 | L248: 추억: 칠엽 중존의 유리단 IV

Sheet REWARD
A1: 아이디 | B1: 보상 그룹 | C1: 요일 | D1: 아이템 아이디 | E1: 순서 | F1: 아이템 수량 | G1: 보상 확률 그룹 | H1: 획득 확률 | I1: #아이템 이름 | J1: #스테이지 이름 | K1: #보상 종류
A2: ID | B2: REWARD_GROUP | C2: DAY | D2: ITEM_ID | E2: SORT | F2: ITEM_COUNT | G2: PROBABILITY_GROUP | H2: PROBABILITY | I2: ITEM_NAME | J2: STAGE_NAME | K2: REWARD_KIND
A3: int | B3: int | C3: int | D3: int | E3: int | F3: int | G3: int | H3: int | I3: 참조 | J3: 참조 | K3: 참조
A4: =100000+B4*ID규칙_보상_그룹_단위+C4*ID규칙_요일_단위+COUNTIFS($B4:B$4,B4,$C4:C$4,C4) -> 100101 | B4: 1 | C4: 0 | D4: 101501 | E4: =COUNTIF($B$4:B4,B4) -> 1 | F4: 5 | G4: 0 | H4: 10000 | I4: =IFERROR(VLOOKUP(D4,ITEM!A:B,2,0)&" X"&F4,"아이템값 없음") -> 원석 X5 | J4: - | K4: 발견 보상
A5: =100000+B5*ID규칙_보상_그룹_단위+C5*ID규칙_요일_단위+COUNTIFS($B$4:B5,B5,$C$4:C5,C5) -> 100102 | B5: 1 | C5: 0 | D5: 103301 | E5: =COUNTIF($B$4:B5,B5) -> 2 | F5: 50 | G5: 0 | H5: 10000 | I5: =IFERROR(VLOOKUP(D5,ITEM!A:B,2,0)&" X"&F5,"아이템값 없음") -> 모라 X50 | J5: - | K5: 발견 보상
A6: =100000+B6*ID규칙_보상_그룹_단위+C6*ID규칙_요일_단위+COUNTIFS($B$4:B6,B6,$C$4:C6,C6) -> 100201 | B6: 2 | C6: 0 | D6: 103301 | E6: =COUNTIF($B$4:B6,B6) -> 1 | F6: 100 | G6: 1 | H6: 10000 | I6: =IFERROR(VLOOKUP(D6,ITEM!A:B,2,0)&" X"&F6,"아이템값 없음") -> 모라 X100 | J6: 축성 비경: 정화의 화염 I | K6: 클리어 보상
A7: =100000+B7*ID규칙_보상_그룹_단위+C7*ID규칙_요일_단위+COUNTIFS($B$4:B7,B7,$C$4:C7,C7) -> 100202 | B7: 2 | C7: 0 | D7: 102301 | E7: =COUNTIF($B$4:B7,B7) -> 2 | F7: 1525 | G7: 2 | H7: 10000 | I7: =IFERROR(VLOOKUP(D7,ITEM!A:B,2,0)&" X"&F7,"아이템값 없음") -> 모험 경력 X1525 | J7: 축성 비경: 정화의 화염 I | K7: 클리어 보상
A8: =100000+B8*ID규칙_보상_그룹_단위+C8*ID규칙_요일_단위+COUNTIFS($B$4:B8,B8,$C$4:C8,C8) -> 100203 | B8: 2 | C8: 0 | D8: 105301 | E8: =COUNTIF($B$4:B8,B8) -> 3 | F8: 15 | G8: 3 | H8: 10000 | I8: =IFERROR(VLOOKUP(D8,ITEM!A:B,2,0)&" X"&F8,"아이템값 없음") -> 호감도 경험치 X15 | J8: 축성 비경: 정화의 화염 I | K8: 클리어 보상
A9: =100000+B9*ID규칙_보상_그룹_단위+C9*ID규칙_요일_단위+COUNTIFS($B$4:B9,B9,$C$4:C9,C9) -> 100204 | B9: 2 | C9: 0 | D9: 106202 | E9: =COUNTIF($B$4:B9,B9) -> 4 | F9: 1 | G9: 4 | H9: 667 | I9: =IFERROR(VLOOKUP(D9,ITEM!A:B,2,0)&" X"&F9,"아이템값 없음") -> 모험가의 꽃 X1 | J9: 축성 비경: 정화의 화염 I | K9: 클리어 보상
A10: =100000+B10*ID규칙_보상_그룹_단위+C10*ID규칙_요일_단위+COUNTIFS($B$4:B10,B10,$C$4:C10,C10) -> 100205 | B10: 2 | C10: 0 | D10: 107202 | E10: =COUNTIF($B$4:B10,B10) -> 5 | F10: 1 | G10: 4 | H10: 667 | I10: =IFERROR(VLOOKUP(D10,ITEM!A:B,2,0)&" X"&F10,"아이템값 없음") -> 모험가의 꽁지 깃털 X1 | J10: 축성 비경: 정화의 화염 I | K10: 클리어 보상
A11: =100000+B11*ID규칙_보상_그룹_단위+C11*ID규칙_요일_단위+COUNTIFS($B$4:B11,B11,$C$4:C11,C11) -> 100206 | B11: 2 | C11: 0 | D11: 108202 | E11: =COUNTIF($B$4:B11,B11) -> 6 | F11: 1 | G11: 4 | H11: 667 | I11: =IFERROR(VLOOKUP(D11,ITEM!A:B,2,0)&" X"&F11,"아이템값 없음") -> 모험가의 회중시계 X1 | J11: 축성 비경: 정화의 화염 I | K11: 클리어 보상
A12: =100000+B12*ID규칙_보상_그룹_단위+C12*ID규칙_요일_단위+COUNTIFS($B$4:B12,B12,$C$4:C12,C12) -> 100207 | B12: 2 | C12: 0 | D12: 109202 | E12: =COUNTIF($B$4:B12,B12) -> 7 | F12: 1 | G12: 4 | H12: 667 | I12: =IFERROR(VLOOKUP(D12,ITEM!A:B,2,0)&" X"&F12,"아이템값 없음") -> 모험가의 황금잔 X1 | J12: 축성 비경: 정화의 화염 I | K12: 클리어 보상
A13: =100000+B13*ID규칙_보상_그룹_단위+C13*ID규칙_요일_단위+COUNTIFS($B$4:B13,B13,$C$4:C13,C13) -> 100208 | B13: 2 | C13: 0 | D13: 110202 | E13: =COUNTIF($B$4:B13,B13) -> 8 | F13: 1 | G13: 4 | H13: 667 | I13: =IFERROR(VLOOKUP(D13,ITEM!A:B,2,0)&" X"&F13,"아이템값 없음") -> 모험가의 머리띠 X1 | J13: 축성 비경: 정화의 화염 I | K13: 클리어 보상
A14: =100000+B14*ID규칙_보상_그룹_단위+C14*ID규칙_요일_단위+COUNTIFS($B$4:B14,B14,$C$4:C14,C14) -> 100209 | B14: 2 | C14: 0 | D14: 106303 | E14: =COUNTIF($B$4:B14,B14) -> 9 | F14: 1 | G14: 4 | H14: 667 | I14: =IFERROR(VLOOKUP(D14,ITEM!A:B,2,0)&" X"&F14,"아이템값 없음") -> 모험가의 꽃 X1 | J14: 축성 비경: 정화의 화염 I | K14: 클리어 보상
A15: =100000+B15*ID규칙_보상_그룹_단위+C15*ID규칙_요일_단위+COUNTIFS($B$4:B15,B15,$C$4:C15,C15) -> 100210 | B15: 2 | C15: 0 | D15: 107303 | E15: =COUNTIF($B$4:B15,B15) -> 10 | F15: 1 | G15: 4 | H15: 667 | I15: =IFERROR(VLOOKUP(D15,ITEM!A:B,2,0)&" X"&F15,"아이템값 없음") -> 모험가의 꽁지 깃털 X1 | J15: 축성 비경: 정화의 화염 I | K15: 클리어 보상
A16: =100000+B16*ID규칙_보상_그룹_단위+C16*ID규칙_요일_단위+COUNTIFS($B$4:B16,B16,$C$4:C16,C16) -> 100211 | B16: 2 | C16: 0 | D16: 108303 | E16: =COUNTIF($B$4:B16,B16) -> 11 | F16: 1 | G16: 4 | H16: 667 | I16: =IFERROR(VLOOKUP(D16,ITEM!A:B,2,0)&" X"&F16,"아이템값 없음") -> 모험가의 회중시계 X1 | J16: 축성 비경: 정화의 화염 I | K16: 클리어 보상
... A4545: =100000+B4545*ID규칙_보상_그룹_단위+C4545*ID규칙_요일_단위+COUNTIFS($B$4:B4545,B4545,$C$4:C4545,C4545) -> 117566 | B4545: 175 | C4545: 0 | D4545: 116418 | E4545: =COUNTIF($B$4:B4545,B4545) -> 66 | F4545: 1 | G4545: 792 | H4545: 2000 | I4545: =IFERROR(VLOOKUP(D4545,ITEM!A:B,2,0)&" X"&F4545,"아이템값 없음") -> 중앙 대륙의 장병기 원형 X1 | J4545: 추억: 칠엽 중존의 유리단 IV | K4545: 클리어 보상

Sheet INDEX_ITEM
B2: INDEX_ITEM
B3: ID 규칙
B4: 1 | C4: 0 | D4: 1 | E4: 1 | F4: 0 | G4: 1 | I4: 아이템 타입 단위 | J4: 1000
D5: ITEM_TYPE | E5: RARE | G5: 순번 | I5: 등급 단위 | J5: 100
B7: 한글 변수 | C7: 영어 변수 | F7: 자료형 | G7: 설명
B8: 아이디 | C8: ID | F8: INT | G8: 아이템 아이디
B9: 분류 | C9: CATEGORY | F9: INT | G9: 아이템 분류
B10: 아이템 타입 | C10: ITEM_TYPE | F10: INT | G10: 아이템 타입
B11: 등급 | C11: RARE | F11: INT | G11: 아이템의 등급
B12: 잠금 여부 | C12: IS_LOCK | F12: INT | G12: 잠금 여부
B13: 누적 수량 | C13: MAX_STACK | F13: INT | G13: 보유 가능 최대 수량
B14: 아이템 옵션 | C14: ITEM_OPTION | F14: INT | G14: 아이템에 붙는 옵션
B15: 세트 그룹 | C15: SET_GROUP | F15: INT | G15: 세트 아이템 그룹
B16: 획득처 그룹 | C16: GAIN_GROUP | F16: INT | G16: 아이템 획득처 그룹
B17: 아이템 이름 | C17: ITEM_NAME | F17: STRING | G17: 아이템 이름
B18: 아이템 아이콘 | C18: ITEM_ICON | F18: STRING | G18: 아이템 아이콘
B19: 아이템 설명 | C19: ITEM_DESC | F19: STRING | G19: 아이템 설명
B21: RARE | F21: ITEM_TYPE
B22: INDEX | C22: 설명 | F22: INDEX | G22: 설명
B23: 1 | C23: ★1 | F23: 1 | G23: 원석
B24: 2 | C24: ★2 | F24: 2 | G24: 모험 경력
B25: 3 | C25: ★3 | F25: 3 | G25: 통용 화폐
B26: 4 | C26: ★4 | F26: 4 | G26: 캐릭터 경험치
B27: 5 | C27: ★5 | F27: 5 | G27: 호감도 경험치
F28: 6 | G28: 생명의 꽃
F29: 7 | G29: 죽음의 깃털
B30: IS_LOCK | F30: 8 | G30: 시간의 모래
B31: INDEX | C31: 설명 | F31: 9 | G31: 공간의 성배
B32: 0 | C32: 잠금 불가능 | F32: 10 | G32: 이성의 왕관
B33: 1 | C33: 잠금 가능 | F33: 11 | G33: 캐릭터 경험치 소재
F34: 12 | G34: 캐릭터 육성 소재
F35: 13 | G35: 캐릭터 돌파 소재
F36: 14 | G36: 특성 육성 소재
F37: 15 | G37: 무기 돌파 소재
F38: 16 | G38: 소재
F39: 17 | G39: 성물 상자
F40: 18 | G40: 소모품
B43: INDEX_CATEGORY
B44: ID 규칙
B45: 1
...

Sheet ITEM
A1: 아이디 | B1: #아이템 이름 | C1: #아이템 세트 이름 | D1: 분류 | E1: 아이템 타입 | F1: 등급 | G1: 잠금 여부 | H1: 누적 수량 | I1: 아이템 옵션 | J1: 세트 그룹 | K1: 획득처 그룹 | L1: 아이템 이름 | M1: 아이템 아이콘 | N1: 아이템 설명
A2: ID | B2: ITEM_NAME | C2: ITEM_SET_NAME | D2: CATEGORY | E2: ITEM_TYPE | F2: RARE | G2: IS_LOCK | H2: MAX_STACK | I2: ITEM_OPTION | J2: SET_GROUP | K2: GAIN_GROUP | L2: ITEM_NAME | M2: ITEM_ICON | N2: ITEM_DESC
A3: int | B3: 참조 | C3: 참조 | D3: int | E3: int | F3: int | G3: int | H3: int | I3: int | J3: int | K3: int | L3: string | M3: string | N3: string
A4: =100000+E4*ID규칙_아이템_타입_단위+F4*ID규칙_등급_단위+COUNTIFS($D$4:D4,D4,$E$4:E4:E4,E4) -> 101501 | B4: 원석 | C4: - | D4: 0 | E4: 1 | F4: 5 | G4: 0 | H4: 999999 | I4: =IF(D4=2,E4*1000+F4,0) -> 0 | J4: =IFERROR(INDEX(SET_GROUP!$B:$B,MATCH(ITEM!C4,SET_GROUP!$N:$N,0)),0) -> 0 | K4: =IFERROR(IF(D4>2,INDEX(ITEM_GAIN_INFO!$B:$B,MATCH(ITEM!B4,ITEM_GAIN_INFO!$G:$G,0)),INDEX(ITEM_GAIN_INFO!$B:$B,MATCH(ITEM!C4,ITEM_GAIN_INFO!$G:$G,0))),0) -> 0 | L4: ="ITEM_NAME_"&A4 -> ITEM_NAME_101501 | M4: ="ITEM_ICON_"&A4 -> ITEM_ICON_101501 | N4: ="ITEM_DESC_"&A4 -> ITEM_DESC_101501
A5: =100000+E5*ID규칙_아이템_타입_단위+F5*ID규칙_등급_단위+COUNTIFS($D$4:D5,D5,$E$4:E5:E5,E5) -> 102301 | B5: 모험 경력 | C5: - | D5: 0 | E5: 2 | F5: 3 | G5: 0 | H5: 999999 | I5: =IF(D5=2,E5*1000+F5,0) -> 0 | J5: =IFERROR(INDEX(SET_GROUP!$B:$B,MATCH(ITEM!C5,SET_GROUP!$N:$N,0)),0) -> 0 | K5: =IFERROR(IF(D5>2,INDEX(ITEM_GAIN_INFO!$B:$B,MATCH(ITEM!B5,ITEM_GAIN_INFO!$G:$G,0)),INDEX(ITEM_GAIN_INFO!$B:$B,MATCH(ITEM!C5,ITEM_GAIN_INFO!$G:$G,0))),0) -> 0 | L5: ="ITEM_NAME_"&A5 -> ITEM_NAME_102301 | M5: ="ITEM_ICON_"&A5 -> ITEM_ICON_102301 | N5: ="ITEM_DESC_"&A5 -> ITEM_DESC_102301
A6: =100000+E6*ID규칙_아이템_타입_단위+F6*ID규칙_등급_단위+COUNTIFS($D$4:D6,D6,$E$4:E6:E6,E6) -> 103301 | B6: 모라 | C6: - | D6: 0 | E6: 3 | F6: 3 | G6: 0 | H6: 2100000000 | I6: =IF(D6=2,E6*1000+F6,0) -> 0 | J6: =IFERROR(INDEX(SET_GROUP!$B:$B,MATCH(ITEM!C6,SET_GROUP!$N:$N,0)),0) -> 0 | K6: =IFERROR(IF(D6>2,INDEX(ITEM_GAIN_INFO!$B:$B,MATCH(ITEM!B6,ITEM_GAIN_INFO!$G:$G,0)),INDEX(ITEM_GAIN_INFO!$B:$B,MATCH(ITEM!C6,ITEM_GAIN_INFO!$G:$G,0))),0) -> 0 | L6: ="ITEM_NAME_"&A6 -> ITEM_NAME_103301 | M6: ="ITEM_ICON_"&A6 -> ITEM_ICON_103301 | N6: ="ITEM_DESC_"&A6 -> ITEM_DESC_103301
A7: =100000+E7*ID규칙_아이템_타입_단위+F7*ID규칙_등급_단위+COUNTIFS($D$4:D7,D7,$E$4:E7:E7,E7) -> 104301 | B7: 캐릭터 경험치 | C7: - | D7: 0 | E7: 4 | F7: 3 | G7: 0 | H7: 2100000000 | I7: =IF(D7=2,E7*1000+F7,0) -> 0 | J7: =IFERROR(INDEX(SET_GROUP!$B:$B,MATCH(ITEM!C7,SET_GROUP!$N:$N,0)),0) -> 0 | K7: =IFERROR(IF(D7>2,INDEX(ITEM_GAIN_INFO!$B:$B,MATCH(ITEM!B7,ITEM_GAIN_INFO!$G:$G,0)),INDEX(ITEM_GAIN_INFO!$B:$B,MATCH(ITEM!C7,ITEM_GAIN_INFO!$G:$G,0))),0) -> 0 | L7: ="ITEM_NAME_"&A7 -> ITEM_NAME_104301 | M7: ="ITEM_ICON_"&A7 -> ITEM_ICON_104301 | N7: ="ITEM_DESC_"&A7 -> ITEM_DESC_104301
A8: =100000+E8*ID규칙_아이템_타입_단위+F8*ID규칙_등급_단위+COUNTIFS($D$4:D8,D8,$E$4:E8:E8,E8) -> 105301 | B8: 호감도 경험치 | C8: - | D8: 0 | E8: 5 | F8: 3 | G8: 0 | H8: 9999 | I8: =IF(D8=2,E8*1000+F8,0) -> 0 | J8: =IFERROR(INDEX(SET_GROUP!$B:$B,MATCH(ITEM!C8,SET_GROUP!$N:$N,0)),0) -> 0 | K8: =IFERROR(IF(D8>2,INDEX(ITEM_GAIN_INFO!$B:$B,MATCH(ITEM!B8,ITEM_GAIN_INFO!$G:$G,0)),INDEX(ITEM_GAIN_INFO!$B:$B,MATCH(ITEM!C8,ITEM_GAIN_INFO!$G:$G,0))),0) -> 0 | L8: ="ITEM_NAME_"&A8 -> ITEM_NAME_105301 | M8: ="ITEM_ICON_"&A8 -> ITEM_ICON_105301 | N8: ="ITEM_DESC_"&A8 -> ITEM_DESC_105301
A9: =100000+E9*ID규칙_아이템_타입_단위+F9*ID규칙_등급_단위+COUNTIFS($D$4:D9,D9,$E$4:E9:E9,E9) -> 106101 | B9: 모험가의 꽃 | C9: 모험가 | D9: 2 | E9: 6 | F9: 1 | G9: 1 | H9: 1 | I9: =IF(D9=2,E9*1000+F9*100,0) -> 6100 | J9: =IFERROR(INDEX(SET_GROUP!$B:$B,MATCH(ITEM!C9,SET_GROUP!$N:$N,0)),0) -> 1 | K9: =IFERROR(IF(D9>2,INDEX(ITEM_GAIN_INFO!$B:$B,MATCH(ITEM!B9,ITEM_GAIN_INFO!$G:$G,0)),INDEX(ITEM_GAIN_INFO!$B:$B,MATCH(ITEM!C9,ITEM_GAIN_INFO!$G:$G,0))),0) -> 1 | L9: ="ITEM_NAME_"&A9 -> ITEM_NAME_106101 | M9: ="ITEM_ICON_"&A9 -> ITEM_ICON_106101 | N9: ="ITEM_DESC_"&A9 -> ITEM_DESC_106101
A10: =100000+E10*ID규칙_아이템_타입_단위+F10*ID규칙_등급_단위+COUNTIFS($D$4:D10,D10,$E$4:E10:E10,E10) -> 106202 | B10: 모험가의 꽃 | C10: 모험가 | D10: 2 | E10: 6 | F10: 2 | G10: 1 | H10: 1 | I10: =IF(D10=2,E10*1000+F10*100,0) -> 6200 | J10: =IFERROR(INDEX(SET_GROUP!$B:$B,MATCH(ITEM!C10,SET_GROUP!$N:$N,0)),0) -> 1 | K10: =IFERROR(IF(D10>2,INDEX(ITEM_GAIN_INFO!$B:$B,MATCH(ITEM!B10,ITEM_GAIN_INFO!$G:$G,0)),INDEX(ITEM_GAIN_INFO!$B:$B,MATCH(ITEM!C10,ITEM_GAIN_INFO!$G:$G,0))),0) -> 1 | L10: ="ITEM_NAME_"&A10 -> ITEM_NAME_106202 | M10: ="ITEM_ICON_"&A10 -> ITEM_ICON_106202 | N10: ="ITEM_DESC_"&A10 -> ITEM_DESC_106202
A11: =100000+E11*ID규칙_아이템_타입_단위+F11*ID규칙_등급_단위+COUNTIFS($D$4:D11,D11,$E$4:E11:E11,E11) -> 106303 | B11: 모험가의 꽃 | C11: 모험가 | D11: 2 | E11: 6 | F11: 3 | G11: 1 | H11: 1 | I11: =IF(D11=2,E11*1000+F11*100,0) -> 6300 | J11: =IFERROR(INDEX(SET_GROUP!$B:$B,MATCH(ITEM!C11,SET_GROUP!$N:$N,0)),0) -> 1 | K11: =IFERROR(IF(D11>2,INDEX(ITEM_GAIN_INFO!$B:$B,MATCH(ITEM!B11,ITEM_GAIN_INFO!$G:$G,0)),INDEX(ITEM_GAIN_INFO!$B:$B,MATCH(ITEM!C11,ITEM_GAIN_INFO!$G:$G,0))),0) -> 1 | L11: ="ITEM_NAME_"&A11 -> ITEM_NAME_106303 | M11: ="ITEM_ICON_"&A11 -> ITEM_ICON_106303 | N11: ="ITEM_DESC_"&A11 -> ITEM_DESC_106303
A12: =100000+E12*ID규칙_아이템_타입_단위+F12*ID규칙_등급_단위+COUNTIFS($D$4:D12,D12,$E$4:E12:E12,E12) -> 107101 | B12: 모험가의 꽁지 깃털 | C12: 모험가 | D12: 2 | E12: 7 | F12: 1 | G12: 1 | H12: 1 | I12: =IF(D12=2,E12*1000+F12*100,0) -> 7100 | J12: =IFERROR(INDEX(SET_GROUP!$B:$B,MATCH(ITEM!C12,SET_GROUP!$N:$N,0)),0) -> 1 | K12: =IFERROR(IF(D12>2,INDEX(ITEM_GAIN_INFO!$B:$B,MATCH(ITEM!B12,ITEM_GAIN_INFO!$G:$G,0)),INDEX(ITEM_GAIN_INFO!$B:$B,MATCH(ITEM!C12,ITEM_GAIN_INFO!$G:$G,0))),0) -> 1 | L12: ="ITEM_NAME_"&A12 -> ITEM_NAME_107101 | M12: ="ITEM_ICON_"&A12 -> ITEM_ICON_107101 | N12: ="ITEM_DESC_"&A12 -> ITEM_DESC_107101
A13: =100000+E13*ID규칙_아이템_타입_단위+F13*ID규칙_등급_단위+COUNTIFS($D$4:D13,D13,$E$4:E13:E13,E13) -> 107202 | B13: 모험가의 꽁지 깃털 | C13: 모험가 | D13: 2 | E13: 7 | F13: 2 | G13: 1 | H13: 1 | I13: =IF(D13=2,E13*1000+F13*100,0) -> 7200 | J13: =IFERROR(INDEX(SET_GROUP!$B:$B,MATCH(ITEM!C13,SET_GROUP!$N:$N,0)),0) -> 1 | K13: =IFERROR(IF(D13>2,INDEX(ITEM_GAIN_INFO!$B:$B,MATCH(ITEM!B13,ITEM_GAIN_INFO!$G:$G,0)),INDEX(ITEM_GAIN_INFO!$B:$B,MATCH(ITEM!C13,ITEM_GAIN_INFO!$G:$G,0))),0) -> 1 | L13: ="ITEM_NAME_"&A13 -> ITEM_NAME_107202 | M13: ="ITEM_ICON_"&A13 -> ITEM_ICON_107202 | N13: ="ITEM_DESC_"&A13 -> ITEM_DESC_107202
A14: =100000+E14*ID규칙_아이템_타입_단위+F14*ID규칙_등급_단위+COUNTIFS($D$4:D14,D14,$E$4:E14:E14,E14) -> 107303 | B14: 모험가의 꽁지 깃털 | C14: 모험가 | D14: 2 | E14: 7 | F14: 3 | G14: 1 | H14: 1 | I14: =IF(D14=2,E14*1000+F14*100,0) -> 7300 | J14: =IFERROR(INDEX(SET_GROUP!$B:$B,MATCH(ITEM!C14,SET_GROUP!$N:$N,0)),0) -> 1 | K14: =IFERROR(IF(D14>2,INDEX(ITEM_GAIN_INFO!$B:$B,MATCH(ITEM!B14,ITEM_GAIN_INFO!$G:$G,0)),INDEX(ITEM_GAIN_INFO!$B:$B,MATCH(ITEM!C14,ITEM_GAIN_INFO!$G:$G,0))),0) -> 1 | L14: ="ITEM_NAME_"&A14 -> ITEM_NAME_107303 | M14: ="ITEM_ICON_"&A14 -> ITEM_ICON_107303 | N14: ="ITEM_DESC_"&A14 -> ITEM_DESC_107303
A15: =100000+E15*ID규칙_아이템_타입_단위+F15*ID규칙_등급_단위+COUNTIFS($D$4:D15,D15,$E$4:E15:E15,E15) -> 108101 | B15: 모험가의 회중시계 | C15: 모험가 | D15: 2 | E15: 8 | F15: 1 | G15: 1 | H15: 1 | I15: =IF(D15=2,E15*1000+F15*100,0) -> 8100 | J15: =IFERROR(INDEX(SET_GROUP!$B:$B,MATCH(ITEM!C15,SET_GROUP!$N:$N,0)),0) -> 1 | K15: =IFERROR(IF(D15>2,INDEX(ITEM_GAIN_INFO!$B:$B,MATCH(ITEM!B15,ITEM_GAIN_INFO!$G:$G,0)),INDEX(ITEM_GAIN_INFO!$B:$B,MATCH(ITEM!C15,ITEM_GAIN_INFO!$G:$G,0))),0) -> 1 | L15: ="ITEM_NAME_"&A15 -> ITEM_NAME_108101 | M15: ="ITEM_ICON_"&A15 -> ITEM_ICON_108101 | N15: ="ITEM_DESC_"&A15 -> ITEM_DESC_108101
A16: =100000+E16*ID규칙_아이템_타입_단위+F16*ID규칙_등급_단위+COUNTIFS($D$4:D16,D16,$E$4:E16:E16,E16) -> 108202 | B16: 모험가의 회중시계 | C16: 모험가 | D16: 2 | E16: 8 | F16: 2 | G16: 1 | H16: 1 | I16: =IF(D16=2,E16*1000+F16*100,0) -> 8200 | J16: =IFERROR(INDEX(SET_GROUP!$B:$B,MATCH(ITEM!C16,SET_GROUP!$N:$N,0)),0) -> 1 | K16: =IFERROR(IF(D16>2,INDEX(ITEM_GAIN_INFO!$B:$B,MATCH(ITEM!B16,ITEM_GAIN_INFO!$G:$G,0)),INDEX(ITEM_GAIN_INFO!$B:$B,MATCH(ITEM!C16,ITEM_GAIN_INFO!$G:$G,0))),0) -> 1 | L16: ="ITEM_NAME_"&A16 -> ITEM_NAME_108202 | M16: ="ITEM_ICON_"&A16 -> ITEM_ICON_108202 | N16: ="ITEM_DESC_"&A16 -> ITEM_DESC_108202
A17: =100000+E17*ID규칙_아이템_타입_단위+F17*ID규칙_등급_단위+COUNTIFS($D$4:D17,D17,$E$4:E17:E17,E17) -> 108303 | B17: 모험가의 회중시계 | C17: 모험가 | D17: 2 | E17: 8 | F17: 3 | G17: 1 | H17: 1 | I17: =IF(D17=2,E17*1000+F17*100,0) -> 8300 | J17: =IFERROR(INDEX(SET_GROUP!$B:$B,MATCH(ITEM!C17,SET_GROUP!$N:$N,0)),0) -> 1 | K17: =IFERROR(IF(D17>2,INDEX(ITEM_GAIN_INFO!$B:$B,MATCH(ITEM!B17,ITEM_GAIN_INFO!$G:$G,0)),INDEX(ITEM_GAIN_INFO!$B:$B,MATCH(ITEM!C17,ITEM_GAIN_INFO!$G:$G,0))),0) -> 1 | L17: ="ITEM_NAME_"&A17 -> ITEM_NAME_108303 | M17: ="ITEM_ICON_"&A17 -> ITEM_ICON_108303 | N17: ="ITEM_DESC_"&A17 -> ITEM_DESC_108303
A18: =100000+E18*ID규칙_아이템_타입_단위+F18*ID규칙_등급_단위+COUNTIFS($D$4:D18,D18,$E$4:E18:E18,E18) -> 109101 | B18: 모험가의 황금잔 | C18: 모험가 | D18: 2 | E18: 9 | F18: 1 | G18: 1 | H18: 1 | I18: =IF(D18=2,E18*1000+F18*100,0) -> 9100 | J18: =IFERROR(INDEX(SET_GROUP!$B:$B,MATCH(ITEM!C18,SET_GROUP!$N:$N,0)),0) -> 1 | K18: =IFERROR(IF(D18>2,INDEX(ITEM_GAIN_INFO!$B:$B,MATCH(ITEM!B18,ITEM_GAIN_INFO!$G:$G,0)),INDEX(ITEM_GAIN_INFO!$B:$B,MATCH(ITEM!C18,ITEM_GAIN_INFO!$G:$G,0))),0) -> 1 | L18: ="ITEM_NAME_"&A18 -> ITEM_NAME_109101 | M18: ="ITEM_ICON_"&A18 -> ITEM_ICON_109101 | N18: ="ITEM_DESC_"&A18 -> ITEM_DESC_109101
A19: =100000+E19*ID규칙_아이템_타입_단위+F19*ID규칙_등급_단위+COUNTIFS($D$4:D19,D19,$E$4:E19:E19,E19) -> 109202 | B19: 모험가의 황금잔 | C19: 모험가 | D19: 2 | E19: 9 | F19: 2 | G19: 1 | H19: 1 | I19: =IF(D19=2,E19*1000+F19*100,0) -> 9200 | J19: =IFERROR(INDEX(SET_GROUP!$B:$B,MATCH(ITEM!C19,SET_GROUP!$N:$N,0)),0) -> 1 | K19: =IFERROR(IF(D19>2,INDEX(ITEM_GAIN_INFO!$B:$B,MATCH(ITEM!B19,ITEM_GAIN_INFO!$G:$G,0)),INDEX(ITEM_GAIN_INFO!$B:$B,MATCH(ITEM!C19,ITEM_GAIN_INFO!$G:$G,0))),0) -> 1 | L19: ="ITEM_NAME_"&A19 -> ITEM_NAME_109202 | M19: ="ITEM_ICON_"&A19 -> ITEM_ICON_109202 | N19: ="ITEM_DESC_"&A19 -> ITEM_DESC_109202
A20: =100000+E20*ID규칙_아이템_타입_단위+F20*ID규칙_등급_단위+COUNTIFS($D$4:D20,D20,$E$4:E20:E20,E20) -> 109303 | B20: 모험가의 황금잔 | C20: 모험가 | D20: 2 | E20: 9 | F20: 3 | G20: 1 | H20: 1 | I20: =IF(D20=2,E20*1000+F20*100,0) -> 9300 | J20: =IFERROR(INDEX(SET_GROUP!$B:$B,MATCH(ITEM!C20,SET_GROUP!$N:$N,0)),0) -> 1 | K20: =IFERROR(IF(D20>2,INDEX(ITEM_GAIN_INFO!$B:$B,MATCH(ITEM!B20,ITEM_GAIN_INFO!$G:$G,0)),INDEX(ITEM_GAIN_INFO!$B:$B,MATCH(ITEM!C20,ITEM_GAIN_INFO!$G:$G,0))),0) -> 1 | L20: ="ITEM_NAME_"&A20 -> ITEM_NAME_109303 | M20: ="ITEM_ICON_"&A20 -> ITEM_ICON_109303 | N20: ="ITEM_DESC_"&A20 -> ITEM_DESC_109303
... A692: =100000+E692*ID규칙_아이템_타입_단위+F692*ID규칙_등급_단위+COUNTIFS($D$4:D692,D692,$E$4:E692:E692,E692) -> 118401 | B692: 이상한 꿈의 용매 | C692: - | D692: 8 | E692: 18 | F692: 4 | G692: 0 | H692: 9999 | I692: =IF(D692=2,E692*1000+F692*100,0) -> 0 | J692: =IFERROR(INDEX(SET_GROUP!$B:$B,MATCH(ITEM!C692,SET_GROUP!$N:$N,0)),0) -> 0 | K692: =IFERROR(IF(D692>2,INDEX(ITEM_GAIN_INFO!$B:$B,MATCH(ITEM!B692,ITEM_GAIN_INFO!$G:$G,0)),INDEX(ITEM_GAIN_INFO!$B:$B,MATCH(ITEM!C692,ITEM_GAIN_INFO!$G:$G,0))),0) -> 314 | L692: ="ITEM_NAME_"&A692 -> ITEM_NAME_118401 | M692: ="ITEM_ICON_"&A692 -> ITEM_ICON_118401 | N692: ="ITEM_DESC_"&A692 -> ITEM_DESC_118401

Sheet CATEGORY
A1: 아이디 | B1: 분류 | C1: 최대 용량 | D1: 순서 | E1: 분류 이름 | F1: 분류 아이콘 | G1: #분류 이름
A2: ID | B2: CATEGORY | C2: MAX_STACK | D2: SORT | E2: CATEGORY_NAME | F2: CATEGORY_ICON | G2: CATEGORY_NAME
A3: int | B3: int | C3: int | D3: int | E3: string | F3: string | G3: 참조
A4: 1 | B4: 1 | C4: 2000 | D4: 1 | E4: ="ITEM_CATEGORY_NAME_"&B4 -> ITEM_CATEGORY_NAME_1 | F4: ="ITEM_CATEGORY_ICON_"&B4 -> ITEM_CATEGORY_ICON_1 | G4: =VLOOKUP(E4,STRING!$A$2733:$B$2741,2,0) -> 무기
A5: 2 | B5: 2 | C5: 1500 | D5: 2 | E5: ="ITEM_CATEGORY_NAME_"&B5 -> ITEM_CATEGORY_NAME_2 | F5: ="ITEM_CATEGORY_ICON_"&B5 -> ITEM_CATEGORY_ICON_2 | G5: =VLOOKUP(E5,STRING!$A$2733:$B$2741,2,0) -> 성유물
A6: 3 | B6: 3 | C6: 2000 | D6: 3 | E6: ="ITEM_CATEGORY_NAME_"&B6 -> ITEM_CATEGORY_NAME_3 | F6: ="ITEM_CATEGORY_ICON_"&B6 -> ITEM_CATEGORY_ICON_3 | G6: =VLOOKUP(E6,STRING!$A$2733:$B$2741,2,0) -> 육성 아이템
A7: 4 | B7: 4 | C7: 2000 | D7: 4 | E7: ="ITEM_CATEGORY_NAME_"&B7 -> ITEM_CATEGORY_NAME_4 | F7: ="ITEM_CATEGORY_ICON_"&B7 -> ITEM_CATEGORY_ICON_4 | G7: =VLOOKUP(E7,STRING!$A$2733:$B$2741,2,0) -> 음식
A8: 5 | B8: 5 | C8: 2000 | D8: 5 | E8: ="ITEM_CATEGORY_NAME_"&B8 -> ITEM_CATEGORY_NAME_5 | F8: ="ITEM_CATEGORY_ICON_"&B8 -> ITEM_CATEGORY_ICON_5 | G8: =VLOOKUP(E8,STRING!$A$2733:$B$2741,2,0) -> 재료
A9: 6 | B9: 6 | C9: 2000 | D9: 6 | E9: ="ITEM_CATEGORY_NAME_"&B9 -> ITEM_CATEGORY_NAME_6 | F9: ="ITEM_CATEGORY_ICON_"&B9 -> ITEM_CATEGORY_ICON_6 | G9: =VLOOKUP(E9,STRING!$A$2733:$B$2741,2,0) -> 간편 아이템
A10: 7 | B10: 7 | C10: 2000 | D10: 7 | E10: ="ITEM_CATEGORY_NAME_"&B10 -> ITEM_CATEGORY_NAME_7 | F10: ="ITEM_CATEGORY_ICON_"&B10 -> ITEM_CATEGORY_ICON_7 | G10: =VLOOKUP(E10,STRING!$A$2733:$B$2741,2,0) -> 임무
