Workbook
Name AlertGetItem: #REF!
Name AlertGetItem_List: #REF!
Name Break: #REF!
Name Break_List: #REF!
Name Broadcast: #REF!
Name Broadcast_List: #REF!
Name CheckTradeRuby_List: #REF!
Name Enchant: #REF!
Name Enchant_List: #REF!
Name FixCreateSlot: #REF!
Name FixCreateSlot_List: #REF!
Name FixSlot: #REF!
Name FixSlot_List: #REF!
Name IncludeSealing: #REF!
Name IncludeSealing_List: #REF!
Name IncludeServerTransfer: #REF!
Name Is_UsedSkill: #REF!
Name Is_UsedSkill_List: #REF!
Name LockFunc: #REF!
Name LockFunc_List: #REF!
Name Main_Category: #REF!
Name Main_Category_List: #REF!
Name PetAutoSell: #REF!
Name PetAutoSell_List: #REF!
Name Sell: #REF!
Name Sell_List: #REF!
Name SetOperatorTool_List: #REF!
Name SetTrade_List: #REF!
Name Skill_Level_Ratio: #REF!
Name Sub_Category: #REF!
Name Sub_Category_List: #REF!
Name T_AutoSort: #REF!
Name T_AutoSort_List: #REF!
Name T_Equip: #REF!
Name T_Equip_List: #REF!
Name T_EquipSlot: #REF!
Name T_EquipSlot_List: #REF!
Name T_ExchangeCategory: #REF!
Name T_ExchangeCategory_List: #REF!
Name T_Goods: #REF!
Name T_Goods_List: #REF!
Name T_ItemGrade: #REF!
Name T_ItemGrade_List: #REF!
Name T_Job: #REF!
Name T_Job_List: #REF!
Name T_RandomBox: #REF!
Name T_RandomBox_List: #REF!
Name T_UiNumber: #REF!
Name T_UiNumber_List: #REF!
Name T_WeaponBone_L: #REF!
Name T_WeaponBone_L_List: #REF!
Name T_WeaponBone_R: #REF!
Name T_WeaponBone_R_List: #REF!
Name Throw: #REF!
Name Throw_List: #REF!
Name Trade: #REF!
Name Trade_List: #REF!
Name TypeGrowth: #REF!
Name TypeGrowth_List: #REF!
Name UsedData_List: #REF!

Sheet INFO
H3: 맵 (섬) 시스템 기획 초안
C7: 1 | D7: 개요
D9: ① MAP
E10: - 섬(MAP) 안을 여러 구역으로 쪼개고, 조건 달성 시 주변 구역이 열리며 맵이 확장되는 구조
F11: → 구역(STAGE)을 클리어해야 다음 구역이 열리는 형태
E32: - 완전 선형이 아닌, 권장 루트만 PRE_STAGE_ID 와 NEXT_STAGE_ID로 지정한다
E33: - 실제 개방은 CONDITION_GROUP으로 유연하게 제어한다
E35: - 몬스터 토벌, 정화, 다리 연결, 탐사도 달성 등.. 다양한 조건으로 섬 구역을 확장한다
E37: - 각 섬마다 히든 스테이지가 존재한다 (0개~N개)
F38: → 기본 맵에서는 실루엣이나 물음표로 표시한다
G39: → 히든 스테이지 오픈 조건 달성 시 노출
E41: - 탐사도(%)를 기반으로 다음 지역(ISLAND)이 오픈된다
E42: - 탐사도: 섬 내 활동 (몬스터 처치, 정화, 채집, 채광, 낚시 등)으로 포인트 획득
F43: → 임계치마다 섬 내부 스테이지 확장 및 다음 섬 오픈
D46: ② 맵 - 계절 기류
D48: - 각 맵에는 계절 타입에 어울리는 계절 기류(SEASON_FLOW)가 존재한다
D49: - 계절 기류(SEASON_FLOW)는 플레이어에게 버프 혹은 디버프를 부여한다
D50: - 각 스테이지의 SEASON_FLOW 는 0~N 종류까지 있을 수 있다.
E52: <원신 지맥 이상 시스템>
C67: 2 | D67: 맵, 스테이지 구조
D69: ① 맵
D71: - 각 맵(섬)마다 계절 타입이 존재한다
E73: <SEASON_TYPE>
F75: TYPE | J75: COMMENT
F76: 0 | J76: NONE
F77: 1 | J77: 봄
F78: 2 | J78: 여름
F79: 3 | J79: 가을
F80: 4 | J80: 겨울 | M80: → 추후 컨셉에 맞게 수정 및 추가 가능성 有
D82: - 각 섬과 스테이지마다 오픈 조건 그룹(CONDITION_GROUP)이 존재한다 → CONDITION 테이블 참조
E83: <CONDITION_TYPE>
F85: TYPE | K85: COMMENT | R85: PARAMETER_1 | X85: PARAMETER_2
F86: 0 | K86: NONE | R86: - | X86: -
F87: 1 | K87: 스테이지 클리어 | R87: STAGE_ID | X87: -
F88: 2 | K88: 탐사도 달성 | R88: % | X88: -
F89: 3 | K89: 퀘스트 클리어 | R89: QUEST_ID | X89: -
F90: 4 | K90: 몬스터 처치 | R90: MONSTER_ID | X90: 마리
F91: 5 | K91: 아이템 획득 | R91: ITEM_ID | X91: 개수
D94: ② 맵 - 계절 기류
D96: - SEASON_FLOW 테이블의 SEASON_FLOW_GROUP 컬럼을 참조한다
...

Sheet DATA
E4: 데이터 구조도
C8: SEASON_FLOW | E8: MAP | G8: STAGE
C9: ID | E9: ID | G9: ID
C10: SEASON_FLOW_GROUP | E10: SEASON_TYPE | G10: STAGE_GROUP
C11: CONDITION_TYPE | E11: STAGE_GROUP | G11: STAGE_TYPE
C12: OPTION_TYPE | E12: CONDITION_GROUP | G12: PRE_STAGE_ID
C13: PARAM | E13: CLEAR_CONDITION_GROUP | G13: NEXT_STAGE_ID
C14: ISRATE | E14: REQ_POWER | G14: STAGE_PREFAB
C15: TIME | E15: SEASON_FLOW_GROUP | G15: STAGE_NAME
C16: COUNT | E16: STAMINA_COST
C17: COOLTIME | E17: SCENE_PREFAB | G17: CONDITION
C18: IS_OVERLAY | E18: SORT | G18: ID
C19: SEASON_FLOW_DESC | E19: MAP_NAME | G19: CONDITION_GROUP
E20: MAP_DESC | G20: CONDITION_TYPE
E21: MAP_IMAGE | G21: PARAM_1
G22: PARAM_2

Sheet MAP
A1: 아이디 | B1: 섬 이름 | C1: 계절 타입 | D1: 스테이지 그룹 | E1: 오픈 조건 그룹 | F1: 클리어 조건 그룹 | G1: 권장 전투력 | H1: 계절 기류 그룹 | I1: 입장 스태미나 | J1: 씬 프리팹 | K1: 순서 | L1: 섬 이름 | M1: 섬 설명 | N1: 섬 이미지
A2: ID | B2: COMMENT | C2: SEASON_TYPE | D2: STAGE_GROUP | E2: CONDITION_GROUP | F2: CLEAR_CONDITION_GROUP | G2: REQ_POWER | H2: SEASON_FLOW_GROUP | I2: STAMINA_COST | J2: SCENE_PREFAB | K2: SORT | L2: MAP_NAME | M2: MAP_DESC | N2: MAP_IMAGE
A3: int | B3: comment | C3: int | D3: int | E3: int | F3: int | G3: int | H3: int | I3: int | J3: string | K3: int | L3: string | M3: string | N3: string
A4: =100000+C4*10000+K4*100+K4 -> 110101 | B4: 모험의 시작 | C4: 1 | D4: =MOD(A4,1000)+1000 -> 1101 | E4: =IFERROR(INDEX(CONDITION!$B$4:$B$16,MATCH(MAP!B4,CONDITION!$G$4:$G$16,0)),"-") -> 101 | F4: =IFERROR(INDEX(CONDITION!$B$4:$B$16,MATCH(MAP!B4,CONDITION!$G$4:$G$16,0)),"-") -> 101 | I4: 5 | K4: =ROW()-3 -> 1 | L4: ="MAP_NAME_"&A4 -> MAP_NAME_110101 | M4: ="MAP_DESC_"&A4 -> MAP_DESC_110101 | N4: ="MAP_IMAGE_"&A4 -> MAP_IMAGE_110101
A5: =100000+C5*10000+K5*100+K5 -> 110202 | B5: 끝 없는 들판 | C5: 1 | D5: =MOD(A5,1000)+1000 -> 1202 | E5: =IFERROR(INDEX(CONDITION!$B$4:$B$16,MATCH(MAP!B5,CONDITION!$G$4:$G$16,0)),"-") -> 202 | F5: =IFERROR(INDEX(CONDITION!$B$4:$B$16,MATCH(MAP!B5,CONDITION!$G$4:$G$16,0)),"-") -> 202 | I5: 5 | K5: =ROW()-3 -> 2 | L5: ="MAP_NAME_"&A5 -> MAP_NAME_110202 | M5: ="MAP_DESC_"&A5 -> MAP_DESC_110202 | N5: ="MAP_IMAGE_"&A5 -> MAP_IMAGE_110202
A6: =100000+C6*10000+K6*100+K6 -> 120303 | B6: 해변 | C6: 2 | D6: =MOD(A6,1000)+1000 -> 1303 | E6: =IFERROR(INDEX(CONDITION!$B$4:$B$16,MATCH(MAP!B6,CONDITION!$G$4:$G$16,0)),"-") -> 303 | F6: =IFERROR(INDEX(CONDITION!$B$4:$B$16,MATCH(MAP!B6,CONDITION!$G$4:$G$16,0)),"-") -> 303 | I6: 5 | K6: =ROW()-3 -> 3 | L6: ="MAP_NAME_"&A6 -> MAP_NAME_120303 | M6: ="MAP_DESC_"&A6 -> MAP_DESC_120303 | N6: ="MAP_IMAGE_"&A6 -> MAP_IMAGE_120303
A7: =100000+C7*10000+K7*100+K7 -> 120404 | B7: 해안 유적지 | C7: 2 | D7: =MOD(A7,1000)+1000 -> 1404 | E7: =IFERROR(INDEX(CONDITION!$B$4:$B$16,MATCH(MAP!B7,CONDITION!$G$4:$G$16,0)),"-") -> 404 | F7: =IFERROR(INDEX(CONDITION!$B$4:$B$16,MATCH(MAP!B7,CONDITION!$G$4:$G$16,0)),"-") -> 404 | I7: 5 | K7: =ROW()-3 -> 4 | L7: ="MAP_NAME_"&A7 -> MAP_NAME_120404 | M7: ="MAP_DESC_"&A7 -> MAP_DESC_120404 | N7: ="MAP_IMAGE_"&A7 -> MAP_IMAGE_120404
A8: =100000+C8*10000+K8*100+K8 -> 130505 | B8: 붉은 보리밭 | C8: 3 | D8: =MOD(A8,1000)+1000 -> 1505 | E8: =IFERROR(INDEX(CONDITION!$B$4:$B$16,MATCH(MAP!B8,CONDITION!$G$4:$G$16,0)),"-") -> 505 | F8: =IFERROR(INDEX(CONDITION!$B$4:$B$16,MATCH(MAP!B8,CONDITION!$G$4:$G$16,0)),"-") -> 505 | I8: 5 | K8: =ROW()-3 -> 5 | L8: ="MAP_NAME_"&A8 -> MAP_NAME_130505 | M8: ="MAP_DESC_"&A8 -> MAP_DESC_130505 | N8: ="MAP_IMAGE_"&A8 -> MAP_IMAGE_130505
A9: =100000+C9*10000+K9*100+K9 -> 130606 | B9: 낙엽산 | C9: 3 | D9: =MOD(A9,1000)+1000 -> 1606 | E9: =IFERROR(INDEX(CONDITION!$B$4:$B$16,MATCH(MAP!B9,CONDITION!$G$4:$G$16,0)),"-") -> 606 | F9: =IFERROR(INDEX(CONDITION!$B$4:$B$16,MATCH(MAP!B9,CONDITION!$G$4:$G$16,0)),"-") -> 606 | I9: 5 | K9: =ROW()-3 -> 6 | L9: ="MAP_NAME_"&A9 -> MAP_NAME_130606 | M9: ="MAP_DESC_"&A9 -> MAP_DESC_130606 | N9: ="MAP_IMAGE_"&A9 -> MAP_IMAGE_130606
A10: =100000+C10*10000+K10*100+K10 -> 140707 | B10: 눈 내리는 마을 | C10: 4 | D10: =MOD(A10,1000)+1000 -> 1707 | E10: =IFERROR(INDEX(CONDITION!$B$4:$B$16,MATCH(MAP!B10,CONDITION!$G$4:$G$16,0)),"-") -> 707 | F10: =IFERROR(INDEX(CONDITION!$B$4:$B$16,MATCH(MAP!B10,CONDITION!$G$4:$G$16,0)),"-") -> 707 | I10: 5 | K10: =ROW()-3 -> 7 | L10: ="MAP_NAME_"&A10 -> MAP_NAME_140707 | M10: ="MAP_DESC_"&A10 -> MAP_DESC_140707 | N10: ="MAP_IMAGE_"&A10 -> MAP_IMAGE_140707
A11: =100000+C11*10000+K11*100+K11 -> 140808 | B11: 얼어붙은 산 | C11: 4 | D11: =MOD(A11,1000)+1000 -> 1808 | E11: =IFERROR(INDEX(CONDITION!$B$4:$B$16,MATCH(MAP!B11,CONDITION!$G$4:$G$16,0)),"-") -> 808 | F11: =IFERROR(INDEX(CONDITION!$B$4:$B$16,MATCH(MAP!B11,CONDITION!$G$4:$G$16,0)),"-") -> 808 | I11: 5 | K11: =ROW()-3 -> 8 | L11: ="MAP_NAME_"&A11 -> MAP_NAME_140808 | M11: ="MAP_DESC_"&A11 -> MAP_DESC_140808 | N11: ="MAP_IMAGE_"&A11 -> MAP_IMAGE_140808

Sheet STAGE
A1: 아이디 | B1: 섬 이름 | C1: 스테이지 이름 | D1: 스테이지 그룹 | E1: 스테이지 타입 | F1: 이전 스테이지 ID | G1: 다음 스테이지 ID | H1: 스테이지 프리팹 | I1: 스테이지 이름
A2: ID | B2: COMMENT | C2: COMMENT | D2: STAGE_GROUP | E2: STAGE_TYPE | F2: PRE_STAGE_ID | G2: NEXT_STAGE_ID | H2: STAGE_PREFAB | I2: STAGE_NAME
A3: int | B3: comment | C3: comment | D3: int | E3: int | F3: int | G3: int | H3: string | I3: string
A4: =E4*1000000+D4*100+COUNTIF($D$4:D4,D4) -> 1110101 | B4: 모험의 시작 | C4: 바람맞이 언덕 | D4: =1000+RIGHT(INDEX(MAP!$A:$A,MATCH(STAGE!B4,MAP!$B:$B,0)),3) -> 1101 | E4: 1 | F4: =IF(A3="int",0,A3) -> 0 | G4: =IF(A5="","0",A5) -> 2110102 | I4: ="STAGE_NAME_"&A4 -> STAGE_NAME_1110101
A5: =E5*1000000+D5*100+COUNTIF($D$4:D5,D5) -> 2110102 | B5: 모험의 시작 | C5: 작은 개울목 | D5: =1000+RIGHT(INDEX(MAP!$A:$A,MATCH(STAGE!B5,MAP!$B:$B,0)),3) -> 1101 | E5: 2 | F5: =IF(A4="int",0,A4) -> 1110101 | G5: =IF(A6="","0",A6) -> 2120201 | I5: ="STAGE_NAME_"&A5 -> STAGE_NAME_2110102
A6: =E6*1000000+D6*100+COUNTIF($D$4:D6,D6) -> 2120201 | B6: 끝 없는 들판 | C6: 지평선 초소 | D6: =1000+RIGHT(INDEX(MAP!$A:$A,MATCH(STAGE!B6,MAP!$B:$B,0)),3) -> 1202 | E6: 2 | F6: =IF(A5="int",0,A5) -> 2110102 | G6: =IF(A7="","0",A7) -> 2120202 | I6: ="STAGE_NAME_"&A6 -> STAGE_NAME_2120201
A7: =E7*1000000+D7*100+COUNTIF($D$4:D7,D7) -> 2120202 | B7: 끝 없는 들판 | C7: 속삭이는 억새밭 | D7: =1000+RIGHT(INDEX(MAP!$A:$A,MATCH(STAGE!B7,MAP!$B:$B,0)),3) -> 1202 | E7: 2 | F7: =IF(A6="int",0,A6) -> 2120201 | G7: =IF(A8="","0",A8) -> 2130301 | I7: ="STAGE_NAME_"&A7 -> STAGE_NAME_2120202
A8: =E8*1000000+D8*100+COUNTIF($D$4:D8,D8) -> 2130301 | B8: 해변 | C8: 파도 그림길 | D8: =1000+RIGHT(INDEX(MAP!$A:$A,MATCH(STAGE!B8,MAP!$B:$B,0)),3) -> 1303 | E8: 2 | F8: =IF(A7="int",0,A7) -> 2120202 | G8: =IF(A9="","0",A9) -> 3130302 | I8: ="STAGE_NAME_"&A8 -> STAGE_NAME_2130301
A9: =E9*1000000+D9*100+COUNTIF($D$4:D9,D9) -> 3130302 | B9: 해변 | C9: 침식의 용치 | D9: =1000+RIGHT(INDEX(MAP!$A:$A,MATCH(STAGE!B9,MAP!$B:$B,0)),3) -> 1303 | E9: 3 | F9: =IF(A8="int",0,A8) -> 2130301 | G9: =IF(A10="","0",A10) -> 3140401 | I9: ="STAGE_NAME_"&A9 -> STAGE_NAME_3130302
A10: =E10*1000000+D10*100+COUNTIF($D$4:D10,D10) -> 3140401 | B10: 해안 유적지 | C10: 무너진 파수탑 | D10: =1000+RIGHT(INDEX(MAP!$A:$A,MATCH(STAGE!B10,MAP!$B:$B,0)),3) -> 1404 | E10: 3 | F10: =IF(A9="int",0,A9) -> 3130302 | G10: =IF(A11="","0",A11) -> 2140402 | I10: ="STAGE_NAME_"&A10 -> STAGE_NAME_3140401
A11: =E11*1000000+D11*100+COUNTIF($D$4:D11,D11) -> 2140402 | B11: 해안 유적지 | C11: 이끼 낀 전당 | D11: =1000+RIGHT(INDEX(MAP!$A:$A,MATCH(STAGE!B11,MAP!$B:$B,0)),3) -> 1404 | E11: 2 | F11: =IF(A10="int",0,A10) -> 3140401 | G11: =IF(A12="","0",A12) -> 2140403 | I11: ="STAGE_NAME_"&A11 -> STAGE_NAME_2140402
A12: =E12*1000000+D12*100+COUNTIF($D$4:D12,D12) -> 2140403 | B12: 해안 유적지 | C12: 봉인된 제단 | D12: =1000+RIGHT(INDEX(MAP!$A:$A,MATCH(STAGE!B12,MAP!$B:$B,0)),3) -> 1404 | E12: 2 | F12: =IF(A11="int",0,A11) -> 2140402 | G12: =IF(A13="","0",A13) -> 3150501 | I12: ="STAGE_NAME_"&A12 -> STAGE_NAME_2140403
A13: =E13*1000000+D13*100+COUNTIF($D$4:D13,D13) -> 3150501 | B13: 붉은 보리밭 | C13: 석양의 방앗간 | D13: =1000+RIGHT(INDEX(MAP!$A:$A,MATCH(STAGE!B13,MAP!$B:$B,0)),3) -> 1505 | E13: 3 | F13: =IF(A12="int",0,A12) -> 2140403 | G13: =IF(A14="","0",A14) -> 2180801 | I13: ="STAGE_NAME_"&A13 -> STAGE_NAME_3150501
A14: =E14*1000000+D14*100+COUNTIF($D$4:D14,D14) -> 2180801 | B14: 얼어붙은 산 | C14: 서릿발 들머리 | D14: =1000+RIGHT(INDEX(MAP!$A:$A,MATCH(STAGE!B14,MAP!$B:$B,0)),3) -> 1808 | E14: 2 | F14: =IF(A13="int",0,A13) -> 3150501 | G14: =IF(A15="","0",A15) -> 2180802 | I14: ="STAGE_NAME_"&A14 -> STAGE_NAME_2180801
A15: =E15*1000000+D15*100+COUNTIF($D$4:D15,D15) -> 2180802 | B15: 얼어붙은 산 | C15: 얼음비 틈새길 | D15: =1000+RIGHT(INDEX(MAP!$A:$A,MATCH(STAGE!B15,MAP!$B:$B,0)),3) -> 1808 | E15: 2 | F15: =IF(A14="int",0,A14) -> 2180801 | G15: =IF(A16="","0",A16) -> 2180803 | I15: ="STAGE_NAME_"&A15 -> STAGE_NAME_2180802
A16: =E16*1000000+D16*100+COUNTIF($D$4:D16,D16) -> 2180803 | B16: 얼어붙은 산 | C16: 매서운 비탈 | D16: =1000+RIGHT(INDEX(MAP!$A:$A,MATCH(STAGE!B16,MAP!$B:$B,0)),3) -> 1808 | E16: 2 | F16: =IF(A15="int",0,A15) -> 2180802 | G16: =IF(A17="","0",A17) -> 0 | I16: ="STAGE_NAME_"&A16 -> STAGE_NAME_2180803

Sheet CONDITION
A1: 아이디 | B1: 조건 그룹 | C1: 조건 타입 | D1: 파라메터_1 | E1: 파라메터_2 | F1: #파라메터 설명 예시 | G1: 섬 이름
A2: ID | B2: CONDITION_GROUP | C2: CONDITION_TYPE | D2: PARAM_1 | E2: PARAM_2 | F2: COMMENT | G2: COMMENT
A3: int | B3: int | C3: int | D3: int | E3: int | F3: comment | G3: comment
A4: =C4*100000+B4*100+COUNTIF($B$4:B4,B4) -> 110101 | B4: =RIGHT(INDEX(MAP!$A:$A,MATCH(CONDITION!G4,MAP!$B:$B,0)),3) -> 101 | C4: 1 | D4: 1110101 | E4: 0 | F4: =IFERROR(IF(C4=3,INDEX(INFO!$K$86:$K$91,MATCH(CONDITION!C4,INFO!$F$86:$F$91,0)),IF(C4=5,"아이템 ID("&D4&") "&E4&"개 획득",IF(C4=4,"몬스터 "&E4&"마리 처치",IF(C4=2,D4/1000&"% 달성 시",IF(C4=1,"<"&INDEX(STAGE!$B:$B,MATCH(CONDITION!D4,STAGE!$A:$A,0))&"> "&INDEX(INFO!$K$86:$K$91,MATCH(CONDITION!C4,INFO!$F$86:$F$91,0))))))),0) -> <모험의 시작> 스테이지 클리어 | G4: 모험의 시작
A5: =C5*100000+B5*100+COUNTIF($B$4:B5,B5) -> 210102 | B5: =RIGHT(INDEX(MAP!$A:$A,MATCH(CONDITION!G5,MAP!$B:$B,0)),3) -> 101 | C5: 2 | D5: 50000 | E5: 0 | F5: =IFERROR(IF(C5=3,INDEX(INFO!$K$86:$K$91,MATCH(CONDITION!C5,INFO!$F$86:$F$91,0)),IF(C5=5,"아이템 ID("&D5&") "&E5&"개 획득",IF(C5=4,"몬스터 "&E5&"마리 처치",IF(C5=2,D5/1000&"% 달성 시",IF(C5=1,"<"&INDEX(STAGE!$B:$B,MATCH(CONDITION!D5,STAGE!$A:$A,0))&"> "&INDEX(INFO!$K$86:$K$91,MATCH(CONDITION!C5,INFO!$F$86:$F$91,0))))))),0) -> 50% 달성 시 | G5: 모험의 시작
A6: =C6*100000+B6*100+COUNTIF($B$4:B6,B6) -> 320201 | B6: =RIGHT(INDEX(MAP!$A:$A,MATCH(CONDITION!G6,MAP!$B:$B,0)),3) -> 202 | C6: 3 | D6: 0 | E6: 0 | F6: =IFERROR(IF(C6=3,INDEX(INFO!$K$86:$K$91,MATCH(CONDITION!C6,INFO!$F$86:$F$91,0)),IF(C6=5,"아이템 ID("&D6&") "&E6&"개 획득",IF(C6=4,"몬스터 "&E6&"마리 처치",IF(C6=2,D6/1000&"% 달성 시",IF(C6=1,"<"&INDEX(STAGE!$B:$B,MATCH(CONDITION!D6,STAGE!$A:$A,0))&"> "&INDEX(INFO!$K$86:$K$91,MATCH(CONDITION!C6,INFO!$F$86:$F$91,0))))))),0) -> 퀘스트 클리어 | G6: 끝 없는 들판
A7: =C7*100000+B7*100+COUNTIF($B$4:B7,B7) -> 420202 | B7: =RIGHT(INDEX(MAP!$A:$A,MATCH(CONDITION!G7,MAP!$B:$B,0)),3) -> 202 | C7: 4 | D7: 105 | E7: 999 | F7: =IFERROR(IF(C7=3,INDEX(INFO!$K$86:$K$91,MATCH(CONDITION!C7,INFO!$F$86:$F$91,0)),IF(C7=5,"아이템 ID("&D7&") "&E7&"개 획득",IF(C7=4,"몬스터 "&E7&"마리 처치",IF(C7=2,D7/1000&"% 달성 시",IF(C7=1,"<"&INDEX(STAGE!$B:$B,MATCH(CONDITION!D7,STAGE!$A:$A,0))&"> "&INDEX(INFO!$K$86:$K$91,MATCH(CONDITION!C7,INFO!$F$86:$F$91,0))))))),0) -> 몬스터 999마리 처치 | G7: 끝 없는 들판
A8: =C8*100000+B8*100+COUNTIF($B$4:B8,B8) -> 530301 | B8: =RIGHT(INDEX(MAP!$A:$A,MATCH(CONDITION!G8,MAP!$B:$B,0)),3) -> 303 | C8: 5 | D8: 578342 | E8: 30 | F8: =IFERROR(IF(C8=3,INDEX(INFO!$K$86:$K$91,MATCH(CONDITION!C8,INFO!$F$86:$F$91,0)),IF(C8=5,"아이템 ID("&D8&") "&E8&"개 획득",IF(C8=4,"몬스터 "&E8&"마리 처치",IF(C8=2,D8/1000&"% 달성 시",IF(C8=1,"<"&INDEX(STAGE!$B:$B,MATCH(CONDITION!D8,STAGE!$A:$A,0))&"> "&INDEX(INFO!$K$86:$K$91,MATCH(CONDITION!C8,INFO!$F$86:$F$91,0))))))),0) -> 아이템 ID(578342) 30개 획득 | G8: 해변
A9: =C9*100000+B9*100+COUNTIF($B$4:B9,B9) -> 130302 | B9: =RIGHT(INDEX(MAP!$A:$A,MATCH(CONDITION!G9,MAP!$B:$B,0)),3) -> 303 | C9: 1 | D9: 3150501 | E9: 0 | F9: =IFERROR(IF(C9=3,INDEX(INFO!$K$86:$K$91,MATCH(CONDITION!C9,INFO!$F$86:$F$91,0)),IF(C9=5,"아이템 ID("&D9&") "&E9&"개 획득",IF(C9=4,"몬스터 "&E9&"마리 처치",IF(C9=2,D9/1000&"% 달성 시",IF(C9=1,"<"&INDEX(STAGE!$B:$B,MATCH(CONDITION!D9,STAGE!$A:$A,0))&"> "&INDEX(INFO!$K$86:$K$91,MATCH(CONDITION!C9,INFO!$F$86:$F$91,0))))))),0) -> <붉은 보리밭> 스테이지 클리어 | G9: 해변
A10: =C10*100000+B10*100+COUNTIF($B$4:B10,B10) -> 240401 | B10: =RIGHT(INDEX(MAP!$A:$A,MATCH(CONDITION!G10,MAP!$B:$B,0)),3) -> 404 | C10: 2 | D10: 64300 | E10: 0 | F10: =IFERROR(IF(C10=3,INDEX(INFO!$K$86:$K$91,MATCH(CONDITION!C10,INFO!$F$86:$F$91,0)),IF(C10=5,"아이템 ID("&D10&") "&E10&"개 획득",IF(C10=4,"몬스터 "&E10&"마리 처치",IF(C10=2,D10/1000&"% 달성 시",IF(C10=1,"<"&INDEX(STAGE!$B:$B,MATCH(CONDITION!D10,STAGE!$A:$A,0))&"> "&INDEX(INFO!$K$86:$K$91,MATCH(CONDITION!C10,INFO!$F$86:$F$91,0))))))),0) -> 64.3% 달성 시 | G10: 해안 유적지
A11: =C11*100000+B11*100+COUNTIF($B$4:B11,B11) -> 340402 | B11: =RIGHT(INDEX(MAP!$A:$A,MATCH(CONDITION!G11,MAP!$B:$B,0)),3) -> 404 | C11: 3 | D11: 0 | E11: 0 | F11: =IFERROR(IF(C11=3,INDEX(INFO!$K$86:$K$91,MATCH(CONDITION!C11,INFO!$F$86:$F$91,0)),IF(C11=5,"아이템 ID("&D11&") "&E11&"개 획득",IF(C11=4,"몬스터 "&E11&"마리 처치",IF(C11=2,D11/1000&"% 달성 시",IF(C11=1,"<"&INDEX(STAGE!$B:$B,MATCH(CONDITION!D11,STAGE!$A:$A,0))&"> "&INDEX(INFO!$K$86:$K$91,MATCH(CONDITION!C11,INFO!$F$86:$F$91,0))))))),0) -> 퀘스트 클리어 | G11: 해안 유적지
A12: =C12*100000+B12*100+COUNTIF($B$4:B12,B12) -> 440403 | B12: =RIGHT(INDEX(MAP!$A:$A,MATCH(CONDITION!G12,MAP!$B:$B,0)),3) -> 404 | C12: 4 | D12: 101 | E12: 10 | F12: =IFERROR(IF(C12=3,INDEX(INFO!$K$86:$K$91,MATCH(CONDITION!C12,INFO!$F$86:$F$91,0)),IF(C12=5,"아이템 ID("&D12&") "&E12&"개 획득",IF(C12=4,"몬스터 "&E12&"마리 처치",IF(C12=2,D12/1000&"% 달성 시",IF(C12=1,"<"&INDEX(STAGE!$B:$B,MATCH(CONDITION!D12,STAGE!$A:$A,0))&"> "&INDEX(INFO!$K$86:$K$91,MATCH(CONDITION!C12,INFO!$F$86:$F$91,0))))))),0) -> 몬스터 10마리 처치 | G12: 해안 유적지
A13: =C13*100000+B13*100+COUNTIF($B$4:B13,B13) -> 450501 | B13: =RIGHT(INDEX(MAP!$A:$A,MATCH(CONDITION!G13,MAP!$B:$B,0)),3) -> 505 | C13: 4 | D13: 103 | E13: 7 | F13: =IFERROR(IF(C13=3,INDEX(INFO!$K$86:$K$91,MATCH(CONDITION!C13,INFO!$F$86:$F$91,0)),IF(C13=5,"아이템 ID("&D13&") "&E13&"개 획득",IF(C13=4,"몬스터 "&E13&"마리 처치",IF(C13=2,D13/1000&"% 달성 시",IF(C13=1,"<"&INDEX(STAGE!$B:$B,MATCH(CONDITION!D13,STAGE!$A:$A,0))&"> "&INDEX(INFO!$K$86:$K$91,MATCH(CONDITION!C13,INFO!$F$86:$F$91,0))))))),0) -> 몬스터 7마리 처치 | G13: 붉은 보리밭
A14: =C14*100000+B14*100+COUNTIF($B$4:B14,B14) -> 460601 | B14: =RIGHT(INDEX(MAP!$A:$A,MATCH(CONDITION!G14,MAP!$B:$B,0)),3) -> 606 | C14: 4 | D14: 129 | E14: 1 | F14: =IFERROR(IF(C14=3,INDEX(INFO!$K$86:$K$91,MATCH(CONDITION!C14,INFO!$F$86:$F$91,0)),IF(C14=5,"아이템 ID("&D14&") "&E14&"개 획득",IF(C14=4,"몬스터 "&E14&"마리 처치",IF(C14=2,D14/1000&"% 달성 시",IF(C14=1,"<"&INDEX(STAGE!$B:$B,MATCH(CONDITION!D14,STAGE!$A:$A,0))&"> "&INDEX(INFO!$K$86:$K$91,MATCH(CONDITION!C14,INFO!$F$86:$F$91,0))))))),0) -> 몬스터 1마리 처치 | G14: 낙엽산
A15: =C15*100000+B15*100+COUNTIF($B$4:B15,B15) -> 570701 | B15: =RIGHT(INDEX(MAP!$A:$A,MATCH(CONDITION!G15,MAP!$B:$B,0)),3) -> 707 | C15: 5 | D15: 11659 | E15: 2 | F15: =IFERROR(IF(C15=3,INDEX(INFO!$K$86:$K$91,MATCH(CONDITION!C15,INFO!$F$86:$F$91,0)),IF(C15=5,"아이템 ID("&D15&") "&E15&"개 획득",IF(C15=4,"몬스터 "&E15&"마리 처치",IF(C15=2,D15/1000&"% 달성 시",IF(C15=1,"<"&INDEX(STAGE!$B:$B,MATCH(CONDITION!D15,STAGE!$A:$A,0))&"> "&INDEX(INFO!$K$86:$K$91,MATCH(CONDITION!C15,INFO!$F$86:$F$91,0))))))),0) -> 아이템 ID(11659) 2개 획득 | G15: 눈 내리는 마을
A16: =C16*100000+B16*100+COUNTIF($B$4:B16,B16) -> 580801 | B16: =RIGHT(INDEX(MAP!$A:$A,MATCH(CONDITION!G16,MAP!$B:$B,0)),3) -> 808 | C16: 5 | D16: 65489 | E16: 3 | F16: =IFERROR(IF(C16=3,INDEX(INFO!$K$86:$K$91,MATCH(CONDITION!C16,INFO!$F$86:$F$91,0)),IF(C16=5,"아이템 ID("&D16&") "&E16&"개 획득",IF(C16=4,"몬스터 "&E16&"마리 처치",IF(C16=2,D16/1000&"% 달성 시",IF(C16=1,"<"&INDEX(STAGE!$B:$B,MATCH(CONDITION!D16,STAGE!$A:$A,0))&"> "&INDEX(INFO!$K$86:$K$91,MATCH(CONDITION!C16,INFO!$F$86:$F$91,0))))))),0) -> 아이템 ID(65489) 3개 획득 | G16: 얼어붙은 산

Sheet SEASON_FLOW
A1: 아이디 | B1: 계절 기류 그룹 | C1: 계절 기류 발동 조건 타입 | D1: 옵션 타입 | E1: 옵션 파라메터 | F1: 옵션 비율 | G1: 지속 시간 | H1: 발동 횟수 | I1: 쿨타임 | J1: 중첩 여부 | K1: 계절 기류 설명 | L1: #계절 기류 설명 예시
A2: ID | B2: SEASON_FLOW_GROUP | C2: CONDITION_TYPE | D2: OPTION_TYPE | E2: PARAM | F2: ISRATE | G2: TIME | H2: COUNT | I2: COOLTIME | J2: IS_OVERLAY | K2: SEASON_FLOW_DESC | L2: COMMENT
A3: int | B3: int | C3: int | D3: int | E3: int | F3: int | G3: int | H3: int | I3: int | J3: int | K3: string | L3: comment
A4: 1 | B4: 1 | C4: 1 | D4: 5 | E4: 6 | F4: 0 | G4: 25000 | H4: 0 | I4: 0 | J4: 0 | K4: ="SEASON_FLOW_DESC_"&A4 -> SEASON_FLOW_DESC_1
A5: 11111 | B5: 1 | C5: 6 | D5: 11 | E5: 10000 | F5: 1 | G5: 200 | H5: 1 | I5: 2500 | J5: 0 | K5: ="SEASON_FLOW_DESC_"&A5 -> SEASON_FLOW_DESC_11111
K6: ="SEASON_FLOW_DESC_"&A6 -> SEASON_FLOW_DESC_
K7: ="SEASON_FLOW_DESC_"&A7 -> SEASON_FLOW_DESC_
K8: ="SEASON_FLOW_DESC_"&A8 -> SEASON_FLOW_DESC_
K9: ="SEASON_FLOW_DESC_"&A9 -> SEASON_FLOW_DESC_
K10: ="SEASON_FLOW_DESC_"&A10 -> SEASON_FLOW_DESC_
K11: ="SEASON_FLOW_DESC_"&A11 -> SEASON_FLOW_DESC_

Sheet STRING
A1: STRING_KEY | B1: DESC
A2: string | B2: string
