Workbook
Name ID규칙_기본능력치그룹_단위: [1]INDEX!$L$39
Name ID규칙_대사_그룹_단위: [1]INDEX!$L$231
Name ID규칙_대상_장비_아이디_단위: [1]INDEX!$L$471
Name ID규칙_등급_단위: [1]INDEX!$L$159
Name ID규칙_사용학생_아이디_단위: [1]INDEX!$L$5
Name ID규칙_스테이지_난이도_단위: [1]INDEX!$L$544
Name ID규칙_스테이지_아이디_단위: [1]INDEX!$L$543
Name ID규칙_스테이지_챕터_단위: [1]INDEX!$L$545
Name ID규칙_슬롯_단위: [1]INDEX!$L$393
Name ID규칙_아이템_구분_단위: [1]INDEX!$L$562
Name ID규칙_아이템_타입_단위: [1]INDEX!$L$563
Name ID규칙_애용품_강화_스킬_그룹_단위: [1]INDEX!$L$340
Name ID규칙_애용품_그룹_단위: [1]INDEX!$L$283
Name ID규칙_애용품_아이디_단위: [1]INDEX!$L$282
Name ID규칙_애용품_티어_단위: [1]INDEX!$L$283
Name ID규칙_장비_아이디_단위: [1]INDEX!$L$392
Name ID규칙_티어_단위: [1]INDEX!$L$394
Name ID규칙_학생_등급_단위: [1]INDEX!$L$183
Name ID규칙_학생_상세_역할_단위: [1]INDEX!$L$182
Name ID규칙_학생_역할_단위: [1]INDEX!$L$181
Name ID규칙_한계_해방_그룹_단위: [1]INDEX!$L$67
Name ID규칙_획득처_그룹_단위: [1]INDEX!$L$502
Name MAIN_STATS_TYPE: [1]INDEX!$B$448:$C$464
Name SKILL_TYPE: [1]INDEX!$B$107:$C$128
Name SPEECH_MAIN_TYPE: [1]INDEX!$B$245:$C$252
Name SPEECH_SUB_TYPE: [1]INDEX!$F$245:$G$275
Name STAGE_DIFFICULTY: [1]INDEX!$B$554:$C$555
Name STATS_TYPE: [1]INDEX!$B$58:$C$60
Name UNIQUE_CONDITION_TYPE: [1]INDEX!$B$364:$C$371
Name UNIQUE_OPTION_TYPE: [1]INDEX!$F$364:$G$385
Name UNIQUE_SUB_OPTION_TYPE: [1]INDEX!$F$324:$G$333
Name 링크_ITEM: ITEM!$A$1
Name 링크_SEASON: SEASON!$A$1
Name 링크_STUDENT: STUDENT!$A$1
Name 링크_리소스_UI: 'ID 카드 커스텀 대회'!$B$335:$AS$357
Name 링크_투표달성보상: VOTE_REWARD!$A$1
Name 상성_강화_아이디_단위: [1]INDEX!$L$135
Name 상성_강화_장소_타입: [1]INDEX!$B$147:$C$149
Name 상성_등급_단위: [1]INDEX!$F$216:$G$221
Name 스킬_강화_그룹_단위: [1]INDEX!$L$92

Sheet ID 카드 커스텀 대회
B1: ◈ 블루 아카이브 - ID 카드 커스텀 대회
B3: · 목차
C5: 1 | D5: 개요 | X5: 3 | Y5: UI 구성
D7: 1.1 ID 카드 커스텀 대회 정의 | Y7: 3.1 ID 카드 커스텀 대회 진입 방법
D8: 1.2 기획 의도 | Y8: 3.2 ID 카드 커스텀 대회 UI 구성
Y9: 3.3 커스텀 ID 카드 제작 UI 구성
Y10: 3.4 투표 UI 구성
C12: 2 | D12: ID 카드 커스텀 대회 상세 기획 | X12: 4 | Y12: 테이블 구성
D14: 2.1 주요 기능 | Y14: 4.1 COMMON
D15: 2.2 제출 조건 | Y15: 4.2 SEASON
D16: 2.3 제출 과정 | Y16: 4.3 RANK_REWARD
D17: 2.4 제출 순서도 | Y17: 4.4 VOTE_REWARD
D18: 2.5 투표 과정 | Y18: 4.5 RESOURSE_LIST
D19: 2.6 투표 순서도 | Y19: 4.6 ITEM
D20: 2.7 투표 진행 보상 구성
D21: 2.8 랭크 구성
B24: 1. 개요
C26: 1.1 | ID 카드 커스텀 대회 정의
D27: - 일정 기간마다 커스텀한 ID 카드로 타 유저들이 투표를 통해 평가하고 순위를 정하는 콘텐츠
D28: - 대회의 보상은 대회 종료 후 정산하여 랭크에 따라 보상이 존재한다.
D29: - 순위권 범위에 해당하는 유저들에게 보상 지급
D30: - 순위의 랭크는 플래티넘/골드/실버/브론즈가 존재한다.
C32: 1.2 | 기획 의도
D33: - 캐릭터의 활동 영역을 한 층 확장하여 캐릭터들에 대한 애정도를 넓히고, 완전히 소외되는 캐릭터를 상대적으로 적게한다.
D34: - 기존 이미지와 캐릭터의 구성으로 사용하던 리소스를 활용하여 개발 기간과 비용을 절감한다.
D35: - ID 카드 커스텀 대회 개최로 총력전 이외에 유저들과 경쟁할 수 있는 콘텐츠를 추가한다.
D36: - ID 카드 커스텀 대회 보상으로 청휘석과 여러 아이템을 제공하여 콘텐츠 참여 의욕을 증가시킨다.
B39: 2. ID 카드 커스텀 대회 상세 기획
N54: <커스텀 대회 UI> | AP54: <ID 카드 커스텀 UI>
AO55: ※ 위 이미지들은 포토샵으로 직접 제작한 이미지입니다.
C57: 2.1 | 주요 기능
D58: - 매 2주마다 (1주일 개최 후, 1주일 휴식) 개최한다.
D59: - ID 카드를 커스텀하여 개최 기간 내에 제출한다.
D60: - 개최 기간 동안 타 유저들의 커스텀 ID 카드를 투표한다 (1일 최대 30표 / 본인 투표 불가능)
E61: → 본인의 커스텀 ID 카드를 제출하지 않아도 타 유저의 ID 카드 투표에 참여할 수 있다.
D62: - 10회 투표할 때마다 보상 지급 (1일 최대 3회 지급)
D63: - 1주일의 개최 기간이 지나면 유저의 순위 범위와 랭크를 집계 기간동안 정산하여 순위에 맞게 보상을 지급한다.
E64: → 집계 기간: 투표 종료 날짜와 종료 시간에서 12시간 후에 집계가 완료된다.
E65: → 집계 기간에는 투표가 불가능하다.
G66: → 여기 클릭 시 시즌 관련 테이블로 이동
...

Sheet COMMON
A1: 내용 | B1: 타입 | C1: 값 | D1: #내용
A2: KEY | B2: TYPE | C2: VALUE | D2: 참조
A3: CUSTOM_ID_CARD_MAX_DRAW | B3: INT | C3: 5000 | D3: 투표 시 ID 카드가 등장하는 횟수 제한 (5000회)
A4: CUSTOM_ID_CARD_MAX_VOTE_QTY | B4: INT | C4: 30 | D4: 일일 투표 횟수를 제한 (30회)
A5: CUSTOM_ID_CARD_MAX_RESOURCE | B5: INT | C5: 2000 | D5: ID 카드에 배치할 수 있는 최대 리소스 개수 (2000개)

Sheet SEASON
A1: 아이디 | B1: 시작 날짜 | C1: 시작 시간 | D1: 종료 날짜 | E1: 종료 시간
A2: ID | B2: START_DATE | C2: START_TIME | D2: END_DATE | E2: END_TIME
A3: int | B3: int | C3: int | D3: int | E3: int
A4: 10001 | B4: 2023-08-10 | C4: 0.52083333 | D4: 2023-08-16 | E4: 0.99998843
A5: 10002 | B5: 2023-08-24 | C5: 0.52083333 | D5: 2023-08-30 | E5: 0.99998843
A6: 10003 | B6: 2023-09-07 | C6: 0.52083333 | D6: 2023-09-13 | E6: 0.99998843
A7: 10004 | B7: 2023-09-21 | C7: 0.52083333 | D7: 2023-09-27 | E7: 0.99998843
A8: 10005 | B8: 2023-10-05 | C8: 0.52083333 | D8: 2023-10-11 | E8: 0.99998843
A9: 10006 | B9: 2023-10-19 | C9: 0.52083333 | D9: 2023-10-25 | E9: 0.99998843
A10: 10007 | B10: 2023-11-02 | C10: 0.52083333 | D10: 2023-11-08 | E10: 0.99998843
A11: 10008 | B11: 2023-11-16 | C11: 0.52083333 | D11: 2023-11-22 | E11: 0.99998843
A12: 10009 | B12: 2023-11-30 | C12: 0.52083333 | D12: 2023-12-06 | E12: 0.99998843
A13: 10010 | B13: 2023-12-14 | C13: 0.52083333 | D13: 2023-12-20 | E13: 0.99998843
A14: 10011 | B14: 2023-12-28 | C14: 0.52083333 | D14: 2024-01-03 | E14: 0.99998843
A15: 10012 | B15: 2024-01-11 | C15: 0.52083333 | D15: 2024-01-17 | E15: 0.99998843
... A41: 10038 | B41: 2025-01-09 | C41: 0.52083333 | D41: 2025-01-15 | E41: 0.99998843

Sheet RANK_REWARD
A1: 아이디 | B1: 랭크 타입 | C1: 순위 백분율 | D1: 아이템 아이디 | E1: 아이템 개수 | F1: 랭크 이름 | G1: 랭크 아이콘 | H1: #보상 설명
A2: ID | B2: RANK_TYPE | C2: PERCENT_RANK | D2: ITEM_ID | E2: ITEM_QTY | F2: RANK_NAME | G2: RANK_ICON | H2: REWARD_DESC
A3: int | B3: int | C3: int | D3: int | E3: int | F3: int | G3: int | H3: 참조
A4: =10000+B4 -> 10001 | B4: 1 | C4: 0.1 | D4: 1717003 | E4: 1200 | F4: ="RANK_NAME_"&B4 -> RANK_NAME_1 | G4: ="RANK_ICON_"&B4 -> RANK_ICON_1 | H4: =VLOOKUP(D4,ITEM!$A$4:$B$346,2,0)&" X"&E4 -> 청휘석 X1200
A5: =10000+B5 -> 10002 | B5: 2 | C5: 0.3 | D5: 1717003 | E5: 900 | F5: ="RANK_NAME_"&B5 -> RANK_NAME_2 | G5: ="RANK_ICON_"&B5 -> RANK_ICON_2 | H5: =VLOOKUP(D5,ITEM!$A$4:$B$346,2,0)&" X"&E5 -> 청휘석 X900
A6: =10000+B6 -> 10003 | B6: 3 | C6: 0.6 | D6: 1717003 | E6: 600 | F6: ="RANK_NAME_"&B6 -> RANK_NAME_3 | G6: ="RANK_ICON_"&B6 -> RANK_ICON_3 | H6: =VLOOKUP(D6,ITEM!$A$4:$B$346,2,0)&" X"&E6 -> 청휘석 X600
A7: =10000+B7 -> 10004 | B7: 4 | C7: 1 | D7: 1717003 | E7: 300 | F7: ="RANK_NAME_"&B7 -> RANK_NAME_4 | G7: ="RANK_ICON_"&B7 -> RANK_ICON_4 | H7: =VLOOKUP(D7,ITEM!$A$4:$B$346,2,0)&" X"&E7 -> 청휘석 X300

Sheet VOTE_REWARD
A1: 아이디 | B1: 투표 횟수 | C1: 아이템 아이디 | D1: 아이템 개수 | E1: #투표 보상 설명
A2: ID | B2: VOTE_QTY | C2: ITEM_ID | D2: ITEM_QTY | E2: VOTE_REWARD_DESC
A3: int | B3: int | C3: int | D3: int | E3: 참고
A4: =10000+B4 -> 10010 | B4: 10 | C4: 303004 | D4: 3 | E4: =VLOOKUP(C4,ITEM!$A:$B,2,0)&" X"&D4 -> 일반 활동 보고서 X3
A5: =10000+B5 -> 10020 | B5: 20 | C5: 304002 | D5: 5 | E5: =VLOOKUP(C5,ITEM!$A:$B,2,0)&" X"&D5 -> 기동석 X5
A6: =10000+B6 -> 10030 | B6: 30 | C6: 1717001 | D6: 50 | E6: =VLOOKUP(C6,ITEM!$A:$B,2,0)&" X"&D6 -> AP X50

Sheet RESOURCE_LIST
A1: 리소스 키 | B1: #리소스 내용 설명
A2: RESOURCE_KEY | B2: 참조
A3: RESOURCE_STUDENT_IMAGE_1 | B3: 시로코
A4: RESOURCE_STUDENT_IMAGE_2 | B4: 호시노
A5: RESOURCE_STUDENT_IMAGE_3 | B5: 세리카
A6: RESOURCE_STUDENT_IMAGE_4 | B6: 노노미
A7: RESOURCE_STUDENT_IMAGE_5 | B7: 아야네
A8: RESOURCE_STUDENT_IMAGE_6 | B8: 아루
A9: RESOURCE_STUDENT_IMAGE_7 | B9: 무츠키
A10: RESOURCE_STUDENT_IMAGE_8 | B10: 카요코
A11: RESOURCE_STUDENT_IMAGE_9 | B11: 하루카
A12: RESOURCE_STUDENT_IMAGE_10 | B12: 히나
... A119: RESOURCE_FIGURE_9 | B119: 리소스_도형_9

Sheet STRING
A1: STRING_KEY | B1: DESC
A2: string | B2: string
A3: TITLE_ID_CARD_CUSTOM_CONFERENCE | B3: ID 카드 커스텀 대회
A4: TITLE_ID_CARD_CUSTOM_EDIT | B4: ID 카드 편집
A5: TITLE_ID_CARD_CUSTOM_VOTE | B5: ID 카드 투표
A6: BUTTON_ID_CARD_EDIT_SUBMIT | B6: 제출하기
A7: BUTTON_ID_CARD_EDIT_VOTE | B7: 투표하기
A8: RESOURCE_ID_CARD_CHARACTER | B8: 대표 캐릭터
A9: RESOURCE_ID_CARD_WALLPAPER | B9: 배경
A10: RESOURCE_ID_CARD_INFORMATION | B10: 표시 정보
A11: RESOURCE_ID_CARD_FIGURE | B11: 도형
A12: RESOURCE_ID_CARD_TEXT | B12: 텍스트
... A20: BUTTON_ID_CARD_VOTE_REWARD | B20: 보상 받기

Sheet ITEM
A1: 아이디 | B1: #아이템 이름 | C1: 아이템 구분 | D1: 아이템 타입 | E1: 누적 수량 | F1: 아이템 이름 | G1: 아이템 아이콘 | H1: 아이템 설명
A2: ID | B2: ITEM_NAME | C2: ITEM_FILTER | D2: ITEM_TYPE | E2: STACK | F2: ITEM_NAME | G2: ITEM_ICON | H2: ITEM_DESC
A3: int | B3: 참조 | C3: int | D3: int | E3: int | F3: string | G3: string | H3: string
A4: =C4*ID규칙_아이템_구분_단위+D4*ID규칙_아이템_타입_단위+COUNTIFS($C$4:C4,C4,$D$4:D4,D4) -> 101001 | B4: 시로코의 엘레프 | C4: 1 | D4: 1 | E4: 9999 | F4: ="ITEM_NAME_"&A4 -> ITEM_NAME_101001 | G4: ="ITEM_ICON_"&A4 -> ITEM_ICON_101001 | H4: ="ITEM_DESC_"&A4 -> ITEM_DESC_101001
A5: =C5*ID규칙_아이템_구분_단위+D5*ID규칙_아이템_타입_단위+COUNTIFS($C$4:C5,C5,$D$4:D5,D5) -> 101002 | B5: 호시노의 엘레프 | C5: 1 | D5: 1 | E5: 9999 | F5: ="ITEM_NAME_"&A5 -> ITEM_NAME_101002 | G5: ="ITEM_ICON_"&A5 -> ITEM_ICON_101002 | H5: ="ITEM_DESC_"&A5 -> ITEM_DESC_101002 | J5: ITEM_FILTER | M5: ITEM_TYPE
A6: =C6*ID규칙_아이템_구분_단위+D6*ID규칙_아이템_타입_단위+COUNTIFS($C$4:C6,C6,$D$4:D6,D6) -> 101003 | B6: 세리카의 엘레프 | C6: 1 | D6: 1 | E6: 9999 | F6: ="ITEM_NAME_"&A6 -> ITEM_NAME_101003 | G6: ="ITEM_ICON_"&A6 -> ITEM_ICON_101003 | H6: ="ITEM_DESC_"&A6 -> ITEM_DESC_101003 | J6: INDEX | K6: 설명 | M6: INDEX | N6: 설명
A7: =C7*ID규칙_아이템_구분_단위+D7*ID규칙_아이템_타입_단위+COUNTIFS($C$4:C7,C7,$D$4:D7,D7) -> 101004 | B7: 노노미의 엘레프 | C7: 1 | D7: 1 | E7: 9999 | F7: ="ITEM_NAME_"&A7 -> ITEM_NAME_101004 | G7: ="ITEM_ICON_"&A7 -> ITEM_ICON_101004 | H7: ="ITEM_DESC_"&A7 -> ITEM_DESC_101004 | J7: 1 | K7: 엘레프 | M7: 1 | N7: 엘레프
A8: =C8*ID규칙_아이템_구분_단위+D8*ID규칙_아이템_타입_단위+COUNTIFS($C$4:C8,C8,$D$4:D8,D8) -> 101005 | B8: 아야네의 엘레프 | C8: 1 | D8: 1 | E8: 9999 | F8: ="ITEM_NAME_"&A8 -> ITEM_NAME_101005 | G8: ="ITEM_ICON_"&A8 -> ITEM_ICON_101005 | H8: ="ITEM_DESC_"&A8 -> ITEM_DESC_101005 | J8: 2 | K8: 코인 | M8: 2 | N8: 코인
A9: =C9*ID규칙_아이템_구분_단위+D9*ID규칙_아이템_타입_단위+COUNTIFS($C$4:C9,C9,$D$4:D9,D9) -> 101006 | B9: 아루의 엘레프 | C9: 1 | D9: 1 | E9: 9999 | F9: ="ITEM_NAME_"&A9 -> ITEM_NAME_101006 | G9: ="ITEM_ICON_"&A9 -> ITEM_ICON_101006 | H9: ="ITEM_DESC_"&A9 -> ITEM_DESC_101006 | J9: 3 | K9: 재료 | M9: 3 | N9: 경험치 재료
A10: =C10*ID규칙_아이템_구분_단위+D10*ID규칙_아이템_타입_단위+COUNTIFS($C$4:C10,C10,$D$4:D10,D10) -> 101007 | B10: 무츠키의 엘레프 | C10: 1 | D10: 1 | E10: 9999 | F10: ="ITEM_NAME_"&A10 -> ITEM_NAME_101007 | G10: ="ITEM_ICON_"&A10 -> ITEM_ICON_101007 | H10: ="ITEM_DESC_"&A10 -> ITEM_DESC_101007 | J10: 4 | K10: 소모품 | M10: 4 | N10: 기동석
A11: =C11*ID규칙_아이템_구분_단위+D11*ID규칙_아이템_타입_단위+COUNTIFS($C$4:C11,C11,$D$4:D11,D11) -> 101008 | B11: 카요코의 엘레프 | C11: 1 | D11: 1 | E11: 9999 | F11: ="ITEM_NAME_"&A11 -> ITEM_NAME_101008 | G11: ="ITEM_ICON_"&A11 -> ITEM_ICON_101008 | H11: ="ITEM_DESC_"&A11 -> ITEM_DESC_101008 | J11: 5 | K11: 수집품 | M11: 5 | N11: 합성용 기동석
A12: =C12*ID규칙_아이템_구분_단위+D12*ID규칙_아이템_타입_단위+COUNTIFS($C$4:C12,C12,$D$4:D12,D12) -> 101009 | B12: 하루카의 엘레프 | C12: 1 | D12: 1 | E12: 9999 | F12: ="ITEM_NAME_"&A12 -> ITEM_NAME_101009 | G12: ="ITEM_ICON_"&A12 -> ITEM_ICON_101009 | H12: ="ITEM_DESC_"&A12 -> ITEM_DESC_101009 | J12: 6 | K12: 선물 | M12: 6 | N12: 부스터 티켓
A13: =C13*ID규칙_아이템_구분_단위+D13*ID규칙_아이템_타입_단위+COUNTIFS($C$4:C13,C13,$D$4:D13,D13) -> 101010 | B13: 히나의 엘레프 | C13: 1 | D13: 1 | E13: 9999 | F13: ="ITEM_NAME_"&A13 -> ITEM_NAME_101010 | G13: ="ITEM_ICON_"&A13 -> ITEM_ICON_101010 | H13: ="ITEM_DESC_"&A13 -> ITEM_DESC_101010 | J13: 7 | K13: 재화 | M13: 7 | N13: 카페 랭크 업
A14: =C14*ID규칙_아이템_구분_단위+D14*ID규칙_아이템_타입_단위+COUNTIFS($C$4:C14,C14,$D$4:D14,D14) -> 101011 | B14: 아코의 엘레프 | C14: 1 | D14: 1 | E14: 9999 | F14: ="ITEM_NAME_"&A14 -> ITEM_NAME_101011 | G14: ="ITEM_ICON_"&A14 -> ITEM_ICON_101011 | H14: ="ITEM_DESC_"&A14 -> ITEM_DESC_101011 | M14: 8 | N14: 제조용 마테리얼
A15: =C15*ID규칙_아이템_구분_단위+D15*ID규칙_아이템_타입_단위+COUNTIFS($C$4:C15,C15,$D$4:D15,D15) -> 101012 | B15: 이오리의 엘레프 | C15: 1 | D15: 1 | E15: 9999 | F15: ="ITEM_NAME_"&A15 -> ITEM_NAME_101012 | G15: ="ITEM_ICON_"&A15 -> ITEM_ICON_101012 | H15: ="ITEM_DESC_"&A15 -> ITEM_DESC_101012 | M15: 9 | N15: 전술 교육 BD
A16: =C16*ID규칙_아이템_구분_단위+D16*ID규칙_아이템_타입_단위+COUNTIFS($C$4:C16,C16,$D$4:D16,D16) -> 101013 | B16: 치나츠의 엘레프 | C16: 1 | D16: 1 | E16: 9999 | F16: ="ITEM_NAME_"&A16 -> ITEM_NAME_101013 | G16: ="ITEM_ICON_"&A16 -> ITEM_ICON_101013 | H16: ="ITEM_DESC_"&A16 -> ITEM_DESC_101013 | M16: 10 | N16: 기술 노트
A17: =C17*ID규칙_아이템_구분_단위+D17*ID규칙_아이템_타입_단위+COUNTIFS($C$4:C17,C17,$D$4:D17,D17) -> 101014 | B17: 하루나의 엘레프 | C17: 1 | D17: 1 | E17: 9999 | F17: ="ITEM_NAME_"&A17 -> ITEM_NAME_101014 | G17: ="ITEM_ICON_"&A17 -> ITEM_ICON_101014 | H17: ="ITEM_DESC_"&A17 -> ITEM_DESC_101014 | M17: 11 | N17: 오파츠
A18: =C18*ID규칙_아이템_구분_단위+D18*ID규칙_아이템_타입_단위+COUNTIFS($C$4:C18,C18,$D$4:D18,D18) -> 101015 | B18: 준코의 엘레프 | C18: 1 | D18: 1 | E18: 9999 | F18: ="ITEM_NAME_"&A18 -> ITEM_NAME_101015 | G18: ="ITEM_ICON_"&A18 -> ITEM_ICON_101015 | H18: ="ITEM_DESC_"&A18 -> ITEM_DESC_101015 | M18: 12 | N18: 이벤트 관련 재료
A19: =C19*ID규칙_아이템_구분_단위+D19*ID규칙_아이템_타입_단위+COUNTIFS($C$4:C19,C19,$D$4:D19,D19) -> 101016 | B19: 이즈미의 엘레프 | C19: 1 | D19: 1 | E19: 9999 | F19: ="ITEM_NAME_"&A19 -> ITEM_NAME_101016 | G19: ="ITEM_ICON_"&A19 -> ITEM_ICON_101016 | H19: ="ITEM_DESC_"&A19 -> ITEM_DESC_101016 | M19: 13 | N19: 소모품
A20: =C20*ID규칙_아이템_구분_단위+D20*ID규칙_아이템_타입_단위+COUNTIFS($C$4:C20,C20,$D$4:D20,D20) -> 101017 | B20: 아카리의 엘레프 | C20: 1 | D20: 1 | E20: 9999 | F20: ="ITEM_NAME_"&A20 -> ITEM_NAME_101017 | G20: ="ITEM_ICON_"&A20 -> ITEM_ICON_101017 | H20: ="ITEM_DESC_"&A20 -> ITEM_DESC_101017 | M20: 14 | N20: 메인 이벤트 수집품
A21: =C21*ID규칙_아이템_구분_단위+D21*ID규칙_아이템_타입_단위+COUNTIFS($C$4:C21,C21,$D$4:D21,D21) -> 101018 | B21: 후우카의 엘레프 | C21: 1 | D21: 1 | E21: 9999 | F21: ="ITEM_NAME_"&A21 -> ITEM_NAME_101018 | G21: ="ITEM_ICON_"&A21 -> ITEM_ICON_101018 | H21: ="ITEM_DESC_"&A21 -> ITEM_DESC_101018 | M21: 15 | N21: 가이드 미션 수집품
A22: =C22*ID규칙_아이템_구분_단위+D22*ID규칙_아이템_타입_단위+COUNTIFS($C$4:C22,C22,$D$4:D22,D22) -> 101019 | B22: 주리의 엘레프 | C22: 1 | D22: 1 | E22: 9999 | F22: ="ITEM_NAME_"&A22 -> ITEM_NAME_101019 | G22: ="ITEM_ICON_"&A22 -> ITEM_ICON_101019 | H22: ="ITEM_DESC_"&A22 -> ITEM_DESC_101019 | M22: 16 | N22: 선물
A23: =C23*ID규칙_아이템_구분_단위+D23*ID규칙_아이템_타입_단위+COUNTIFS($C$4:C23,C23,$D$4:D23,D23) -> 101020 | B23: 세나의 엘레프 | C23: 1 | D23: 1 | E23: 9999 | F23: ="ITEM_NAME_"&A23 -> ITEM_NAME_101020 | G23: ="ITEM_ICON_"&A23 -> ITEM_ICON_101020 | H23: ="ITEM_DESC_"&A23 -> ITEM_DESC_101020 | M23: 17 | N23: 재화
A24: =C24*ID규칙_아이템_구분_단위+D24*ID규칙_아이템_타입_단위+COUNTIFS($C$4:C24,C24,$D$4:D24,D24) -> 101021 | B24: 이로하의 엘레프 | C24: 1 | D24: 1 | E24: 9999 | F24: ="ITEM_NAME_"&A24 -> ITEM_NAME_101021 | G24: ="ITEM_ICON_"&A24 -> ITEM_ICON_101021 | H24: ="ITEM_DESC_"&A24 -> ITEM_DESC_101021
A25: =C25*ID규칙_아이템_구분_단위+D25*ID규칙_아이템_타입_단위+COUNTIFS($C$4:C25,C25,$D$4:D25,D25) -> 101022 | B25: 메구의 엘레프 | C25: 1 | D25: 1 | E25: 9999 | F25: ="ITEM_NAME_"&A25 -> ITEM_NAME_101022 | G25: ="ITEM_ICON_"&A25 -> ITEM_ICON_101022 | H25: ="ITEM_DESC_"&A25 -> ITEM_DESC_101022
A26: =C26*ID규칙_아이템_구분_단위+D26*ID규칙_아이템_타입_단위+COUNTIFS($C$4:C26,C26,$D$4:D26,D26) -> 101023 | B26: 노아의 엘레프 | C26: 1 | D26: 1 | E26: 9999 | F26: ="ITEM_NAME_"&A26 -> ITEM_NAME_101023 | G26: ="ITEM_ICON_"&A26 -> ITEM_ICON_101023 | H26: ="ITEM_DESC_"&A26 -> ITEM_DESC_101023
A27: =C27*ID규칙_아이템_구분_단위+D27*ID규칙_아이템_타입_단위+COUNTIFS($C$4:C27,C27,$D$4:D27,D27) -> 101024 | B27: 유우카의 엘레프 | C27: 1 | D27: 1 | E27: 9999 | F27: ="ITEM_NAME_"&A27 -> ITEM_NAME_101024 | G27: ="ITEM_ICON_"&A27 -> ITEM_ICON_101024 | H27: ="ITEM_DESC_"&A27 -> ITEM_DESC_101024
A28: =C28*ID규칙_아이템_구분_단위+D28*ID규칙_아이템_타입_단위+COUNTIFS($C$4:C28,C28,$D$4:D28,D28) -> 101025 | B28: 코유키의 엘레프 | C28: 1 | D28: 1 | E28: 9999 | F28: ="ITEM_NAME_"&A28 -> ITEM_NAME_101025 | G28: ="ITEM_ICON_"&A28 -> ITEM_ICON_101025 | H28: ="ITEM_DESC_"&A28 -> ITEM_DESC_101025
A29: =C29*ID규칙_아이템_구분_단위+D29*ID규칙_아이템_타입_단위+COUNTIFS($C$4:C29,C29,$D$4:D29,D29) -> 101026 | B29: 치히로의 엘레프 | C29: 1 | D29: 1 | E29: 9999 | F29: ="ITEM_NAME_"&A29 -> ITEM_NAME_101026 | G29: ="ITEM_ICON_"&A29 -> ITEM_ICON_101026 | H29: ="ITEM_DESC_"&A29 -> ITEM_DESC_101026
A30: =C30*ID규칙_아이템_구분_단위+D30*ID규칙_아이템_타입_단위+COUNTIFS($C$4:C30,C30,$D$4:D30,D30) -> 101027 | B30: 하레의 엘레프 | C30: 1 | D30: 1 | E30: 9999 | F30: ="ITEM_NAME_"&A30 -> ITEM_NAME_101027 | G30: ="ITEM_ICON_"&A30 -> ITEM_ICON_101027 | H30: ="ITEM_DESC_"&A30 -> ITEM_DESC_101027
A31: =C31*ID규칙_아이템_구분_단위+D31*ID규칙_아이템_타입_단위+COUNTIFS($C$4:C31,C31,$D$4:D31,D31) -> 101028 | B31: 미카의 엘레프 | C31: 1 | D31: 1 | E31: 9999 | F31: ="ITEM_NAME_"&A31 -> ITEM_NAME_101028 | G31: ="ITEM_ICON_"&A31 -> ITEM_ICON_101028 | H31: ="ITEM_DESC_"&A31 -> ITEM_DESC_101028
A32: =C32*ID규칙_아이템_구분_단위+D32*ID규칙_아이템_타입_단위+COUNTIFS($C$4:C32,C32,$D$4:D32,D32) -> 101029 | B32: 코타마의 엘레프 | C32: 1 | D32: 1 | E32: 9999 | F32: ="ITEM_NAME_"&A32 -> ITEM_NAME_101029 | G32: ="ITEM_ICON_"&A32 -> ITEM_ICON_101029 | H32: ="ITEM_DESC_"&A32 -> ITEM_DESC_101029
A33: =C33*ID규칙_아이템_구분_단위+D33*ID규칙_아이템_타입_단위+COUNTIFS($C$4:C33,C33,$D$4:D33,D33) -> 101030 | B33: 네루의 엘레프 | C33: 1 | D33: 1 | E33: 9999 | F33: ="ITEM_NAME_"&A33 -> ITEM_NAME_101030 | G33: ="ITEM_ICON_"&A33 -> ITEM_ICON_101030 | H33: ="ITEM_DESC_"&A33 -> ITEM_DESC_101030
A34: =C34*ID규칙_아이템_구분_단위+D34*ID규칙_아이템_타입_단위+COUNTIFS($C$4:C34,C34,$D$4:D34,D34) -> 101031 | B34: 아스나의 엘레프 | C34: 1 | D34: 1 | E34: 9999 | F34: ="ITEM_NAME_"&A34 -> ITEM_NAME_101031 | G34: ="ITEM_ICON_"&A34 -> ITEM_ICON_101031 | H34: ="ITEM_DESC_"&A34 -> ITEM_DESC_101031
A35: =C35*ID규칙_아이템_구분_단위+D35*ID규칙_아이템_타입_단위+COUNTIFS($C$4:C35,C35,$D$4:D35,D35) -> 101032 | B35: 카린의 엘레프 | C35: 1 | D35: 1 | E35: 9999 | F35: ="ITEM_NAME_"&A35 -> ITEM_NAME_101032 | G35: ="ITEM_ICON_"&A35 -> ITEM_ICON_101032 | H35: ="ITEM_DESC_"&A35 -> ITEM_DESC_101032
... A343: =C343*ID규칙_아이템_구분_단위+D343*ID규칙_아이템_타입_단위+COUNTIFS($C$4:C343,C343,$D$4:D343,D343) -> 616052 | B343: 보드게임 「더 인생」 | C343: 6 | D343: 16 | E343: 9999 | F343: ="ITEM_NAME_"&A343 -> ITEM_NAME_616052 | G343: ="ITEM_ICON_"&A343 -> ITEM_ICON_616052 | H343: ="ITEM_DESC_"&A343 -> ITEM_DESC_616052
A344: =C344*ID규칙_아이템_구분_단위+D344*ID규칙_아이템_타입_단위+COUNTIFS($C$4:C344,C344,$D$4:D344,D344) -> 1717001 | B344: AP | C344: 17 | D344: 17 | E344: 999999
A345: =C345*ID규칙_아이템_구분_단위+D345*ID규칙_아이템_타입_단위+COUNTIFS($C$4:C345,C345,$D$4:D345,D345) -> 1717002 | B345: 크레딧 | C345: 17 | D345: 17 | E345: 2100000000
A346: =C346*ID규칙_아이템_구분_단위+D346*ID규칙_아이템_타입_단위+COUNTIFS($C$4:C346,C346,$D$4:D346,D346) -> 1717003 | B346: 청휘석 | C346: 17 | D346: 17 | E346: 999999

Sheet STUDENT
A1: 아이디 | B1: #학생 이름 | C1: 역할 | D1: 상세 역할 | E1: 등급 | F1: 최대 레벨 | G1: 공격 위치 | H1: 공격 타입 | I1: 방어 타입 | J1: 시가전 등급 | K1: 야전 등급 | L1: 실내전 등급 | M1: 대사 그룹 | N1: 애용품 그룹 | O1: 학생 이름 | P1: 학생 이미지
A2: ID | B2: STUDENT_NAME | C2: ROLE | D2: DETAIL_ROLE | E2: RANK | F2: MAX_LEVEL | G2: POSITION_TYPE | H2: OFFENSE_TYPE | I2: DEFENSE_TYPE | J2: CITY_WAR_RANK | K2: OUTSIDE_WAR_RANK | L2: INSIDE_WAR_RANK | M2: SPEECH_GROUP | N2: UNIQUE_ITEM_GROUP | O2: STUDENT_NAME | P2: STUDENT_IMAGE
A3: int | B3: 참조 | C3: int | D3: int | E3: int | F3: int | G3: int | H3: int | I3: int | J3: int | K3: int | L3: int | M3: int | N3: int | O3: string | P3: string
A4: =C4*ID규칙_학생_역할_단위+D4*ID규칙_학생_상세_역할_단위+E4*ID규칙_학생_등급_단위+COUNTIF($C$4:C4,C4) -> 11301 | B4: 시로코 | C4: 1 | D4: 1 | E4: 3 | F4: 81 | G4: 2 | H4: 1 | I4: 1 | J4: 2 | K4: 4 | L4: 6 | M4: =C4*10000+D4*1000+E4*100+COUNTIF($C$4:C4,C4) -> 11301 | N4: =IFERROR(VLOOKUP(B4,[1]STUDENT_UNIQUE_ITEM!$C:$D,2,0),0) -> 11301 | O4: ="STUDENT_NAME_"&A4 -> STUDENT_NAME_11301 | P4: ="STUDENT_IMAGE_"&A4 -> STUDENT_IMAGE_11301
A5: =C5*ID규칙_학생_역할_단위+D5*ID규칙_학생_상세_역할_단위+E5*ID규칙_학생_등급_단위+COUNTIF($C$4:C5,C5) -> 12302 | B5: 호시노 | C5: 1 | D5: 2 | E5: 3 | F5: 81 | G5: 1 | H5: 2 | I5: 2 | J5: 6 | K5: 2 | L5: 4 | M5: =C5*10000+D5*1000+E5*100+COUNTIF($C$4:C5,C5) -> 12302 | N5: =IFERROR(VLOOKUP(B5,[1]STUDENT_UNIQUE_ITEM!$C:$D,2,0),0) -> 0 | O5: ="STUDENT_NAME_"&A5 -> STUDENT_NAME_12302 | P5: ="STUDENT_IMAGE_"&A5 -> STUDENT_IMAGE_12302
A6: =C6*ID규칙_학생_역할_단위+D6*ID규칙_학생_상세_역할_단위+E6*ID규칙_학생_등급_단위+COUNTIF($C$4:C6,C6) -> 11203 | B6: 세리카 | C6: 1 | D6: 1 | E6: 2 | F6: 81 | G6: 2 | H6: 1 | I6: 1 | J6: 3 | K6: 6 | L6: 3 | M6: =C6*10000+D6*1000+E6*100+COUNTIF($C$4:C6,C6) -> 11203 | N6: =IFERROR(VLOOKUP(B6,[1]STUDENT_UNIQUE_ITEM!$C:$D,2,0),0) -> 0 | O6: ="STUDENT_NAME_"&A6 -> STUDENT_NAME_11203 | P6: ="STUDENT_IMAGE_"&A6 -> STUDENT_IMAGE_11203
A7: =C7*ID규칙_학생_역할_단위+D7*ID규칙_학생_상세_역할_단위+E7*ID규칙_학생_등급_단위+COUNTIF($C$4:C7,C7) -> 11204 | B7: 노노미 | C7: 1 | D7: 1 | E7: 2 | F7: 81 | G7: 3 | H7: 2 | I7: 2 | J7: 3 | K7: 3 | L7: 6 | M7: =C7*10000+D7*1000+E7*100+COUNTIF($C$4:C7,C7) -> 11204 | N7: =IFERROR(VLOOKUP(B7,[1]STUDENT_UNIQUE_ITEM!$C:$D,2,0),0) -> 0 | O7: ="STUDENT_NAME_"&A7 -> STUDENT_NAME_11204 | P7: ="STUDENT_IMAGE_"&A7 -> STUDENT_IMAGE_11204
A8: =C8*ID규칙_학생_역할_단위+D8*ID규칙_학생_상세_역할_단위+E8*ID규칙_학생_등급_단위+COUNTIF($C$4:C8,C8) -> 23201 | B8: 아야네 | C8: 2 | D8: 3 | E8: 2 | F8: 81 | G8: 3 | H8: 2 | I8: 1 | J8: 6 | K8: 3 | L8: 3 | M8: =C8*10000+D8*1000+E8*100+COUNTIF($C$4:C8,C8) -> 23201 | N8: =IFERROR(VLOOKUP(B8,[1]STUDENT_UNIQUE_ITEM!$C:$D,2,0),0) -> 0 | O8: ="STUDENT_NAME_"&A8 -> STUDENT_NAME_23201 | P8: ="STUDENT_IMAGE_"&A8 -> STUDENT_IMAGE_23201
A9: =C9*ID규칙_학생_역할_단위+D9*ID규칙_학생_상세_역할_단위+E9*ID규칙_학생_등급_단위+COUNTIF($C$4:C9,C9) -> 11305 | B9: 아루 | C9: 1 | D9: 1 | E9: 3 | F9: 81 | G9: 3 | H9: 1 | I9: 1 | J9: 2 | K9: 4 | L9: 6 | M9: =C9*10000+D9*1000+E9*100+COUNTIF($C$4:C9,C9) -> 11305 | N9: =IFERROR(VLOOKUP(B9,[1]STUDENT_UNIQUE_ITEM!$C:$D,2,0),0) -> 11305 | O9: ="STUDENT_NAME_"&A9 -> STUDENT_NAME_11305 | P9: ="STUDENT_IMAGE_"&A9 -> STUDENT_IMAGE_11305
A10: =C10*ID규칙_학생_역할_단위+D10*ID규칙_학생_상세_역할_단위+E10*ID규칙_학생_등급_단위+COUNTIF($C$4:C10,C10) -> 11206 | B10: 무츠키 | C10: 1 | D10: 1 | E10: 2 | F10: 81 | G10: 3 | H10: 1 | I10: 1 | J10: 3 | K10: 3 | L10: 6 | M10: =C10*10000+D10*1000+E10*100+COUNTIF($C$4:C10,C10) -> 11206 | N10: =IFERROR(VLOOKUP(B10,[1]STUDENT_UNIQUE_ITEM!$C:$D,2,0),0) -> 0 | O10: ="STUDENT_NAME_"&A10 -> STUDENT_NAME_11206 | P10: ="STUDENT_IMAGE_"&A10 -> STUDENT_IMAGE_11206
A11: =C11*ID규칙_학생_역할_단위+D11*ID규칙_학생_상세_역할_단위+E11*ID규칙_학생_등급_단위+COUNTIF($C$4:C11,C11) -> 14207 | B11: 카요코 | C11: 1 | D11: 4 | E11: 2 | F11: 81 | G11: 1 | H11: 1 | I11: 2 | J11: 3 | K11: 6 | L11: 3 | M11: =C11*10000+D11*1000+E11*100+COUNTIF($C$4:C11,C11) -> 14207 | N11: =IFERROR(VLOOKUP(B11,[1]STUDENT_UNIQUE_ITEM!$C:$D,2,0),0) -> 0 | O11: ="STUDENT_NAME_"&A11 -> STUDENT_NAME_14207 | P11: ="STUDENT_IMAGE_"&A11 -> STUDENT_IMAGE_14207
A12: =C12*ID규칙_학생_역할_단위+D12*ID규칙_학생_상세_역할_단위+E12*ID규칙_학생_등급_단위+COUNTIF($C$4:C12,C12) -> 11108 | B12: 하루카 | C12: 1 | D12: 1 | E12: 1 | F12: 81 | G12: 1 | H12: 1 | I12: 1 | J12: 5 | K12: 4 | L12: 3 | M12: =C12*10000+D12*1000+E12*100+COUNTIF($C$4:C12,C12) -> 11108 | N12: =IFERROR(VLOOKUP(B12,[1]STUDENT_UNIQUE_ITEM!$C:$D,2,0),0) -> 0 | O12: ="STUDENT_NAME_"&A12 -> STUDENT_NAME_11108 | P12: ="STUDENT_IMAGE_"&A12 -> STUDENT_IMAGE_11108
A13: =C13*ID규칙_학생_역할_단위+D13*ID규칙_학생_상세_역할_단위+E13*ID규칙_학생_등급_단위+COUNTIF($C$4:C13,C13) -> 11309 | B13: 히나 | C13: 1 | D13: 1 | E13: 3 | F13: 81 | G13: 3 | H13: 1 | I13: 2 | J13: 2 | K13: 6 | L13: 6 | M13: =C13*10000+D13*1000+E13*100+COUNTIF($C$4:C13,C13) -> 11309 | N13: =IFERROR(VLOOKUP(B13,[1]STUDENT_UNIQUE_ITEM!$C:$D,2,0),0) -> 11309 | O13: ="STUDENT_NAME_"&A13 -> STUDENT_NAME_11309 | P13: ="STUDENT_IMAGE_"&A13 -> STUDENT_IMAGE_11309
A14: =C14*ID규칙_학생_역할_단위+D14*ID규칙_학생_상세_역할_단위+E14*ID규칙_학생_등급_단위+COUNTIF($C$4:C14,C14) -> 24302 | B14: 아코 | C14: 2 | D14: 4 | E14: 3 | F14: 81 | G14: 3 | H14: 3 | I14: 2 | J14: 6 | K14: 4 | L14: 2 | M14: =C14*10000+D14*1000+E14*100+COUNTIF($C$4:C14,C14) -> 24302 | N14: =IFERROR(VLOOKUP(B14,[1]STUDENT_UNIQUE_ITEM!$C:$D,2,0),0) -> 0 | O14: ="STUDENT_NAME_"&A14 -> STUDENT_NAME_24302 | P14: ="STUDENT_IMAGE_"&A14 -> STUDENT_IMAGE_24302
A15: =C15*ID규칙_학생_역할_단위+D15*ID규칙_학생_상세_역할_단위+E15*ID규칙_학생_등급_단위+COUNTIF($C$4:C15,C15) -> 11310 | B15: 이오리 | C15: 1 | D15: 1 | E15: 3 | F15: 81 | G15: 3 | H15: 1 | I15: 3 | J15: 5 | K15: 5 | L15: 2 | M15: =C15*10000+D15*1000+E15*100+COUNTIF($C$4:C15,C15) -> 11310 | N15: =IFERROR(VLOOKUP(B15,[1]STUDENT_UNIQUE_ITEM!$C:$D,2,0),0) -> 0 | O15: ="STUDENT_NAME_"&A15 -> STUDENT_NAME_11310 | P15: ="STUDENT_IMAGE_"&A15 -> STUDENT_IMAGE_11310
... A99: =C99*ID규칙_학생_역할_단위+D99*ID규칙_학생_상세_역할_단위+E99*ID규칙_학생_등급_단위+COUNTIF($C$4:C99,C99) -> 24330 | B99: 미쿠 | C99: 2 | D99: 4 | E99: 3 | F99: 81 | G99: 3 | H99: 1 | I99: 1 | J99: 2 | K99: 6 | L99: 4 | M99: =C99*10000+D99*1000+E99*100+COUNTIF($C$4:C99,C99) -> 24330 | N99: =IFERROR(VLOOKUP(B99,[1]STUDENT_UNIQUE_ITEM!$C:$D,2,0),0) -> 0 | O99: ="STUDENT_NAME_"&A99 -> STUDENT_NAME_24330 | P99: ="STUDENT_IMAGE_"&A99 -> STUDENT_IMAGE_24330
