Workbook
Name AlertGetItem: #REF!
Name AlertGetItem_List: #REF!
Name Break: #REF!
Name Break_List: #REF!
Name Broadcast: #REF!
Name Broadcast_List: #REF!
Name CheckTradeRuby_List: #REF!
Name Enchant: #REF!
Name Enchant_List: #REF!
Name FixCreateSlot: #REF!
Name FixCreateSlot_List: #REF!
Name FixSlot: #REF!
Name FixSlot_List: #REF!
Name IncludeSealing: #REF!
Name IncludeSealing_List: #REF!
Name IncludeServerTransfer: #REF!
Name Is_UsedSkill: #REF!
Name Is_UsedSkill_List: #REF!
Name LockFunc: #REF!
Name LockFunc_List: #REF!
Name Main_Category: #REF!
Name Main_Category_List: #REF!
Name PetAutoSell: #REF!
Name PetAutoSell_List: #REF!
Name Sell: #REF!
Name Sell_List: #REF!
Name SetOperatorTool_List: #REF!
Name SetTrade_List: #REF!
Name Skill_Level_Ratio: #REF!
Name Sub_Category: #REF!
Name Sub_Category_List: #REF!
Name T_AutoSort: #REF!
Name T_AutoSort_List: #REF!
Name T_Equip: #REF!
Name T_Equip_List: #REF!
Name T_EquipSlot: #REF!
Name T_EquipSlot_List: #REF!
Name T_ExchangeCategory: #REF!
Name T_ExchangeCategory_List: #REF!
Name T_Goods: #REF!
Name T_Goods_List: #REF!
Name T_ItemGrade: #REF!
Name T_ItemGrade_List: #REF!
Name T_Job: #REF!
Name T_Job_List: #REF!
Name T_RandomBox: #REF!
Name T_RandomBox_List: #REF!
Name T_UiNumber: #REF!
Name T_UiNumber_List: #REF!
Name T_WeaponBone_L: #REF!
Name T_WeaponBone_L_List: #REF!
Name T_WeaponBone_R: #REF!
Name T_WeaponBone_R_List: #REF!
Name Throw: #REF!
Name Throw_List: #REF!
Name Trade: #REF!
Name Trade_List: #REF!
Name TypeGrowth: #REF!
Name TypeGrowth_List: #REF!
Name UsedData_List: #REF!

Sheet INFO
H3: 명함(칭호) 시스템 기획 초안
C7: 1 | D7: 개요
E9: - 명함 획득 조건 달성 시 명함을 획득 가능하다.
E11: - 각 명함마다 옵션이 존재한다.
F12: ㄴ 획득한 명함 카테고리에 어울리는 능력치를 착용할 수 있게하여 (전투, 탐험 등..) 여러 분야의 컨텐츠를 플레이하여 수집하도록 한다
G13: ex) 탐험(채집)으로 명함 획득 시 채집에 유리한 능력치를 제공하는 형태
E15: - 명함 등급에 따른 보상 및 총 수집 옵션이 존재하고, 획득한 명함에 대한 추가 능력치로 인하여 수집력을 높인다
E17: - 각 명함마다 경험치 값이 존재하며, 그에 따라 명함 등급을 올릴 수 있다.
F18: ㄴ 경험치 값은 게이지와 숫자로 같이 표현한다.
G19: → 경험치 값은 REWARD 테이블의 ITEM_ID에 포함한다.
E21: - 각 캐릭터마다 명함 착용이 가능하다.
F22: ㄴ 캐릭터 1인당 1개씩 착용 가능하다.
F23: ㄴ 명함을 장착하는 건 장비 탭에서 같이 장착하게끔 설정. (캐릭터마다 다른 명함을 장착해야하기 때문)
E25: - 명함에 여러 디자인 (꾸밈 요소)이 들어가면서, 추후 콜라보나 이벤트 명함으로도 확장할 수 있다.
E27: - 캐릭터 머리 위에 표시되는 형태 | N27: (추후 개발 상황에 따라 변동 가능성 있음)
C31: 2 | D31: UI 초안
T59: 명함 메인 UI
T61: 필터 구성: 전체, 보유 명함, 미보유 명함
T91: 명함 등급 팝업

Sheet UI_설명
H3: UI 세부 설명
D7: 1 | E7: 개요
AP9: * 총 4개의 구역으로 나누어서 UI 구성을 설명한다.
AQ11: 번호 | AR11: 설명
AQ12: 1 | AR12: 상단 UI | AZ12: [이동]
AQ13: 2 | AR13: 명함 등급 및 명함 카테고리 | AZ13: [이동]
AQ14: 3 | AR14: 명함 목록 | AZ14: [이동]
AQ15: 4 | AR15: 명함 상세 | AZ15: [이동]
D37: 2 | E37: UI 구성
E39: 1 | F39: 상단 UI
AP41: ① 명함 정보 구성
AQ42: - 이전( < ) 버튼 터치 시 이전 화면으로 이동
AQ44: - 명함 STRING_KEY
AT46: STRING_KEY | AY46: 내용
AT47: NAMECARD_TITLE | AY47: 명함
AQ50: - ( ? ) 아이콘 터치 시 명함에 대한 간략한 튜토리얼 팝업 출력
AR51: ~튜토리얼 팝업 창 구성은 준비 중~
AQ52: 번호 | AR52: 튜토리얼 팝업 내용 | BP52: STRING_KEY
AQ53: 1/3 | AR53: 다양한 콘텐츠를 플레이하면 「명함」을 획득할 수 있습니다 | BP53: NAMECARD_TUTORIAL_TEXT_1
AQ54: 2/3 | AR54: 「명함」은 조사단당 1개씩 장착할 수 있으며, 장착 시 다양한 효과가 발동합니다 | BP54: NAMECARD_TUTORIAL_TEXT_2
AQ55: 3/3 | AR55: 「명함」을 수집해 명함 등급을 올리면, 등급 보상과 수집 옵션으로 추가 성장을 기대할 수 있습니다! | BP55: NAMECARD_TUTORIAL_TEXT_3
AP58: ② 설정 및 나가기 버튼
AQ59: - 설정 버튼
AQ61: - ( X ) 버튼 터치 시 로비로 이동
E74: 2 | F74: 명함 등급 및 명함 카테고리
AP76: ① 명함 등급
AT78: - 경험치 값은 게이지와 숫자로 같이 표현한다.
AW80: 참조 테이블 | BD80: 참조 컬럼 | BJ80: 내용
AW81: NAMECARD_GRADE | BD81: NAMECARD_GRADE | BJ81: 명함 등급
AW82: NAMECARD_GRADE | BD82: NEED_EXP | BJ82: 필요 경험치
AW83: NAMECARD_GRADE | BD83: CUMULATIVE_EXP | BJ83: 누적 경험치
AT85: ㄴ 총 누적 경험치 양을 판단하여 명함 등급을 출력한다.
AT86: ㄴ 다음 등급의 필요 경험치를 판단하여, 다음 등급까지의 경험치 양을 UI에 게이지 형태로 노출한다.
AT89: - '명함 등급' 텍스트 표시
AY91: STRING_KEY | BG91: 내용
AY92: NAMECARD_GRADE_TEXT | BG92: 명함 등급
AT94: - [획득 처리 된 명함 개수 / 전체 명함 개수] 표시
AU95: ㄴ NAMECARD 테이블을 참조하여 명함 개수를 COUNT한다.
AT98: - 돋보기 아이콘 터치 치 명함 등급 팝업 출력
AP108: ① 명함 등급 STRING
...

Sheet DATA
E4: 데이터 구조도
C8: NAMECARD | E8: OPTION | G8: NAMECARD_GRADE
C9: ID | E9: ID | G9: ID
C10: OPTION_GROUP | E10: OPTION_GROUP | G10: NAMECARD_GRADE
C11: NAMECARD_CATEGORY | E11: OPTION_TYPE | G11: NEED_EXP
C12: CONDITION_GROUP | E12: ISRATE | G12: CUMULATIVE_EXP
C13: REWARD_GROUP | E13: PARAM | G13: OPTION_GROUP
C14: NAMECARD_NAME | G14: REWARD_GROUP
C15: NAMECARD_DESC
C16: SORT
C19: NAMECARD_CATEGORY | E19: CONDITION | G19: ITEM
C20: ID | E20: ID | G20: ID
C21: NAMECARD_CATEGORY | E21: CONDITION_GROUP | G21: ITEM_CATEGORY
C22: NAMECARD_CATEGORY_NAME | E22: CONDITION_TYPE | G22: ITEM_TYPE
C23: SORT | E23: PARAM | G23: ···
E24: SORT | G24: ITEM_ICON
G25: ITEM_DESC
E27: REWARD
E28: ID
E29: REWARD_GROUP
E30: ITEM_ID
E31: ITEM_COUNT
E32: ISRATE
E33: SORT

Sheet NAMECARD
A1: 아이디 | B1: 명함 이름 | C1: 명함 옵션 그룹 | D1: 명함 카테고리 | E1: 획득 조건 그룹 | F1: 보상 그룹 | G1: 명함 이름 | H1: 명함 설명 | I1: 명함 이미지 | J1: 순서
A2: ID | B2: COMMENT | C2: OPTION_GROUP | D2: NAMECARD_CATEGORY | E2: CONDITION_GROUP | F2: REWARD_GROUP | G2: NAMECARD_NAME | H2: NAMECARD_DESC | I2: NAMECARD_IMAGE | J2: SORT
A3: int | B3: comment | C3: int | D3: int | E3: int | F3: int | G3: string | H3: string | I3: string | J3: int
A4: =1000000+C4*100+D4 -> 1000101 | B4: 하늘 높이 솟은 신극 | C4: =INDEX(OPTION!$B:$B,MATCH(NAMECARD!B4,OPTION!$G:$G,0)) -> 1 | D4: 1 | G4: ="NAMECARD_NAME_"&A4 -> NAMECARD_NAME_1000101 | H4: ="NAMECARD_DESC_"&A4 -> NAMECARD_DESC_1000101 | I4: ="NAMECARD_IMAGE_"&A4 -> NAMECARD_IMAGE_1000101 | J4: 1
A5: =1000000+C5*100+D5 -> 1000202 | B5: 바람의 땅에서 위세를 떨치다 | C5: =INDEX(OPTION!$B:$B,MATCH(NAMECARD!B5,OPTION!$G:$G,0)) -> 2 | D5: 2 | G5: ="NAMECARD_NAME_"&A5 -> NAMECARD_NAME_1000202 | H5: ="NAMECARD_DESC_"&A5 -> NAMECARD_DESC_1000202 | I5: ="NAMECARD_IMAGE_"&A5 -> NAMECARD_IMAGE_1000202 | J5: 2
A6: =1000000+C6*100+D6 -> 1000303 | B6: 아름다운 여정: 프롤로그 | C6: =INDEX(OPTION!$B:$B,MATCH(NAMECARD!B6,OPTION!$G:$G,0)) -> 3 | D6: 3 | G6: ="NAMECARD_NAME_"&A6 -> NAMECARD_NAME_1000303 | H6: ="NAMECARD_DESC_"&A6 -> NAMECARD_DESC_1000303 | I6: ="NAMECARD_IMAGE_"&A6 -> NAMECARD_IMAGE_1000303 | J6: 3
A7: =1000000+C7*100+D7 -> 1000404 | B7: 악령이여 물러가라 | C7: =INDEX(OPTION!$B:$B,MATCH(NAMECARD!B7,OPTION!$G:$G,0)) -> 4 | D7: 4 | G7: ="NAMECARD_NAME_"&A7 -> NAMECARD_NAME_1000404 | H7: ="NAMECARD_DESC_"&A7 -> NAMECARD_DESC_1000404 | I7: ="NAMECARD_IMAGE_"&A7 -> NAMECARD_IMAGE_1000404 | J7: 4
A8: =1000000+C8*100+D8 -> 1000505 | B8: 즐거움을 찾아서 | C8: =INDEX(OPTION!$B:$B,MATCH(NAMECARD!B8,OPTION!$G:$G,0)) -> 5 | D8: 5 | G8: ="NAMECARD_NAME_"&A8 -> NAMECARD_NAME_1000505 | H8: ="NAMECARD_DESC_"&A8 -> NAMECARD_DESC_1000505 | I8: ="NAMECARD_IMAGE_"&A8 -> NAMECARD_IMAGE_1000505 | J8: 5
A9: =1000000+C9*100+D9 -> 1000606 | B9: 통달한 | C9: =INDEX(OPTION!$B:$B,MATCH(NAMECARD!B9,OPTION!$G:$G,0)) -> 6 | D9: 6 | G9: ="NAMECARD_NAME_"&A9 -> NAMECARD_NAME_1000606 | H9: ="NAMECARD_DESC_"&A9 -> NAMECARD_DESC_1000606 | I9: ="NAMECARD_IMAGE_"&A9 -> NAMECARD_IMAGE_1000606 | J9: 6
A10: =1000000+C10*100+D10 -> 1000701 | B10: 신세대 | C10: =INDEX(OPTION!$B:$B,MATCH(NAMECARD!B10,OPTION!$G:$G,0)) -> 7 | D10: 1 | G10: ="NAMECARD_NAME_"&A10 -> NAMECARD_NAME_1000701 | H10: ="NAMECARD_DESC_"&A10 -> NAMECARD_DESC_1000701 | I10: ="NAMECARD_IMAGE_"&A10 -> NAMECARD_IMAGE_1000701 | J10: 7
A11: =1000000+C11*100+D11 -> 1000802 | B11: 자주 아픈 | C11: =INDEX(OPTION!$B:$B,MATCH(NAMECARD!B11,OPTION!$G:$G,0)) -> 8 | D11: 2 | G11: ="NAMECARD_NAME_"&A11 -> NAMECARD_NAME_1000802 | H11: ="NAMECARD_DESC_"&A11 -> NAMECARD_DESC_1000802 | I11: ="NAMECARD_IMAGE_"&A11 -> NAMECARD_IMAGE_1000802 | J11: 8
A12: =1000000+C12*100+D12 -> 1000903 | B12: 불운한 | C12: =INDEX(OPTION!$B:$B,MATCH(NAMECARD!B12,OPTION!$G:$G,0)) -> 9 | D12: 3 | G12: ="NAMECARD_NAME_"&A12 -> NAMECARD_NAME_1000903 | H12: ="NAMECARD_DESC_"&A12 -> NAMECARD_DESC_1000903 | I12: ="NAMECARD_IMAGE_"&A12 -> NAMECARD_IMAGE_1000903 | J12: 9
A13: =1000000+C13*100+D13 -> 1001004 | B13: 훌륭하게 준비된 | C13: =INDEX(OPTION!$B:$B,MATCH(NAMECARD!B13,OPTION!$G:$G,0)) -> 10 | D13: 4 | G13: ="NAMECARD_NAME_"&A13 -> NAMECARD_NAME_1001004 | H13: ="NAMECARD_DESC_"&A13 -> NAMECARD_DESC_1001004 | I13: ="NAMECARD_IMAGE_"&A13 -> NAMECARD_IMAGE_1001004 | J13: 10

Sheet OPTION
A1: 아이디 | B1: 명함 옵션 그룹 | C1: 옵션 타입 | D1: 옵션 비율 | E1: 옵션 값 | F1: 옵션 내용 | G1: 칭호 이름
A2: ID | B2: OPTION_GROUP | C2: OPTION_TYPE | D2: ISRATE | E2: PARAM | F2: COMMENT | G2: COMMENT
A3: int | B3: int | C3: int | D3: int | E3: int | F3: comment | G3: comment
A4: =100000+C4*100+COUNT($B$4:B4) -> 100101 | B4: 1 | C4: 1 | D4: 0 | F4: 생명력 +10 | G4: 하늘 높이 솟은 신극
A5: =100000+C5*100+COUNT($B$4:B5) -> 100102 | B5: 1 | C5: 1 | D5: 0 | F5: 치유력 +10 | G5: 하늘 높이 솟은 신극
A6: =100000+C6*100+COUNT($B$4:B6) -> 100103 | B6: 1 | C6: 1 | D6: 1 | F6: 치명타 확률 +1% | G6: 하늘 높이 솟은 신극
A7: =100000+C7*100+COUNT($B$4:B7) -> 100204 | B7: 2 | C7: 2 | D7: 0 | G7: 바람의 땅에서 위세를 떨치다
A8: =100000+C8*100+COUNT($B$4:B8) -> 100305 | B8: 3 | C8: 3 | G8: 아름다운 여정: 프롤로그
A9: =100000+C9*100+COUNT($B$4:B9) -> 100406 | B9: 4 | C9: 4 | G9: 악령이여 물러가라
A10: =100000+C10*100+COUNT($B$4:B10) -> 100507 | B10: 5 | C10: 5 | G10: 즐거움을 찾아서
A11: =100000+C11*100+COUNT($B$4:B11) -> 100608 | B11: 6 | C11: 6 | G11: 통달한
A12: =100000+C12*100+COUNT($B$4:B12) -> 100709 | B12: 7 | C12: 7 | G12: 신세대
A13: =100000+C13*100+COUNT($B$4:B13) -> 100810 | B13: 8 | C13: 8 | G13: 자주 아픈
A14: =100000+C14*100+COUNT($B$4:B14) -> 100911 | B14: 9 | C14: 9 | G14: 불운한
A15: =100000+C15*100+COUNT($B$4:B15) -> 101012 | B15: 10 | C15: 10 | G15: 훌륭하게 준비된

Sheet NAMECARD_CATEGORY
A1: 아이디 | B1: 명함 카테고리 | C1: 명함 카테고리 이름 | D1: 명함 카테고리 이름 | E1: 순서
A2: ID | B2: NAMECARD_CATEGORY | C2: NAMECARD_CATEGORY_NAME | D2: COMMENT | E2: SORT
A3: int | B3: int | C3: string | D3: comment | E3: int
A4: 1 | B4: 1 | C4: ="NAMECARD_CATEGORY_NAME_"&A4 -> NAMECARD_CATEGORY_NAME_1 | D4: 육성 | E4: 1
A5: 2 | B5: 2 | C5: ="NAMECARD_CATEGORY_NAME_"&A5 -> NAMECARD_CATEGORY_NAME_2 | D5: 아이템 | E5: 2
A6: 3 | B6: 3 | C6: ="NAMECARD_CATEGORY_NAME_"&A6 -> NAMECARD_CATEGORY_NAME_3 | D6: 탐험 | E6: 3
A7: 4 | B7: 4 | C7: ="NAMECARD_CATEGORY_NAME_"&A7 -> NAMECARD_CATEGORY_NAME_4 | D7: 전투 | E7: 4
A8: 5 | B8: 5 | C8: ="NAMECARD_CATEGORY_NAME_"&A8 -> NAMECARD_CATEGORY_NAME_5 | D8: 이벤트 | E8: 5
A9: 6 | B9: 6 | C9: ="NAMECARD_CATEGORY_NAME_"&A9 -> NAMECARD_CATEGORY_NAME_6 | D9: 즐겨찾기 | E9: 6

Sheet CONDITION
A1: 아이디 | B1: 획득 조건 그룹 | C1: 획득 조건 타입 | D1: 획득 조건 값 | E1: 명함 이름 | F1: 순서
A2: ID | B2: CONDITION_GROUP | C2: CONDITION_TYPE | D2: PARAM | E2: COMMENT | F2: SORT
A3: int | B3: int | C3: int | D3: int | E3: comment | F3: int
E4: 하늘 높이 솟은 신극 | F4: 1
E5: 바람의 땅에서 위세를 떨치다 | F5: 2
E6: 아름다운 여정: 프롤로그 | F6: 3
E7: 악령이여 물러가라 | F7: 4
E8: 즐거움을 찾아서 | F8: 5
E9: 통달한 | F9: 6
E10: 신세대 | F10: 7
C12: 스탯 달성
C13: 아이템 획득
C14: 재화 사용 | D14: 퀘스트 테이블 참조
C15: 광물 채집
C16: 등등

Sheet REWARD
A1: 아이디 | B1: 보상 그룹 | C1: 보상 아이템 ID | D1: 아이템 수량 | E1: 획득 확률 | F1: 명함 이름 | G1: 순서
A2: ID | B2: REWARD_GROUP | C2: ITEM_ID | D2: ITEM_COUNT | E2: ISRATE | F2: COMMENT | G2: SORT
A3: int | B3: int | C3: int | D3: int | E3: int | F3: comment | G3: int
F4: 하늘 높이 솟은 신극 | G4: 1
F5: 바람의 땅에서 위세를 떨치다 | G5: 2
F6: 아름다운 여정: 프롤로그 | G6: 3
F7: 악령이여 물러가라 | G7: 4
F8: 즐거움을 찾아서 | G8: 5
F9: 통달한 | G9: 6
F10: 신세대 | G10: 7
C12: 아이템 테이블 참조

Sheet NAMECARD_GRADE
A1: 아이디 | B1: 명함 등급 | C1: 필요 경험치 | D1: 누적 경험치 | E1: 명함 등급 옵션 그룹 | F1: 명함 등급 보상 그룹
A2: ID | B2: NAMECARD_GRADE | C2: NEED_EXP | D2: CUMULATIVE_EXP | E2: OPTION_GROUP | F2: REWARD_GROUP
A3: int | B3: int | C3: int64 | D3: int64 | E3: int | F3: int
A4: 1 | B4: 1
A5: 2 | B5: 2
A6: 3 | B6: 3
A7: 4 | B7: 4
A8: 5 | B8: 5
A9: 6 | B9: 6
A10: 7 | B10: 7
A11: 8 | B11: 8
A12: 9 | B12: 9
A13: 10 | B13: 10
A14: 11 | B14: 11
A15: 12 | B15: 12
... A27: 24 | B27: 24

Sheet STRING
A1: STRING_KEY | B1: DESC
A2: string | B2: string
