Workbook
Name AlertGetItem: #REF!
Name AlertGetItem_List: #REF!
Name Break: #REF!
Name Break_List: #REF!
Name Broadcast: #REF!
Name Broadcast_List: #REF!
Name CheckTradeRuby_List: #REF!
Name Enchant: #REF!
Name Enchant_List: #REF!
Name FixCreateSlot: #REF!
Name FixCreateSlot_List: #REF!
Name FixSlot: #REF!
Name FixSlot_List: #REF!
Name IncludeSealing: #REF!
Name IncludeSealing_List: #REF!
Name IncludeServerTransfer: #REF!
Name Is_UsedSkill: #REF!
Name Is_UsedSkill_List: #REF!
Name LockFunc: #REF!
Name LockFunc_List: #REF!
Name Main_Category: #REF!
Name Main_Category_List: #REF!
Name PetAutoSell: #REF!
Name PetAutoSell_List: #REF!
Name Sell: #REF!
Name Sell_List: #REF!
Name SetOperatorTool_List: #REF!
Name SetTrade_List: #REF!
Name Skill_Level_Ratio: #REF!
Name Sub_Category: #REF!
Name Sub_Category_List: #REF!
Name T_AutoSort: #REF!
Name T_AutoSort_List: #REF!
Name T_Equip: #REF!
Name T_Equip_List: #REF!
Name T_EquipSlot: #REF!
Name T_EquipSlot_List: #REF!
Name T_ExchangeCategory: #REF!
Name T_ExchangeCategory_List: #REF!
Name T_Goods: #REF!
Name T_Goods_List: #REF!
Name T_ItemGrade: #REF!
Name T_ItemGrade_List: #REF!
Name T_Job: #REF!
Name T_Job_List: #REF!
Name T_RandomBox: #REF!
Name T_RandomBox_List: #REF!
Name T_UiNumber: #REF!
Name T_UiNumber_List: #REF!
Name T_WeaponBone_L: #REF!
Name T_WeaponBone_L_List: #REF!
Name T_WeaponBone_R: #REF!
Name T_WeaponBone_R_List: #REF!
Name Throw: #REF!
Name Throw_List: #REF!
Name Trade: #REF!
Name Trade_List: #REF!
Name TypeGrowth: #REF!
Name TypeGrowth_List: #REF!
Name UsedData_List: #REF!

Sheet INFO
H3: 카드 기획 초안
C7: 1 | D7: 개요
E9: - 스텔라소라의 <레코드> 시스템, 쿠키런 : 모험의 탑의 <아티팩트> 시스템을 레퍼런스로 작성하였다.
D11: ① 획득 경로
E12: - 캐릭터 뽑기 시 카드가 포함되어 나오는 형태.
D14: ② 장착
E15: - 각 캐릭터마다 최대 3개의 카드를 장착할 수 있다. (메인 카드 최대 1개, 보조 카드 최대 2개 장착 가능)
E16: - 캐릭터 장비 장착 UI에 카드 장착 UI를 배치할 예정
D18: ③ 카드 옵션 구성
E19: - 1, 2, 3, 4, 5 희귀도의 카드가 존재하며, 희귀도마다 능력치에 차이가 있다.
G21: TYPE | K21: COMMENT
G22: 0 | K22: NONE
G23: 1 | K23: 일반
G24: 2 | K24: 레어
G25: 3 | K25: 에픽
G26: 4 | K26: 유니크
G27: 5 | K27: 레전더리
E29: - 카드는 기본 옵션 , 메인 옵션, 보조 옵션이 존재한다.
G31: TYPE | K31: COMMENT
G32: 0 | K32: NONE
G33: 1 | K33: 기본
G34: 2 | K34: 보조
G35: 3 | K35: 메인
F37: → 기본 옵션은 최대 2개가 존재할 수 있고, 낮은 등급의 카드(3단계 이하)는 1개만 존재한다.
G38: → 3단계 이하의 카드는 속성 능력치를 증가시키는 옵션이 붙지 않는다.
F39: → 최대 2개가 존재하는 기본 옵션의 경우, 둘 중 하나는 무조건 카드의 속성 타입을 증가시키는 옵션이어야 한다.
G40: ex) 옵션1: 공격력, 옵션2: 여름 속성 피해 보너스
E42: - 기본 옵션은 해당 카드를 장착했을 때 옵션이 항상 발동한다.
E43: - 메인 옵션은 '메인 카드'에 장착했을 때 옵션이 발동되고, 보조 옵션은 '보조 카드'에 장착했을 때 옵션이 발동된다.
D45: ④ 성장 구조
E46: - 성장(LEVEL): 성장 재료(게임 재화 + 카드)를 소모하여 카드 EXP를 획득하여 레벨 상승을 할 수 있다.
F47: - 카드 성장(레벨 업) 시 높아지는 옵션: 기본, 서브
F48: - 현 돌파 등급의 '등급 내 최대 레벨'을 넘길 수 없다. (초과 시 돌파 필요)
G49: → 같은 돌파 등급 내에서 EXP 값 초과 시, 이월 처리
G50: → 같은 돌파 등급 내에서 등급 내 최대 레벨일 경우 초과하는 EXP 값은 절삭 처리
F52: - 등급이 높은 카드일수록 재료로 사용할 때 경험치 획득량이 높다.
F53: - 강화된 카드를 강화 재료로 사용할 때 강화로 얻은 경험치의 80%를 얻을 수 있다.
G54: → (강화로 얻은 경험치의 80%)+(카드의 기본 경험치)
E56: - 돌파(AWAKE): 특정 레벨 구간의 상한 값에 도달하면, 지정 아이템을 소모하여 돌파할 수 있고, 추가적인 카드 성장이 가능하다.
F57: - 별 0개부터 최대 6개까지 도달할 수 있다.
...

Sheet UI_INFO
C4: 1 | D4: 카드 진입 경로
C40: 2 | D40: 카드 목록
AU43: ① 카테고리 탭
AV44: - 캐릭터 관련 2개 리소스(캐릭터, 카드)를 한 화면에서 전환하여 탐색과 관리의 효율을 높인다.
AV46: 1-1 구성
AW47: - 아이콘과 텍스트로 카테고리가 구성되어 있다.
AW48: - 순서는 조사단원 → 카드 순서 고정한다.
AW49: - 선택한 탭은 활성화 상태가 되며, 비활성 탭과 컬러의 차이를 둔다.
AW50: - 선택 탭의 기본 값은 '조사단원' 이다.
AY54: <활성> | BE54: <비활성>
AV56: 1-2 캐싱 정책
AW57: - 앱 재시작 및 화면 재진입 시 기본 값인 '조사단원'으로 초기화
AX58: → 스크롤 위치는 초기화
AU61: ② 필터
AV62: - 고급 정렬 조건을 설정할 수 있는 탭과, 오름차순과 내림차순을 정하는 탭이 존재한다.
AV63: - '필터 설정' 버튼 터치 시 팝업 창이 출력된다.
AU71: ③ 필터 설정 팝업 창
AV72: - X 버튼 혹은 팝업 창 이외의 화면 터치 시 팝업 창이 종료된다.
AV73: - 확인 버튼 터치 시 필터 설정을 저장하며 팝업 창이 종료된다.
AV75: ① 초기화 버튼 및 초기값
AW76: - 초기화 버튼 터치 시 필터 설정이 초기화 된다. 하기 설정 초기값 참고
AW78: - 필터 설정 초기값:
AX79: * 첫 진입 시 기본 값: 정렬 영역 = 레벨 순
AX80: - 첫 진입 시 기본 값: 필터 영역 = 탭 전부 비활성 처리(미선택 상태)
AX81: * 앱 재시작 및 화면 재진입 시 마지막으로 선택한 값을 유지
AV83: ② 정렬 영역
AW84: - 정렬 영역의 버튼은 한 번에 하나만 선택할 수 있다.
AZ86: 필터 타입 | BD86: 내용 | BR86: 순서
AZ87: 레벨 순 | BD87: 카드 레벨 값에 따라 순서 정렬 | BR87: 1
AZ88: ★ 개수 순 | BD88: 카드 ★ 개수를 판단하여 순서 정렬 | BR88: 2
AZ89: 등급 순 | BD89: 카드의 등급을 판단하여 순서 정렬 | BR89: 3
AZ90: 이름 순 | BD90: 카드의 이름 순서대로 정렬 | BR90: 4
AZ91: 획득 시기 순 | BD91: 카드 목록 등록 시각을 기준으로 정렬 | BR91: 5
AW92: 즐겨찾기 | BD92: ON: 즐겨찾기 표시된 카드 우선 정렬 | BQ92: 6
BD93: OFF: 즐겨찾기 표시하지 않은 카드 우선 정렬
AW96: - 필터 타입의 값이 동률일 경우:
AX97: 필터 타입의 순서(SORT)로 보조 정렬 처리한다.
AV99: ③ 필터 영역
AW100: - 등급, 속성, ★ 개수로 나뉘어져 있다.
AW101: - 필터는 다중 선택이 가능하며, 하나도 선택하지 않았을 경우 전체로 간주한다.
...

Sheet DATA
E4: 데이터 구조도
C8: CARD | E8: LEVEL_GROUP
C9: ID | E9: ID
C10: ATTIRUBUTE_TYPE | E10: LEVEL_GROUP
C11: RARITY | E11: CARD_LEVEL
C12: LEVEL_GROUP | E12: IS_AWAKE
C13: AWAKE_GROUP | E13: AWAKE_LEVEL
C14: MAX_LEVEL | E14: DEFAULT_OPTION_ID
C15: CARD_NAME | E15: SUB_OPTION_ID
C16: CARD_IMAGE
C21: CARD_EXP_INFO | E21: AWAKE_GROUP
C22: ID | E22: ID
C23: RARITY | E23: AWAKE_GROUP
C24: CARD_LEVEL | E24: AWAKE_LEVEL
C25: NEED_EXP | E25: MAX_LEVEL
C26: CUMULATIVE_EXP | E26: ITEM_ID_1
C27: DEFAULT_MATERIAL_EXP | E27: PARAM_1
C28: NEED_GOLD | E28: ITEM_ID_2
C29: CUMULATIVE_GOLD | E29: PARAM_2
E30: MAIN_OPTION_ID
B38: 속성 타입 | F38: 희귀도
B39: 값 | C39: 설명 | F39: 값 | G39: 설명
B40: 0 | C40: NONE | F40: 0 | G40: NONE
B41: 1 | C41: 봄 | F41: 1 | G41: 일반
B42: 2 | C42: 여름 | F42: 2 | G42: 레어
B43: 3 | C43: 가을 | F43: 3 | G43: 에픽
B44: 4 | C44: 겨울 | F44: 4 | G44: 유니크
F45: 5 | G45: 레전더리
B48: 비율 여부
B49: 값 | C49: 설명
B50: 0 | C50: 정수
B51: 1 | C51: 비율

Sheet CARD
A1: 아이디 | B1: 카드 이름 | C1: 속성 타입 | D1: 희귀도 | E1: 성장 그룹 | F1: 돌파 그룹 | G1: 최대 레벨 | H1: 최대 돌파 단계 | I1: 카드 이름 | J1: 카드 이미지
A2: ID | B2: COMMENT | C2: ATTRIBUTE_TYPE | D2: RARITY | E2: LEVEL_GROUP | F2: AWAKE_GROUP | G2: MAX_LEVEL | H2: MAX_AWAKE | I2: CARD_NAME | J2: CARD_IMAGE
A3: int | B3: comment | C3: int | D3: int | E3: int | F3: int | G3: int | H3: int | I3: string | J3: string
A4: =10000+C4*1000+D4*100+COUNTIFS($C$4:C4,C4,$D$4:D4,D4) -> 11101 | B4: 카드 이름 1 | C4: 1 | D4: 1 | E4: =RIGHT(A4,4) -> 1101 | F4: =RIGHT(A4,4) -> 1101 | G4: 70 | H4: 6 | I4: ="CARD_NAME_"&A4 -> CARD_NAME_11101 | J4: ="CARD_IMAGE_"&A4 -> CARD_IMAGE_11101
A5: =10000+C5*1000+D5*100+COUNTIFS($C$4:C5,C5,$D$4:D5,D5) -> 12201 | B5: 카드 이름 2 | C5: 2 | D5: 2 | E5: =RIGHT(A5,4) -> 2201 | F5: =RIGHT(A5,4) -> 2201 | G5: 70 | H5: 6 | I5: ="CARD_NAME_"&A5 -> CARD_NAME_12201 | J5: ="CARD_IMAGE_"&A5 -> CARD_IMAGE_12201
A6: =10000+C6*1000+D6*100+COUNTIFS($C$4:C6,C6,$D$4:D6,D6) -> 13301 | B6: 카드 이름 3 | C6: 3 | D6: 3 | E6: =RIGHT(A6,4) -> 3301 | F6: =RIGHT(A6,4) -> 3301 | G6: 70 | H6: 6 | I6: ="CARD_NAME_"&A6 -> CARD_NAME_13301 | J6: ="CARD_IMAGE_"&A6 -> CARD_IMAGE_13301
A7: =10000+C7*1000+D7*100+COUNTIFS($C$4:C7,C7,$D$4:D7,D7) -> 14401 | B7: 카드 이름 4 | C7: 4 | D7: 4 | E7: =RIGHT(A7,4) -> 4401 | F7: =RIGHT(A7,4) -> 4401 | G7: 70 | H7: 6 | I7: ="CARD_NAME_"&A7 -> CARD_NAME_14401 | J7: ="CARD_IMAGE_"&A7 -> CARD_IMAGE_14401
A8: =10000+C8*1000+D8*100+COUNTIFS($C$4:C8,C8,$D$4:D8,D8) -> 11501 | B8: 카드 이름 5 | C8: 1 | D8: 5 | E8: =RIGHT(A8,4) -> 1501 | F8: =RIGHT(A8,4) -> 1501 | G8: 70 | H8: 6 | I8: ="CARD_NAME_"&A8 -> CARD_NAME_11501 | J8: ="CARD_IMAGE_"&A8 -> CARD_IMAGE_11501
A9: =10000+C9*1000+D9*100+COUNTIFS($C$4:C9,C9,$D$4:D9,D9) -> 12202 | B9: 카드 이름 6 | C9: 2 | D9: 2 | E9: =RIGHT(A9,4) -> 2202 | F9: =RIGHT(A9,4) -> 2202 | G9: 70 | H9: 6 | I9: ="CARD_NAME_"&A9 -> CARD_NAME_12202 | J9: ="CARD_IMAGE_"&A9 -> CARD_IMAGE_12202
A10: =10000+C10*1000+D10*100+COUNTIFS($C$4:C10,C10,$D$4:D10,D10) -> 13101 | B10: 카드 이름 7 | C10: 3 | D10: 1 | E10: =RIGHT(A10,4) -> 3101 | F10: =RIGHT(A10,4) -> 3101 | G10: 70 | H10: 6 | I10: ="CARD_NAME_"&A10 -> CARD_NAME_13101 | J10: ="CARD_IMAGE_"&A10 -> CARD_IMAGE_13101

Sheet LEVEL_GROUP
A1: 아이디 | B1: 성장 그룹 | C1: 카드 레벨 단계 | D1: 돌파 여부 | E1: 돌파 등급 | F1: 기본 옵션 ID | G1: 서브 옵션 ID | H1: 카드 이름
A2: ID | B2: LEVEL_GROUP | C2: CARD_LEVEL | D2: IS_AWAKE | E2: AWAKE_LEVEL | F2: DEFAULT_OPTION_ID | G2: SUB_OPTION_ID | H2: COMMENT
A3: int | B3: int | C3: int | D3: int | E3: int | F3: int | G3: int | H3: comment
A4: =1000000+B4*100+C4 -> 1110101 | B4: =RIGHT(INDEX(CARD!$A$4:$A$10,MATCH(LEVEL_GROUP!H4,CARD!$B$4:$B$10,0)),4) -> 1101 | C4: 1 | D4: 0 | E4: 0 | H4: 카드 이름 1
A5: =1000000+B5*100+C5 -> 1110102 | B5: =RIGHT(INDEX(CARD!$A$4:$A$10,MATCH(LEVEL_GROUP!H5,CARD!$B$4:$B$10,0)),4) -> 1101 | C5: 2 | D5: 0 | E5: 0 | H5: 카드 이름 1
A6: =1000000+B6*100+C6 -> 1110103 | B6: =RIGHT(INDEX(CARD!$A$4:$A$10,MATCH(LEVEL_GROUP!H6,CARD!$B$4:$B$10,0)),4) -> 1101 | C6: 3 | D6: 0 | E6: 0 | H6: 카드 이름 1
A7: =1000000+B7*100+C7 -> 1110104 | B7: =RIGHT(INDEX(CARD!$A$4:$A$10,MATCH(LEVEL_GROUP!H7,CARD!$B$4:$B$10,0)),4) -> 1101 | C7: 4 | D7: 0 | E7: 0 | H7: 카드 이름 1
A8: =1000000+B8*100+C8 -> 1110105 | B8: =RIGHT(INDEX(CARD!$A$4:$A$10,MATCH(LEVEL_GROUP!H8,CARD!$B$4:$B$10,0)),4) -> 1101 | C8: 5 | D8: 0 | E8: 0 | H8: 카드 이름 1
A9: =1000000+B9*100+C9 -> 1110106 | B9: =RIGHT(INDEX(CARD!$A$4:$A$10,MATCH(LEVEL_GROUP!H9,CARD!$B$4:$B$10,0)),4) -> 1101 | C9: 6 | D9: 0 | E9: 0 | H9: 카드 이름 1
A10: =1000000+B10*100+C10 -> 1110107 | B10: =RIGHT(INDEX(CARD!$A$4:$A$10,MATCH(LEVEL_GROUP!H10,CARD!$B$4:$B$10,0)),4) -> 1101 | C10: 7 | D10: 0 | E10: 0 | H10: 카드 이름 1
A11: =1000000+B11*100+C11 -> 1110108 | B11: =RIGHT(INDEX(CARD!$A$4:$A$10,MATCH(LEVEL_GROUP!H11,CARD!$B$4:$B$10,0)),4) -> 1101 | C11: 8 | D11: 0 | E11: 0 | H11: 카드 이름 1
A12: =1000000+B12*100+C12 -> 1110109 | B12: =RIGHT(INDEX(CARD!$A$4:$A$10,MATCH(LEVEL_GROUP!H12,CARD!$B$4:$B$10,0)),4) -> 1101 | C12: 9 | D12: 0 | E12: 0 | H12: 카드 이름 1
A13: =1000000+B13*100+C13 -> 1110110 | B13: =RIGHT(INDEX(CARD!$A$4:$A$10,MATCH(LEVEL_GROUP!H13,CARD!$B$4:$B$10,0)),4) -> 1101 | C13: 10 | D13: 1 | E13: 0 | H13: 카드 이름 1
A14: =1000000+B14*100+C14 -> 1110111 | B14: =RIGHT(INDEX(CARD!$A$4:$A$10,MATCH(LEVEL_GROUP!H14,CARD!$B$4:$B$10,0)),4) -> 1101 | C14: 11 | D14: 0 | E14: 1 | H14: 카드 이름 1
A15: =1000000+B15*100+C15 -> 1110112 | B15: =RIGHT(INDEX(CARD!$A$4:$A$10,MATCH(LEVEL_GROUP!H15,CARD!$B$4:$B$10,0)),4) -> 1101 | C15: 12 | D15: 0 | E15: 1 | H15: 카드 이름 1
... A73: =1000000+B73*100+C73 -> 1110170 | B73: =RIGHT(INDEX(CARD!$A$4:$A$10,MATCH(LEVEL_GROUP!H73,CARD!$B$4:$B$10,0)),4) -> 1101 | C73: 70 | D73: 1 | E73: 6 | H73: 카드 이름 1

Sheet AWAKE_GROUP
A1: 아이디 | B1: 돌파 그룹 | C1: 돌파 등급 | D1: 등급 내 최대 레벨 | E1: 아이템 아이디_1 | F1: 값_1 | G1: 아이템 아이디_2 | H1: 값_2 | I1: 메인 옵션 ID | J1: 카드 이름
A2: ID | B2: AWAKE_GROUP | C2: AWAKE_LEVEL | D2: MAX_LEVEL | E2: ITEM_ID_1 | F2: PARAM_1 | G2: ITEM_ID_2 | H2: PARAM_2 | I2: MAIN_OPTION_ID | J2: COMMENT
A3: int | B3: int | C3: int | D3: int | E3: int | F3: int | G3: int | H3: int | I3: int | J3: comment
A4: =100000+B4*10+C4 -> 111011 | B4: =RIGHT(INDEX(CARD!$A$4:$A$10,MATCH(AWAKE_GROUP!J4,CARD!$B$4:$B$10,0)),4) -> 1101 | C4: 1 | D4: 20 | J4: 카드 이름 1
A5: =100000+B5*10+C5 -> 111012 | B5: =RIGHT(INDEX(CARD!$A$4:$A$10,MATCH(AWAKE_GROUP!J5,CARD!$B$4:$B$10,0)),4) -> 1101 | C5: 2 | D5: 30 | J5: 카드 이름 1
A6: =100000+B6*10+C6 -> 111013 | B6: =RIGHT(INDEX(CARD!$A$4:$A$10,MATCH(AWAKE_GROUP!J6,CARD!$B$4:$B$10,0)),4) -> 1101 | C6: 3 | D6: 40 | J6: 카드 이름 1
A7: =100000+B7*10+C7 -> 111014 | B7: =RIGHT(INDEX(CARD!$A$4:$A$10,MATCH(AWAKE_GROUP!J7,CARD!$B$4:$B$10,0)),4) -> 1101 | C7: 4 | D7: 50 | J7: 카드 이름 1
A8: =100000+B8*10+C8 -> 111015 | B8: =RIGHT(INDEX(CARD!$A$4:$A$10,MATCH(AWAKE_GROUP!J8,CARD!$B$4:$B$10,0)),4) -> 1101 | C8: 5 | D8: 60 | J8: 카드 이름 1
A9: =100000+B9*10+C9 -> 111016 | B9: =RIGHT(INDEX(CARD!$A$4:$A$10,MATCH(AWAKE_GROUP!J9,CARD!$B$4:$B$10,0)),4) -> 1101 | C9: 6 | D9: 70 | J9: 카드 이름 1
A10: =100000+B10*10+C10 -> 122011 | B10: =RIGHT(INDEX(CARD!$A$4:$A$10,MATCH(AWAKE_GROUP!J10,CARD!$B$4:$B$10,0)),4) -> 2201 | C10: 1 | D10: 20 | J10: 카드 이름 2
A11: =100000+B11*10+C11 -> 122012 | B11: =RIGHT(INDEX(CARD!$A$4:$A$10,MATCH(AWAKE_GROUP!J11,CARD!$B$4:$B$10,0)),4) -> 2201 | C11: 2 | D11: 30 | J11: 카드 이름 2
A12: =100000+B12*10+C12 -> 122013 | B12: =RIGHT(INDEX(CARD!$A$4:$A$10,MATCH(AWAKE_GROUP!J12,CARD!$B$4:$B$10,0)),4) -> 2201 | C12: 3 | D12: 40 | J12: 카드 이름 2
A13: =100000+B13*10+C13 -> 122014 | B13: =RIGHT(INDEX(CARD!$A$4:$A$10,MATCH(AWAKE_GROUP!J13,CARD!$B$4:$B$10,0)),4) -> 2201 | C13: 4 | D13: 50 | J13: 카드 이름 2
A14: =100000+B14*10+C14 -> 122015 | B14: =RIGHT(INDEX(CARD!$A$4:$A$10,MATCH(AWAKE_GROUP!J14,CARD!$B$4:$B$10,0)),4) -> 2201 | C14: 5 | D14: 60 | J14: 카드 이름 2
A15: =100000+B15*10+C15 -> 122016 | B15: =RIGHT(INDEX(CARD!$A$4:$A$10,MATCH(AWAKE_GROUP!J15,CARD!$B$4:$B$10,0)),4) -> 2201 | C15: 6 | D15: 70 | J15: 카드 이름 2
... A45: =100000+B45*10+C45 -> 131016 | B45: =RIGHT(INDEX(CARD!$A$4:$A$10,MATCH(AWAKE_GROUP!J45,CARD!$B$4:$B$10,0)),4) -> 3101 | C45: 6 | D45: 70 | J45: 카드 이름 7

Sheet CARD_EXP_INFO
A1: 아이디 | B1: 카드 등급 | C1: 카드 레벨 단계 | D1: 필요 경험치 | E1: 누적 경험치 | F1: 기본 재료 경험치 값 | G1: 필요 골드 | H1: 누적 골드
A2: ID | B2: RARITY | C2: CARD_LEVEL | D2: NEED_EXP | E2: CUMULATIVE_EXP | F2: DEFAULT_MATERIAL_EXP | G2: NEED_GOLD | H2: CUMULATIVE_GOLD
A3: int | B3: int | C3: int | D3: int64 | E3: int64 | F3: int | G3: int64 | H3: int64
A4: =B4*100+C4 -> 101 | B4: 1 | C4: 1 | D4: 300 | E4: 300 | F4: =ROUNDDOWN(E4*80%,0) -> 240
A5: =B5*100+C5 -> 102 | B5: 1 | C5: 2 | D5: =ROUND(D4+72.5,0) -> 373 | E5: =D5+E4 -> 673 | F5: =ROUNDDOWN(E5*80%,0) -> 538
A6: =B6*100+C6 -> 103 | B6: 1 | C6: 3 | D6: =ROUND(D5+72.5,0) -> 446 | E6: =D6+E5 -> 1119 | F6: =ROUNDDOWN(E6*80%,0) -> 895
A7: =B7*100+C7 -> 104 | B7: 1 | C7: 4 | D7: =ROUND(D6+72.5,0) -> 519 | E7: =D7+E6 -> 1638 | F7: =ROUNDDOWN(E7*80%,0) -> 1310
A8: =B8*100+C8 -> 105 | B8: 1 | C8: 5 | D8: =ROUND(D7+72.5,0) -> 592 | E8: =D8+E7 -> 2230 | F8: =ROUNDDOWN(E8*80%,0) -> 1784
A9: =B9*100+C9 -> 106 | B9: 1 | C9: 6 | D9: =ROUND(D8+72.5,0) -> 665 | E9: =D9+E8 -> 2895 | F9: =ROUNDDOWN(E9*80%,0) -> 2316
A10: =B10*100+C10 -> 107 | B10: 1 | C10: 7 | D10: =ROUND(D9+72.5,0) -> 738 | E10: =D10+E9 -> 3633 | F10: =ROUNDDOWN(E10*80%,0) -> 2906
A11: =B11*100+C11 -> 108 | B11: 1 | C11: 8 | D11: =ROUND(D10+72.5,0) -> 811 | E11: =D11+E10 -> 4444 | F11: =ROUNDDOWN(E11*80%,0) -> 3555
A12: =B12*100+C12 -> 109 | B12: 1 | C12: 9 | D12: =ROUND(D11+72.5,0) -> 884 | E12: =D12+E11 -> 5328 | F12: =ROUNDDOWN(E12*80%,0) -> 4262
A13: =B13*100+C13 -> 110 | B13: 1 | C13: 10 | D13: =ROUND(D12+72.5,0) -> 957 | E13: =D13+E12 -> 6285 | F13: =ROUNDDOWN(E13*80%,0) -> 5028
A14: =B14*100+C14 -> 111 | B14: 1 | C14: 11 | D14: =ROUND(D13+72.5,0) -> 1030 | E14: =D14+E13 -> 7315 | F14: =ROUNDDOWN(E14*80%,0) -> 5852
A15: =B15*100+C15 -> 112 | B15: 1 | C15: 12 | D15: =ROUND(D14+72.5,0) -> 1103 | E15: =D15+E14 -> 8418 | F15: =ROUNDDOWN(E15*80%,0) -> 6734
A16: =B16*100+C16 -> 113 | B16: 1 | C16: 13 | D16: =ROUND(D15+72.5,0) -> 1176 | E16: =D16+E15 -> 9594 | F16: =ROUNDDOWN(E16*80%,0) -> 7675
... A19: =B19*100+C19 -> 116 | B19: 1 | C19: 16 | D19: =ROUND(D18+72.5,0) -> 1395 | E19: =D19+E18 -> 13560 | F19: =ROUNDDOWN(E19*80%,0) -> 10848
A20: =B20*100+C20 -> 117 | B20: 1 | C20: 17
A21: =B21*100+C21 -> 118 | B21: 1 | C21: 18
A22: =B22*100+C22 -> 119 | B22: 1 | C22: 19
A23: =B23*100+C23 -> 120 | B23: 1 | C23: 20
A24: =B24*100+C24 -> 121 | B24: 1 | C24: 21
A25: =B25*100+C25 -> 122 | B25: 1 | C25: 22
A26: =B26*100+C26 -> 123 | B26: 1 | C26: 23
A27: =B27*100+C27 -> 124 | B27: 1 | C27: 24
A28: =B28*100+C28 -> 125 | B28: 1 | C28: 25
A29: =B29*100+C29 -> 126 | B29: 1 | C29: 26
A30: =B30*100+C30 -> 127 | B30: 1 | C30: 27
A31: =B31*100+C31 -> 128 | B31: 1 | C31: 28
... A353: =B353*100+C353 -> 570 | B353: 5 | C353: 70

Sheet OPTION
A1: 아이디 | B1: 옵션 그룹 | C1: 옵션 타입 | D1: 옵션 비율 | E1: 옵션 값 | F1: 옵션 내용 | G1: 칭호 이름
A2: ID | B2: OPTION_GROUP | C2: OPTION_TYPE | D2: ISRATE | E2: OPTION_VALUE | F2: COMMENT | G2: COMMENT
A3: int | B3: int | C3: int | D3: int | E3: int | F3: comment | G3: comment
A4: =100000+C4*100+COUNT($B$4:B4) -> 100101 | B4: 1 | C4: 1 | D4: 0 | E4: 10 | F4: 생명력 +10 | G4: 하늘 높이 솟은 신극
A5: =100000+C5*100+COUNT($B$4:B5) -> 100102 | B5: 1 | C5: 1 | D5: 0 | E5: 10 | F5: 치유력 +10 | G5: 하늘 높이 솟은 신극
A6: =100000+C6*100+COUNT($B$4:B6) -> 100103 | B6: 1 | C6: 1 | D6: 1 | E6: 100 | F6: 치명타 확률 +1% | G6: 하늘 높이 솟은 신극
A7: =100000+C7*100+COUNT($B$4:B7) -> 100204 | B7: 2 | C7: 2 | D7: 0 | G7: 바람의 땅에서 위세를 떨치다
A8: =100000+C8*100+COUNT($B$4:B8) -> 100305 | B8: 3 | C8: 3 | G8: 아름다운 여정: 프롤로그
A9: =100000+C9*100+COUNT($B$4:B9) -> 100406 | B9: 4 | C9: 4 | G9: 악령이여 물러가라
A10: =100000+C10*100+COUNT($B$4:B10) -> 100507 | B10: 5 | C10: 5 | G10: 즐거움을 찾아서
A11: =100000+C11*100+COUNT($B$4:B11) -> 100608 | B11: 6 | C11: 6 | G11: 통달한
A12: =100000+C12*100+COUNT($B$4:B12) -> 100709 | B12: 7 | C12: 7 | G12: 신세대
A13: =100000+C13*100+COUNT($B$4:B13) -> 100810 | B13: 8 | C13: 8 | G13: 자주 아픈
A14: =100000+C14*100+COUNT($B$4:B14) -> 100911 | B14: 9 | C14: 9 | G14: 불운한
A15: =100000+C15*100+COUNT($B$4:B15) -> 101012 | B15: 10 | C15: 10 | G15: 훌륭하게 준비된
