Workbook

Sheet INFO
H3: 캐릭터 기획 초안
C7: 1 | D7: 개요
D9: - 캐릭터 시스템의 기능 및 규칙을 설명한다.
D11: ① 캐릭터 타입
E12: 1-1 캐릭터 속성
F13: - 캐릭터의 속성은 봄, 여름, 가을 겨울의 속성을 가진다
F14: - 각 속성별로 상성이 존재하며, 상성에 따라 공격 및 방어력이 달라진다.
H16: 속성 | K16: 내용
H17: 1 | K17: 봄
H18: 2 | K18: 여름
H19: 3 | K19: 가을
H20: 4 | K20: 겨울
E22: 1-2 캐릭터 등급
F23: - 캐릭터 뽑기에서 출현하는 등급은 1, 2, 3등급만 존재한다.
G24: → 4, 5, 6등급은 돌파로 달성해야 한다.
F25: - 캐릭터의 등급은 최대 ★6까지 존재하고, 각 캐릭터의 영혼석(조각)과 게임 재화를 통하여 돌파하는 시스템이다.
H27: 등급 | L27: 필요 영혼석 개수
H28: 1 | L28: 30
H29: 2 | L29: 50
H30: 3 | L30: 80
H31: 4 | L31: 100
H32: 5 | L32: 120
H33: 6 | L33: 0
F35: - 태생이 ★1인 캐릭터가 ★6이 되려면 영혼석이 총 380개 필요하며, 태생이 ★3인 캐릭터가 ★6이 되려면 영혼석이 총 300개 필요하다
E37: 1-3 캐릭터 역할군
F38: - 각 캐릭터는 역할군이 존재한다.
F39: - 착용할 수 있는 장비의 타입과는 별개이다.
H41: 속성 | K41: 내용 | M41: 상세 설명
H42: 1 | K42: 딜러 | M42: 높은 공격력과 치명타로 적에게 강한 피해를 주는 역할군
H43: 2 | K43: 탱커 | M43: 높은 HP와 회피력, 방어력을 갖고있는 역할군
H44: 3 | K44: 힐러 | M44: 아군을 치유하는 역할군
H45: 4 | K45: 서포터 | M45: 아군 혹은 적에게 버프/디버프를 주는 역할군
D48: ② 캐릭터 레벨 성장
E49: - 캐릭터의 최대 레벨은 계정(조사단장)의 레벨을 초과할 수 없다.
E50: - 캐릭터의 레벨은 경험치 성장 재료(ITEM)와 게임 재화로 성장시킬 수 있다.
E51: - 캐릭터의 레벨을 성장시킬 때마다 일부 STATUS 값이 상승한다. (각 역할군에 어울리는 스탯이 더 많이 상승)
F52: ex) 딜러 역할군 → 공격력 25, 치명타 피해 15, HP 5 상승
F53: ex) 탱커 역할군 → 공격력 5, 방어력 20, HP 15 상승
D55: ③ 스킬
E56: - 스킬은 기본 스킬, 메인 스킬, 서브 스킬, 필살기 스킬이 존재한다.
...

Sheet DATA
F4: 데이터 구조도
C8: SPEECH | E8: CHARACTER | G8: CHARACTER_SKILL | I8: AFFECTION_GAIN
C9: ID | E9: ID | G9: ID | I9: ID
C10: SPEECH_GROUP | E10: ATTRIBUTE_TYPE | G10: CHARACTER_SKILL_GROUP | I10: AFFECTION_GAIN_TYPE
C11: SPEECH_TYPE | E11: BASE_RARITY | G11: CHARACTER_SKILL_SUB_GROUP | I11: AFFECTION_GAIN_PARAM
C12: SPEECH_NAME | E12: MAX_RARITY | G12: SKILL_GROUP | I12: DEFAULT_AFFECTION_PARAM
C13: CHARACTER_AUDIO | E13: ROLE | G13: UNLOCK_AWAKE_LEVEL
E14: FACTION_TYPE | G14: SUB_GROUP_NAME
E15: EQUIP_TYPE
E16: MAX_LEVEL
C17: AFFECTION_EXP_INFO | E17: MAX_AFFECTION
C18: ID | E18: CHARACTER_SKILL_GROUP | G18: AFFECTION_ITEM
C19: AFFECTION_LEVEL | E19: CHARACTER_EXP_GROUP | G19: ID
C20: NEED_AFFECTION_EXP | E20: AWAKE_GROUP | G20: AFFECTION_ITEM_GROUP
C21: STATUS_ID | E21: AFFECTION_ITEM_GROUP | G21: RARITY
E22: AFFECTION_PREF_GROUP | G22: NEED_AFFECTION_LEVEL
E23: SPEECH_GROUP | G23: STATUS_ID
E24: CHARACTER_PIECE_ID | G24: CHARACTER_SKILL_GROUP
C25: AWAKE_GROUP | E25: CHARACTER_NAME | G25: AFFECTION_ITEM_NAME
C26: ID | E26: CHARACTER_IMAGE | G26: AFFECTION_ITEM_IMAGE
C27: AWAKE_GROUP | E27: CHARACTER_DESC | G27: AFFECTION_ITEM_DESC
C28: AWAKE_LEVEL
C29: NEED_PIECE_COUNT
C30: NEED_GOLD | E30: CHARACTER_STATUS | G30: CHARACTER_EXP
C31: STATUS_ID | E31: ID | G31: ID
C32: MAX_AFFECTION_LEVEL | E32: HP | G32: CHARACTER_EXP_GROUP
E33: ATTACK | G33: CHARACTER_LEVEL
E34: DEFFENCE | G34: NEED_EXP
E35: CRITICAL_RATE | G35: NEED_GOLD
C36: AFFECTION_PREF | E36: CRITICAL_DAMAGE | G36: ATTACK
C37: ID | E37: SPRING_INCREASE | G37: DEFFENCE
C38: AFFECTION_PREF_GROUP | E38: SUMMER_INCREASE | G38: HP
C39: ITEM_ID | E39: AUTUMN_INCREASE
C40: PREFERENCE_TYPE | E40: WINTER_INCREASE
C41: MULTIPLIER_AFFECTION_PARAM | E41: SPRING_RESISTANCE
E42: SUMMER_RESISTANCE
E43: AUTUMN_RESISTANCE
E44: WINTER_RESISTANCE
B52: CHARACTER
B54: 속성 타입 | F54: 캐릭터 기본 등급
...

Sheet CHARACTER
A1: 아이디 | B1: 캐릭터 이름 | C1: 속성 타입 | D1: 기본 등급 | E1: 최대 등급 | F1: 역할군 | G1: 세력 타입 | H1: 장비 타입 | I1: 최대 레벨 | J1: 최대 호감도 | K1: 캐릭터 스킬 그룹 | L1: 캐릭터 성장 그룹 | M1: 돌파 그룹 | N1: 애용품 그룹 | O1: 선호 선물 그룹 | P1: 대사 그룹 | Q1: 캐릭터 조각 ID | R1: 캐릭터 이름 | S1: 캐릭터 이미지 | T1: 캐릭터 설명
A2: ID | B2: COMMENT | C2: ATTRIBUTE_TYPE | D2: BASE_RARITY | E2: MAX_RARITY | F2: ROLE | G2: FACTION_TYPE | H2: EQUIP_TYPE | I2: MAX_LEVEL | J2: MAX_AFFECTION | K2: CHARACTER_SKILL_GROUP | L2: CHARACTER_EXP_GROUP | M2: AWAKE_GROUP | N2: AFFECTION_ITEM_GROUP | O2: AFFECTION_PREF_GROUP | P2: SPEECH_GROUP | Q2: CHARACTER_PIECE_ID | R2: CHARACTER_NAME | S2: CHARACTER_IMAGE | T2: CHARACTER_DESC
A3: int | B3: comment | C3: int | D3: int | E3: int | F3: int | G3: int | H3: int | I3: int | J3: int | K3: int | L3: int | M3: int | N3: int | O3: int | P3: int | Q3: int | R3: string | S3: string | T3: string
A4: =100000+C4*10000+D4*1000+F4*100+COUNTIFS($C$4:C4,C4,$D$4:D4,D4) -> 111101 | B4: 캐릭터 이름 1 | C4: 1 | D4: 1 | E4: 6 | F4: 1 | G4: 0 | H4: 0 | I4: 100 | J4: =IF(D4=3,20,10) -> 10 | K4: =RIGHT(A4,4) -> 1101 | L4: =RIGHT(A4,4) -> 1101 | M4: =RIGHT(A4,4) -> 1101 | N4: =RIGHT(A4,4)+10000 -> 11101 | P4: 1 | R4: ="CHARACTER_NAME_"&A4 -> CHARACTER_NAME_111101 | S4: ="CHARACTER_IMAGE_"&A4 -> CHARACTER_IMAGE_111101 | T4: ="CHARACTER_DESC_"&A4 -> CHARACTER_DESC_111101
A5: =100000+C5*10000+D5*1000+F5*100+COUNTIFS($C$4:C5,C5,$D$4:D5,D5) -> 122201 | B5: 캐릭터 이름 2 | C5: 2 | D5: 2 | E5: 6 | F5: 2 | G5: 0 | H5: 0 | I5: 100 | J5: =IF(D5=3,20,10) -> 10 | K5: =RIGHT(A5,4) -> 2201 | L5: =RIGHT(A5,4) -> 2201 | M5: =RIGHT(A5,4) -> 2201 | N5: =RIGHT(A5,4)+10000 -> 12201 | P5: 1 | R5: ="CHARACTER_NAME_"&A5 -> CHARACTER_NAME_122201 | S5: ="CHARACTER_IMAGE_"&A5 -> CHARACTER_IMAGE_122201 | T5: ="CHARACTER_DESC_"&A5 -> CHARACTER_DESC_122201
A6: =100000+C6*10000+D6*1000+F6*100+COUNTIFS($C$4:C6,C6,$D$4:D6,D6) -> 133301 | B6: 캐릭터 이름 3 | C6: 3 | D6: 3 | E6: 6 | F6: 3 | G6: 0 | H6: 0 | I6: 100 | J6: =IF(D6=3,20,10) -> 20 | K6: =RIGHT(A6,4) -> 3301 | L6: =RIGHT(A6,4) -> 3301 | M6: =RIGHT(A6,4) -> 3301 | N6: =RIGHT(A6,4)+10000 -> 13301 | P6: 1 | R6: ="CHARACTER_NAME_"&A6 -> CHARACTER_NAME_133301 | S6: ="CHARACTER_IMAGE_"&A6 -> CHARACTER_IMAGE_133301 | T6: ="CHARACTER_DESC_"&A6 -> CHARACTER_DESC_133301
A7: =100000+C7*10000+D7*1000+F7*100+COUNTIFS($C$4:C7,C7,$D$4:D7,D7) -> 141401 | B7: 캐릭터 이름 4 | C7: 4 | D7: 1 | E7: 6 | F7: 4 | G7: 0 | H7: 0 | I7: 100 | J7: =IF(D7=3,20,10) -> 10 | K7: =RIGHT(A7,4) -> 1401 | L7: =RIGHT(A7,4) -> 1401 | M7: =RIGHT(A7,4) -> 1401 | N7: =RIGHT(A7,4)+10000 -> 11401 | P7: 1 | R7: ="CHARACTER_NAME_"&A7 -> CHARACTER_NAME_141401 | S7: ="CHARACTER_IMAGE_"&A7 -> CHARACTER_IMAGE_141401 | T7: ="CHARACTER_DESC_"&A7 -> CHARACTER_DESC_141401
A8: =100000+C8*10000+D8*1000+F8*100+COUNTIFS($C$4:C8,C8,$D$4:D8,D8) -> 112101 | B8: 캐릭터 이름 5 | C8: 1 | D8: 2 | E8: 6 | F8: 1 | G8: 0 | H8: 0 | I8: 100 | J8: =IF(D8=3,20,10) -> 10 | K8: =RIGHT(A8,4) -> 2101 | L8: =RIGHT(A8,4) -> 2101 | M8: =RIGHT(A8,4) -> 2101 | N8: =RIGHT(A8,4)+10000 -> 12101 | P8: 1 | R8: ="CHARACTER_NAME_"&A8 -> CHARACTER_NAME_112101 | S8: ="CHARACTER_IMAGE_"&A8 -> CHARACTER_IMAGE_112101 | T8: ="CHARACTER_DESC_"&A8 -> CHARACTER_DESC_112101
A9: =100000+C9*10000+D9*1000+F9*100+COUNTIFS($C$4:C9,C9,$D$4:D9,D9) -> 123201 | B9: 캐릭터 이름 6 | C9: 2 | D9: 3 | E9: 6 | F9: 2 | G9: 0 | H9: 0 | I9: 100 | J9: =IF(D9=3,20,10) -> 20 | K9: =RIGHT(A9,4) -> 3201 | L9: =RIGHT(A9,4) -> 3201 | M9: =RIGHT(A9,4) -> 3201 | N9: =RIGHT(A9,4)+10000 -> 13201 | P9: 1 | R9: ="CHARACTER_NAME_"&A9 -> CHARACTER_NAME_123201 | S9: ="CHARACTER_IMAGE_"&A9 -> CHARACTER_IMAGE_123201 | T9: ="CHARACTER_DESC_"&A9 -> CHARACTER_DESC_123201
A10: =100000+C10*10000+D10*1000+F10*100+COUNTIFS($C$4:C10,C10,$D$4:D10,D10) -> 133302 | B10: 캐릭터 이름 7 | C10: 3 | D10: 3 | E10: 6 | F10: 3 | G10: 0 | H10: 0 | I10: 100 | J10: =IF(D10=3,20,10) -> 20 | K10: =RIGHT(A10,4) -> 3302 | L10: =RIGHT(A10,4) -> 3302 | M10: =RIGHT(A10,4) -> 3302 | N10: =RIGHT(A10,4)+10000 -> 13302 | P10: 1 | R10: ="CHARACTER_NAME_"&A10 -> CHARACTER_NAME_133302 | S10: ="CHARACTER_IMAGE_"&A10 -> CHARACTER_IMAGE_133302 | T10: ="CHARACTER_DESC_"&A10 -> CHARACTER_DESC_133302
Q12: ITEM 테이블 참조

Sheet CHARACTER_STATUS
A1: 아이디 | B1: 체력 | C1: 공격력 | D1: 방어력 | E1: 치명타 확률 | F1: 치명타 피해 | G1: 코스트 회복력 | H1: 봄 속성 피해 | I1: 여름 속성 피해 | J1: 가을 속성 피해 | K1: 겨울 속성 피해 | L1: 봄 속성 저항력 | M1: 여름 속성 저항력 | N1: 가을 속성 저항력 | O1: 겨울 속성 저항력 | P1: #참조
A2: ID | B2: HP | C2: ATTACK | D2: DEFFENCE | E2: CRITICAL_RATE | F2: CRITICAL_DAMAGE | G2: SP_RECOVERY | H2: SPRING_INCREASE | I2: SUMMER_INCREASE | J2: AUTUMN_INCREASE | K2: WINTER_INCREASE | L2: SPRING_RESISTANCE | M2: SUMMER_RESISTANCE | N2: AUTUMN_RESISTANCE | O2: WINTER_RESISTANCE | P2: COMMENT
A3: int | B3: int | C3: int | D3: int | E3: float | F3: int | G3: int | H3: int | I3: int | J3: int | K3: int | L3: int | M3: int | N3: int | O3: int | P3: comment
A4: 111101 | B4: 10000 | C4: 500 | D4: 500 | E4: 0.1 | F4: 1 | G4: 1 | H4: 1 | I4: 1 | J4: 1 | K4: 1 | L4: 1 | M4: 1 | N4: 1 | O4: 1 | P4: 캐릭터 이름 1
A5: 122201 | B5: 10000 | C5: 500 | D5: 500 | E5: 0.1 | F5: 1 | G5: 1 | H5: 1 | I5: 1 | J5: 1 | K5: 1 | L5: 1 | M5: 1 | N5: 1 | O5: 1 | P5: 캐릭터 이름 1
A6: 133301 | B6: 10000 | C6: 500 | D6: 500 | E6: 0.1 | F6: 1 | G6: 1 | H6: 1 | I6: 1 | J6: 1 | K6: 1 | L6: 1 | M6: 1 | N6: 1 | O6: 1 | P6: 캐릭터 이름 1
A7: 141401 | B7: 10000 | C7: 500 | D7: 500 | E7: 0.1 | F7: 1 | G7: 1 | H7: 1 | I7: 1 | J7: 1 | K7: 1 | L7: 1 | M7: 1 | N7: 1 | O7: 1 | P7: 캐릭터 이름 1
A8: 112101 | B8: 10000 | C8: 500 | D8: 500 | E8: 0.1 | F8: 1 | G8: 1 | H8: 1 | I8: 1 | J8: 1 | K8: 1 | L8: 1 | M8: 1 | N8: 1 | O8: 1 | P8: 캐릭터 이름 1
A9: 123201 | B9: 10000 | C9: 500 | D9: 500 | E9: 0.1 | F9: 1 | G9: 1 | H9: 1 | I9: 1 | J9: 1 | K9: 1 | L9: 1 | M9: 1 | N9: 1 | O9: 1 | P9: 캐릭터 이름 1
A10: 133302 | B10: 10000 | C10: 500 | D10: 500 | E10: 0.1 | F10: 1 | G10: 1 | H10: 1 | I10: 1 | J10: 1 | K10: 1 | L10: 1 | M10: 1 | N10: 1 | O10: 1 | P10: 캐릭터 이름 1

Sheet CHARACTER_SKILL
A1: 아이디 | B1: 캐릭터 스킬 그룹 | C1: 서브 그룹 | D1: 스킬 그룹 | E1: 해금 돌파 등급 | F1: 서브 그룹 이름 | G1: 서브 그룹 아이콘 | H1: 스킬 이름 | I1: 캐릭터 이름
A2: ID | B2: CHARACTER_SKILL_GROUP | C2: CHARACTER_SKILL_SUB_GROUP | D2: SKILL_GROUP | E2: UNLOCK_AWAKE_LEVEL | F2: SUB_GROUP_NAME | G2: SUB_GROUP_ICON | H2: COMMENT | I2: COMMENT | K2: ※ 스킬 테이블은 따로 정리함
A3: int | B3: int | C3: int | D3: int | E3: int | F3: string | G3: string | H3: comment | I3: comment
A4: =10000000+B4*1000+RIGHT(C4,1)*100+COUNTIF($B$4:B4,B4) -> 11101101 | B4: =RIGHT(INDEX(CHARACTER!$A$4:$A$10,MATCH(I4,CHARACTER!$B$4:$B$10,0)),4) -> 1101 | C4: =B4*10+COUNTIF($B$4:B4,B4) -> 11011 | E4: 1 | F4: ="CHARACTER_SKILL_SUB_GROUP_NAME_"&C4 -> CHARACTER_SKILL_SUB_GROUP_NAME_11011 | G4: ="CHARACTER_SKILL_SUB_GROUP_ICON_"&C4 -> CHARACTER_SKILL_SUB_GROUP_ICON_11011 | H4: 캐릭터 1의 기본 스킬 | I4: 캐릭터 이름 1
A5: =10000000+B5*1000+RIGHT(C5,1)*100+COUNTIF($B$4:B5,B5) -> 11101202 | B5: =RIGHT(INDEX(CHARACTER!$A$4:$A$10,MATCH(I5,CHARACTER!$B$4:$B$10,0)),4) -> 1101 | C5: =B5*10+COUNTIF($B$4:B5,B5) -> 11012 | E5: 2 | F5: ="CHARACTER_SKILL_SUB_GROUP_NAME_"&C5 -> CHARACTER_SKILL_SUB_GROUP_NAME_11012 | G5: ="CHARACTER_SKILL_SUB_GROUP_ICON_"&C5 -> CHARACTER_SKILL_SUB_GROUP_ICON_11012 | H5: 캐릭터 1의 메인 스킬 | I5: 캐릭터 이름 1
A6: =10000000+B6*1000+RIGHT(C6,1)*100+COUNTIF($B$4:B6,B6) -> 11101303 | B6: =RIGHT(INDEX(CHARACTER!$A$4:$A$10,MATCH(I6,CHARACTER!$B$4:$B$10,0)),4) -> 1101 | C6: =B6*10+COUNTIF($B$4:B6,B6) -> 11013 | E6: 3 | F6: ="CHARACTER_SKILL_SUB_GROUP_NAME_"&C6 -> CHARACTER_SKILL_SUB_GROUP_NAME_11013 | G6: ="CHARACTER_SKILL_SUB_GROUP_ICON_"&C6 -> CHARACTER_SKILL_SUB_GROUP_ICON_11013 | H6: 캐릭터 1의 서브 스킬 | I6: 캐릭터 이름 1
A7: =10000000+B7*1000+RIGHT(C7,1)*100+COUNTIF($B$4:B7,B7) -> 11101404 | B7: =RIGHT(INDEX(CHARACTER!$A$4:$A$10,MATCH(I7,CHARACTER!$B$4:$B$10,0)),4) -> 1101 | C7: =B7*10+COUNTIF($B$4:B7,B7) -> 11014 | E7: 3 | F7: ="CHARACTER_SKILL_SUB_GROUP_NAME_"&C7 -> CHARACTER_SKILL_SUB_GROUP_NAME_11014 | G7: ="CHARACTER_SKILL_SUB_GROUP_ICON_"&C7 -> CHARACTER_SKILL_SUB_GROUP_ICON_11014 | H7: 캐릭터 1의 필살기 | I7: 캐릭터 이름 1
A8: =10000000+B8*1000+RIGHT(C8,1)*100+COUNTIF($B$4:B8,B8) -> 12201101 | B8: =RIGHT(INDEX(CHARACTER!$A$4:$A$10,MATCH(I8,CHARACTER!$B$4:$B$10,0)),4) -> 2201 | C8: =B8*10+COUNTIF($B$4:B8,B8) -> 22011 | E8: 1 | F8: ="CHARACTER_SKILL_SUB_GROUP_NAME_"&C8 -> CHARACTER_SKILL_SUB_GROUP_NAME_22011 | G8: ="CHARACTER_SKILL_SUB_GROUP_ICON_"&C8 -> CHARACTER_SKILL_SUB_GROUP_ICON_22011 | H8: 캐릭터 2의 기본 스킬 | I8: 캐릭터 이름 2
A9: =10000000+B9*1000+RIGHT(C9,1)*100+COUNTIF($B$4:B9,B9) -> 12201202 | B9: =RIGHT(INDEX(CHARACTER!$A$4:$A$10,MATCH(I9,CHARACTER!$B$4:$B$10,0)),4) -> 2201 | C9: =B9*10+COUNTIF($B$4:B9,B9) -> 22012 | E9: 2 | F9: ="CHARACTER_SKILL_SUB_GROUP_NAME_"&C9 -> CHARACTER_SKILL_SUB_GROUP_NAME_22012 | G9: ="CHARACTER_SKILL_SUB_GROUP_ICON_"&C9 -> CHARACTER_SKILL_SUB_GROUP_ICON_22012 | H9: 캐릭터 2의 메인 스킬 | I9: 캐릭터 이름 2
A10: =10000000+B10*1000+RIGHT(C10,1)*100+COUNTIF($B$4:B10,B10) -> 12201303 | B10: =RIGHT(INDEX(CHARACTER!$A$4:$A$10,MATCH(I10,CHARACTER!$B$4:$B$10,0)),4) -> 2201 | C10: =B10*10+COUNTIF($B$4:B10,B10) -> 22013 | E10: 3 | F10: ="CHARACTER_SKILL_SUB_GROUP_NAME_"&C10 -> CHARACTER_SKILL_SUB_GROUP_NAME_22013 | G10: ="CHARACTER_SKILL_SUB_GROUP_ICON_"&C10 -> CHARACTER_SKILL_SUB_GROUP_ICON_22013 | H10: 캐릭터 2의 서브 스킬 | I10: 캐릭터 이름 2
A11: =10000000+B11*1000+RIGHT(C11,1)*100+COUNTIF($B$4:B11,B11) -> 12201404 | B11: =RIGHT(INDEX(CHARACTER!$A$4:$A$10,MATCH(I11,CHARACTER!$B$4:$B$10,0)),4) -> 2201 | C11: =B11*10+COUNTIF($B$4:B11,B11) -> 22014 | E11: 3 | F11: ="CHARACTER_SKILL_SUB_GROUP_NAME_"&C11 -> CHARACTER_SKILL_SUB_GROUP_NAME_22014 | G11: ="CHARACTER_SKILL_SUB_GROUP_ICON_"&C11 -> CHARACTER_SKILL_SUB_GROUP_ICON_22014 | H11: 캐릭터 2의 필살기 | I11: 캐릭터 이름 2
A12: =10000000+B12*1000+RIGHT(C12,1)*100+COUNTIF($B$4:B12,B12) -> 13301101 | B12: =RIGHT(INDEX(CHARACTER!$A$4:$A$10,MATCH(I12,CHARACTER!$B$4:$B$10,0)),4) -> 3301 | C12: =B12*10+COUNTIF($B$4:B12,B12) -> 33011 | E12: 1 | F12: ="CHARACTER_SKILL_SUB_GROUP_NAME_"&C12 -> CHARACTER_SKILL_SUB_GROUP_NAME_33011 | G12: ="CHARACTER_SKILL_SUB_GROUP_ICON_"&C12 -> CHARACTER_SKILL_SUB_GROUP_ICON_33011 | I12: 캐릭터 이름 3
A13: =10000000+B13*1000+RIGHT(C13,1)*100+COUNTIF($B$4:B13,B13) -> 13301202 | B13: =RIGHT(INDEX(CHARACTER!$A$4:$A$10,MATCH(I13,CHARACTER!$B$4:$B$10,0)),4) -> 3301 | C13: =B13*10+COUNTIF($B$4:B13,B13) -> 33012 | E13: 2 | F13: ="CHARACTER_SKILL_SUB_GROUP_NAME_"&C13 -> CHARACTER_SKILL_SUB_GROUP_NAME_33012 | G13: ="CHARACTER_SKILL_SUB_GROUP_ICON_"&C13 -> CHARACTER_SKILL_SUB_GROUP_ICON_33012 | I13: 캐릭터 이름 3
A14: =10000000+B14*1000+RIGHT(C14,1)*100+COUNTIF($B$4:B14,B14) -> 13301303 | B14: =RIGHT(INDEX(CHARACTER!$A$4:$A$10,MATCH(I14,CHARACTER!$B$4:$B$10,0)),4) -> 3301 | C14: =B14*10+COUNTIF($B$4:B14,B14) -> 33013 | E14: 3 | F14: ="CHARACTER_SKILL_SUB_GROUP_NAME_"&C14 -> CHARACTER_SKILL_SUB_GROUP_NAME_33013 | G14: ="CHARACTER_SKILL_SUB_GROUP_ICON_"&C14 -> CHARACTER_SKILL_SUB_GROUP_ICON_33013 | I14: 캐릭터 이름 3
A15: =10000000+B15*1000+RIGHT(C15,1)*100+COUNTIF($B$4:B15,B15) -> 13301404 | B15: =RIGHT(INDEX(CHARACTER!$A$4:$A$10,MATCH(I15,CHARACTER!$B$4:$B$10,0)),4) -> 3301 | C15: =B15*10+COUNTIF($B$4:B15,B15) -> 33014 | E15: 3 | F15: ="CHARACTER_SKILL_SUB_GROUP_NAME_"&C15 -> CHARACTER_SKILL_SUB_GROUP_NAME_33014 | G15: ="CHARACTER_SKILL_SUB_GROUP_ICON_"&C15 -> CHARACTER_SKILL_SUB_GROUP_ICON_33014 | I15: 캐릭터 이름 3
A16: =10000000+B16*1000+RIGHT(C16,1)*100+COUNTIF($B$4:B16,B16) -> 11401101 | B16: =RIGHT(INDEX(CHARACTER!$A$4:$A$10,MATCH(I16,CHARACTER!$B$4:$B$10,0)),4) -> 1401 | C16: =B16*10+COUNTIF($B$4:B16,B16) -> 14011 | E16: 1 | F16: ="CHARACTER_SKILL_SUB_GROUP_NAME_"&C16 -> CHARACTER_SKILL_SUB_GROUP_NAME_14011 | G16: ="CHARACTER_SKILL_SUB_GROUP_ICON_"&C16 -> CHARACTER_SKILL_SUB_GROUP_ICON_14011 | I16: 캐릭터 이름 4
A17: =10000000+B17*1000+RIGHT(C17,1)*100+COUNTIF($B$4:B17,B17) -> 11401202 | B17: =RIGHT(INDEX(CHARACTER!$A$4:$A$10,MATCH(I17,CHARACTER!$B$4:$B$10,0)),4) -> 1401 | C17: =B17*10+COUNTIF($B$4:B17,B17) -> 14012 | E17: 2 | F17: ="CHARACTER_SKILL_SUB_GROUP_NAME_"&C17 -> CHARACTER_SKILL_SUB_GROUP_NAME_14012 | G17: ="CHARACTER_SKILL_SUB_GROUP_ICON_"&C17 -> CHARACTER_SKILL_SUB_GROUP_ICON_14012 | I17: 캐릭터 이름 4
A18: =10000000+B18*1000+RIGHT(C18,1)*100+COUNTIF($B$4:B18,B18) -> 11401303 | B18: =RIGHT(INDEX(CHARACTER!$A$4:$A$10,MATCH(I18,CHARACTER!$B$4:$B$10,0)),4) -> 1401 | C18: =B18*10+COUNTIF($B$4:B18,B18) -> 14013 | E18: 3 | F18: ="CHARACTER_SKILL_SUB_GROUP_NAME_"&C18 -> CHARACTER_SKILL_SUB_GROUP_NAME_14013 | G18: ="CHARACTER_SKILL_SUB_GROUP_ICON_"&C18 -> CHARACTER_SKILL_SUB_GROUP_ICON_14013 | I18: 캐릭터 이름 4
A19: =10000000+B19*1000+RIGHT(C19,1)*100+COUNTIF($B$4:B19,B19) -> 11401404 | B19: =RIGHT(INDEX(CHARACTER!$A$4:$A$10,MATCH(I19,CHARACTER!$B$4:$B$10,0)),4) -> 1401 | C19: =B19*10+COUNTIF($B$4:B19,B19) -> 14014 | E19: 3 | F19: ="CHARACTER_SKILL_SUB_GROUP_NAME_"&C19 -> CHARACTER_SKILL_SUB_GROUP_NAME_14014 | G19: ="CHARACTER_SKILL_SUB_GROUP_ICON_"&C19 -> CHARACTER_SKILL_SUB_GROUP_ICON_14014 | I19: 캐릭터 이름 4
A20: =10000000+B20*1000+RIGHT(C20,1)*100+COUNTIF($B$4:B20,B20) -> 12101101 | B20: =RIGHT(INDEX(CHARACTER!$A$4:$A$10,MATCH(I20,CHARACTER!$B$4:$B$10,0)),4) -> 2101 | C20: =B20*10+COUNTIF($B$4:B20,B20) -> 21011 | E20: 1 | F20: ="CHARACTER_SKILL_SUB_GROUP_NAME_"&C20 -> CHARACTER_SKILL_SUB_GROUP_NAME_21011 | G20: ="CHARACTER_SKILL_SUB_GROUP_ICON_"&C20 -> CHARACTER_SKILL_SUB_GROUP_ICON_21011 | I20: 캐릭터 이름 5
A21: =10000000+B21*1000+RIGHT(C21,1)*100+COUNTIF($B$4:B21,B21) -> 12101202 | B21: =RIGHT(INDEX(CHARACTER!$A$4:$A$10,MATCH(I21,CHARACTER!$B$4:$B$10,0)),4) -> 2101 | C21: =B21*10+COUNTIF($B$4:B21,B21) -> 21012 | E21: 2 | F21: ="CHARACTER_SKILL_SUB_GROUP_NAME_"&C21 -> CHARACTER_SKILL_SUB_GROUP_NAME_21012 | G21: ="CHARACTER_SKILL_SUB_GROUP_ICON_"&C21 -> CHARACTER_SKILL_SUB_GROUP_ICON_21012 | I21: 캐릭터 이름 5
A22: =10000000+B22*1000+RIGHT(C22,1)*100+COUNTIF($B$4:B22,B22) -> 12101303 | B22: =RIGHT(INDEX(CHARACTER!$A$4:$A$10,MATCH(I22,CHARACTER!$B$4:$B$10,0)),4) -> 2101 | C22: =B22*10+COUNTIF($B$4:B22,B22) -> 21013 | E22: 3 | F22: ="CHARACTER_SKILL_SUB_GROUP_NAME_"&C22 -> CHARACTER_SKILL_SUB_GROUP_NAME_21013 | G22: ="CHARACTER_SKILL_SUB_GROUP_ICON_"&C22 -> CHARACTER_SKILL_SUB_GROUP_ICON_21013 | I22: 캐릭터 이름 5
A23: =10000000+B23*1000+RIGHT(C23,1)*100+COUNTIF($B$4:B23,B23) -> 12101404 | B23: =RIGHT(INDEX(CHARACTER!$A$4:$A$10,MATCH(I23,CHARACTER!$B$4:$B$10,0)),4) -> 2101 | C23: =B23*10+COUNTIF($B$4:B23,B23) -> 21014 | E23: 3 | F23: ="CHARACTER_SKILL_SUB_GROUP_NAME_"&C23 -> CHARACTER_SKILL_SUB_GROUP_NAME_21014 | G23: ="CHARACTER_SKILL_SUB_GROUP_ICON_"&C23 -> CHARACTER_SKILL_SUB_GROUP_ICON_21014 | I23: 캐릭터 이름 5
... A31: =10000000+B31*1000+RIGHT(C31,1)*100+COUNTIF($B$4:B31,B31) -> 13302404 | B31: =RIGHT(INDEX(CHARACTER!$A$4:$A$10,MATCH(I31,CHARACTER!$B$4:$B$10,0)),4) -> 3302 | C31: =B31*10+COUNTIF($B$4:B31,B31) -> 33024 | E31: 3 | F31: ="CHARACTER_SKILL_SUB_GROUP_NAME_"&C31 -> CHARACTER_SKILL_SUB_GROUP_NAME_33024 | G31: ="CHARACTER_SKILL_SUB_GROUP_ICON_"&C31 -> CHARACTER_SKILL_SUB_GROUP_ICON_33024 | I31: 캐릭터 이름 7

Sheet AWAKE_GROUP
A1: 아이디 | B1: 돌파 그룹 | C1: 돌파 등급 | D1: 영혼석 개수 | E1: 필요 골드 | F1: 능력치 ID | G1: 최대 호감도 레벨 | H1: #참조
A2: ID | B2: AWAKE_GROUP | C2: AWAKE_LEVEL | D2: NEED_PIECE_COUNT | E2: NEED_GOLD | F2: STATUS_ID | G2: MAX_AFFECTION_LEVEL | H2: COMMENT
A3: int | B3: int | C3: int | D3: int | E3: int | F3: int | G3: int | H3: comment
A4: =100000+B4*10+C4 -> 111011 | B4: =RIGHT(INDEX(CHARACTER!$A$4:$A$10,MATCH(AWAKE_GROUP!H4,CHARACTER!$B$4:$B$10,0)),4) -> 1101 | C4: 1 | D4: 30 | E4: 10000 | F4: 111101 | G4: 10 | H4: 캐릭터 이름 1
A5: =100000+B5*10+C5 -> 111012 | B5: =RIGHT(INDEX(CHARACTER!$A$4:$A$10,MATCH(AWAKE_GROUP!H5,CHARACTER!$B$4:$B$10,0)),4) -> 1101 | C5: 2 | D5: 50 | E5: 40000 | F5: 122201 | G5: 10 | H5: 캐릭터 이름 1
A6: =100000+B6*10+C6 -> 111013 | B6: =RIGHT(INDEX(CHARACTER!$A$4:$A$10,MATCH(AWAKE_GROUP!H6,CHARACTER!$B$4:$B$10,0)),4) -> 1101 | C6: 3 | D6: 80 | E6: 90000 | F6: 133301 | G6: 20 | H6: 캐릭터 이름 1
A7: =100000+B7*10+C7 -> 111014 | B7: =RIGHT(INDEX(CHARACTER!$A$4:$A$10,MATCH(AWAKE_GROUP!H7,CHARACTER!$B$4:$B$10,0)),4) -> 1101 | C7: 4 | D7: 100 | E7: 200000 | F7: 141401 | G7: 20 | H7: 캐릭터 이름 1
A8: =100000+B8*10+C8 -> 111015 | B8: =RIGHT(INDEX(CHARACTER!$A$4:$A$10,MATCH(AWAKE_GROUP!H8,CHARACTER!$B$4:$B$10,0)),4) -> 1101 | C8: 5 | D8: 120 | E8: 1000000 | F8: 112101 | G8: 100 | H8: 캐릭터 이름 1
A9: =100000+B9*10+C9 -> 111016 | B9: =RIGHT(INDEX(CHARACTER!$A$4:$A$10,MATCH(AWAKE_GROUP!H9,CHARACTER!$B$4:$B$10,0)),4) -> 1101 | C9: 6 | D9: 0 | E9: 0 | F9: 123201 | G9: 0 | H9: 캐릭터 이름 1
A10: =100000+B10*10+C10 -> 122012 | B10: =RIGHT(INDEX(CHARACTER!$A$4:$A$10,MATCH(AWAKE_GROUP!H10,CHARACTER!$B$4:$B$10,0)),4) -> 2201 | C10: 2 | D10: 50 | E10: 40000 | G10: 10 | H10: 캐릭터 이름 2
A11: =100000+B11*10+C11 -> 122013 | B11: =RIGHT(INDEX(CHARACTER!$A$4:$A$10,MATCH(AWAKE_GROUP!H11,CHARACTER!$B$4:$B$10,0)),4) -> 2201 | C11: 3 | D11: 80 | E11: 90000 | G11: 20 | H11: 캐릭터 이름 2
A12: =100000+B12*10+C12 -> 122014 | B12: =RIGHT(INDEX(CHARACTER!$A$4:$A$10,MATCH(AWAKE_GROUP!H12,CHARACTER!$B$4:$B$10,0)),4) -> 2201 | C12: 4 | D12: 100 | E12: 200000 | G12: 20 | H12: 캐릭터 이름 2
A13: =100000+B13*10+C13 -> 122015 | B13: =RIGHT(INDEX(CHARACTER!$A$4:$A$10,MATCH(AWAKE_GROUP!H13,CHARACTER!$B$4:$B$10,0)),4) -> 2201 | C13: 5 | D13: 120 | E13: 1000000 | G13: 100 | H13: 캐릭터 이름 2
A14: =100000+B14*10+C14 -> 122016 | B14: =RIGHT(INDEX(CHARACTER!$A$4:$A$10,MATCH(AWAKE_GROUP!H14,CHARACTER!$B$4:$B$10,0)),4) -> 2201 | C14: 6 | D14: 0 | E14: 0 | G14: 0 | H14: 캐릭터 이름 2
A15: =100000+B15*10+C15 -> 133013 | B15: =RIGHT(INDEX(CHARACTER!$A$4:$A$10,MATCH(AWAKE_GROUP!H15,CHARACTER!$B$4:$B$10,0)),4) -> 3301 | C15: 3 | D15: 80 | E15: 90000 | G15: 20 | H15: 캐릭터 이름 3
A16: =100000+B16*10+C16 -> 133014 | B16: =RIGHT(INDEX(CHARACTER!$A$4:$A$10,MATCH(AWAKE_GROUP!H16,CHARACTER!$B$4:$B$10,0)),4) -> 3301 | C16: 4 | D16: 100 | E16: 200000 | G16: 20 | H16: 캐릭터 이름 3
A17: =100000+B17*10+C17 -> 133015 | B17: =RIGHT(INDEX(CHARACTER!$A$4:$A$10,MATCH(AWAKE_GROUP!H17,CHARACTER!$B$4:$B$10,0)),4) -> 3301 | C17: 5 | D17: 120 | E17: 1000000 | G17: 100 | H17: 캐릭터 이름 3
A18: =100000+B18*10+C18 -> 133016 | B18: =RIGHT(INDEX(CHARACTER!$A$4:$A$10,MATCH(AWAKE_GROUP!H18,CHARACTER!$B$4:$B$10,0)),4) -> 3301 | C18: 6 | D18: 0 | E18: 0 | G18: 0 | H18: 캐릭터 이름 3
A19: =100000+B19*10+C19 -> 114011 | B19: =RIGHT(INDEX(CHARACTER!$A$4:$A$10,MATCH(AWAKE_GROUP!H19,CHARACTER!$B$4:$B$10,0)),4) -> 1401 | C19: 1 | D19: 30 | E19: 10000 | G19: 10 | H19: 캐릭터 이름 4
A20: =100000+B20*10+C20 -> 114012 | B20: =RIGHT(INDEX(CHARACTER!$A$4:$A$10,MATCH(AWAKE_GROUP!H20,CHARACTER!$B$4:$B$10,0)),4) -> 1401 | C20: 2 | D20: 50 | E20: 40000 | G20: 10 | H20: 캐릭터 이름 4
A21: =100000+B21*10+C21 -> 114013 | B21: =RIGHT(INDEX(CHARACTER!$A$4:$A$10,MATCH(AWAKE_GROUP!H21,CHARACTER!$B$4:$B$10,0)),4) -> 1401 | C21: 3 | D21: 80 | E21: 90000 | G21: 20 | H21: 캐릭터 이름 4
... A37: =100000+B37*10+C37 -> 133026 | B37: =RIGHT(INDEX(CHARACTER!$A$4:$A$10,MATCH(AWAKE_GROUP!H37,CHARACTER!$B$4:$B$10,0)),4) -> 3302 | C37: 6 | D37: 0 | E37: 0 | G37: 0 | H37: 캐릭터 이름 7

Sheet CHARACTER_EXP
A1: 아이디 | B1: 캐릭터 성장 그룹 | C1: 캐릭터 레벨 단계 | D1: 필요 경험치 | E1: 필요 골드 | F1: 공격력 | G1: 방어력 | H1: 체력 | I1: #참조
A2: ID | B2: CHARACTER_EXP_GROUP | C2: CHARACTER_LEVEL | D2: NEED_EXP | E2: NEED_GOLD | F2: ATTACK | G2: DEFFENCE | H2: HP | I2: COMMENT
A3: int | B3: int | C3: int | D3: int | E3: int | F3: int | G3: int | H3: int | I3: comment
A4: =10000000+B4*1000+C4 -> 11101001 | B4: =RIGHT(INDEX(CHARACTER!$A$4:$A$10,MATCH(CHARACTER_EXP!I4,CHARACTER!$B$4:$B$10,0)),4) -> 1101 | C4: 1 | I4: 캐릭터 이름 1
A5: =10000000+B5*1000+C5 -> 11101002 | B5: =RIGHT(INDEX(CHARACTER!$A$4:$A$10,MATCH(CHARACTER_EXP!I5,CHARACTER!$B$4:$B$10,0)),4) -> 1101 | C5: 2 | I5: 캐릭터 이름 1
A6: =10000000+B6*1000+C6 -> 11101003 | B6: =RIGHT(INDEX(CHARACTER!$A$4:$A$10,MATCH(CHARACTER_EXP!I6,CHARACTER!$B$4:$B$10,0)),4) -> 1101 | C6: 3 | I6: 캐릭터 이름 1
A7: =10000000+B7*1000+C7 -> 11101004 | B7: =RIGHT(INDEX(CHARACTER!$A$4:$A$10,MATCH(CHARACTER_EXP!I7,CHARACTER!$B$4:$B$10,0)),4) -> 1101 | C7: 4 | I7: 캐릭터 이름 1
A8: =10000000+B8*1000+C8 -> 11101005 | B8: =RIGHT(INDEX(CHARACTER!$A$4:$A$10,MATCH(CHARACTER_EXP!I8,CHARACTER!$B$4:$B$10,0)),4) -> 1101 | C8: 5 | I8: 캐릭터 이름 1
A9: =10000000+B9*1000+C9 -> 11101006 | B9: =RIGHT(INDEX(CHARACTER!$A$4:$A$10,MATCH(CHARACTER_EXP!I9,CHARACTER!$B$4:$B$10,0)),4) -> 1101 | C9: 6 | I9: 캐릭터 이름 1
A10: =10000000+B10*1000+C10 -> 11101007 | B10: =RIGHT(INDEX(CHARACTER!$A$4:$A$10,MATCH(CHARACTER_EXP!I10,CHARACTER!$B$4:$B$10,0)),4) -> 1101 | C10: 7 | I10: 캐릭터 이름 1
A11: =10000000+B11*1000+C11 -> 11101008 | B11: =RIGHT(INDEX(CHARACTER!$A$4:$A$10,MATCH(CHARACTER_EXP!I11,CHARACTER!$B$4:$B$10,0)),4) -> 1101 | C11: 8 | I11: 캐릭터 이름 1
A12: =10000000+B12*1000+C12 -> 11101009 | B12: =RIGHT(INDEX(CHARACTER!$A$4:$A$10,MATCH(CHARACTER_EXP!I12,CHARACTER!$B$4:$B$10,0)),4) -> 1101 | C12: 9 | I12: 캐릭터 이름 1
A13: =10000000+B13*1000+C13 -> 11101010 | B13: =RIGHT(INDEX(CHARACTER!$A$4:$A$10,MATCH(CHARACTER_EXP!I13,CHARACTER!$B$4:$B$10,0)),4) -> 1101 | C13: 10 | I13: 캐릭터 이름 1
A14: =10000000+B14*1000+C14 -> 11101011 | B14: =RIGHT(INDEX(CHARACTER!$A$4:$A$10,MATCH(CHARACTER_EXP!I14,CHARACTER!$B$4:$B$10,0)),4) -> 1101 | C14: 11 | I14: 캐릭터 이름 1
A15: =10000000+B15*1000+C15 -> 11101012 | B15: =RIGHT(INDEX(CHARACTER!$A$4:$A$10,MATCH(CHARACTER_EXP!I15,CHARACTER!$B$4:$B$10,0)),4) -> 1101 | C15: 12 | I15: 캐릭터 이름 1
... A703: =10000000+B703*1000+C703 -> 13302100 | B703: =RIGHT(INDEX(CHARACTER!$A$4:$A$10,MATCH(CHARACTER_EXP!I703,CHARACTER!$B$4:$B$10,0)),4) -> 3302 | C703: 100 | I703: 캐릭터 이름 7

Sheet AFFECTION_EXP
A1: 아이디 | B1: 호감도 레벨 단계 | C1: 필요 호감도 경험치 | D1: 능력치 ID
A2: ID | B2: AFFECTION_LEVEL | C2: NEED_AFFECTION_EXP | D2: STATUS_ID
A3: int | B3: int | C3: int | D3: int
A4: 1 | B4: 1 | D4: 111101
A5: 2 | B5: 2 | D5: 122201
A6: 3 | B6: 3 | D6: 133301
A7: 4 | B7: 4 | D7: 141401
A8: 5 | B8: 5 | D8: 112101
A9: 6 | B9: 6 | D9: 123201
A10: 7 | B10: 7 | D10: 133302
A11: 8 | B11: 8
A12: 9 | B12: 9
A13: 10 | B13: 10
A14: 11 | B14: 11
A15: 12 | B15: 12
A16: 13 | B16: 13
A17: 14 | B17: 14
A18: 15 | B18: 15
A19: 16 | B19: 16
A20: 17 | B20: 17
A21: 18 | B21: 18
A22: 19 | B22: 19
... A103: 100 | B103: 100

Sheet AFFECTION_ITEM
A1: 아이디 | B1: 애용품 그룹 | C1: 등급 | D1: 필요 호감도 레벨 | E1: 능력치 ID | F1: 강화 스킬 그룹 | G1: 애용품 이름 | H1: 애용품 이미지 | I1: 애용품 설명 | J1: 애용품 이름 | K1: 사용 캐릭터 이름
A2: ID | B2: AFFECTION_ITEM_GROUP | C2: RARITY | D2: NEED_AFFECTION_LEVEL | E2: STATUS_ID | F2: CHARACTER_SKILL_GROUP | G2: AFFECTION_ITEM_NAME | H2: AFFECTION_ITEM_IMAGE | I2: AFFECTION_ITEM_DESC | J2: COMMENT | K2: COMMENT
A3: int | B3: int | C3: int | D3: int | E3: int | F3: int | G3: string | H3: string | I3: string | J3: comment | K3: comment
A4: =B4*10+C4 -> 111011 | B4: =10000+RIGHT(INDEX(CHARACTER!$A$4:$A$10,MATCH(K4,CHARACTER!$B$4:$B$10,0)),4) -> 11101 | C4: 1 | D4: 20 | G4: ="AFFECTION_ITEM_NAME_"&B4 -> AFFECTION_ITEM_NAME_11101 | H4: ="AFFECTION_ITEM_IMAGE_"&B4 -> AFFECTION_ITEM_IMAGE_11101 | I4: ="AFFECTION_ITEM_DESC_"&B4 -> AFFECTION_ITEM_DESC_11101 | J4: 애용품 이름 1 | K4: 캐릭터 이름 1
A5: =B5*10+C5 -> 111012 | B5: =10000+RIGHT(INDEX(CHARACTER!$A$4:$A$10,MATCH(K5,CHARACTER!$B$4:$B$10,0)),4) -> 11101 | C5: 2 | D5: 40 | G5: ="AFFECTION_ITEM_NAME_"&B5 -> AFFECTION_ITEM_NAME_11101 | H5: ="AFFECTION_ITEM_IMAGE_"&B5 -> AFFECTION_ITEM_IMAGE_11101 | I5: ="AFFECTION_ITEM_DESC_"&B5 -> AFFECTION_ITEM_DESC_11101 | J5: 애용품 이름 1 | K5: 캐릭터 이름 1
A6: =B6*10+C6 -> 122011 | B6: =10000+RIGHT(INDEX(CHARACTER!$A$4:$A$10,MATCH(K6,CHARACTER!$B$4:$B$10,0)),4) -> 12201 | C6: 1 | D6: 20 | G6: ="AFFECTION_ITEM_NAME_"&B6 -> AFFECTION_ITEM_NAME_12201 | H6: ="AFFECTION_ITEM_IMAGE_"&B6 -> AFFECTION_ITEM_IMAGE_12201 | I6: ="AFFECTION_ITEM_DESC_"&B6 -> AFFECTION_ITEM_DESC_12201 | J6: 애용품 이름 2 | K6: 캐릭터 이름 2
A7: =B7*10+C7 -> 122012 | B7: =10000+RIGHT(INDEX(CHARACTER!$A$4:$A$10,MATCH(K7,CHARACTER!$B$4:$B$10,0)),4) -> 12201 | C7: 2 | D7: 40 | G7: ="AFFECTION_ITEM_NAME_"&B7 -> AFFECTION_ITEM_NAME_12201 | H7: ="AFFECTION_ITEM_IMAGE_"&B7 -> AFFECTION_ITEM_IMAGE_12201 | I7: ="AFFECTION_ITEM_DESC_"&B7 -> AFFECTION_ITEM_DESC_12201 | J7: 애용품 이름 2 | K7: 캐릭터 이름 2
A8: =B8*10+C8 -> 133011 | B8: =10000+RIGHT(INDEX(CHARACTER!$A$4:$A$10,MATCH(K8,CHARACTER!$B$4:$B$10,0)),4) -> 13301 | C8: 1 | D8: 20 | G8: ="AFFECTION_ITEM_NAME_"&B8 -> AFFECTION_ITEM_NAME_13301 | H8: ="AFFECTION_ITEM_IMAGE_"&B8 -> AFFECTION_ITEM_IMAGE_13301 | I8: ="AFFECTION_ITEM_DESC_"&B8 -> AFFECTION_ITEM_DESC_13301 | J8: 애용품 이름 3 | K8: 캐릭터 이름 3
A9: =B9*10+C9 -> 133012 | B9: =10000+RIGHT(INDEX(CHARACTER!$A$4:$A$10,MATCH(K9,CHARACTER!$B$4:$B$10,0)),4) -> 13301 | C9: 2 | D9: 40 | G9: ="AFFECTION_ITEM_NAME_"&B9 -> AFFECTION_ITEM_NAME_13301 | H9: ="AFFECTION_ITEM_IMAGE_"&B9 -> AFFECTION_ITEM_IMAGE_13301 | I9: ="AFFECTION_ITEM_DESC_"&B9 -> AFFECTION_ITEM_DESC_13301 | J9: 애용품 이름 3 | K9: 캐릭터 이름 3
A10: =B10*10+C10 -> 114011 | B10: =10000+RIGHT(INDEX(CHARACTER!$A$4:$A$10,MATCH(K10,CHARACTER!$B$4:$B$10,0)),4) -> 11401 | C10: 1 | D10: 20 | G10: ="AFFECTION_ITEM_NAME_"&B10 -> AFFECTION_ITEM_NAME_11401 | H10: ="AFFECTION_ITEM_IMAGE_"&B10 -> AFFECTION_ITEM_IMAGE_11401 | I10: ="AFFECTION_ITEM_DESC_"&B10 -> AFFECTION_ITEM_DESC_11401 | J10: 애용품 이름 4 | K10: 캐릭터 이름 4
A11: =B11*10+C11 -> 114012 | B11: =10000+RIGHT(INDEX(CHARACTER!$A$4:$A$10,MATCH(K11,CHARACTER!$B$4:$B$10,0)),4) -> 11401 | C11: 2 | D11: 40 | G11: ="AFFECTION_ITEM_NAME_"&B11 -> AFFECTION_ITEM_NAME_11401 | H11: ="AFFECTION_ITEM_IMAGE_"&B11 -> AFFECTION_ITEM_IMAGE_11401 | I11: ="AFFECTION_ITEM_DESC_"&B11 -> AFFECTION_ITEM_DESC_11401 | J11: 애용품 이름 4 | K11: 캐릭터 이름 4
A12: =B12*10+C12 -> 121011 | B12: =10000+RIGHT(INDEX(CHARACTER!$A$4:$A$10,MATCH(K12,CHARACTER!$B$4:$B$10,0)),4) -> 12101 | C12: 1 | D12: 20 | G12: ="AFFECTION_ITEM_NAME_"&B12 -> AFFECTION_ITEM_NAME_12101 | H12: ="AFFECTION_ITEM_IMAGE_"&B12 -> AFFECTION_ITEM_IMAGE_12101 | I12: ="AFFECTION_ITEM_DESC_"&B12 -> AFFECTION_ITEM_DESC_12101 | J12: 애용품 이름 5 | K12: 캐릭터 이름 5
A13: =B13*10+C13 -> 121012 | B13: =10000+RIGHT(INDEX(CHARACTER!$A$4:$A$10,MATCH(K13,CHARACTER!$B$4:$B$10,0)),4) -> 12101 | C13: 2 | D13: 40 | G13: ="AFFECTION_ITEM_NAME_"&B13 -> AFFECTION_ITEM_NAME_12101 | H13: ="AFFECTION_ITEM_IMAGE_"&B13 -> AFFECTION_ITEM_IMAGE_12101 | I13: ="AFFECTION_ITEM_DESC_"&B13 -> AFFECTION_ITEM_DESC_12101 | J13: 애용품 이름 5 | K13: 캐릭터 이름 5
A14: =B14*10+C14 -> 132011 | B14: =10000+RIGHT(INDEX(CHARACTER!$A$4:$A$10,MATCH(K14,CHARACTER!$B$4:$B$10,0)),4) -> 13201 | C14: 1 | D14: 20 | G14: ="AFFECTION_ITEM_NAME_"&B14 -> AFFECTION_ITEM_NAME_13201 | H14: ="AFFECTION_ITEM_IMAGE_"&B14 -> AFFECTION_ITEM_IMAGE_13201 | I14: ="AFFECTION_ITEM_DESC_"&B14 -> AFFECTION_ITEM_DESC_13201 | J14: 애용품 이름 6 | K14: 캐릭터 이름 6
A15: =B15*10+C15 -> 132012 | B15: =10000+RIGHT(INDEX(CHARACTER!$A$4:$A$10,MATCH(K15,CHARACTER!$B$4:$B$10,0)),4) -> 13201 | C15: 2 | D15: 40 | G15: ="AFFECTION_ITEM_NAME_"&B15 -> AFFECTION_ITEM_NAME_13201 | H15: ="AFFECTION_ITEM_IMAGE_"&B15 -> AFFECTION_ITEM_IMAGE_13201 | I15: ="AFFECTION_ITEM_DESC_"&B15 -> AFFECTION_ITEM_DESC_13201 | J15: 애용품 이름 6 | K15: 캐릭터 이름 6

Sheet AFFECTION_GAIN
A1: 아이디 | B1: 호감도 획득처 타입 | C1: 호감도 획득처 값 | D1: 호감도 상승 값_기본
A2: ID | B2: AFFECTION_GAIN_TYPE | C2: AFFECTION_GAIN_PARAM | D2: DEFAULT_AFFECTION_PARAM
A3: int | B3: int | C3: int | D3: int
A4: 1 | D4: 100
A5: 2 | D5: 60
A6: 3 | D6: 20
A7: 4 | D7: 4
A8: 5
A9: 6
A10: 7
A11: 8
A12: 9
A13: 10
B15: 0 NONE | C15: → 0
B16: 1 선물 | C16: → 아이템 ID
B17: 2 스테이지 클리어 | C17: → 스테이지 ID
B18: 3 퀘스트 | C18: → 퀘스트 ID

Sheet AFFECTION_PREF
A1: 아이디 | B1: 선호 선물 그룹 | C1: 아이템 ID | D1: 선호도 타입 | E1: 호감도 상승 값_배수 | F1: 캐릭터 이름
A2: ID | B2: AFFECTION_PREF_GROUP | C2: ITEM_ID | D2: PREFERENCE_TYPE | E2: MULTIPLIER_AFFECTION_PARAM | F2: COMMENT
A3: int | B3: int | C3: int | D3: int | E3: float | F3: comment
A4: 1 | D4: 1 | E4: 2 | F4: 캐릭터 이름 1
A5: 2 | D5: 2 | E5: 1.5 | F5: 캐릭터 이름 1
A6: 3 | D6: 3 | E6: 1 | F6: 캐릭터 이름 1
A7: 4 | D7: 4 | E7: 0.5 | F7: 캐릭터 이름 1
A8: 5 | F8: 캐릭터 이름 1
A9: 6 | F9: 캐릭터 이름 1
A10: 7 | F10: 캐릭터 이름 1
A11: 8 | F11: 캐릭터 이름 1
A12: 9 | F12: 캐릭터 이름 1
A13: 10 | F13: 캐릭터 이름 1
D15: 0 NONE
D16: 1 사랑하는 선물
D17: 2 좋아하는 선물
D18: 3 중립적인 선물
D19: 4 싫어하는 선물

Sheet SPEECH
A1: 아이디 | B1: 캐릭터 대사 그룹 | C1: 대사 타입 | D1: 대사 이름 | E1: 캐릭터 오디오 파일 경로
A2: ID | B2: SPEECH_GROUP | C2: SPEECH_TYPE | D2: SPEECH_NAME | E2: CHARACTER_AUDIO
A3: int | B3: int | C3: int | D3: string | E3: string
A4: 1 | B4: 1
A5: 2 | B5: 1
A6: 3 | B6: 1
A7: 4 | B7: 1
A8: 5 | B8: 1
A9: 6 | B9: 1
A10: 7 | B10: 1
